Workbook

Sheet BOM new
A1: No. | C1: 母件料号 Parent Item Code | D1: 母件料名 Parent Item Name | E1: 子件项次 Child Item Code | F1: 子项 Child Item Name | G1: 工序号( công đoạn sẽ trừ NVL) | H1: 用量 Dosage | I1: 母件底数 Parent Item Quantity | J1: 用量单位 UOM | K1: 损耗类型 | L1: 固定损耗 | M1: 变动损耗 | N1: BOM子项_从数量 | O1: BOM子项_到数量
C2: Parent code | D2: parent name | E2: Child | F2: Chind name | G2: Công đoan | H2: tiêu hao
A3: 1 (Hosiden) | C3: 120394 | D3: PK Hosiden HEG Cover HGU0810-27PW(3) | E3: 301612 | F3: CNC Hosiden HEG Stand Cover HGU0810-27PW(3) | G3: Polishing | H3: 1 | I3: 1 | J3: PCS | P3: =VLOOKUP(C3,COSTING!C270:D319,2,0) -> #N/A
C4: 120394 | D4: PK Hosiden HEG Cover HGU0810-27PW(3) | E4: 800832 | F4: PE bag 177*58*27 | G4: Packing | H4: 1 | I4: 1 | J4: EA | P4: =VLOOKUP(C4,COSTING!C271:D536,2,0) -> #N/A
C5: 301612 | D5: CNC Hosiden HEG Stand Cover HGU0810-27PW(3) | E5: 210351 | F5: CA Hosiden HGU0810-270120 Stand Cover | G5: CNC 1 | H5: 1 | I5: 1 | J5: PCS | P5: =VLOOKUP(C5,COSTING!C272:D536,2,0) -> #N/A
C6: 210351 | D6: CA Hosiden HGU0810-270120 Stand Cover | E6: 760010 | F6: Hợp kim maggie 2190W AZ91D để chế tạo khung xương điện thoại di động, kt 60x10x5cm | G6: Casting | H6: 0.13853 | I6: 1 | J6: KG | P6: =VLOOKUP(C6,COSTING!C273:D536,2,0) -> #N/A
A7: 2 (Hyoseong) | C7: 120424 | D7: PK HYOSEONG MQ4 T33 Coupling Base Cover H0345034C00 | E7: 301646 | F7: CNC HYOSEONG MQ4 T33 Coupling Base Cover H0345034C00 | G7: Cleaning | H7: 1 | I7: 1 | J7: PCS | P7: =VLOOKUP(C7,COSTING!C274:D536,2,0) -> #N/A
C8: 120424 | D8: PK HYOSEONG MQ4 T33 Coupling Base Cover H0345034C00 | E8: 762259 | F8: Carton tray IN/YLR 44 3 plates 2 surface yellow/Khay carton ba lớp hai mặt vàng IN/YLR44 525*350*85 | G8: Packing | H8: 0.02381 | I8: 1 | J8: EA | P8: =VLOOKUP(C8,COSTING!C275:D536,2,0) -> #N/A
C9: 120424 | D9: PK HYOSEONG MQ4 T33 Coupling Base Cover H0345034C00 | E9: 800837 | F9: Devide pad BR80-5R/Vách dài MQ4 (5 khía) 501x75mm | G9: Packing | H9: 0.08658 | I9: 1 | J9: EA | P9: =VLOOKUP(C9,COSTING!C276:D536,2,0) -> #N/A
C10: 120424 | D10: PK HYOSEONG MQ4 T33 Coupling Base Cover H0345034C00 | E10: 800838 | F10: Devide pad BR81-6R/Vách ngắn MQ4 (6 khía) 340x75mm | G10: Packing | H10: 0.103896 | I10: 1 | J10: EA | P10: =VLOOKUP(C10,COSTING!C277:D536,2,0) -> #N/A
C11: 301646 | D11: CNC HYOSEONG MQ4 T33 Coupling Base Cover H0345034C00 | E11: 210381 | F11: CA HYOSEONG MQ4 T33 Coupling Base Cover H0345034C00 | G11: CNC 1 | H11: 1 | I11: 1 | J11: PCS | P11: =VLOOKUP(C11,COSTING!C277:D536,2,0) -> #N/A
C12: 210381 | D12: CA HYOSEONG MQ4 T33 Coupling Base Cover H0345034C00 | E12: 762802 | F12: Aluminium ALDCS 12 Fe 0.9%-Nhôm thỏi ALDC12 thành phần Fe 0.9% | G12: Casting | H12: 0.27061 | I12: 1 | J12: KG | P12: =VLOOKUP(C12,COSTING!C278:D536,2,0) -> #N/A
A13: 3 (Hyoseong) | C13: 120423 | D13: PK HYOSEONG GEN5 STATOR BLOCK SOLO H1000004C01 | E13: 301645 | F13: CNC HYOSEONG GEN5 STATOR BLOCK SOLO H1000004C01 | G13: Cleaning | H13: 1 | I13: 1 | J13: PCS | P13: =VLOOKUP(C13,COSTING!C279:D536,2,0) -> PK HYOSEONG GEN5 STATOR BLOCK SOLO H1000004C01
C14: 120423 | D14: PK HYOSEONG GEN5 STATOR BLOCK SOLO H1000004C01 | E14: 762599 | F14: Carton box 3 plates YLR63/Thùng carton 3 lớp 1V5 Cover 528*352*104mm | G14: Packing | H14: 0.03571 | I14: 1 | J14: EA | P14: =VLOOKUP(C14,COSTING!C280:D536,2,0) -> PK HYOSEONG GEN5 STATOR BLOCK SOLO H1000004C01
C15: 120423 | D15: PK HYOSEONG GEN5 STATOR BLOCK SOLO H1000004C01 | E15: 800839 | F15: Devide pad BR82-3R/vách dài gen 5 (3 khía) sz 504x101mm | G15: Packing | H15: 0.21428 | I15: 1 | J15: EA | P15: =VLOOKUP(C15,COSTING!C515:D536,2,0) -> #N/A
C16: 120423 | D16: PK HYOSEONG GEN5 STATOR BLOCK SOLO H1000004C01 | E16: 800840 | F16: Devide pad BR83-6R/Vách ngắn gen 5 (6 khía) kt 342x101mm | G16: Packing | H16: 0.10714 | I16: 1 | J16: EA | P16: =VLOOKUP(C16,COSTING!C280:D536,2,0) -> PK HYOSEONG GEN5 STATOR BLOCK SOLO H1000004C01
C17: 301645 | D17: CNC HYOSEONG GEN5 STATOR BLOCK SOLO H1000004C01 | E17: 210380 | F17: CA HYOSEONG GEN5 STATOR BLOCK SOLO H1000004C01 | G17: CNC 1 | H17: 1 | I17: 1 | J17: PCS | P17: =VLOOKUP(C17,COSTING!C280:D536,2,0) -> #N/A
C18: 210380 | D18: CA HYOSEONG GEN5 STATOR BLOCK SOLO H1000004C01 | E18: 762802 | F18: Aluminium ALDCS 12 Fe 0.9%-Nhôm thỏi ALDC12 thành phần Fe 0.9% | G18: Casting | H18: 0.22936 | I18: 1 | J18: KG | P18: =VLOOKUP(C18,COSTING!C280:D536,2,0) -> #N/A
A19: 4 LG | C19: 120168 | D19: PK OMS ENTRY LENS HOLDER 3CAC00203A | E19: 301189 | F19: CNC OMS ENTRY LENS 3CAC00203A | G19: N-Chromate | H19: 1 | I19: 1 | J19: PCS | P19: =VLOOKUP(C19,COSTING!C280:D536,2,0) -> PK OMS ENTRY LENS HOLDER 3CAC00203A
C20: 120168 | D20: PK OMS ENTRY LENS HOLDER 3CAC00203A | E20: 760018 | F20: Carton box. 5 Plate: 1 surface Yellow, 1 surface raw. Thùng carton 5 lớp,mặt ngoài vàng, mặt trong thô MC-YLR01 | G20: Packing | H20: 0.00025 | I20: 1 | J20: EA | P20: =VLOOKUP(C20,COSTING!C280:D536,2,0) -> PK OMS ENTRY LENS HOLDER 3CAC00203A
C21: 301189 | D21: CNC OMS ENTRY LENS 3CAC00203A | E21: 210159 | F21: CA OMS ENTRY LENS 3CAC00203A | G21: CNC 1 | H21: 1 | I21: 1 | J21: PCS | P21: =VLOOKUP(C21,COSTING!C280:D536,2,0) -> #N/A
C22: 210159 | D22: CA OMS ENTRY LENS 3CAC00203A | E22: 762802 | F22: Aluminium ALDCS 12 Fe 0.9%-Nhôm thỏi ALDC12 thành phần Fe 0.9% | G22: Casting | H22: 0.04335 | I22: 1 | J22: KG | P22: =VLOOKUP(C22,COSTING!C280:D536,2,0) -> #N/A
A23: 5 LG | C23: 120178 | D23: PK 570W 3MAM00541A | E23: 301314 | F23: CNC 570W 3MAM00541A | G23: Cleaning | H23: 1 | I23: 1 | J23: PCS | P23: =VLOOKUP(C23,COSTING!C282:D536,2,0) -> PK 570W 3MAM00541A
C24: 120178 | D24: PK 570W 3MAM00541A | E24: 762207 | F24: Bearing 608A21T1XZZ1#MC-02 K NS7ST-3BBB00019A | G24: Caulking | H24: 1 | I24: 1 | J24: EA | P24: =VLOOKUP(C24,COSTING!C283:D536,2,0) -> PK 570W 3MAM00541A
C25: 120178 | D25: PK 570W 3MAM00541A | E25: 762262 | F25: Carton tray IN/YLR 45 3 plates 2 surface yellow/Khay carton 3 lớp 2 mặt vàng IN/YLR45 525*350*122 | G25: Packing | H25: 0.025 | I25: 1 | J25: EA | P25: =VLOOKUP(C25,COSTING!C284:D536,2,0) -> PK 570W 3MAM00541A
C26: 120178 | D26: PK 570W 3MAM00541A | E26: 762263 | F26: Devide pad 3 plates 2 surface yellow (9R) BR36-9R/Vách carton 3 lớp 2 mặt vàng BR36-9R 338*119 | G26: Packing | H26: 0.075 | I26: 1 | J26: EA | P26: =VLOOKUP(C26,COSTING!C285:D536,2,0) -> PK 570W 3MAM00541A
C27: 120178 | D27: PK 570W 3MAM00541A | E27: 762264 | F27: Devide pad 3 plates 2 surface yellow (3R) BR37-3R/Vách carton 3 lớp 2 mặt vàng BR37-3R 501*119 | G27: Packing | H27: 0.225 | I27: 1 | J27: EA | P27: =VLOOKUP(C27,COSTING!C286:D536,2,0) -> PK 570W 3MAM00541A
C28: 301314 | D28: CNC 570W 3MAM00541A | E28: 210166 | F28: CA LGIT 570W 3MAM00541A | G28: CNC 1 | H28: 1 | I28: 1 | J28: PCS | P28: =VLOOKUP(C28,COSTING!C287:D536,2,0) -> #N/A
C29: 210166 | D29: CA LGIT 570W 3MAM00541A | E29: 762802 | F29: Aluminium ALDCS 12 Fe 0.9%-Nhôm thỏi ALDC12 thành phần Fe 0.9% | G29: Casting | H29: 0.439 | I29: 1 | J29: KG | P29: =VLOOKUP(C29,COSTING!C288:D536,2,0) -> #N/A
A30: 6 LG | C30: 120165 | D30: PK PSA BMS Bottom Cover 3CAC00182A | E30: 301186 | F30: CNC PSA BMS Bottom Cover 3CAC00182A | G30: N-Chromate | H30: 1 | I30: 1 | J30: PCS | P30: =VLOOKUP(C30,COSTING!C289:D536,2,0) -> PK PSA BMS Bottom Cover 3CAC00182A
C31: 120165 | D31: PK PSA BMS Bottom Cover 3CAC00182A | E31: 762265 | F31: Carton tray IN/YLR 46 3 plates 2 surface yellow/Khay carton 3 lớp 2 mặt vàng IN/YLR46 525*350*109 | G31: Packing | H31: 0.04 | I31: 1 | J31: EA | P31: =VLOOKUP(C31,COSTING!C290:D536,2,0) -> PK PSA BMS Bottom Cover 3CAC00182A
C32: 120165 | D32: PK PSA BMS Bottom Cover 3CAC00182A | E32: 762266 | F32: Devide pad 3 plates 2 surface yellow (2R) BR38-2R/Vách carton 3 lớp 2 mặt vàng BR38-2R 338*106 | G32: Packing | H32: 0.96 | I32: 1 | J32: EA | P32: =VLOOKUP(C32,COSTING!C291:D536,2,0) -> PK PSA BMS Bottom Cover 3CAC00182A
C33: 120165 | D33: PK PSA BMS Bottom Cover 3CAC00182A | E33: 762267 | F33: Devide pad 3 plates 2 surface yellow (24R) BR39-24R/Vách carton 3 lớp 2 mặt vàng BR39-24R 501*106 | G33: Packing | H33: 0.08 | I33: 1 | J33: EA | P33: =VLOOKUP(C33,COSTING!C292:D536,2,0) -> PK PSA BMS Bottom Cover 3CAC00182A
C34: 301186 | D34: CNC PSA BMS Bottom Cover 3CAC00182A | E34: 210156 | F34: CA PSA BMS Bottom Cover 3CAC00182A | G34: CNC 1 | H34: 1 | I34: 1 | J34: PCS | P34: =VLOOKUP(C34,COSTING!C293:D536,2,0) -> #N/A
C35: 210156 | D35: CA PSA BMS Bottom Cover 3CAC00182A | E35: 762802 | F35: Aluminium ALDCS 12 Fe 0.9%-Nhôm thỏi ALDC12 thành phần Fe 0.9% | G35: Casting | H35: 0.79582 | I35: 1 | J35: KG | P35: =VLOOKUP(C35,COSTING!C294:D536,2,0) -> #N/A
A36: 7 LG | C36: 120166 | D36: PK PSA BMS Top Cover 3CAC00181A | E36: 301187 | F36: CNC PSA BMS Top Cover 3CAC00181A | G36: N-Chromate | H36: 1 | I36: 1 | J36: PCS | P36: =VLOOKUP(C36,COSTING!C294:D536,2,0) -> PK PSA BMS Top Cover 3CAC00181A
C37: 120166 | D37: PK PSA BMS Top Cover 3CAC00181A | E37: 762266 | F37: Devide pad 3 plates 2 surface yellow (2R) BR38-2R/Vách carton 3 lớp 2 mặt vàng BR38-2R 338*106 | G37: Packing | H37: 0.9 | I37: 1 | J37: EA | P37: =VLOOKUP(C37,COSTING!C295:D536,2,0) -> PK PSA BMS Top Cover 3CAC00181A
C38: 120166 | D38: PK PSA BMS Top Cover 3CAC00181A | E38: 762268 | F38: Devide pad 3 plates 2 surface yellow (9R) BR40-9R/Vách carton 3 lớp 2 mặt vàng BR40-9R 501*106 | G38: Packing | H38: 0.2 | I38: 1 | J38: EA | P38: =VLOOKUP(C38,COSTING!C296:D536,2,0) -> PK PSA BMS Top Cover 3CAC00181A
C39: 120166 | D39: PK PSA BMS Top Cover 3CAC00181A | E39: 762265 | F39: Carton tray IN/YLR 46 3 plates 2 surface yellow/Khay carton 3 lớp 2 mặt vàng IN/YLR46 525*350*109 | G39: Packing | H39: 0.1 | I39: 1 | J39: EA | P39: =VLOOKUP(C39,COSTING!C297:D536,2,0) -> PK PSA BMS Top Cover 3CAC00181A
C40: 301187 | D40: CNC PSA BMS Top Cover 3CAC00181A | E40: 210157 | F40: CA PSA BMS Top Cover 3CAC00181A | G40: CNC 1 | H40: 1 | I40: 1 | J40: PCS | P40: =VLOOKUP(C40,COSTING!C298:D536,2,0) -> #N/A
...

Sheet COSTING
U2: =+U4='Manufacturing Cost.'!M7 -> TRUE
D3: COSTING TABLE Apr.2026 | U3: 622 | V3: 627 | W3: =Y4=Outsoucing!J2 -> TRUE | X3: 627 | Y3: 627
Q4: =Q113+R113+R269+R536 -> 2.3186101e+10 | S4: =SUM(S7:S535) -> 275658.5 | U4: =+U113+U269+U536 -> 7.8122116e+09 | V4: =+V113+V269+V536 -> 2.5809805e+10 | W4: =ROUND((U4+V4+X4),0)=ROUND((('Manufacturing Cost.'!M7+'Manufacturing Cost.'!N7+'Manufacturing Cost.'!O7)+'Re-allowcate'!J27),0) -> TRUE | X4: =+X113+X269+X536 -> 1.1305394e+10 | Y4: =+Y113+Y269+Y536 -> 1339026728 | Z4: =+Z113+Z269+Z536 -> 1.5831593e+11 | AB4: =+AB113+AB269+AB536 -> 0
A5: Type | B5: Key Parent and chid | C5: Item code | D5: Item Parent Name | E5: In Qty | F5: NG Qty | G5: TOT Pro | H5: Item Child Code | I5: Item Child Name | J5: Process | K5: Usage | L5: 母件底数 Parent Item Quantity | M5: 用量单位 UOM | N5: Material Using BOM | O5: Qty Actual Material Issue | P5: Ave price | Q5: Actual Material Amt | R5: Raw-other-Amt | S5: Working hour | T5: Working hour(%) | U5: Direct Labour Cost | V5: Manufactuing Cost | W5: Working hour Allocation Indirect(%) | X5: Indirect cost | Y5: Outsourcing Fee | Z5: Total Cost(Include NG) | AA5: Unit cost Input | AB5: Remark
A7: WIP 1 | B7: =C7&H7 -> 210145762802 | C7: 210145 | D7: CA LGIT Gen3 AL5 | E7: 78082 | F7: 1971 | G7: =+E7+F7 -> 80053 | H7: 762802 | I7: Aluminium ALDCS 12 Fe 0.9%-Nhôm thỏi ALDC12 thành phần Fe 0.9% | J7: Casting | K7: 0.6665 | L7: 1 | M7: KG | N7: =K7*(E7+F7) -> 53355.324 | O7: 53669.333 | P7: 25493.055 | Q7: =O7*P7 -> 1.3681953e+09 | R7: 0 | S7: =VLOOKUP(C7,'Working Hours'!A:I,9,0)*G7 -> 2065.3674 | T7: =S7/SUM($S$7:$S$112) -> 0.05088998 | U7: =SUMIFS('Manufacturing Cost.'!N:N,'Manufacturing Cost.'!G:G,"622",'Manufacturing Cost.'!H:H,"0501")*T7 -> 1.0121078e+08 | V7: =SUMIFS('Manufacturing Cost.'!N:N,'Manufacturing Cost.'!G:G,"627",'Manufacturing Cost.'!H:H,"0501")*T7 -> 5.6881394e+08 | W7: =S7/SUM($S$7:$S$507) -> 0.0075240417 | X7: =SUMIFS('Manufacturing Cost.'!N:N,'Manufacturing Cost.'!H:H,"indirect",'Manufacturing Cost.'!G:G,"627")*W7 -> 85062259 | Y7: =SUMIF(Outsoucing!D:D,C7,Outsoucing!J:J) -> 0 | Z7: =Q7+R7+U7+V7+X7+Y7 -> 2.1232823e+09 | AA7: =IF(Z7<>0,(Z7/(E7+F7)),0) -> 26523.457 | AC7: 2.1232823e+09 | AD7: =+Z7-AC7 -> 0
A8: WIP 1 | B8: =C8&H8 -> 210148762802 | C8: 210148 | D8: CA LGIT Gen 2 | E8: 0 | F8: 0 | G8: =+E8+F8 -> 0 | H8: 762802 | I8: Aluminium ALDCS 12 Fe 0.9%-Nhôm thỏi ALDC12 thành phần Fe 0.9% | J8: Casting | K8: 0.3087 | L8: 1 | M8: KG | N8: =K8*(E8+F8) -> 0 | O8: 0 | P8: 25493.055 | Q8: =O8*P8 -> 0 | R8: 0 | S8: =VLOOKUP(C8,'Working Hours'!A:I,9,0)*G8 -> 0 | T8: =S8/SUM($S$7:$S$112) -> 0 | U8: =SUMIFS('Manufacturing Cost.'!N:N,'Manufacturing Cost.'!G:G,"622",'Manufacturing Cost.'!H:H,"0501")*T8 -> 0 | V8: =SUMIFS('Manufacturing Cost.'!N:N,'Manufacturing Cost.'!G:G,"627",'Manufacturing Cost.'!H:H,"0501")*T8 -> 0 | W8: =S8/SUM($S$7:$S$507) -> 0 | X8: =SUMIFS('Manufacturing Cost.'!N:N,'Manufacturing Cost.'!H:H,"indirect",'Manufacturing Cost.'!G:G,"627")*W8 -> 0 | Y8: =SUMIF(Outsoucing!D:D,C8,Outsoucing!J:J) -> 0 | Z8: =Q8+R8+U8+V8+X8+Y8 -> 0 | AA8: =IF(Z8<>0,(Z8/(E8+F8)),0) -> 0 | AC8: 0 | AD8: =+Z8-AC8 -> 0
A9: WIP 1 | B9: =C9&H9 -> 210152760309 | C9: 210152 | D9: CA Qualcomm Bittra 55-PM920 Front housing | E9: 0 | F9: 0 | G9: =+E9+F9 -> 0 | H9: 760309 | I9: Aluminum Ingots ADC3 , Hợp kim nhôm ADC3 | J9: Casting | K9: 0.19633 | L9: 1 | M9: KG | N9: =K9*(E9+F9) -> 0 | O9: 0 | P9: 88365.489 | Q9: =O9*P9 -> 0 | R9: 0 | S9: =VLOOKUP(C9,'Working Hours'!A:I,9,0)*G9 -> 0 | T9: =S9/SUM($S$7:$S$112) -> 0 | U9: =SUMIFS('Manufacturing Cost.'!N:N,'Manufacturing Cost.'!G:G,"622",'Manufacturing Cost.'!H:H,"0501")*T9 -> 0 | V9: =SUMIFS('Manufacturing Cost.'!N:N,'Manufacturing Cost.'!G:G,"627",'Manufacturing Cost.'!H:H,"0501")*T9 -> 0 | W9: =S9/SUM($S$7:$S$507) -> 0 | X9: =SUMIFS('Manufacturing Cost.'!N:N,'Manufacturing Cost.'!H:H,"indirect",'Manufacturing Cost.'!G:G,"627")*W9 -> 0 | Y9: =SUMIF(Outsoucing!D:D,C9,Outsoucing!J:J) -> 0 | Z9: =Q9+R9+U9+V9+X9+Y9 -> 0 | AA9: =IF(Z9<>0,(Z9/(E9+F9)),0) -> 0 | AC9: 0 | AD9: =+Z9-AC9 -> 0
A10: WIP 1 | B10: =C10&H10 -> 210158762802 | C10: 210158 | D10: CA OMS ENTRY_3CAC00250A VCSEL COVER | E10: 0 | F10: 0 | G10: =+E10+F10 -> 0 | H10: 762802 | I10: Aluminium ALDCS 12 Fe 0.9%-Nhôm thỏi ALDC12 thành phần Fe 0.9% | J10: Casting | K10: 0.06433 | L10: 1 | M10: KG | N10: =K10*(E10+F10) -> 0 | O10: 0 | P10: 25493.055 | Q10: =O10*P10 -> 0 | R10: 0 | S10: =VLOOKUP(C10,'Working Hours'!A:I,9,0)*G10 -> 0 | T10: =S10/SUM($S$7:$S$112) -> 0 | U10: =SUMIFS('Manufacturing Cost.'!N:N,'Manufacturing Cost.'!G:G,"622",'Manufacturing Cost.'!H:H,"0501")*T10 -> 0 | V10: =SUMIFS('Manufacturing Cost.'!N:N,'Manufacturing Cost.'!G:G,"627",'Manufacturing Cost.'!H:H,"0501")*T10 -> 0 | W10: =S10/SUM($S$7:$S$507) -> 0 | X10: =SUMIFS('Manufacturing Cost.'!N:N,'Manufacturing Cost.'!H:H,"indirect",'Manufacturing Cost.'!G:G,"627")*W10 -> 0 | Y10: =SUMIF(Outsoucing!D:D,C10,Outsoucing!J:J) -> 0 | Z10: =Q10+R10+U10+V10+X10+Y10 -> 0 | AA10: =IF(Z10<>0,(Z10/(E10+F10)),0) -> 0 | AC10: 0 | AD10: =+Z10-AC10 -> 0
A11: WIP 1 | B11: =C11&H11 -> 210159762802 | C11: 210159 | D11: CA OMS ENTRY LENS 3CAC00203A | E11: 0 | F11: 0 | G11: =+E11+F11 -> 0 | H11: 762802 | I11: Aluminium ALDCS 12 Fe 0.9%-Nhôm thỏi ALDC12 thành phần Fe 0.9% | J11: Casting | K11: 0.04335 | L11: 1 | M11: KG | N11: =K11*(E11+F11) -> 0 | O11: 0 | P11: 25493.055 | Q11: =O11*P11 -> 0 | R11: 0 | S11: =VLOOKUP(C11,'Working Hours'!A:I,9,0)*G11 -> 0 | T11: =S11/SUM($S$7:$S$112) -> 0 | U11: =SUMIFS('Manufacturing Cost.'!N:N,'Manufacturing Cost.'!G:G,"622",'Manufacturing Cost.'!H:H,"0501")*T11 -> 0 | V11: =SUMIFS('Manufacturing Cost.'!N:N,'Manufacturing Cost.'!G:G,"627",'Manufacturing Cost.'!H:H,"0501")*T11 -> 0 | W11: =S11/SUM($S$7:$S$507) -> 0 | X11: =SUMIFS('Manufacturing Cost.'!N:N,'Manufacturing Cost.'!H:H,"indirect",'Manufacturing Cost.'!G:G,"627")*W11 -> 0 | Y11: =SUMIF(Outsoucing!D:D,C11,Outsoucing!J:J) -> 0 | Z11: =Q11+R11+U11+V11+X11+Y11 -> 0 | AA11: =IF(Z11<>0,(Z11/(E11+F11)),0) -> 0 | AC11: 0 | AD11: =+Z11-AC11 -> 0
A12: WIP 1 | B12: =C12&H12 -> 210171762249 | C12: 210171 | D12: CA ZF TRW - GM EU2L Housing A021D074 | E12: 49850 | F12: 2430 | G12: =+E12+F12 -> 52280 | H12: 762249 | I12: Aluminum S3Y/Nhôm hợp kim dạng thanh S3Y | J12: Casting | K12: 0.22739 | L12: 1 | M12: KG | N12: =K12*(E12+F12) -> 11887.949 | O12: 12860.194 | P12: 33082.841 | Q12: =O12*P12 -> 4.2545176e+08 | R12: 0 | S12: =VLOOKUP(C12,'Working Hours'!A:I,9,0)*G12 -> 711.008 | T12: =S12/SUM($S$7:$S$112) -> 0.017519005 | U12: =SUMIFS('Manufacturing Cost.'!N:N,'Manufacturing Cost.'!G:G,"622",'Manufacturing Cost.'!H:H,"0501")*T12 -> 34842069 | V12: =SUMIFS('Manufacturing Cost.'!N:N,'Manufacturing Cost.'!G:G,"627",'Manufacturing Cost.'!H:H,"0501")*T12 -> 1.9581565e+08 | W12: =S12/SUM($S$7:$S$507) -> 0.0025901706 | X12: =SUMIFS('Manufacturing Cost.'!N:N,'Manufacturing Cost.'!H:H,"indirect",'Manufacturing Cost.'!G:G,"627")*W12 -> 29282900 | Y12: =SUMIF(Outsoucing!D:D,C12,Outsoucing!J:J) -> 0 | Z12: =Q12+R12+U12+V12+X12+Y12 -> 6.8539238e+08 | AA12: =IF(Z12<>0,(Z12/(E12+F12)),0) -> 13110.03 | AC12: 6.8539238e+08 | AD12: =+Z12-AC12 -> 0
A13: WIP 1 | B13: =C13&H13 -> 210172762249 | C13: 210172 | D13: CA ZF TRW-Nissan/FCA/GMT 4.8 Lenmount | E13: 290546 | F13: 21627 | G13: =+E13+F13 -> 312173 | H13: 762249 | I13: Aluminum S3Y/Nhôm hợp kim dạng thanh S3Y | J13: Casting | K13: 0.05228 | L13: 1 | M13: KG | N13: =K13*(E13+F13) -> 16320.404 | O13: 15092.158 | P13: 33082.841 | Q13: =O13*P13 -> 4.9929145e+08 | R13: 0 | S13: =VLOOKUP(C13,'Working Hours'!A:I,9,0)*G13 -> 2247.6456 | T13: =S13/SUM($S$7:$S$112) -> 0.055381255 | U13: =SUMIFS('Manufacturing Cost.'!N:N,'Manufacturing Cost.'!G:G,"622",'Manufacturing Cost.'!H:H,"0501")*T13 -> 1.101431e+08 | V13: =SUMIFS('Manufacturing Cost.'!N:N,'Manufacturing Cost.'!G:G,"627",'Manufacturing Cost.'!H:H,"0501")*T13 -> 6.190144e+08 | W13: =S13/SUM($S$7:$S$507) -> 0.0081880731 | X13: =SUMIFS('Manufacturing Cost.'!N:N,'Manufacturing Cost.'!H:H,"indirect",'Manufacturing Cost.'!G:G,"627")*W13 -> 92569396 | Y13: =SUMIF(Outsoucing!D:D,C13,Outsoucing!J:J) -> 0 | Z13: =Q13+R13+U13+V13+X13+Y13 -> 1.3210183e+09 | AA13: =IF(Z13<>0,(Z13/(E13+F13)),0) -> 4231.6867 | AC13: 1.3210183e+09 | AD13: =+Z13-AC13 -> 0
A14: WIP 1 | B14: =C14&H14 -> 210178762802 | C14: 210178 | D14: CA LGIT MPC5.5 Cover lens 3HDC00003A | E14: 144040 | F14: 5038 | G14: =+E14+F14 -> 149078 | H14: 762802 | I14: Aluminium ALDCS 12 Fe 0.9%-Nhôm thỏi ALDC12 thành phần Fe 0.9% | J14: Casting | K14: 0.062 | L14: 1 | M14: KG | N14: =K14*(E14+F14) -> 9242.836 | O14: 11492.143 | P14: 25493.055 | Q14: =O14*P14 -> 2.9296984e+08 | R14: 0 | S14: =VLOOKUP(C14,'Working Hours'!A:I,9,0)*G14 -> 1162.8084 | T14: =S14/SUM($S$7:$S$112) -> 0.02865122 | U14: =SUMIFS('Manufacturing Cost.'!N:N,'Manufacturing Cost.'!G:G,"622",'Manufacturing Cost.'!H:H,"0501")*T14 -> 56981990 | V14: =SUMIFS('Manufacturing Cost.'!N:N,'Manufacturing Cost.'!G:G,"627",'Manufacturing Cost.'!H:H,"0501")*T14 -> 3.2024406e+08 | W14: =S14/SUM($S$7:$S$507) -> 0.0042360594 | X14: =SUMIFS('Manufacturing Cost.'!N:N,'Manufacturing Cost.'!H:H,"indirect",'Manufacturing Cost.'!G:G,"627")*W14 -> 47890322 | Y14: =SUMIF(Outsoucing!D:D,C14,Outsoucing!J:J) -> 0 | Z14: =Q14+R14+U14+V14+X14+Y14 -> 7.1808621e+08 | AA14: =IF(Z14<>0,(Z14/(E14+F14)),0) -> 4816.849 | AC14: 7.1808621e+08 | AD14: =+Z14-AC14 -> 0
A15: WIP 1 | B15: =C15&H15 -> 210179762249 | C15: 210179 | D15: CA TRW-FCA 4.8 Housing | E15: 108420 | F15: 4966 | G15: =+E15+F15 -> 113386 | H15: 762249 | I15: Aluminum S3Y/Nhôm hợp kim dạng thanh S3Y | J15: Casting | K15: 0.258199 | L15: 1 | M15: KG | N15: =K15*(E15+F15) -> 29276.152 | O15: 25512.578 | P15: 33082.841 | Q15: =O15*P15 -> 8.4402858e+08 | R15: 0 | S15: =VLOOKUP(C15,'Working Hours'!A:I,9,0)*G15 -> 1542.0496 | T15: =S15/SUM($S$7:$S$112) -> 0.0379956 | U15: =SUMIFS('Manufacturing Cost.'!N:N,'Manufacturing Cost.'!G:G,"622",'Manufacturing Cost.'!H:H,"0501")*T15 -> 75566237 | V15: =SUMIFS('Manufacturing Cost.'!N:N,'Manufacturing Cost.'!G:G,"627",'Manufacturing Cost.'!H:H,"0501")*T15 -> 4.2468924e+08 | W15: =S15/SUM($S$7:$S$507) -> 0.0056176182 | X15: =SUMIFS('Manufacturing Cost.'!N:N,'Manufacturing Cost.'!H:H,"indirect",'Manufacturing Cost.'!G:G,"627")*W15 -> 63509390 | Y15: =SUMIF(Outsoucing!D:D,C15,Outsoucing!J:J) -> 0 | Z15: =Q15+R15+U15+V15+X15+Y15 -> 1.4077934e+09 | AA15: =IF(Z15<>0,(Z15/(E15+F15)),0) -> 12415.937 | AC15: 1.4077934e+09 | AD15: =+Z15-AC15 -> 0
A16: WIP 1 | B16: =C16&H16 -> 210180762249 | C16: 210180 | D16: CA TRW-FCA 4.8 Cover | E16: 83422 | F16: 3700 | G16: =+E16+F16 -> 87122 | H16: 762249 | I16: Aluminum S3Y/Nhôm hợp kim dạng thanh S3Y | J16: Casting | K16: 0.15738 | L16: 1 | M16: KG | N16: =K16*(E16+F16) -> 13711.26 | O16: 15267.21 | P16: 33082.841 | Q16: =O16*P16 -> 5.0508268e+08 | R16: 0 | S16: =VLOOKUP(C16,'Working Hours'!A:I,9,0)*G16 -> 409.4734 | T16: =S16/SUM($S$7:$S$112) -> 0.010089291 | U16: =SUMIFS('Manufacturing Cost.'!N:N,'Manufacturing Cost.'!G:G,"622",'Manufacturing Cost.'!H:H,"0501")*T16 -> 20065739 | V16: =SUMIFS('Manufacturing Cost.'!N:N,'Manufacturing Cost.'!G:G,"627",'Manufacturing Cost.'!H:H,"0501")*T16 -> 1.1277131e+08 | W16: =S16/SUM($S$7:$S$507) -> 0.0014916934 | X16: =SUMIFS('Manufacturing Cost.'!N:N,'Manufacturing Cost.'!H:H,"indirect",'Manufacturing Cost.'!G:G,"627")*W16 -> 16864182 | Y16: =SUMIF(Outsoucing!D:D,C16,Outsoucing!J:J) -> 0 | Z16: =Q16+R16+U16+V16+X16+Y16 -> 6.5478391e+08 | AA16: =IF(Z16<>0,(Z16/(E16+F16)),0) -> 7515.7125 | AC16: 6.5478391e+08 | AD16: =+Z16-AC16 -> 0
A17: WIP 1 | B17: =C17&H17 -> 210191762802 | C17: 210191 | D17: CA LGIT OMS Front 3CAC00207A | E17: 0 | F17: 0 | G17: =+E17+F17 -> 0 | H17: 762802 | I17: Aluminium ALDCS 12 Fe 0.9%-Nhôm thỏi ALDC12 thành phần Fe 0.9% | J17: Casting | K17: 0.04163 | L17: 1 | M17: KG | N17: =K17*(E17+F17) -> 0 | O17: 0 | P17: 25493.055 | Q17: =O17*P17 -> 0 | R17: 0 | S17: =VLOOKUP(C17,'Working Hours'!A:I,9,0)*G17 -> 0 | T17: =S17/SUM($S$7:$S$112) -> 0 | U17: =SUMIFS('Manufacturing Cost.'!N:N,'Manufacturing Cost.'!G:G,"622",'Manufacturing Cost.'!H:H,"0501")*T17 -> 0 | V17: =SUMIFS('Manufacturing Cost.'!N:N,'Manufacturing Cost.'!G:G,"627",'Manufacturing Cost.'!H:H,"0501")*T17 -> 0 | W17: =S17/SUM($S$7:$S$507) -> 0 | X17: =SUMIFS('Manufacturing Cost.'!N:N,'Manufacturing Cost.'!H:H,"indirect",'Manufacturing Cost.'!G:G,"627")*W17 -> 0 | Y17: =SUMIF(Outsoucing!D:D,C17,Outsoucing!J:J) -> 0 | Z17: =Q17+R17+U17+V17+X17+Y17 -> 0 | AA17: =IF(Z17<>0,(Z17/(E17+F17)),0) -> 0 | AC17: 0 | AD17: =+Z17-AC17 -> 0
A18: WIP 1 | B18: =C18&H18 -> 210192762249 | C18: 210192 | D18: CA ZF TRW - GM EU2L Cover A021D075 | E18: 34422 | F18: 2100 | G18: =+E18+F18 -> 36522 | H18: 762249 | I18: Aluminum S3Y/Nhôm hợp kim dạng thanh S3Y | J18: Casting | K18: 0.14131 | L18: 1 | M18: KG | N18: =K18*(E18+F18) -> 5160.9238 | O18: 3264.261 | P18: 33082.841 | Q18: =O18*P18 -> 1.0799103e+08 | R18: 0 | S18: =VLOOKUP(C18,'Working Hours'!A:I,9,0)*G18 -> 171.6534 | T18: =S18/SUM($S$7:$S$112) -> 0.0042294838 | U18: =SUMIFS('Manufacturing Cost.'!N:N,'Manufacturing Cost.'!G:G,"622",'Manufacturing Cost.'!H:H,"0501")*T18 -> 8411663 | V18: =SUMIFS('Manufacturing Cost.'!N:N,'Manufacturing Cost.'!G:G,"627",'Manufacturing Cost.'!H:H,"0501")*T18 -> 47274324 | W18: =S18/SUM($S$7:$S$507) -> 0.00062532571 | X18: =SUMIFS('Manufacturing Cost.'!N:N,'Manufacturing Cost.'!H:H,"indirect",'Manufacturing Cost.'!G:G,"627")*W18 -> 7069553.8 | Y18: =SUMIF(Outsoucing!D:D,C18,Outsoucing!J:J) -> 0 | Z18: =Q18+R18+U18+V18+X18+Y18 -> 1.7074657e+08 | AA18: =IF(Z18<>0,(Z18/(E18+F18)),0) -> 4675.1703 | AC18: 1.7074657e+08 | AD18: =+Z18-AC18 -> 0
... A73: WIP 1 | B73: =C73&H73 -> 210402762802 | C73: 210402 | D73: CA Mando Brose JG REPS ME210JGRW0 Housing cover | E73: 3731 | F73: 263 | G73: =+E73+F73 -> 3994 | H73: 762802 | I73: Aluminium ALDCS 12 Fe 0.9%, Nhôm thỏi ALDC12 thành phần Fe 0.9% | J73: Casting | K73: 0.52821 | L73: 1 | M73: KG | N73: =K73*(E73+F73) -> 2109.6707 | O73: 607.4415 | P73: 25493.055 | Q73: =O73*P73 -> 15485540 | R73: 0 | S73: =VLOOKUP(C73,'Working Hours'!A:I,9,0)*G73 -> 39.5406 | T73: =S73/SUM($S$7:$S$112) -> 0.0009742675 | U73: =SUMIFS('Manufacturing Cost.'!N:N,'Manufacturing Cost.'!G:G,"622",'Manufacturing Cost.'!H:H,"0501")*T73 -> 1937638.3 | V73: =SUMIFS('Manufacturing Cost.'!N:N,'Manufacturing Cost.'!G:G,"627",'Manufacturing Cost.'!H:H,"0501")*T73 -> 10889706 | W73: =S73/SUM($S$7:$S$507) -> 0.00014404465 | X73: =SUMIFS('Manufacturing Cost.'!N:N,'Manufacturing Cost.'!H:H,"indirect",'Manufacturing Cost.'!G:G,"627")*W73 -> 1628481.6 | Y73: =SUMIF(Outsoucing!D:D,C73,Outsoucing!J:J) -> 0 | Z73: =Q73+R73+U73+V73+X73+Y73 -> 29941366 | AA73: =IF(Z73<>0,(Z73/(E73+F73)),0) -> 7496.5864 | AC73: 29941366 | AD73: =+Z73-AC73 -> 0
A74: WIP 1 | B74: =C74&H74 -> 551243800786 | C74: 551243 | D74: IN Qualcomm MTP MTP PAKALA CA90-58183-5 FRAME, WLAN AREA, MULTIPURPOSE | E74: 0 | F74: 0 | G74: =+E74+F74 -> 0 | H74: 800786 | I74: Resin Lucky Enpla PC- LPC1001F 9306(BK), Hạt nhựa nguyên sinh Lucky Enpla PC- LPC1001F 9306(BK) | J74: Casting | K74: 0.00624 | M74: KG | N74: =K74*(E74+F74) -> 0 | O74: 0 | P74: 152445.57 | Q74: =O74*P74 -> 0 | R74: 0 | S74: =VLOOKUP(C74,'Working Hours'!A:I,9,0)*G74 -> 0 | T74: =S74/SUM($S$7:$S$112) -> 0 | U74: =SUMIFS('Manufacturing Cost.'!N:N,'Manufacturing Cost.'!G:G,"622",'Manufacturing Cost.'!H:H,"0501")*T74 -> 0 | V74: =SUMIFS('Manufacturing Cost.'!N:N,'Manufacturing Cost.'!G:G,"627",'Manufacturing Cost.'!H:H,"0501")*T74 -> 0 | W74: =S74/SUM($S$7:$S$507) -> 0 | X74: =SUMIFS('Manufacturing Cost.'!N:N,'Manufacturing Cost.'!H:H,"indirect",'Manufacturing Cost.'!G:G,"627")*W74 -> 0 | Y74: =SUMIF(Outsoucing!D:D,C74,Outsoucing!J:J) -> 0 | Z74: =Q74+R74+U74+V74+X74+Y74 -> 0 | AA74: =IF(Z74<>0,(Z74/(E74+F74)),0) -> 0 | AC74: 0 | AD74: =+Z74-AC74 -> 0
A75: WIP 1 | B75: =C75&H75 -> 210151762802 | C75: 210151 | D75: CA Qualcomm Lahaina 55-PP323-1 Module 0 | E75: 0 | F75: 0 | G75: =+E75+F75 -> 0 | H75: 762802 | I75: Aluminium ALDCS 12 Fe 0.9%, Nhôm thỏi ALDC12 thành phần Fe 0.9% | J75: Casting | K75: 0.04422 | L75: 1 | M75: KG | N75: =K75*(E75+F75) -> 0 | O75: 0 | P75: 25493.055 | Q75: =O75*P75 -> 0 | R75: 0 | S75: =VLOOKUP(C75,'Working Hours'!A:I,9,0)*G75 -> 0 | T75: =S75/SUM($S$7:$S$112) -> 0 | U75: =SUMIFS('Manufacturing Cost.'!N:N,'Manufacturing Cost.'!G:G,"622",'Manufacturing Cost.'!H:H,"0501")*T75 -> 0 | V75: =SUMIFS('Manufacturing Cost.'!N:N,'Manufacturing Cost.'!G:G,"627",'Manufacturing Cost.'!H:H,"0501")*T75 -> 0 | W75: =S75/SUM($S$7:$S$507) -> 0 | X75: =SUMIFS('Manufacturing Cost.'!N:N,'Manufacturing Cost.'!H:H,"indirect",'Manufacturing Cost.'!G:G,"627")*W75 -> 0 | Y75: =SUMIF(Outsoucing!D:D,C75,Outsoucing!J:J) -> 0 | Z75: =Q75+R75+U75+V75+X75+Y75 -> 0 | AA75: =IF(Z75<>0,(Z75/(E75+F75)),0) -> 0 | AC75: 0 | AD75: =+Z75-AC75 -> 0
A76: WIP 1 | B76: =C76&H76 -> 210403762802 | C76: 210403 | D76: CA Mando Brose US4 GE844EM003 cover | E76: 0 | F76: 0 | G76: =+E76+F76 -> 0 | H76: 762802 | I76: Aluminium ALDCS 12 Fe 0.9%, Nhôm thỏi ALDC12 thành phần Fe 0.9% | J76: Casting | K76: 0.5282 | L76: 1 | M76: KG | N76: =K76*(E76+F76) -> 0 | O76: 0 | P76: 25493.055 | Q76: =O76*P76 -> 0 | R76: 0 | S76: =VLOOKUP(C76,'Working Hours'!A:I,9,0)*G76 -> 0 | T76: =S76/SUM($S$7:$S$112) -> 0 | U76: =SUMIFS('Manufacturing Cost.'!N:N,'Manufacturing Cost.'!G:G,"622",'Manufacturing Cost.'!H:H,"0501")*T76 -> 0 | V76: =SUMIFS('Manufacturing Cost.'!N:N,'Manufacturing Cost.'!G:G,"627",'Manufacturing Cost.'!H:H,"0501")*T76 -> 0 | W76: =S76/SUM($S$7:$S$507) -> 0 | X76: =SUMIFS('Manufacturing Cost.'!N:N,'Manufacturing Cost.'!H:H,"indirect",'Manufacturing Cost.'!G:G,"627")*W76 -> 0 | Y76: =SUMIF(Outsoucing!D:D,C76,Outsoucing!J:J) -> 0 | Z76: =Q76+R76+U76+V76+X76+Y76 -> 0 | AA76: =IF(Z76<>0,(Z76/(E76+F76)),0) -> 0 | AC76: 0 | AD76: =+Z76-AC76 -> 0
A77: WIP 1 | B77: =C77&H77 -> 210404762802 | C77: 210404 | D77: CA Mando Brose LT2 ME200LT200 DIECAST HOUSING | E77: 370 | F77: 0 | G77: =+E77+F77 -> 370 | H77: 762802 | I77: Aluminium ALDCS 12 Fe 0.9%, Nhôm thỏi ALDC12 thành phần Fe 0.9% | J77: Casting | K77: 1.61047 | L77: 1 | M77: KG | N77: =K77*(E77+F77) -> 595.8739 | O77: 128.8376 | P77: 25493.055 | Q77: =O77*P77 -> 3284464.1 | R77: 0 | S77: =VLOOKUP(C77,'Working Hours'!A:I,9,0)*G77 -> 13.912 | T77: =S77/SUM($S$7:$S$112) -> 0.00034278715 | U77: =SUMIFS('Manufacturing Cost.'!N:N,'Manufacturing Cost.'!G:G,"622",'Manufacturing Cost.'!H:H,"0501")*T77 -> 681740.39 | V77: =SUMIFS('Manufacturing Cost.'!N:N,'Manufacturing Cost.'!G:G,"627",'Manufacturing Cost.'!H:H,"0501")*T77 -> 3831444 | W77: =S77/SUM($S$7:$S$507) -> 5.0680798e-05 | X77: =SUMIFS('Manufacturing Cost.'!N:N,'Manufacturing Cost.'!H:H,"indirect",'Manufacturing Cost.'!G:G,"627")*W77 -> 572966.41 | Y77: =SUMIF(Outsoucing!D:D,C77,Outsoucing!J:J) -> 0 | Z77: =Q77+R77+U77+V77+X77+Y77 -> 8370614.9 | AA77: =IF(Z77<>0,(Z77/(E77+F77)),0) -> 22623.284 | AC77: 8370614.9 | AD77: =+Z77-AC77 -> 0
A78: WIP 1 | B78: =C78&H78 -> 210405760011 | C78: 210405 | D78: CA SM-A176B | E78: 997013 | F78: 40157 | G78: =+E78+F78 -> 1037170 | H78: 760011 | I78: Aluminum alloy bar S36, Nhôm hợp kim dạng thanh S36 | J78: Casting | K78: 0.1786 | L78: 1 | M78: KG | N78: =K78*(E78+F78) -> 185238.56 | O78: 148672.71 | P78: 15519.439 | Q78: =O78*P78 -> 2.3073171e+09 | R78: 0 | S78: =VLOOKUP(C78,'Working Hours'!A:I,9,0)*G78 -> 18046.758 | T78: =S78/SUM($S$7:$S$112) -> 0.44466624 | U78: =SUMIFS('Manufacturing Cost.'!N:N,'Manufacturing Cost.'!G:G,"622",'Manufacturing Cost.'!H:H,"0501")*T78 -> 8.843591e+08 | V78: =SUMIFS('Manufacturing Cost.'!N:N,'Manufacturing Cost.'!G:G,"627",'Manufacturing Cost.'!H:H,"0501")*T78 -> 4.9701799e+09 | W78: =S78/SUM($S$7:$S$507) -> 0.065743538 | X78: =SUMIFS('Manufacturing Cost.'!N:N,'Manufacturing Cost.'!H:H,"indirect",'Manufacturing Cost.'!G:G,"627")*W78 -> 7.4325663e+08 | Y78: =SUMIF(Outsoucing!D:D,C78,Outsoucing!J:J) -> 207068994 | Z78: =Q78+R78+U78+V78+X78+Y78 -> 9.1121818e+09 | AA78: =IF(Z78<>0,(Z78/(E78+F78)),0) -> 8785.6202 | AC78: 9.1121818e+09 | AD78: =+Z78-AC78 -> 0
A79: WIP 1 | B79: =C79&H79 -> 210406760309 | C79: 210406 | D79: CA Qualcomm AMBOSELI 55-84713-1 HIELD, HEATSINK, RF CARD, PICTOR/ALIOTH" | E79: 347 | F79: 0 | G79: =+E79+F79 -> 347 | H79: 760309 | I79: Aluminum Ingots ADC3 , Hợp kim nhôm ADC3 | J79: Casting | K79: 0.144 | L79: 1 | M79: KG | N79: =K79*(E79+F79) -> 49.968 | O79: 49.968 | P79: 88365.489 | Q79: =O79*P79 -> 4415446.7 | R79: 0 | S79: =VLOOKUP(C79,'Working Hours'!A:I,9,0)*G79 -> 6.8359 | T79: =S79/SUM($S$7:$S$112) -> 0.00016843435 | U79: =SUMIFS('Manufacturing Cost.'!N:N,'Manufacturing Cost.'!G:G,"622",'Manufacturing Cost.'!H:H,"0501")*T79 -> 334984.84 | V79: =SUMIFS('Manufacturing Cost.'!N:N,'Manufacturing Cost.'!G:G,"627",'Manufacturing Cost.'!H:H,"0501")*T79 -> 1882645.8 | W79: =S79/SUM($S$7:$S$507) -> 2.490288e-05 | X79: =SUMIFS('Manufacturing Cost.'!N:N,'Manufacturing Cost.'!H:H,"indirect",'Manufacturing Cost.'!G:G,"627")*W79 -> 281536.88 | Y79: =SUMIF(Outsoucing!D:D,C79,Outsoucing!J:J) -> 0 | Z79: =Q79+R79+U79+V79+X79+Y79 -> 6914614.3 | AA79: =IF(Z79<>0,(Z79/(E79+F79)),0) -> 19926.842 | AC79: 6914614.3 | AD79: =+Z79-AC79 -> 0
A80: WIP 1 | B80: =C80&H80 -> 210407762802 | C80: 210407 | D80: CA Mando Brose JG RWS Cover GE844EM111 | E80: 285 | F80: 0 | G80: =+E80+F80 -> 285 | H80: 762802 | I80: Aluminium ALDCS 12 Fe 0.9%, Nhôm thỏi ALDC12 thành phần Fe 0.9% | J80: Casting | K80: 0.5364 | L80: 1 | M80: KG | N80: =K80*(E80+F80) -> 152.874 | O80: 536.4 | P80: 25493.055 | Q80: =O80*P80 -> 13674475 | R80: 0 | S80: =VLOOKUP(C80,'Working Hours'!A:I,9,0)*G80 -> 2.8215 | T80: =S80/SUM($S$7:$S$112) -> 6.952084e-05 | U80: =SUMIFS('Manufacturing Cost.'!N:N,'Manufacturing Cost.'!G:G,"622",'Manufacturing Cost.'!H:H,"0501")*T80 -> 138264.12 | V80: =SUMIFS('Manufacturing Cost.'!N:N,'Manufacturing Cost.'!G:G,"627",'Manufacturing Cost.'!H:H,"0501")*T80 -> 777057.17 | W80: =S80/SUM($S$7:$S$507) -> 1.0278599e-05 | X80: =SUMIFS('Manufacturing Cost.'!N:N,'Manufacturing Cost.'!H:H,"indirect",'Manufacturing Cost.'!G:G,"627")*W80 -> 116203.62 | Y80: =SUMIF(Outsoucing!D:D,C80,Outsoucing!J:J) -> 0 | Z80: =Q80+R80+U80+V80+X80+Y80 -> 14706000 | AA80: =IF(Z80<>0,(Z80/(E80+F80)),0) -> 51599.999 | AC80: 14706000 | AD80: =+Z80-AC80 -> 0
A81: WIP 1 | B81: =C81&H81 -> 210183762802 | C81: 210183 | D81: CA LG IKC Camera Base 3CAC00180A | E81: 2251 | F81: 127 | G81: =+E81+F81 -> 2378 | H81: 762802 | I81: Aluminium ALDCS 12 Fe 0.9%, Nhôm thỏi ALDC12 thành phần Fe 0.9% | J81: Casting | K81: 0.0292 | L81: 1 | M81: KG | N81: =K81*(E81+F81) -> 69.4376 | O81: 0 | P81: 25493.055 | Q81: =O81*P81 -> 0 | R81: 0 | S81: =VLOOKUP(C81,'Working Hours'!A:I,9,0)*G81 -> 33.292 | T81: =S81/SUM($S$7:$S$112) -> 0.00082030403 | U81: =SUMIFS('Manufacturing Cost.'!N:N,'Manufacturing Cost.'!G:G,"622",'Manufacturing Cost.'!H:H,"0501")*T81 -> 1631433.4 | V81: =SUMIFS('Manufacturing Cost.'!N:N,'Manufacturing Cost.'!G:G,"627",'Manufacturing Cost.'!H:H,"0501")*T81 -> 9168806.4 | W81: =S81/SUM($S$7:$S$507) -> 0.00012128128 | X81: =SUMIFS('Manufacturing Cost.'!N:N,'Manufacturing Cost.'!H:H,"indirect",'Manufacturing Cost.'!G:G,"627")*W81 -> 1371132.7 | Y81: =SUMIF(Outsoucing!D:D,C81,Outsoucing!J:J) -> 0 | Z81: =Q81+R81+U81+V81+X81+Y81 -> 12171372 | AA81: =IF(Z81<>0,(Z81/(E81+F81)),0) -> 5118.3231 | AC81: 12171372 | AD81: =+Z81-AC81 -> 0
A82: WIP 1 | B82: =C82&H82 -> 210408762802 | C82: 210408 | D82: CA Mando Brose JK1-LHD Housing ME200V1200 | E82: 60 | F82: 0 | G82: =+E82+F82 -> 60 | H82: 762802 | I82: Aluminium ALDCS 12 Fe 0.9%, Nhôm thỏi ALDC12 thành phần Fe 0.9% | J82: Casting | K82: 1.01964 | L82: 1 | M82: KG | N82: =K82*(E82+F82) -> 61.1784 | O82: 61.1784 | P82: 25493.055 | Q82: =O82*P82 -> 1559624.3 | R82: 0 | S82: =VLOOKUP(C82,'Working Hours'!A:I,9,0)*G82 -> 1.602 | T82: =S82/SUM($S$7:$S$112) -> 3.9472758e-05 | U82: =SUMIFS('Manufacturing Cost.'!N:N,'Manufacturing Cost.'!G:G,"622",'Manufacturing Cost.'!H:H,"0501")*T82 -> 78504.033 | V82: =SUMIFS('Manufacturing Cost.'!N:N,'Manufacturing Cost.'!G:G,"627",'Manufacturing Cost.'!H:H,"0501")*T82 -> 441199.92 | W82: =S82/SUM($S$7:$S$507) -> 5.8360149e-06 | X82: =SUMIFS('Manufacturing Cost.'!N:N,'Manufacturing Cost.'!H:H,"indirect",'Manufacturing Cost.'!G:G,"627")*W82 -> 65978.45 | Y82: =SUMIF(Outsoucing!D:D,C82,Outsoucing!J:J) -> 3666166 | Z82: =Q82+R82+U82+V82+X82+Y82 -> 5811472.7 | AA82: =IF(Z82<>0,(Z82/(E82+F82)),0) -> 96857.879 | AC82: 5811472.7 | AD82: =+Z82-AC82 -> 0
A83: WIP 1 | B83: =C83&H83 -> 210409762802 | C83: 210409 | D83: CA ZF Wabco OGM2.0 IPM2.0 Housing_Base new A032N890/A032N891 | E83: 0 | F83: 0 | G83: =+E83+F83 -> 0 | H83: 762802 | I83: Aluminium ALDCS 12 Fe 0.9%, Nhôm thỏi ALDC12 thành phần Fe 0.9% | J83: Casting | K83: 0.6243 | L83: 1 | M83: KG | N83: =K83*(E83+F83) -> 0 | O83: 0 | P83: 25493.055 | Q83: =O83*P83 -> 0 | R83: 0 | S83: =VLOOKUP(C83,'Working Hours'!A:I,9,0)*G83 -> 0 | T83: =S83/SUM($S$7:$S$112) -> 0 | U83: =SUMIFS('Manufacturing Cost.'!N:N,'Manufacturing Cost.'!G:G,"622",'Manufacturing Cost.'!H:H,"0501")*T83 -> 0 | V83: =SUMIFS('Manufacturing Cost.'!N:N,'Manufacturing Cost.'!G:G,"627",'Manufacturing Cost.'!H:H,"0501")*T83 -> 0 | W83: =S83/SUM($S$7:$S$507) -> 0 | X83: =SUMIFS('Manufacturing Cost.'!N:N,'Manufacturing Cost.'!H:H,"indirect",'Manufacturing Cost.'!G:G,"627")*W83 -> 0 | Y83: =SUMIF(Outsoucing!D:D,C83,Outsoucing!J:J) -> 0 | Z83: =Q83+R83+U83+V83+X83+Y83 -> 0 | AA83: =IF(Z83<>0,(Z83/(E83+F83)),0) -> 0 | AC83: 0 | AD83: =+Z83-AC83 -> 0
A84: WIP 1 | B84: =C84&H84 -> 551244762762 | C84: 551244 | D84: IN Qualcomm MTP SM7750 CA90-28768-3 FRAME, WLAN AREA, MULTIPURPOSE | E84: 0 | F84: 0 | G84: =+E84+F84 -> 0 | H84: 762762 | I84: PC LGF 1308M 98309(BK) - PC +GF20% (LDS resin), resin) PC LGF 1308M(update:30%) | J84: Casting | K84: 0.0172 | L84: 1 | M84: KG | N84: =K84*(E84+F84) -> 0 | O84: 0 | P84: 127233.07 | Q84: =O84*P84 -> 0 | R84: 0 | S84: =VLOOKUP(C84,'Working Hours'!A:I,9,0)*G84 -> 0 | T84: =S84/SUM($S$7:$S$112) -> 0 | U84: =SUMIFS('Manufacturing Cost.'!N:N,'Manufacturing Cost.'!G:G,"622",'Manufacturing Cost.'!H:H,"0501")*T84 -> 0 | V84: =SUMIFS('Manufacturing Cost.'!N:N,'Manufacturing Cost.'!G:G,"627",'Manufacturing Cost.'!H:H,"0501")*T84 -> 0 | W84: =S84/SUM($S$7:$S$507) -> 0 | X84: =SUMIFS('Manufacturing Cost.'!N:N,'Manufacturing Cost.'!H:H,"indirect",'Manufacturing Cost.'!G:G,"627")*W84 -> 0 | Y84: =SUMIF(Outsoucing!D:D,C84,Outsoucing!J:J) -> 0 | Z84: =Q84+R84+U84+V84+X84+Y84 -> 0 | AA84: =IF(Z84<>0,(Z84/(E84+F84)),0) -> 0 | AC84: 0 | AD84: =+Z84-AC84 -> 0
A85: WIP 1 | B85: =C85&H85 -> 551245762762 | C85: 551245 | D85: IN Qualcomm KAANAPALI CA90-58184-2 CARRIER FRAME, ASSY | E85: 0 | F85: 0 | G85: =+E85+F85 -> 0 | H85: 762762 | I85: PC LGF 1308M 98309(BK) - PC +GF20% (LDS resin), resin) PC LGF 1308M(update:30%) | J85: Casting | K85: 0.07776 | L85: 1 | M85: KG | N85: =K85*(E85+F85) -> 0 | O85: 0 | P85: 127233.07 | Q85: =O85*P85 -> 0 | R85: 0 | S85: =VLOOKUP(C85,'Working Hours'!A:I,9,0)*G85 -> 0 | T85: =S85/SUM($S$7:$S$112) -> 0 | U85: =SUMIFS('Manufacturing Cost.'!N:N,'Manufacturing Cost.'!G:G,"622",'Manufacturing Cost.'!H:H,"0501")*T85 -> 0 | V85: =SUMIFS('Manufacturing Cost.'!N:N,'Manufacturing Cost.'!G:G,"627",'Manufacturing Cost.'!H:H,"0501")*T85 -> 0 | W85: =S85/SUM($S$7:$S$507) -> 0 | X85: =SUMIFS('Manufacturing Cost.'!N:N,'Manufacturing Cost.'!H:H,"indirect",'Manufacturing Cost.'!G:G,"627")*W85 -> 0 | Y85: =SUMIF(Outsoucing!D:D,C85,Outsoucing!J:J) -> 0 | Z85: =Q85+R85+U85+V85+X85+Y85 -> 0 | AA85: =IF(Z85<>0,(Z85/(E85+F85)),0) -> 0 | AC85: 0 | AD85: =+Z85-AC85 -> 0
A86: WIP 1 | B86: =C86&H86 -> 210411760011 | C86: 210411 | D86: CA SM-A376B | E86: 1096 | F86: 0 | G86: =+E86+F86 -> 1096 | H86: 760011 | I86: Aluminum alloy bar S36, Nhôm hợp kim dạng thanh S36 | J86: Casting | K86: 0.1871 | L86: 1 | M86: KG | N86: =K86*(E86+F86) -> 205.0616 | O86: 304.4848 | P86: 15519.439 | Q86: =O86*P86 -> 4725433.3 | R86: 0 | S86: =VLOOKUP(C86,'Working Hours'!A:I,9,0)*G86 -> 33.2088 | T86: =S86/SUM($S$7:$S$112) -> 0.00081825401 | U86: =SUMIFS('Manufacturing Cost.'!N:N,'Manufacturing Cost.'!G:G,"622",'Manufacturing Cost.'!H:H,"0501")*T86 -> 1627356.3 | V86: =SUMIFS('Manufacturing Cost.'!N:N,'Manufacturing Cost.'!G:G,"627",'Manufacturing Cost.'!H:H,"0501")*T86 -> 9145892.7 | W86: =S86/SUM($S$7:$S$507) -> 0.00012097818 | X86: =SUMIFS('Manufacturing Cost.'!N:N,'Manufacturing Cost.'!H:H,"indirect",'Manufacturing Cost.'!G:G,"627")*W86 -> 1367706.1 | Y86: =SUMIF(Outsoucing!D:D,C86,Outsoucing!J:J) -> 0 | Z86: =Q86+R86+U86+V86+X86+Y86 -> 16866388 | AA86: =IF(Z86<>0,(Z86/(E86+F86)),0) -> 15389.04 | AC86: 16866388 | AD86: =+Z86-AC86 -> 0
... A105: WIP 1 | B105: =C105&H105 -> 551255800786 | C105: 551255 | D105: IN Qualcomm MAILI 55-97051-1 ALTERED FRAME, CAMERA CARD COVER ASSY_PROCESS | E105: 1200 | F105: 0 | G105: =+E105+F105 -> 1200 | H105: 800786 | I105: Resin Lucky Enpla PC- LPC1001F 9306(BK), Hạt nhựa nguyên sinh Lucky Enpla PC- LPC1001F 9306(BK) | J105: Injection | K105: 0.0065 | L105: 1 | M105: KG | N105: =K105*(E105+F105) -> 7.8 | O105: 30.09903 | P105: 152445.57 | Q105: =O105*P105 -> 4588463.9 | R105: 1600328 | S105: =VLOOKUP(C105,'Working Hours'!A:I,9,0)*G105 -> 10.8 | T105: =S105/SUM($S$7:$S$112) -> 0.00026610848 | U105: =SUMIFS('Manufacturing Cost.'!N:N,'Manufacturing Cost.'!G:G,"622",'Manufacturing Cost.'!H:H,"0501")*T105 -> 529240.67 | V105: =SUMIFS('Manufacturing Cost.'!N:N,'Manufacturing Cost.'!G:G,"627",'Manufacturing Cost.'!H:H,"0501")*T105 -> 2974381.5 | W105: =S105/SUM($S$7:$S$507) -> 3.934392e-05 | X105: =SUMIFS('Manufacturing Cost.'!N:N,'Manufacturing Cost.'!H:H,"indirect",'Manufacturing Cost.'!G:G,"627")*W105 -> 444798.54 | Y105: =SUMIF(Outsoucing!D:D,C105,Outsoucing!J:J) -> 0 | Z105: =Q105+R105+U105+V105+X105+Y105 -> 10137213 | AA105: =IF(Z105<>0,(Z105/(E105+F105)),0) -> 8447.6772 | AC105: 10137213 | AD105: =+Z105-AC105 -> 0
A106: WIP 1 | B106: =C106&H106 -> 551222800450 | C106: 551222 | D106: IN Qualcomm ADP Ride Arnage(4.0) 50-36927-3 Inlet Bafle SOC 2 | E106: 100 | F106: 0 | G106: =+E106+F106 -> 100 | H106: 800450 | I106: Resin PC/ABS/HR5007A/BLACK, Hạt nhựa nguyên sinh màu đen PC/ABS/HR5007A | J106: Injection | K106: 0.0074 | L106: 1 | M106: KG | N106: =K106*(E106+F106) -> 0.74 | O106: 0.74 | P106: 34448.491 | Q106: =O106*P106 -> 25491.883 | R106: 92023.741 | S106: =VLOOKUP(C106,'Working Hours'!A:I,9,0)*G106 -> 1.11 | T106: =S106/SUM($S$7:$S$112) -> 2.7350038e-05 | U106: =SUMIFS('Manufacturing Cost.'!N:N,'Manufacturing Cost.'!G:G,"622",'Manufacturing Cost.'!H:H,"0501")*T106 -> 54394.18 | V106: =SUMIFS('Manufacturing Cost.'!N:N,'Manufacturing Cost.'!G:G,"627",'Manufacturing Cost.'!H:H,"0501")*T106 -> 305700.32 | W106: =S106/SUM($S$7:$S$507) -> 4.0436807e-06 | X106: =SUMIFS('Manufacturing Cost.'!N:N,'Manufacturing Cost.'!H:H,"indirect",'Manufacturing Cost.'!G:G,"627")*W106 -> 45715.405 | Y106: =SUMIF(Outsoucing!D:D,C106,Outsoucing!J:J) -> 0 | Z106: =Q106+R106+U106+V106+X106+Y106 -> 523325.53 | AA106: =IF(Z106<>0,(Z106/(E106+F106)),0) -> 5233.2553 | AC106: 523325.53
A107: WIP 1 | B107: =C107&H107 -> 551254800450 | C107: 551254 | D107: IN QualcommIDP CEDROS_55-PR954-80_ASSY, SUB-ASSY, REAR HOUSING | E107: 350 | F107: 0 | G107: =+E107+F107 -> 350 | H107: 800450 | I107: Resin PC/ABS/HR5007A/BLACK, Hạt nhựa nguyên sinh màu đen PC/ABS/HR5007A | J107: Injection | K107: 0.0507 | L107: 1 | M107: KG | N107: =K107*(E107+F107) -> 17.745 | O107: 17.745 | P107: 34448.491 | Q107: =O107*P107 -> 611288.46 | R107: 1465410.9 | S107: =VLOOKUP(C107,'Working Hours'!A:I,9,0)*G107 -> 6.79 | T107: =S107/SUM($S$7:$S$112) -> 0.00016730339 | U107: =SUMIFS('Manufacturing Cost.'!N:N,'Manufacturing Cost.'!G:G,"622",'Manufacturing Cost.'!H:H,"0501")*T107 -> 332735.57 | V107: =SUMIFS('Manufacturing Cost.'!N:N,'Manufacturing Cost.'!G:G,"627",'Manufacturing Cost.'!H:H,"0501")*T107 -> 1870004.7 | W107: =S107/SUM($S$7:$S$507) -> 2.4735669e-05 | X107: =SUMIFS('Manufacturing Cost.'!N:N,'Manufacturing Cost.'!H:H,"indirect",'Manufacturing Cost.'!G:G,"627")*W107 -> 279646.49 | Y107: =SUMIF(Outsoucing!D:D,C107,Outsoucing!J:J) -> 0 | Z107: =Q107+R107+U107+V107+X107+Y107 -> 4559086.1 | AA107: =IF(Z107<>0,(Z107/(E107+F107)),0) -> 13025.96 | AC107: 4559086.1
A108: WIP 1 | B108: =C108&H108 -> 551256763008 | C108: 551256 | D108: IN A 147-9222-001 SIDE SHIELD, LEFT,BUCK HMD | E108: 100 | F108: 0 | G108: =+E108+F108 -> 100 | H108: 763008 | I108: Resin Markrolon LQ3187/ Hạt nhựa Markrolon LQ3187 (NAT) | J108: Injection | K108: 0.0035 | L108: 1 | M108: KG | N108: =K108*(E108+F108) -> 0.35 | O108: 0.49 | P108: 439096.27 | Q108: =O108*P108 -> 215157.17 | R108: 326220.93 | S108: =VLOOKUP(C108,'Working Hours'!A:I,9,0)*G108 -> 1.94 | T108: =S108/SUM($S$7:$S$112) -> 4.7800968e-05 | U108: =SUMIFS('Manufacturing Cost.'!N:N,'Manufacturing Cost.'!G:G,"622",'Manufacturing Cost.'!H:H,"0501")*T108 -> 95067.305 | V108: =SUMIFS('Manufacturing Cost.'!N:N,'Manufacturing Cost.'!G:G,"627",'Manufacturing Cost.'!H:H,"0501")*T108 -> 534287.05 | W108: =S108/SUM($S$7:$S$507) -> 7.0673339e-06 | X108: =SUMIFS('Manufacturing Cost.'!N:N,'Manufacturing Cost.'!H:H,"indirect",'Manufacturing Cost.'!G:G,"627")*W108 -> 79898.997 | Y108: =SUMIF(Outsoucing!D:D,C108,Outsoucing!J:J) -> 0 | Z108: =Q108+R108+U108+V108+X108+Y108 -> 1250631.4 | AA108: =IF(Z108<>0,(Z108/(E108+F108)),0) -> 12506.314 | AC108: 1250631.4
A109: WIP 1 | B109: =C109&H109 -> 551257763008 | C109: 551257 | D109: IN A 147-9223-001 SIDE SHIELD, RIGHT,BUCK HMD | E109: 140 | F109: 0 | G109: =+E109+F109 -> 140 | H109: 763008 | I109: Resin Markrolon LQ3187/ Hạt nhựa Markrolon LQ3187 (NAT) | J109: Injection | K109: 0.0035 | L109: 1 | M109: KG | N109: =K109*(E109+F109) -> 0.49 | O109: 0.49 | P109: 439096.27 | Q109: =O109*P109 -> 215157.17 | R109: 694500.93 | S109: =VLOOKUP(C109,'Working Hours'!A:I,9,0)*G109 -> 2.716 | T109: =S109/SUM($S$7:$S$112) -> 6.6921355e-05 | U109: =SUMIFS('Manufacturing Cost.'!N:N,'Manufacturing Cost.'!G:G,"622",'Manufacturing Cost.'!H:H,"0501")*T109 -> 133094.23 | V109: =SUMIFS('Manufacturing Cost.'!N:N,'Manufacturing Cost.'!G:G,"627",'Manufacturing Cost.'!H:H,"0501")*T109 -> 748001.87 | W109: =S109/SUM($S$7:$S$507) -> 9.8942674e-06 | X109: =SUMIFS('Manufacturing Cost.'!N:N,'Manufacturing Cost.'!H:H,"indirect",'Manufacturing Cost.'!G:G,"627")*W109 -> 111858.6 | Y109: =SUMIF(Outsoucing!D:D,C109,Outsoucing!J:J) -> 0 | Z109: =Q109+R109+U109+V109+X109+Y109 -> 1902612.8 | AA109: =IF(Z109<>0,(Z109/(E109+F109)),0) -> 13590.091 | AC109: 1902612.8
A110: WIP 1 | B110: =C110&H110 -> 551258763995 | C110: 551258 | D110: IN A 150-6547-002 TEMPLE ARM, LEFT ,BUCK HMD | E110: 90 | F110: 0 | G110: =+E110+F110 -> 90 | H110: 763995 | I110: EMS-GRIVORY GRILAMID TR 90 NZ, 10% GLASS FILL, Tan499/Hạt nhựa Grilamid TR90, 10% Glass Fill, màu Tan499 | J110: Injection | K110: 0.00601 | L110: 1 | M110: KG | N110: =K110*(E110+F110) -> 0.5409 | O110: 3.8581 | P110: 0 | Q110: =O110*P110 -> 0 | R110: 60000 | S110: =VLOOKUP(C110,'Working Hours'!A:I,9,0)*G110 -> 1.125 | T110: =S110/SUM($S$7:$S$112) -> 2.7719633e-05 | U110: =SUMIFS('Manufacturing Cost.'!N:N,'Manufacturing Cost.'!G:G,"622",'Manufacturing Cost.'!H:H,"0501")*T110 -> 55129.236 | V110: =SUMIFS('Manufacturing Cost.'!N:N,'Manufacturing Cost.'!G:G,"627",'Manufacturing Cost.'!H:H,"0501")*T110 -> 309831.41 | W110: =S110/SUM($S$7:$S$507) -> 4.0983251e-06 | X110: =SUMIFS('Manufacturing Cost.'!N:N,'Manufacturing Cost.'!H:H,"indirect",'Manufacturing Cost.'!G:G,"627")*W110 -> 46333.181 | Y110: =SUMIF(Outsoucing!D:D,C110,Outsoucing!J:J) -> 0 | Z110: =Q110+R110+U110+V110+X110+Y110 -> 471293.82 | AA110: =IF(Z110<>0,(Z110/(E110+F110)),0) -> 5236.598 | AC110: 471293.82
A111: WIP 1 | B111: =C111&H111 -> 551259763995 | C111: 551259 | D111: IN A 150-6548-002 TEMPLE ARM, RIGHT ,BUCK HMD | E111: 90 | F111: 0 | G111: =+E111+F111 -> 90 | H111: 763995 | I111: EMS-GRIVORY GRILAMID TR 90 NZ, 10% GLASS FILL, Tan499/Hạt nhựa Grilamid TR90, 10% Glass Fill, màu Tan499 | J111: Injection | K111: 0.00601 | L111: 1 | M111: KG | N111: =K111*(E111+F111) -> 0.5409 | O111: 1.1419 | P111: 0 | Q111: =O111*P111 -> 0 | R111: 114000 | S111: =VLOOKUP(C111,'Working Hours'!A:I,9,0)*G111 -> 1.125 | T111: =S111/SUM($S$7:$S$112) -> 2.7719633e-05 | U111: =SUMIFS('Manufacturing Cost.'!N:N,'Manufacturing Cost.'!G:G,"622",'Manufacturing Cost.'!H:H,"0501")*T111 -> 55129.236 | V111: =SUMIFS('Manufacturing Cost.'!N:N,'Manufacturing Cost.'!G:G,"627",'Manufacturing Cost.'!H:H,"0501")*T111 -> 309831.41 | W111: =S111/SUM($S$7:$S$507) -> 4.0983251e-06 | X111: =SUMIFS('Manufacturing Cost.'!N:N,'Manufacturing Cost.'!H:H,"indirect",'Manufacturing Cost.'!G:G,"627")*W111 -> 46333.181 | Y111: =SUMIF(Outsoucing!D:D,C111,Outsoucing!J:J) -> 0 | Z111: =Q111+R111+U111+V111+X111+Y111 -> 525293.82 | AA111: =IF(Z111<>0,(Z111/(E111+F111)),0) -> 5836.598 | AC111: 525293.82
A113: TOTAL WIP1 | B113: =C113&H113 | E113: =SUM(E7:E112) -> 2701239 | F113: =SUM(F7:F112) -> 101071 | G113: =SUM(G7:G112) -> 2802310 | N113: =SUM(N7:N112) -> 812617.8 | O113: =SUM(O7:O112) -> 738825.74 | Q113: =SUM(Q7:Q112) -> 1.7818048e+10 | R113: =SUM(R7:R112) -> 6512668.5 | U113: =SUM(U7:U112) -> 1.9888155e+09 | V113: =SUM(V7:V112) -> 1.1177327e+10 | X113: =SUM(X7:X112) -> 1.6714933e+09 | Y113: =SUM(Y7:Y112) -> 212278388 | Z113: =SUM(Z7:Z112) -> 3.2874475e+10 | AB113: =SUM(AB7:AB98) -> 0 | AC113: 0
A114: WIP 2 | B114: =C114&H114 -> 301161210145 | C114: 301161 | D114: CNC LGIT Gen3 AL5 | E114: 68139 | F114: 8040 | G114: =+E114+F114 -> 76179 | H114: 210145 | I114: CA LGIT Gen3 AL5 | J114: CNC 1 | K114: 1 | L114: 1 | M114: PCS | N114: =K114*(E114+F114) -> 76179 | P114: =IF(AND(Z114<>0,G114<>0),Z114/G114,"") -> 37968.87 | Q114: 2.0717543e+09 | R114: 0 | S114: =VLOOKUP(C114,'Working Hours'!A:I,9,0)*G114 -> 3092.8674 | T114: =S114/SUM($S$114:$S$245) -> 0.061508563 | U114: =SUMIF('Re-allowcate'!C:C,C114,'Re-allowcate'!N:N) -> 1.467667e+08 | V114: =SUMIFS('Manufacturing Cost.'!N:N,'Manufacturing Cost.'!G:G,"627",'Manufacturing Cost.'!H:H,"CNC1")*T114+SUMIF('Re-allowcate'!C:C,C114,'Re-allowcate'!J:J) -> 5.465297e+08 | W114: =S114/SUM($S$7:$S$507) -> 0.011267179 | X114: =SUMIFS('Manufacturing Cost.'!N:N,'Manufacturing Cost.'!H:H,"indirect",'Manufacturing Cost.'!G:G,"627")*W114 -> 1.273799e+08 | Y114: =SUMIF(Outsoucing!D:D,C114,Outsoucing!J:J) -> 0 | Z114: =Q114+R114+U114+V114+X114+Y114 -> 2.8924306e+09 | AA114: =IF(Z114<>0,(Z114/(E114+F114)),0) -> 37968.87 | AB114: LG | AC114: 2.8924306e+09 | AD114: =+Z114-AC114 -> 0
A115: WIP 2 | B115: =C115&H115 -> 301178210148 | C115: 301178 | D115: CNC LGIT Gen 2 | E115: 0 | F115: 0 | G115: =+E115+F115 -> 0 | H115: 210148 | I115: CA LGIT Gen 2 | J115: CNC 1 | K115: 1 | L115: 1 | M115: PCS | N115: =K115*(E115+F115) -> 0 | P115: =IF(AND(Z115<>0,G115<>0),Z115/G115,"") | Q115: 0 | R115: 0 | S115: =VLOOKUP(C115,'Working Hours'!A:I,9,0)*G115 -> 0 | T115: =S115/SUM($S$114:$S$236) -> 0 | U115: =SUMIF('Re-allowcate'!C:C,C115,'Re-allowcate'!N:N) -> 0 | V115: =SUMIFS('Manufacturing Cost.'!N:N,'Manufacturing Cost.'!G:G,"627",'Manufacturing Cost.'!H:H,"CNC1")*T115+SUMIF('Re-allowcate'!C:C,C115,'Re-allowcate'!J:J) -> 0 | W115: =S115/SUM($S$7:$S$507) -> 0 | X115: =SUMIFS('Manufacturing Cost.'!N:N,'Manufacturing Cost.'!H:H,"indirect",'Manufacturing Cost.'!G:G,"627")*W115 -> 0 | Y115: =SUMIF(Outsoucing!D:D,C115,Outsoucing!J:J) -> 0 | Z115: =Q115+R115+U115+V115+X115+Y115 -> 0 | AA115: =IF(Z115<>0,(Z115/(E115+F115)),0) -> 0 | AB115: LG | AC115: 0 | AD115: =+Z115-AC115 -> 0
...

Sheet Piv
B1: TB | C1: 622
A3: =C3&D3 | B3: Sum of Pro cost
B4: Expense Allocation Group.Code | C4: Expense Allocation Group | D4: Department | E4: Total
B5: 41070100 | C5: Direct labour costs | D5: Production 1 | E5: 874420444
B6: 41070100 | C6: Direct labour costs | D6: Production 2 | E6: 1507469792
B7: 41070100 | C7: Direct labour costs | D7: Production 3 | E7: 1225735086
B8: 41070101 | C8: Direct labour costs-Overtime | D8: Production 1 | E8: 816675102
B9: 41070101 | C9: Direct labour costs-Overtime | D9: Production 2 | E9: 1161826090
B10: 41070101 | C10: Direct labour costs-Overtime | D10: Production 3 | E10: 1021161665
B11: 41070102 | C11: Direct labour cost-Trade union | D11: Production 1 | E11: 14993000
B12: 41070102 | C12: Direct labour cost-Trade union | D12: Production 2 | E12: 24378000
B13: 41070102 | C13: Direct labour cost-Trade union | D13: Production 3 | E13: 21494900
B14: 41070104 | C14: Direct labour costs - Labor- SHUI | D14: Production 1 | E14: 163158750
B15: 41070104 | C15: Direct labour costs - Labor- SHUI | D15: Production 2 | E15: 261853500
B16: 41070104 | C16: Direct labour costs - Labor- SHUI | D16: Production 3 | E16: 231664188
... B22: 41070105 | C22: Direct labour costs- Labor - Outsourcing | D22: Production 3 | E22: 52884300
B23: Grand Total | E23: 7812211598
J213: 3.3839429e+10
J214: =+J213-G214 -> 3.3839429e+10

Sheet Book GL
A1: Loại | B1: Description | C1: ERP | D1: Acc name | E1: VAS | F1: Nợ | G1: Có | H1: Department | I1: Dept. Code
A2: 1- Kết chuyển chi nhân công trực tiếp | B2: Kết chuyển chi phí nhân công TT/ Transfer Derect cost labour | C2: 41070100 | D2: Direct labour costs | E2: 622 | G2: 874420444 | H2: Production 1
B3: Kết chuyển chi phí nhân công TT/ Transfer Derect cost labour | C3: 41070100 | D3: Direct labour costs | E3: 622 | G3: 1507469792 | H3: Production 2
B4: Kết chuyển chi phí nhân công TT/ Transfer Derect cost labour | C4: 41070100 | D4: Direct labour costs | E4: 622 | G4: 1225735086 | H4: Production 3
B5: Kết chuyển chi phí nhân công TT/ Transfer Derect cost labour | C5: 41070101 | D5: Direct labour costs-Overtime | E5: 622 | G5: 816675102 | H5: Production 1
B6: Kết chuyển chi phí nhân công TT/ Transfer Derect cost labour | C6: 41070101 | D6: Direct labour costs-Overtime | E6: 622 | G6: 1161826090 | H6: Production 2
B7: Kết chuyển chi phí nhân công TT/ Transfer Derect cost labour W | C7: 41070101 | D7: Direct labour costs-Overtime | E7: 622 | G7: 1021161665 | H7: Production 3
B8: Kết chuyển chi phí nhân công TT/ Transfer Derect cost labour | C8: 41070102 | D8: Direct labour cost-Trade union | E8: 622 | G8: 14993000 | H8: Production 1
B9: Kết chuyển chi phí nhân công TT/ Transfer Derect cost labour | C9: 41070102 | D9: Direct labour cost-Trade union | E9: 622 | G9: 24378000 | H9: Production 2
B10: Kết chuyển chi phí nhân công TT/ Transfer Derect cost labour | C10: 41070102 | D10: Direct labour cost-Trade union | E10: 622 | G10: 21494900 | H10: Production 3
B11: Kết chuyển chi phí nhân công TT/ Transfer Derect cost labour | C11: 41070104 | D11: Direct labour costs - Labor- SHUI | E11: 622 | G11: 163158750 | H11: Production 1
B12: Kết chuyển chi phí nhân công TT/ Transfer Derect cost labour | C12: 41070104 | D12: Direct labour costs - Labor- SHUI | E12: 622 | G12: 261853500 | H12: Production 2
B13: Kết chuyển chi phí nhân công TT/ Transfer Derect cost labour | C13: 41070104 | D13: Direct labour costs - Labor- SHUI | E13: 622 | G13: 231664188 | H13: Production 3
B14: Kết chuyển chi phí nhân công TT/ Transfer Derect cost labour | C14: 41070103 | D14: Direct labour costs- bonus | E14: 622 | G14: 48495799 | H14: Production 1
... B19: Kết chuyển chi phí nhân công TT/ Transfer Derect cost labour | C19: 41070105 | D19: Direct labour costs- Labor - Outsourcing | E19: 622 | G19: 52884300 | H19: Production 3
B20: Kết chuyển chi phí nhân công TT/ Transfer Derect cost labour | C20: 41010201 | D20: Production costs - labor - basic wage | E20: 631 | F20: =SUMIF($H$2:$H$19,H20,$G$2:$G$19) -> 1988815495 | H20: Production 1
B21: Kết chuyển chi phí nhân công TT/ Transfer Derect cost labour | C21: 41010201 | D21: Production costs - labor - basic wage | E21: 631 | F21: =SUMIF($H$2:$H$19,H21,$G$2:$G$19) -> 3192297686 | H21: Production 2
B22: Kết chuyển chi phí nhân công TT/ Transfer Derect cost labour | C22: 41010201 | D22: Production costs - labor - basic wage | E22: 631 | F22: =SUMIF($H$2:$H$19,H22,$G$2:$G$19) -> 2631098417 | H22: Production 3
F23: =SUM(F20:F22) -> 7812211598 | G23: =SUM(G2:G19) -> 7812211598
A24: 1- Kết chuyển chí gia công ngoài
B25: Kết chuyển chi phí gia công ngoài /trsf OS fee for Anodizing | C25: 12220100 | D25: Material purchasing | E25: trsf | G25: =+F31 -> 212278388 | H25: Production 1
B26: Kết chuyển chi phí gia công ngoài /trsf OS fee for lasering | C26: 12220100 | D26: Material purchasing | E26: trsf | H26: Production 2
B27: Kết chuyển chi phí gia công ngoài /trsf OS fee for Painting (UV) | C27: 12220100 | D27: Material purchasing | E27: trsf | G27: =Outsoucing!J2-G30-G25 -> 1065490056 | H27: Production 3
B28: Kết chuyển chi phí gia công ngoài /trsf OS fee for CNC model Stand cover | C28: 12220100 | D28: Material purchasing | E28: trsf
B29: Kết chuyển chi phí gia công ngoài /trsf OS fee for CNC model J100, NX4, ACP housing | C29: 12220100 | D29: Material purchasing | E29: trsf
B30: Kết chuyển chi phí gia công ngoài /trsf OS fee for sand blasting model BYD housing/Phí gia công phun cát tháng 07.2024 | C30: 41059802 | D30: Manufacturing costs - Outsourcing fee | E30: 627 | G30: 61258284 | H30: Production 3
B31: Kết chuyển chi phí gia công ngoài W2 | C31: 41010400 | D31: Production costs - Outsoucing | E31: 631 | F31: =+COSTING!Y113 -> 212278388 | H31: Production 1
B32: Kết chuyển chi phí gia công ngoài W2 | C32: 41010400 | D32: Production costs - Outsoucing | E32: 631 | F32: =+COSTING!Y269 -> 206497200 | H32: Production 2
B33: Kết chuyển chi phí gia công ngoài W3 | C33: 41010400 | D33: Production costs - Outsoucing | E33: 631 | F33: =+COSTING!Y536 -> 920251140 | H33: Production 3
F34: =SUM(F25:F33) -> 1339026728 | G34: =SUM(G25:G32) -> 1339026728
A35: 3- Kết chuyển chi phí NVL xuất cho SX
B36: kết chuyển chi phí NVL trực tiếp / Trsf RM to calculate costing | C36: 41080100 | D36: Direct raw material costs | E36: 621 | G36: =COSTING!Q113+COSTING!R113 -> 1.782456e+10 | H36: Production 1 | I36: 0501
B37: kết chuyển chi phí NVL trực tiếp / Trsf RM to calculate costing | C37: 41080100 | D37: Direct raw material costs | E37: 621 | G37: =COSTING!R269 -> 3.3842751e+08 | H37: Production 2 | I37: 0502
B38: kết chuyển chi phí NVL trực tiếp / Trsf RM to calculate costing | C38: 41080100 | D38: Direct raw material costs | E38: 621 | G38: =COSTING!R536-G39 -> 4.8534825e+09 | H38: Production 3 | I38: 0503
B39: kết chuyển chi phí NVL trực tiếp / Trsf RM to calculate costing Mold | C39: 41080100 | D39: Direct raw material costs | E39: 621 | G39: 1.6963051e+08 | H39: Production 3 | I39: 0503 | J39: FG-mold
B40: kết chuyển chi phí NVL trực tiếp / Trsf RM to calculate costing | C40: 41010100 | D40: Production costs - materials | E40: 631 | F40: =+G36 -> 1.782456e+10 | H40: Production 1 | I40: 0501
B41: kết chuyển chi phí NVL trực tiếp / Trsf RM to calculate costing | C41: 41010100 | D41: Production costs - materials | E41: 631 | F41: =+G37 -> 3.3842751e+08 | G41: =+F37 -> 0 | H41: Production 2 | I41: 0502
B42: kết chuyển chi phí NVL trực tiếp / Trsf RM to calculate costing | C42: 41010100 | D42: Production costs - materials | E42: 631 | F42: =+G38+G39 -> 5.023113e+09 | G42: =+F38+F39 -> 0 | H42: Production 3 | I42: 0503
F43: =SUM(F36:F42) -> 2.3186101e+10 | G43: =SUM(G36:G42) -> 2.3186101e+10
A44: 4- Kết chuyển chi phí CCDC xuất cho SX
...

Sheet Manufacturing Cost.
M1: 622 | N1: 627 | O1: Inventory Management
K2: =COSTING!U113-M2 -> 0 | L2: 0501 | M2: =+SUMIFS($N$10:$N$380,$G$10:$G$380,$M$1,$H$10:$H$380,$L2) -> 1988815495 | N2: =+SUMIFS($N$10:$N$380,$G$10:$G$380,$N$1,$H$10:$H$380,$L2) -> 9.2859369e+09 | O2: =SUMIFS($N$9:$N$421,$O$9:$O$421,$O$1,$H$9:$H$421,L2) -> 1.8913901e+09 | P2: =SUBTOTAL(9,N2:O2) -> 1.1177327e+10
K3: =M3-COSTING!U536 -> 0 | L3: 0503 | M3: =+SUMIFS($N$10:$N$380,$G$10:$G$380,$M$1,$H$10:$H$380,$L3) -> 2631098417 | N3: =+SUMIFS($N$10:$N$380,$G$10:$G$380,$N$1,$H$10:$H$380,$L3) -> 2.7615923e+09 | O3: =SUMIFS($N$9:$N$421,$O$9:$O$421,$O$1,$H$9:$H$421,L3) -> 3.0780027e+08 | P3: =SUBTOTAL(9,N3:O3) -> 3.0693926e+09
J4: =+J6-J5 -> 61258279 | K4: =M4+M5-COSTING!U269 -> 0 | L4: CNC1 | M4: =+SUMIFS($M$10:$M$380,$G$10:$G$380,$M$1,$H$10:$H$380,$L4) -> 1838795093 | N4: =+SUMIFS($N$10:$N$380,$G$10:$G$380,$N$1,$H$10:$H$380,$L4) -> 3791911443 | O4: =SUMIFS($N$9:$N$421,$O$9:$O$421,$O$1,$H$9:$H$421,L4) -> 1.0499567e+09 | P4: =SUBTOTAL(9,N4:O4) -> 4.8418682e+09
J5: 2.2929396e+09 | L5: CNC2 | M5: =+SUMIFS($N$10:$N$380,$G$10:$G$380,$M$1,$H$10:$H$380,$L5) -> 1353502593 | N5: =+SUMIFS($N$10:$N$380,$G$10:$G$380,$N$1,$H$10:$H$380,$L5) -> 3279187011 | O5: =SUMIFS($N$9:$N$421,$O$9:$O$421,$O$1,$H$9:$H$421,L5) -> 1.1490907e+09 | P5: =SUBTOTAL(9,N5:O5) -> 4.4282777e+09
J6: =+J8-J7 -> 2.3541978e+09 | K6: =COSTING!X4-'Manufacturing Cost.'!N6-O6 -> -5.4836273e-06 | L6: Indirect | M6: =+SUMIFS($N$10:$N$380,$G$10:$G$380,$M$1,$H$10:$H$380,$L6) -> 0 | N6: =+SUMIFS($N$10:$N$380,$G$10:$G$380,$N$1,$H$10:$H$380,$L6) -> 1.0207615e+10 | O6: =SUMIFS($N$9:$N$421,$O$9:$O$421,$O$1,$H$9:$H$421,L6) -> 1.0977797e+09 | P6: =SUBTOTAL(9,M6:O6) -> 1.1305394e+10
J7: 1277768444 | M7: =SUM(M2:M6) -> 7812211598 | N7: =SUM(N2:N6) -> 2.9326242e+10 | O7: =SUM(O2:O6) -> 5.4960174e+09 | P7: =SUBTOTAL(9,N7:O7) -> 3.482226e+10 | Q7: =SUM(M7:O7)-COSTING!U4-COSTING!V4-COSTING!X4+'Re-allowcate'!J18 -> -0.23185635
I8: 3.2958209e+10 | J8: =+I8-N7 -> 3.6319663e+09 | M8: =SUM(M10:M421)-'Re-allowcate'!J27-'Re-allowcate'!N27 -> -5.0407 | N8: =SUM(N10:N475)+SUMIF(G9:G379,"622",M9:M379)=(M7+N7+O7) -> TRUE
A9: Booking Period | B9: Cost Field | C9: Cost Type | D9: Expense Allocation Group.Code | E9: Expense Allocation Group | F9: Department | G9: TB | H9: Dept | I9: Work Center | J9: Name CC | K9: PL Daily Schedule | L9: Current Level Cost | M9: Re-alowcate | N9: Total Cost | O9: Source Application.Name | P9: Pro cost | Q9: Item.Finance Classes.Class Code | R9: Labor
C10: GL | D10: 41050101 | E10: Manufacturing costs - Local staff salary - basic wage | F10: Warehouse | G10: 627 | H10: Indirect | I10: C-6400 | J10: Warehouse | N10: 112381706 | O10: General Ledger | P10: =+M10+N10 -> 112381706
C11: GL | D11: 41050101 | E11: Manufacturing costs - Local staff salary - basic wage | F11: Utility | G11: 627 | H11: Indirect | I11: C-6000 | J11: Prod support | N11: 445206179 | O11: General Ledger | P11: =+M11+N11 -> 445206179
