Workbook
Name __DemandLoad: TRUE
Name __IntlFixup: TRUE
Name _1: #N/A
Name _2: #N/A
Name _3: #N/A
Name _4: #N/A
Name _5: #N/A
Name _6: #N/A
Name _Order1: 255
Name _Order2: 255
Name _Regression_Int: 1
Name \a: #N/A
Name \b: #N/A
Name \e: #N/A
Name \m: #N/A
Name \q: #N/A
Name \r: #N/A
Name \s: #N/A
Name aa: #N/A
Name aaa: #N/A
Name aaaa: #N/A
Name aaaaa: #N/A
Name aaaaaa: #N/A
Name as: #N/A
Name AS2DocOpenMode: "AS2DocumentEdit"
Name AS2ReportLS: 1
Name AS2SyncStepLS: 0
Name AS2VersionLS: 300
Name asd: #N/A
Name asdf: #N/A
Name asdfg: #N/A
Name asxz: #N/A
Name bbb: #N/A
Name bbbbb: #N/A
Name BG_Del: 15
Name BG_Ins: 4
Name BG_Mod: 6
Name book: #N/A
Name book2: #N/A
Name book3: #N/A
Name ccc: #N/A
Name cccccccccccccccccccccc: #N/A
Name dd: #N/A
Name ddd: #N/A
Name DSFDSF: #N/A
Name erre: #N/A
Name fff: #N/A
Name fghgfjk: #N/A
Name gfgfgf: #N/A
Name ggg: #N/A
Name GHJ: #N/A
Name GO: #N/A
Name GoAssetChart: #N/A
Name GoBack: #N/A
Name GoBalanceSheet: #N/A
Name GoCashFlow: #N/A
Name GoData: #N/A
Name GoIncomeChart: #N/A
Name h: #N/A
Name han: #N/A

Sheet Sale detail by code
E1: Sale | H1: COGS (sale out) | K1: Cost of Producing in Feb
A2: Code | B2: Name | C2: Item No. | D2: Item Name | E2: Qty | F2: VND | G2: USD | H2: Unit cost (everage) VND | I2: VND | J2: USD | K2: Unit cost product | L2: VND | M2: USD
A3: FG | B3: ELENTEC | C3: 120425 | D3: PK SM-A156E | E3: 46400 | F3: 776457600 | G3: =+F3/26000 -> 29863.754 | H3: 19655.967 | I3: =+H3*E3 -> 9.1203685e+08 | J3: =+I3/26000 -> 35078.341 | K3: 17463.275 | L3: =+K3*E3 -> 8.1029595e+08 | M3: =+L3/26000 -> 31165.229
A4: FG | B4: ELENTEC | C4: 120434 | D4: PK SM-A266B | E4: 55533 | F4: 1014698976 | G4: =+F4/26000 -> 39026.884 | H4: 19471.798 | I4: =+H4*E4 -> 1.0813273e+09 | J4: =+I4/26000 -> 41589.513 | K4: 24299.323 | L4: =+K4*E4 -> 1.3494143e+09 | M4: =+L4/26000 -> 51900.551
A5: FG | B5: ELENTEC | C5: 120438 | D5: PK SM-A176B | E5: 589680 | F5: 9546919200 | G5: =+F5/26000 -> 367189.2 | H5: 18096.416 | I5: =+H5*E5 -> 1.0671095e+10 | J5: =+I5/26000 -> 410426.72 | K5: 19124.579 | L5: =+K5*E5 -> 1.1277382e+10 | M5: =+L5/26000 -> 433745.46
A6: FG | B6: ELENTEC | C6: 120443 | D6: PK SM-A376B | E6: 411900 | F6: 8331501300 | G6: =+F6/26000 -> 320442.36 | H6: 19943.711 | I6: =+H6*E6 -> 8.2148144e+09 | J6: =+I6/26000 -> 315954.4 | K6: 19792.519 | L6: =+K6*E6 -> 8.1525387e+09 | M6: =+L6/26000 -> 313559.18
A7: FG | B7: INTOPS | C7: 120438 | D7: PK SM-A176B | E7: 168480 | F7: 2773180800 | G7: =+F7/26000 -> 106660.8 | H7: 18096.416 | I7: =+H7*E7 -> 3.0488842e+09 | J7: =+I7/26000 -> 117264.78 | K7: 19124.579 | L7: =+K7*E7 -> 3.2221091e+09 | M7: =+L7/26000 -> 123927.27
A8: FG | B8: SEVT | C8: 101196 | D8: PK B6 Main Sub6 - GH94-39228A (Samsung) | E8: 21100 | F8: 370516000 | G8: =+F8/26000 -> 14250.615 | H8: 26471.907 | I8: =+H8*E8 -> 5.5855724e+08 | J8: =+I8/26000 -> 21482.971 | K8: 26471.907 | L8: =+K8*E8 -> 5.5855724e+08 | M8: =+L8/26000 -> 21482.971
A9: FG | B9: SEVT | C9: 101202 | D9: PK Q5MMW-GH94-36580A (Samsung) | E9: 21901 | F9: 558212688 | G9: =+F9/26000 -> 21469.719 | H9: 20211.909 | I9: =+H9*E9 -> 4.4266103e+08 | J9: =+I9/26000 -> 17025.424 | K9: 20211.909 | L9: =+K9*E9 -> 4.4266103e+08 | M9: =+L9/26000 -> 17025.424
A10: FG | B10: SEVT | C10: 101203 | D10: PK Q5 MAIN SUB6/GH94-36611A (Samsung) | E10: 200 | F10: 5754228 | G10: =+F10/26000 -> 221.31646 | H10: 21418.927 | I10: =+H10*E10 -> 4283785.4 | J10: =+I10/26000 -> 164.76098 | K10: 21418.927 | L10: =+K10*E10 -> 4283785.4 | M10: =+L10/26000 -> 164.76098
A11: FG | B11: SEVT | C11: 101284 | D11: PK B7R Sub- GH94-42329A ( Samsung) | E11: 13552 | F11: 245494480 | G11: =+F11/26000 -> 9442.0954 | H11: 56369.955 | I11: =+H11*E11 -> 7.6392563e+08 | J11: =+I11/26000 -> 29381.755 | K11: 56369.955 | L11: =+K11*E11 -> 7.6392563e+08 | M11: =+L11/26000 -> 29381.755
A12: FG | B12: SEVT | C12: 101285 | D12: PK B7R Main Sub6 - GH94-42274A( Samsung) | E12: 15060 | F12: 257706720 | G12: =+F12/26000 -> 9911.7969 | H12: 38227.208 | I12: =+H12*E12 -> 5.7570175e+08 | J12: =+I12/26000 -> 22142.375 | K12: 38227.208 | L12: =+K12*E12 -> 5.7570175e+08 | M12: =+L12/26000 -> 22142.375
A13: FG | B13: SEVT | C13: 101286 | D13: PK B7 Sub- GH94-42470A ( Samsung) | E13: 83366 | F13: 1676156796 | G13: =+F13/26000 -> 64467.569 | H13: 16320.965 | I13: =+H13*E13 -> 1.3606136e+09 | J13: =+I13/26000 -> 52331.291 | K13: 16320.965 | L13: =+K13*E13 -> 1.3606136e+09 | M13: =+L13/26000 -> 52331.291
A14: FG | B14: SEVT | C14: 101288 | D14: PK B7 Main Sub 6 GH94-42417A ( Samsung) | E14: 336 | F14: 6134016 | G14: =+F14/26000 -> 235.92369 | H14: 11657.829 | I14: =+H14*E14 -> 3917030.6 | J14: =+I14/26000 -> 150.65502 | K14: 11657.829 | L14: =+K14*E14 -> 3917030.6 | M14: =+L14/26000 -> 150.65502
... A45: FG | B45: MFG | C45: 101342 | D45: PK A 149-0314-001 FRAME, EYE SIDE, BUCK HMD | E45: 15 | F45: 40062120 | G45: =+F45/26000 -> 1540.8508 | H45: 6151859.3 | I45: =+H45*E45 -> 92277889 | J45: =+I45/26000 -> 3549.1496 | K45: 6151859.3 | L45: =+K45*E45 -> 92277889 | M45: =+L45/26000 -> 3549.1496
A46: Trading | B46: MFG | C46: 785015 | D46: Oring Mold for P/N: 143-8808-001-A03 & 143-6225-001-A04 | E46: 1 | F46: 89541936 | G46: =+F46/26000 -> 3443.9206 | H46: 44625000 | I46: =+H46*E46 -> 44625000 | J46: =+I46/26000 -> 1716.3462 | K46: =+H46 -> 44625000 | L46: =+K46*E46 -> 44625000 | M46: =+L46/26000 -> 1716.3462
A47: Trading | B47: MFG | C47: 901175 | D47: 50-60551-1 ADHESIVE, Adhesive display, Linh kiện Qualcomm 50-60551-1 | E47: 1000 | F47: 32828520 | G47: =+F47/26000 -> 1262.6354 | H47: 11474 | I47: =+H47*E47 -> 11474000 | J47: =+I47/26000 -> 441.30769 | K47: =+H47 -> 11474 | L47: =+K47*E47 -> 11474000 | M47: =+L47/26000 -> 441.30769
A48: Trading | B48: MFG | C48: 901430 | D48: 135-8837-003_ISW ANTENNA ENCLOSURE, FRONT SENSORS, C3 INJECTION MOLD (1ST INJECTION) | E48: 1 | F48: 2.0774458e+08 | G48: =+F48/26000 -> 7990.1763 | H48: 180000000 | I48: =+H48*E48 -> 180000000 | J48: =+I48/26000 -> 6923.0769 | K48: =+H48 -> 180000000 | L48: =+K48*E48 -> 180000000 | M48: =+L48/26000 -> 6923.0769
A49: Trading | B49: MFG | C49: 901431 | D49: 135-8837-003_ISW ANTENNA ENCLOSURE , FRONT SENSORS, C3 INJECTION MOLD (2nd INJECTION) | E49: 1 | F49: 2.0774458e+08 | G49: =+F49/26000 -> 7990.1763 | H49: 150000000 | I49: =+H49*E49 -> 150000000 | J49: =+I49/26000 -> 5769.2308 | K49: =+H49 -> 150000000 | L49: =+K49*E49 -> 150000000 | M49: =+L49/26000 -> 5769.2308
A50: Trading | B50: MFG | C50: 901432 | D50: 142-7607-002 LOW LIGHT SENSOR BAR INJECTION MOLD | E50: 1 | F50: 2.1335932e+08 | G50: =+F50/26000 -> 8206.1278 | H50: 170000000 | I50: =+H50*E50 -> 170000000 | J50: =+I50/26000 -> 6538.4615 | K50: =+H50 -> 170000000 | L50: =+K50*E50 -> 170000000 | M50: =+L50/26000 -> 6538.4615
A51: Trading | B51: MFG | C51: 901433 | D51: 132-8032-006 _VF Grip_Low Light_C6 INJECTION MOLD - Material : NAK80 | E51: 1 | F51: 1.3475297e+08 | G51: =+F51/26000 -> 5182.8065 | H51: 150000000 | I51: =+H51*E51 -> 150000000 | J51: =+I51/26000 -> 5769.2308 | K51: =+H51 -> 150000000 | L51: =+K51*E51 -> 150000000 | M51: =+L51/26000 -> 5769.2308
A52: Trading | B52: MFG | C52: 901434 | D52: 136-2429-002_ Button Membrane_ Front UI_ C2 INJECTION MOLD | E52: 1 | F52: 111171375 | G52: =+F52/26000 -> 4275.8221 | H52: 130000000 | I52: =+H52*E52 -> 130000000 | J52: =+I52/26000 -> 5000 | K52: =+H52 -> 130000000 | L52: =+K52*E52 -> 130000000 | M52: =+L52/26000 -> 5000
A53: Trading | B53: MFG | C53: 901435 | D53: 132-8032-006, VF Grip, Low Light, C6, RevA, 11-10-25 Silicone Mold | E53: 1 | F53: 1.3475297e+08 | G53: =+F53/26000 -> 5182.8065 | H53: 68000000 | I53: =+H53*E53 -> 68000000 | J53: =+I53/26000 -> 2615.3846 | K53: =+H53 -> 68000000 | L53: =+K53*E53 -> 68000000 | M53: =+L53/26000 -> 2615.3846
A54: Trading | B54: MFG | C54: 901436 | D54: 136-2429-002, Button Membrane, Front UI, C2, RevA Silicone Mold | E54: 1 | F54: 111171375 | G54: =+F54/26000 -> 4275.8221 | H54: 56000000 | I54: =+H54*E54 -> 56000000 | J54: =+I54/26000 -> 2153.8462 | K54: =+H54 -> 56000000 | L54: =+K54*E54 -> 56000000 | M54: =+L54/26000 -> 2153.8462
A55: Trading | B55: MFG | C55: 901437 | D55: 143-0466-001 _ BODY COMPUTE_ANTENNA_CAPS _ LEFT & RIGHT_INJECTION MOLD 2525 | E55: 1 | F55: 212661936 | G55: =+F55/26000 -> 8179.3052 | H55: 150000000 | I55: =+H55*E55 -> 150000000 | J55: =+I55/26000 -> 5769.2308 | K55: =+H55 -> 150000000 | L55: =+K55*E55 -> 150000000 | M55: =+L55/26000 -> 5769.2308
A56: Trading | B56: MFG | C56: 901458 | D56: O-ring for Battery Pack Rear-to-Front Cable (P/N: 143-8808-001-A03) | E56: 15 | F56: 181749 | G56: =+F56/26000 -> 6.9903462 | H56: 12495 | I56: =+H56*E56 -> 187425 | J56: =+I56/26000 -> 7.2086538 | K56: =+H56 -> 12495 | L56: =+K56*E56 -> 187425 | M56: =+L56/26000 -> 7.2086538
A57: Trading | B57: MFG | C57: 901459 | D57: Oring for BATTERY PACK, TOP LID (P/N: 143-6225-001-A04) | E57: 15 | F57: 471774 | G57: =+F57/26000 -> 18.145154 | H57: 12495 | I57: =+H57*E57 -> 187425 | J57: =+I57/26000 -> 7.2086538 | K57: =+H57 -> 12495 | L57: =+K57*E57 -> 187425 | M57: =+L57/26000 -> 7.2086538
A58: FG | B58: LG YANTAI | C58: 120157 | D58: PK LGIT Gen3 AL5 | E58: 38016 | F58: 2158263360 | G58: =+F58/26000 -> 83010.129 | H58: 48824.223 | I58: =+H58*E58 -> 1.8561017e+09 | J58: =+I58/26000 -> 71388.525 | K58: 50620.495 | L58: =+K58*E58 -> 1.9243888e+09 | M58: =+L58/26000 -> 74014.952
A59: FG | B59: LG YANTAI | C59: 120362 | D59: PK LGIT MPC5.5 Cover lens 3HDC00003A | E59: 83819 | F59: 1.9062715e+09 | G59: =+F59/26000 -> 73318.135 | H59: 13779.559 | I59: =+H59*E59 -> 1.1549889e+09 | J59: =+I59/26000 -> 44422.649 | K59: 14228.907 | L59: =+K59*E59 -> 1.1926527e+09 | M59: =+L59/26000 -> 45871.26
A60: FG | B60: LG YANTAI | C60: 120411 | D60: PK PK LGIT MQ4a PE Cover | E60: 16200 | F60: 593541540 | G60: =+F60/26000 -> 22828.521 | H60: 26655.358 | I60: =+H60*E60 -> 4.318168e+08 | J60: =+I60/26000 -> 16608.339 | K60: 27038.492 | L60: =+K60*E60 -> 4.3802357e+08 | M60: =+L60/26000 -> 16847.06
A61: FG | B61: LG YANTAI | C61: 120414 | D61: PK LGIT MQ4a PE Housing 3CAZ00039A | E61: 16200 | F61: 1383536970 | G61: =+F61/26000 -> 53212.96 | H61: =108739.09367+2355212817 -> 2.3553216e+09 | I61: =+H61*E61 -> 3.8156209e+13 | J61: =+I61/26000 -> 1.4675465e+09 | K61: =+H61 -> 2.3553216e+09 | L61: =+K61*E61 -> 3.8156209e+13 | M61: =+L61/26000 -> 1.4675465e+09
A62: FG | B62: LG YANTAI | C62: 120415 | D62: PK LGIT 3CAZ00041A CL4 Housing | E62: 31446 | F62: 2.7334606e+09 | G62: =+F62/26000 -> 105133.1 | H62: 63694.348 | I62: =+H62*E62 -> 2.0029325e+09 | J62: =+I62/26000 -> 77035.864 | K62: 78595.287 | L62: =+K62*E62 -> 2.4715074e+09 | M62: =+L62/26000 -> 95057.976
A63: FG | B63: LG YANTAI | C63: 120416 | D63: PK LGIT 3CAZ00042A CL4 Cover | E63: 19099 | F63: 6.6046721e+08 | G63: =+F63/26000 -> 25402.585 | H63: 25784.69 | I63: =+H63*E63 -> 4.9246179e+08 | J63: =+I63/26000 -> 18940.838 | K63: 27793.351 | L63: =+K63*E63 -> 5.3082521e+08 | M63: =+L63/26000 -> 20416.354
A64: Trading | B64: LG YANTAI | C64: 901371 | D64: Mold Die casting CL4 Housing 1 CAV (Full set) #17 | E64: 1 | F64: 6.1736723e+08 | G64: =+F64/26000 -> 23744.893 | H64: 450000000 | I64: =+H64*E64 -> 450000000 | J64: =+I64/26000 -> 17307.692 | K64: =+H64 -> 450000000 | L64: =+K64*E64 -> 450000000 | M64: =+L64/26000 -> 17307.692
A65: FG | B65: LG KOREA | C65: 120332 | D65: PK LGIT DCU15 3CAC00306A Housing | E65: 27000 | F65: 479512995 | G65: =+F65/26000 -> 18442.807 | H65: 9931.666 | I65: =+H65*E65 -> 2.6815498e+08 | J65: =+I65/26000 -> 10313.653 | K65: 9018.5208 | L65: =+K65*E65 -> 2.4350006e+08 | M65: =+L65/26000 -> 9365.387
A66: FG | B66: LG KOREA | C66: 120333 | D66: PK LGIT DCU15 3CAC00307A Cover | E66: 27000 | F66: 337538175 | G66: =+F66/26000 -> 12982.237 | H66: 5942.602 | I66: =+H66*E66 -> 1.6045025e+08 | J66: =+I66/26000 -> 6171.1636 | K66: 4345.8392 | L66: =+K66*E66 -> 1.1733766e+08 | M66: =+L66/26000 -> 4512.9869
A67: FG | B67: LG MEXICO | C67: 120411 | D67: PK PK LGIT MQ4a PE Cover | E67: 20000 | F67: 724920000 | G67: =+F67/26000 -> 27881.538 | H67: 26655.358 | I67: =+H67*E67 -> 5.3310716e+08 | J67: =+I67/26000 -> 20504.122 | K67: 27038.492 | L67: =+K67*E67 -> 5.4076984e+08 | M67: =+L67/26000 -> 20798.84
A68: FG | B68: LG MEXICO | C68: 120414 | D68: PK LGIT MQ4a PE Housing 3CAZ00039A | E68: 20000 | F68: 1662138000 | G68: =+F68/26000 -> 63928.385 | H68: 61253.781 | I68: =+H68*E68 -> 1.2250756e+09 | J68: =+I68/26000 -> 47118.293 | K68: =+H68 -> 61253.781 | L68: =+K68*E68 -> 1.2250756e+09 | M68: =+L68/26000 -> 47118.293
A69: FG | B69: LG MEXICO | C69: 120415 | D69: PK LGIT 3CAZ00041A CL4 Housing | E69: 20000 | F69: 1693206000 | G69: =+F69/26000 -> 65123.308 | H69: 63694.348 | I69: =+H69*E69 -> 1.273887e+09 | J69: =+I69/26000 -> 48995.652 | K69: 78595.287 | L69: =+K69*E69 -> 1.5719057e+09 | M69: =+L69/26000 -> 60457.913
A70: FG | B70: LG MEXICO | C70: 120416 | D70: PK LGIT 3CAZ00042A CL4 Cover | E70: 20000 | F70: 683496000 | G70: =+F70/26000 -> 26288.308 | H70: 25784.69 | I70: =+H70*E70 -> 5.1569379e+08 | J70: =+I70/26000 -> 19834.377 | K70: 27793.351 | L70: =+K70*E70 -> 5.5586702e+08 | M70: =+L70/26000 -> 21379.501
...

Sheet Sch 1 - Sales
C1: Sales summary 2026
D2: 25000 | E2: 25000 | F2: 25000 | G2: 25500 | H2: 25500 | I2: 25500 | J2: 25500 | K2: 25500 | L2: 26000 | M2: 26000 | N2: 26000 | O2: 26000 | P2: Ex.rate: | Q2: 26000
B3: STT | C3: By Customer | D3: Jan | E3: Feb | F3: Mar | G3: Apr | H3: May | I3: Jun | J3: July | K3: Aug | L3: Sep | M3: Oct | N3: Nov | O3: Dec | P3: Total | Q3: % | R3: Cos
A4: CD-0004 | B4: =SUBTOTAL(3,$C$3:C3) -> 1 | C4: ELENTEC | D4: 604744.27 | E4: 756522.2 | F4: 608328.86 | G4: 415561.43 | P4: =+SUM(D4:O4) -> 2385156.8 | Q4: =+P4/$P$32 -> 0.1681923 | R4: Samsung Others
A5: CD-0003 | B5: =SUBTOTAL(3,$C$3:C4) -> 2 | C5: INTOPS | D5: 335328.18 | E5: 106660.8 | F5: 113821.5 | G5: 188120.69 | P5: =+SUM(D5:O5) -> 743931.17 | Q5: =+P5/$P$32 -> 0.052459234 | R5: Samsung Others
A6: CD-0005 | B6: =SUBTOTAL(3,$C$3:C5) -> 3 | C6: MOBASE | D6: 32440.034 | E6: 0 | F6: 41155.034 | G6: 55359.36 | P6: =+SUM(D6:O6) -> 128954.43 | Q6: =+P6/$P$32 -> 0.0090933823 | R6: Samsung Others
A7: CD-0001 | B7: =SUBTOTAL(3,$C$3:C6) -> 4 | C7: SEVT | D7: 593607.82 | E7: 397029.05 | F7: 638739.25 | G7: 395524.35 | P7: =+SUM(D7:O7) -> 2024900.5 | Q7: =+P7/$P$32 -> 0.14278838 | R7: Samsung CNC: Sale
A8: CF-0023-1 | B8: 5 | C8: MFG-Qualcomm | D8: 69610.571 | E8: 41511.335 | F8: 50108.973 | G8: 60343.375 | P8: =+SUM(D8:O8) -> 221574.25 | Q8: =+P8/$P$32 -> 0.015624585 | R8: Qualcomm ( Mobile)
A9: CF-0023-2 | B9: 6 | C9: MFG-ASG | D9: 0 | E9: 58059.391 | F9: 20296.514 | G9: 82073.518 | P9: =+SUM(D9:O9) -> 160429.42 | Q9: =+P9/$P$32 -> 0.011312881 | R9: Qualcomm ( Mobile)
A10: CF-0005 | B10: =SUBTOTAL(3,$C$3:C9) -> 7 | C10: LG YANTAI | D10: 439497.67 | E10: 386650.32 | F10: 730071.83 | G10: 592426.44 | P10: =+SUM(D10:O10) -> 2148646.3 | Q10: =+P10/$P$32 -> 0.15151447 | R10: LGIT
A11: CF-0012 | B11: =SUBTOTAL(3,$C$3:C10) -> 8 | C11: LG KOREA | D11: 27064.312 | E11: 31425.045 | F11: 76617.498 | G11: 76718.642 | P11: =+SUM(D11:O11) -> 211825.5 | Q11: =+P11/$P$32 -> 0.014937139 | R11: LGIT
A12: CF-0006 | B12: =SUBTOTAL(3,$C$3:C11) -> 9 | C12: LG MEXICO | D12: 34795.633 | E12: 230453.46 | F12: 27226.136 | G12: 264238.78 | P12: =+SUM(D12:O12) -> 556714.01 | Q12: =+P12/$P$32 -> 0.039257383 | R12: LGIT
A13: CF-0007 | B13: =SUBTOTAL(3,$C$3:C12) -> 10 | C13: ZF POLAND | D13: 196323.69 | E13: 194930.25 | F13: 186807.09 | G13: 175585.87 | P13: =+SUM(D13:O13) -> 753646.89 | Q13: =+P13/$P$32 -> 0.05314435 | R13: ZF
A14: CF-0010 | B14: =SUBTOTAL(3,$C$3:C13) -> 11 | C14: ZF SHANGHAI | D14: 82267.015 | E14: 0 | F14: 102419.41 | G14: 89314.257 | P14: =+SUM(D14:O14) -> 274000.69 | Q14: =+P14/$P$32 -> 0.0193215 | R14: ZF
A15: CF-0009 | B15: =SUBTOTAL(3,$C$3:C14) -> 12 | C15: ZF US | D15: 292701.27 | E15: 0 | F15: 399697.3 | G15: 4829.9798 | P15: =+SUM(D15:O15) -> 697228.55 | Q15: =+P15/$P$32 -> 0.049165941 | R15: ZF
A16: CF-0011 | B16: =SUBTOTAL(3,$C$3:C15) -> 13 | C16: ZF UK | D16: 58523.918 | E16: 67931.002 | F16: 87723.904 | G16: 95266.498 | P16: =+SUM(D16:O16) -> 309445.32 | Q16: =+P16/$P$32 -> 0.021820923 | R16: ZF
A17: CF-0017 | B17: =SUBTOTAL(3,$C$3:C16) -> 14 | C17: ZF MEXICO | D17: 110834.5 | E17: 109746.14 | F17: 111174.61 | G17: 0 | P17: =+SUM(D17:O17) -> 331755.25 | Q17: =+P17/$P$32 -> 0.023394135 | R17: ZF
A18: CF-0029 | B18: 16 | C18: ZF BRASIL | G18: 19419.771 | P18: =+SUM(D18:O18) -> 19419.771 | Q18: =+P18/$P$32 -> 0.0013694093 | R18: ZF
A19: CF-0013 | B19: =SUBTOTAL(3,$C$3:C17) -> 15 | C19: MANDO (ZHANGJIAGANG) | D19: 513233.63 | E19: 594948.02 | F19: 658588.51 | G19: 524204.8 | P19: =+SUM(D19:O19) -> 2290975 | Q19: =+P19/$P$32 -> 0.16155096 | R19: Mando
A20: CF-0015 | B20: =SUBTOTAL(3,$C$3:C19) -> 17 | C20: HL KLEMOVE INDIA | D20: 109952.43 | E20: 73594.524 | F20: 74493.236 | G20: 111853.98 | P20: =+SUM(D20:O20) -> 369894.17 | Q20: =+P20/$P$32 -> 0.026083549 | R20: Mando
A21: CF-0027 | B21: =SUBTOTAL(3,$C$3:C20) -> 18 | C21: MANDO CORPORATION | D21: 429.243 | E21: 1140.1615 | G21: 18270.47 | P21: =+SUM(D21:O21) -> 19839.875 | Q21: =+P21/$P$32 -> 0.0013990335 | R21: Mando
A22: CF-0014 | B22: =SUBTOTAL(3,$C$3:C21) -> 19 | C22: MANDO KOREA | D22: 0 | E22: 0 | G22: 0 | P22: =+SUM(D22:O22) -> 0 | Q22: =+P22/$P$32 -> 0 | R22: Mando
A23: CD-0008 | B23: =SUBTOTAL(3,$C$3:C22) -> 20 | C23: TTI | D23: 0 | E23: 0 | G23: 0 | P23: =+SUM(D23:O23) -> 0 | Q23: =+P23/$P$32 -> 0 | R23: TTI
A24: CF-0019 | B24: =SUBTOTAL(3,$C$3:C23) -> 21 | C24: HYOSEONG | D24: 0 | E24: 0 | G24: 0 | P24: =+SUM(D24:O24) -> 0 | Q24: =+P24/$P$32 -> 0 | R24: Hyoseong
A25: CF-0022 | B25: =SUBTOTAL(3,$C$3:C24) -> 22 | C25: DORIGO | D25: 0 | E25: 0 | G25: 0 | P25: =+SUM(D25:O25) -> 0 | Q25: =+P25/$P$32 -> 0 | R25: Dorigo
A26: CF-0028 | B26: =SUBTOTAL(3,$C$3:C25) -> 23 | C26: TAILYN | D26: 23541.21 | E26: 0 | F26: 23505.09 | G26: 0 | P26: =+SUM(D26:O26) -> 47046.3 | Q26: =+P26/$P$32 -> 0.0033175285 | R26: TAILYN
A27: CD-0027 | B27: =SUBTOTAL(3,$C$3:C26) -> 24 | C27: LONG BÌNH | D27: 0 | E27: 0 | F27: 704 | G27: 4296 | P27: =+SUM(D27:O27) -> 5000 | Q27: =+P27/$P$32 -> 0.00035258123 | R27: LONG BINH
A28: CD-0012 | B28: =SUBTOTAL(3,$C$3:C27) -> 25 | C28: THUAN THANH | D28: 22187.783 | E28: 10306.643 | F28: 29313.916 | G28: 29493.846 | P28: =+SUM(D28:O28) -> 91302.189 | Q28: =+P28/$P$32 -> 0.0064382877 | R28: Waste
A29: CD-0013 | B29: =SUBTOTAL(3,$C$3:C28) -> 26 | C29: BÌNH NGUYÊN | D29: 30274.907 | E29: 15704.634 | F29: 32224.831 | G29: 19322.124 | P29: =+SUM(D29:O29) -> 97526.497 | Q29: =+P29/$P$32 -> 0.0068772025 | R29: Waste
A30: CD-0010 | B30: =SUBTOTAL(3,$C$3:C29) -> 27 | C30: TONKIN | D30: 15630.07 | E30: 22544.773 | F30: 24441.486 | G30: 22867.343 | P30: =+SUM(D30:O30) -> 85483.671 | Q30: =+P30/$P$32 -> 0.0060279877 | R30: Waste
A31: CD-0015 | B31: =SUBTOTAL(3,$C$3:C30) -> 28 | C31: MINH PHÚC | D31: 53192.902 | E31: 44673.601 | F31: 59051.469 | G31: 49514.685 | P31: =+SUM(D31:O31) -> 206432.66 | Q31: =+P31/$P$32 -> 0.014556856 | R31: Waste
B32: Total Sales | D32: =SUM(D4:D31) -> 3646181.1 | E32: =SUM(E4:E31) -> 3143831.3 | F32: =SUM(F4:F31) -> 4096510.4 | G32: =SUM(G4:G31) -> 3294606.2 | H32: =SUM(H4:H31) -> 0 | I32: =SUM(I4:I31) -> 0 | J32: =SUM(J4:J31) -> 0 | K32: =SUM(K4:K31) -> 0 | ... Q32: =SUM(Q4:Q31) -> 1 | R32: =+(D32+E32+F32)*25000+(G32+H32+I32+J32)*25500+K32*25500+L32*26000+M32*26000+N32*26000+O32*26000 -> 3.5617553e+11
C33: TB | D33: 3646181.1 | E33: 3143831.3 | F33: =3457771.19413846+F7 -> 4096510.4 | G33: 3294606.2

Sheet 02.Income Statement 
B1: 01. 2020Y Monthly Income Statement
B2: Income Statement | P2: [unit: USD]
B3: Description | C3: Jan.26 | D3: Feb.26 | E3: Mar.26 | F3: Apr.26 | G3: May.26 | H3: Jun.26 | I3: Jul.26 | J3: Aug.26 | K3: Sep.26 | L3: Oct.26 | M3: Nov.26 | N3: Dec.26 | O3: TotalY26 | P3: 4월 수정 | Q3: 조정내용
B4: Total Sale | C4: =SUM(C5:C7) -> 3646181.1 | D4: =SUM(D5:D7) -> 3143831.3 | E4: =SUM(E5:E7) -> 4096510.4 | F4: =SUM(F5:F7) -> 3294606.2 | G4: =SUM(G5:G7) -> 0 | H4: =SUM(H5:H7) -> 0 | I4: =SUM(I5:I7) -> 0 | J4: =SUM(J5:J7) -> 0 | ... N4: =SUM(N5:N7) -> 0 | O4: =SUM(C4:N4) -> 14181129 | P4: =SUM(P5:P7) -> 3375582.2
B5: Sales | C5: 3468446.9 | D5: 2951628.6 | E5: 3887018.2 | F5: 3055323.5 | O5: =SUM(C5:N5) -> 13362417 | P5: =3055323.54918077+'비용 증가 사유'!E12 -> 3136299.5 | Q5: A276 금형 정상 매출 반영시 (+8만불)
B6: Sales-trading | C6: 56448.55 | D6: 98973.047 | E6: 64460.585 | F6: 118084.66 | O6: =SUM(C6:N6) -> 337966.84 | P6: 118084.66
B7: Sales -scrap | C7: 121285.66 | D7: 93229.652 | E7: 145031.7 | F7: 121198 | O7: =SUM(C7:N7) -> 480745.01 | P7: 121198
B8: Cost of Goods Sold | C8: =C9+C10-C11+C12 -> 2633553.7 | D8: =D9+D10-D11+D12 -> 2581808.6 | E8: =E9+E10-E11+E12-E13+265 -> 3130898.4 | F8: =F9+F10-F11+F12 -> 2825043.4 | G8: =G9+G10-G11+G12+G13 -> 0 | H8: =H9+H10-H11+H12+H13 -> 0 | I8: =I9+I10-I11+I12+I13 -> 0 | J8: =J9+J10-J11+J12+J13 -> 0 | K8: =K9+K10-K11+K12+K13 -> 0 | L8: =L9+L10-L11+L12+L13 -> 0 | M8: =M9+M10-M11+M12+M13 -> 0 | N8: =N9+N10-N11+N12+N13 -> 0 | O8: =SUM(C8:N8) -> 11171304 | P8: =P9+P10-P11+P12 -> 2814781.4
B9: Beginning Goods | C9: 1552094.3 | D9: 1685226.7 | E9: 1326384.5 | F9: 846959.1 | O9: =SUM(C9:N9) -> 5410664.5 | P9: 846959.1
B10: Manufacturing cost | C10: 2662039.5 | D10: 2210773.2 | E10: 2856536.5 | F10: 2717168.7 | O10: =SUM(C10:N10) -> 10446518 | P10: =2717168.6991031-50000-15000+'비용 증가 사유'!F12 -> 2706906.7 | Q10: OT관리 (-5만불) + 금형원가반영 (+5.4만불)
B11: Ending Goods | C11: 1629668 | D11: 1326384.5 | E11: 846959.1 | F11: 808791.43 | O11: =SUM(C11:N11) -> 4611803 | P11: 808791.43
B12: Cost of Trading & Others | C12: 49088 | D12: 12193.199 | E12: -92960 | F12: 69707 | O12: =SUM(C12:N12) -> 38028.199 | P12: 69707
B13: Clear stock | C13: 204746.19 | D13: =+'PL USD'!F17 -> 95089.477 | E13: 112368.48 | O13: =SUM(C13:N13) -> 412204.15
B14: Gross margin | C14: =C4-C8-C13 -> 807881.19 | D14: =D4-D8-D13 -> 466933.26 | E14: =E4-E8-E13 -> 853243.6 | F14: =F4-F8-F13 -> 469562.84 | G14: =G4-G8 -> 0 | H14: =H4-H8 -> 0 | I14: =I4-I8 -> 0 | J14: =J4-J8 -> 0 | K14: =K4-K8 -> 0 | L14: =L4-L8 -> 0 | M14: =M4-M8 -> 0 | N14: =N4-N8 -> 0 | O14: =O4-O8 -> 3009825 | P14: =P4-P8-P13 -> 560800.84
B15: SA&GA | C15: 348666.18 | D15: =+'PL USD'!F46 -> 334109.77 | E15: =+'PL USD'!G46 -> 351521.91 | F15: =+'PL USD'!H46 -> 366191.26 | O15: =SUM(C15:N15) -> 1400489.1 | P15: =F15-12000 -> 354191.26 | Q15: Air 물류비 관리 (-1.2만불)
B16: R&D | C16: 70161.86 | D16: =+'PL USD'!F62 -> 59271.189 | E16: =+'PL USD'!G62 -> 65128.591 | F16: =+'PL USD'!H62 -> 64351.366 | O16: =SUM(C16:N16) -> 258913.01 | P16: =F16 -> 64351.366
B17: Operating profit | C17: =+C14-C15-C16 -> 389053.15 | D17: =+D14-D15-D16 -> 73552.302 | E17: =+E14-E15-E16 -> 436593.1 | F17: =+F14-F15-F16 -> 39020.217 | G17: =G14-G15-G16 -> 0 | H17: =H14-H15-H16 -> 0 | I17: =I14-I15-I16 -> 0 | J17: =J14-J15-J16 -> 0 | K17: =K14-K15-K16 -> 0 | L17: =L14-L15-L16 -> 0 | M17: =M14-M15-M16 -> 0 | N17: =N14-N15-N16 -> 0 | O17: =O14-O15-O16 -> 1350422.9 | P17: =+P14-P15-P16 -> 142258.22
B18: Other Profit & Loss | C18: -96154.297 | D18: -73552.302 | E18: =-395029.837433846 -> -395029.84 | F18: -29210.882 | O18: =SUM(C18:N18) -> -593947.32 | P18: -29210.882
B19: investment income | O19: =SUM(C19:N19) -> 0
B20: Ordinary profit | C20: =C17+C18 -> 292898.86 | D20: =D17+D18 -> 0 | E20: =E17+E18 -> 41563.259 | F20: =F17+F18 -> 9809.3356 | G20: =G17+G18 -> 0 | H20: =H17+H18 -> 0 | I20: =I17+I18 -> 0 | J20: =J17+J18 -> 0 | ... P20: =P17+P18 -> 113047.34
B21: Non - deductable expense | C21: 14107 | D21: 9892.8426 | E21: 8792 | F21: 13566 | O21: =SUM(C21:N21) -> 46357.843 | P21: 13566
B22: Chargable income accumulated | C22: =+C20+C21 -> 307005.86 | D22: =+D20+D21 -> 9892.8426 | E22: =+E20+E21 -> 50355.259 | F22: =+F20+F21 -> 23375.336 | G22: =+G20+G21 -> 0 | H22: =+H20+H21 -> 0 | I22: =+I20+I21 -> 0 | J22: =+J20+J21 -> 0 | ... N22: =+N20+N21 -> 0 | O22: =SUM(C22:N22) -> 390629.29 | P22: =+P20+P21 -> 126613.34 | S22: Carried forward Losses | T22: Remaining
B23: CIT 20% | O23: =SUM(C23:N23) -> 0
B24: Net Income Before clear stock | C24: =+C20+C13+C23 -> 497645.05 | D24: =+D20+D13-D23 -> 95089.477 | E24: =+E20+E13-E23+Q18 -> 153931.74 | F24: =+F20+F13-F23 -> 9809.3356 | G24: =+G20+G13-G23 -> 0 | H24: =+H20+H13-H23 -> 0 | I24: =+I20+I13-I23 -> 0 | J24: =+J20+J13-J23 -> 0 | K24: =+K20+K13-K23 -> 0 | L24: =+L20+L13-L23 -> 0 | M24: =+M20+M13-M23 -> 0 | N24: =+N20-N23+N13 -> 0 | O24: =+O20+O13-O23+S24 -> 1168679.7 | P24: =+P20+P13-P23 -> 113047.34
B25: Net Income After clear stock | C25: =+C20-C23 -> 292898.86 | D25: =+D20-D23 -> 0 | E25: =+E20-E23 -> 41563.259 | F25: =+F20-F23 -> 9809.3356 | G25: =+G20-G23 -> 0 | H25: =+H20-H23 -> 0 | I25: =+I20-I23 -> 0 | J25: =+J20-J23 -> 0 | ... N25: =+N20-N23 -> 0 | O25: =SUM(C25:N25) -> 344271.45 | P25: =+P20-P23 -> 113047.34 | S25: 941645.19 | T25: =+S25-O22 -> 551015.9
B26: Gross profit Margin | C26: =IF(C14/C4<>0,C14/C4,"") -> 0.22156914 | D26: =IF(D14/D4<>0,D14/D4,"") -> 0.14852363 | E26: =IF(E14/E4<>0,E14/E4,"") -> 0.20828547 | F26: =IF(F14/F4<>0,F14/F4,"") -> 0.14252473 | G26: =IF(G14/G4<>0,G14/G4,"") -> #DIV/0! | H26: =IF(H14/H4<>0,H14/H4,"") -> #DIV/0! | I26: =IF(I14/I4<>0,I14/I4,"") -> #DIV/0! | J26: =IF(J14/J4<>0,J14/J4,"") -> #DIV/0! | ... N26: =IF(N14/N4<>0,N14/N4,"") -> #DIV/0! | O26: =O14/O4 -> 0.21224157 | P26: =IF(P14/P4<>0,P14/P4,"") -> 0.16613455
B27: COGSTS | C27: =C8/C4 -> 0.72227726 | D27: =D8/D4 -> 0.82123 | E27: =E8/E4 -> 0.76428424 | F27: =F8/F4 -> 0.85747527 | G27: =G8/G4 -> #DIV/0! | H27: =H8/H4 -> #DIV/0! | I27: =I8/I4 -> #DIV/0! | J27: =J8/J4 -> #DIV/0! | ... P27: =P8/P4 -> 0.83386545
B28: Business management fee rate | C28: =(C15+C16)/C4 -> 0.11486759 | D28: =(D15+D16)/D4 -> 0.12512788 | E28: =(E15+E16)/E4 -> 0.10170864 | F28: =(F15+F16)/F4 -> 0.13068106 | G28: =(G15+G16)/G4 -> #DIV/0! | H28: =(H15+H16)/H4 -> #DIV/0! | I28: =(I15+I16)/I4 -> #DIV/0! | J28: =(J15+J16)/J4 -> #DIV/0! | ... P28: =(P15+P16)/P4 -> 0.12399124
B29: Net Profit Margin ( before) | C29: =C24/C4 -> 0.13648391 | D29: =D24/D4 -> 0.030246367 | E29: =E24/E4 -> 0.037576307 | F29: =F24/F4 -> 0.0029773924 | G29: =G24/G4 -> #DIV/0! | H29: =H24/H4 -> #DIV/0! | I29: =I24/I4 -> #DIV/0! | J29: =J24/J4 -> #DIV/0! | ... P29: =P24/P4 -> 0.03348973 | Q29: 약 +3% 개선
B30: Net Profit Margin ( after) | C30: =C25/C4 -> 0.08033031 | D30: =D25/D4 -> 0 | E30: =E25/E4 -> 0.010146016 | F30: =F25/F4 -> 0.0029773924 | G30: =G25/G4 -> #DIV/0! | H30: =H25/H4 -> #DIV/0! | I30: =I25/I4 -> #DIV/0! | J30: =J25/J4 -> #DIV/0! | ... P30: =P25/P4 -> 0.03348973
B31: EBITDA | C31: =+C25+C33+C34+C35+C36 -> 703640.85 | D31: =+D25+D33+D34+D35+D36 -> 400745.32 | E31: =+E25+E33+E34+E35+E36 -> 432934.01 | F31: =+F25+F33+F34+F35+F36 -> 407234.1 | G31: =+G25+G33+G34+G35+G36 -> 0 | H31: =+H25+H33+H34+H35+H36 -> 0 | I31: =+I25+I33+I34+I35+I36 -> 0 | J31: =+J24+J33+J34+J35+J36 -> 0 | K31: =+K24+K33+K34+K35+K36 -> 0 | L31: =+L24+L33+L34+L35+L36 -> 0 | M31: =+M24+M33+M34+M35+M36 -> 0 | N31: =+N24+N33+N34+N35+N36 -> 0 | O31: =+O25+O33+O34+O35+O36 -> 1944554.3 | P31: =+P25+P33+P34+P35+P36 -> 510472.1
B33: Interest Expenses | C33: 77451.044 | D33: 63055.526 | E33: 52889.094 | F33: =+'PL USD'!H90 -> 58686.246 | O33: =SUM(C33:N33) -> 252081.91 | P33: =F33 -> 58686.246
B34: Taxes | C34: 0 | D34: 0 | E34: 0 | O34: =SUM(C34:N34) -> 0
B35: Depreciation | C35: 205800.61 | D35: 209386.77 | E35: 209759.11 | F35: =+'PL USD'!H92 -> 205689.61 | O35: =SUM(C35:N35) -> 830636.09 | P35: =F35 -> 205689.61
B36: Amortization | C36: 127490.34 | D36: 128303.03 | E36: 128722.55 | F36: =+'PL USD'!H93 -> 133048.9 | O36: =SUM(C36:N36) -> 517564.82 | P36: =F36 -> 133048.9

Sheet PL USD
A1: Statement of Comprehensive Income | C1: Statement of Comprehensive Income
A2: January 2024 through Dec 2024 | C2: January 2026 through Dec 2026 | D2: 25000 | E2: 25000 | F2: 25000 | G2: 25000 | H2: 25000 | I2: 25000 | J2: 25000 | K2: 25000 | L2: 25000 | M2: 25000 | N2: 25000 | O2: 25000 | P2: 25000
D3: 12 | E3: 01 | F3: 02 | G3: 03 | H3: 04 | I3: 05 | J3: 06 | K3: 07 | L3: 08 | M3: 09 | N3: 10 | O3: 11 | P3: 12 | Q3: 4 | S3: Monthly
D4: 45992 | E4: Jan.26 | F4: February | G4: March | H4: April | I4: May | J4: June | K4: Jul | L4: Aug | M4: Sep | N4: Oct | O4: Nov | P4: Dec | Q4: Total | R4: % | S4: Average
A5: 4-0000 | C5: Income | D5: =+D6+D7+D8 -> 4017516.6 | E5: =+E6+E7+E8 -> 3646181.1 | F5: =+F6+F7+F8 -> 3143831.3 | G5: =+G9 -> 4096510.4 | H5: =+H6+H7+H8 -> 3294606.2 | Q5: =SUM(E5:OFFSET(E5,0,$Q$3-1)) -> 14181129
A6: 4-1000 | C6: Sales | D6: 3823390 | E6: 3468446.9 | F6: 2951628.6 | G6: 3887018.2 | H6: 3055323.5 | Q6: =SUM(E6:OFFSET(E6,0,$Q$3-1)) -> 13362417 | S6: =AVERAGE(E6:OFFSET(E6,0,$Q$3-1)) -> 3340604.3
A7: 4-1001 | C7: Sales-trading | D7: 54436.813 | E7: 56448.55 | F7: 98973.047 | G7: 64460.585 | H7: 118084.66 | Q7: =SUM(E7:OFFSET(E7,0,$Q$3-1)) -> 337966.84 | S7: =AVERAGE(E7:OFFSET(E7,0,$Q$3-1)) -> 84491.711
A8: 4-1002 | C8: Sales -scrapt | D8: 139689.74 | E8: 121285.66 | F8: 93229.652 | G8: 145031.7 | H8: 121198 | Q8: =SUM(E8:OFFSET(E8,0,$Q$3-1)) -> 480745.01 | S8: =AVERAGE(E8:OFFSET(E8,0,$Q$3-1)) -> 120186.25
C9: Total Income | D9: =SUM(D6:D8) -> 4017516.6 | E9: =SUM(E6:E8) -> 3646181.1 | F9: =SUM(F6:F8) -> 3143831.3 | G9: =SUM(G6:G8) -> 4096510.4 | H9: 3294606.2 | Q9: =SUM(Q6:Q8) -> 14181129 | S9: =AVERAGE(E9:OFFSET(E9,0,$Q$3-1)) -> 3545282.3
A10: 5-0000 | C10: Cost of Goods Sold | D10: 3299928.3 | E10: 2633553.7 | F10: 2581808.6 | G10: 3130898.3 | H10: 2825043.3 | Q10: =SUM(E10:OFFSET(E10,0,$Q$3-1)) -> 11171304 | S10: =AVERAGE(E10:OFFSET(E10,0,$Q$3-1)) -> 2792826
A11: 5-1001 | C11: Beginning Goods | D11: 1454995 | E11: 1552094.3 | F11: 1685226.7 | G11: 1326384.5 | H11: 846959.1 | Q11: =SUM(E11:OFFSET(E11,0,$Q$3-1)) -> 5410664.5 | S11: =AVERAGE(E11:OFFSET(E11,0,$Q$3-1)) -> 1352666.1
A12: 5-1002 | C12: Manufacturing cost | D12: 3264245.8 | E12: 2816146.9 | F12: 2210773.2 | G12: 2856536.5 | H12: 2717168.7 | Q12: =SUM(E12:OFFSET(E12,0,$Q$3-1)) -> 10600625 | S12: =AVERAGE(E12:OFFSET(E12,0,$Q$3-1)) -> 2650156.3
A13: 5-1003 | C13: Ending Goods | D13: 1532520.9 | E13: 1665118 | F13: 1326384.5 | G13: 846959.1 | H13: 808791.43 | Q13: =SUM(E13:OFFSET(E13,0,$Q$3-1)) -> 4647253 | S13: =AVERAGE(E13:OFFSET(E13,0,$Q$3-1)) -> 1161813.2
A14: 5-1004 | C14: Cost of other sold | D14: 74475.206 | E14: 14119.821 | F14: 31288.489 | G14: -139435.4 | H14: -16440.744 | Q14: =SUM(E14:OFFSET(E14,0,$Q$3-1)) -> -110467.84 | S14: =AVERAGE(E14:OFFSET(E14,0,$Q$3-1)) -> -27616.96
A15: 5-1005 | C15: Cost of trading | D15: 38733.077 | E15: 40113.887 | F15: 75994.187 | G15: 46740.305 | H15: 86147.695 | Q15: =SUM(E15:OFFSET(E15,0,$Q$3-1)) -> 248996.07 | S15: =AVERAGE(E15:OFFSET(E15,0,$Q$3-1)) -> 62249.019
C16: Total Cost of Goods Sold | D16: =+D10 -> 3299928.3 | E16: =+E10 -> 2633553.7 | F16: =+F10 -> 2581808.6 | G16: =+G10 -> 3130898.3 | H16: =+H10 -> 2825043.3 | Q16: =+Q10 -> 11171304 | S16: =AVERAGE(E16:OFFSET(E16,0,$Q$3-1)) -> 2792826
C17: CLEAR STOCK | D17: 227313.96 | E17: 204746.19 | F17: =2472326397.42279/26000 -> 95089.477 | G17: 112368.48 | Q17: =SUM(E17:OFFSET(E17,0,$Q$3-1)) -> 412204.15 | S17: =AVERAGE(E17:OFFSET(E17,0,$Q$3-1)) -> 137401.38
C18: Gross Profit without clear stock | D18: =D5-D10 -> 717588.32 | E18: =E5-E10 -> 1012627.4 | F18: =F5-F10 -> 562022.74 | G18: =G5-G10 -> 965612.18 | H18: =H5-H10 -> 469562.89 | I18: =I5-I10 -> 0 | J18: =J5-J10 -> 0 | K18: =K5-K10 -> 0 | ... Q18: =Q5-Q10 -> 3009825.2 | R18: =+Q18/Q5 -> 0.21224158 | S18: =AVERAGE(E18:OFFSET(E18,0,$Q$3-1)) -> 752456.3
C19: Gross margin | D19: =+D18/D5 -> 0.1786149 | E19: =+E18/E5 -> 0.27772273 | F19: =+F18/F5 -> 0.17877 | G19: =+G18/G5 -> 0.23571579 | H19: =+H18/H5 -> 0.14252474 | Q19: =+Q18/Q5 -> 0.21224158
C20: Gross Profit clear stock | D20: =+D9-D16-D17 -> 490274.36 | E20: =+E9-E16-E17 -> 807881.18 | F20: =+F9-F16-F17 -> 466933.26 | G20: =+G9-G16-G17 -> 853243.7 | H20: =+H9-H16-H17 -> 469562.89 | Q20: =+Q9-Q16-Q17 -> 2597621 | R20: =+Q20/Q5 -> 0.18317449 | S20: =AVERAGE(E20:OFFSET(E20,0,$Q$3-1)) -> 649405.26
C21: Gross margin | D21: =+D20/D5 -> 0.12203418 | E21: =+E20/E5 -> 0.22156913 | F21: =+F20/F5 -> 0.14852363 | G21: =+G20/G5 -> 0.20828549 | H21: =+H20/H5 -> 0.14252474 | Q21: =+Q20/Q5 -> 0.18317449
A22: 6-0000 | C22: Expenses(SA&GA) | D22: Dec.25 | E22: Jan.26 | F22: Feb.26 | G22: Mar.26 | H22: Apr.26 | I22: May.26 | J22: Jun.26 | K22: Jul.26 | L22: Aug.26 | M22: Sep.26 | N22: Oct.26 | O22: Nov.26 | P22: Dec.26 | Q22: Total | R22: % | S22: Average
A23: 6-0101 | C23: Salary (Included PIT,SHUI) | D23: 132527.42 | E23: 111161.2 | F23: 112429.82 | G23: 112019.33 | H23: 111093.04 | Q23: =SUM(E23:OFFSET(E23,0,$Q$3-1)) -> 446703.39 | R23: =+Q23/($Q$46+$Q$62) -> 0.26919538 | S23: =AVERAGE(E23:OFFSET(E23,0,$Q$3-1)) -> 111675.85
A24: 6-0102 | C24: Meal + other Welfare | D24: 21448.983 | E24: 7760.4779 | F24: 9958.0508 | G24: 8847.4437 | H24: 13127.86 | Q24: =SUM(E24:OFFSET(E24,0,$Q$3-1)) -> 39693.833 | R24: =+Q24/($Q$46+$Q$62) -> 0.023920563 | S24: =AVERAGE(E24:OFFSET(E24,0,$Q$3-1)) -> 9923.4581
A25: 6-0103 | C25: Travel -business trips | D25: 1642.5093 | E25: 3053.386 | F25: 9733.6693 | G25: -3304.3547 | H25: 760.47231 | Q25: =SUM(E25:OFFSET(E25,0,$Q$3-1)) -> 10243.173 | R25: =+Q25/($Q$46+$Q$62) -> 0.0061728093 | S25: =AVERAGE(E25:OFFSET(E25,0,$Q$3-1)) -> 2560.7932
A26: 6-0104 | C26: Logistics | D26: 51957.065 | E26: 59898.606 | F26: 35460.457 | G26: 43152.636 | H26: 68193.467 | Q26: =SUM(E26:OFFSET(E26,0,$Q$3-1)) -> 206705.17 | R26: =+Q26/($Q$46+$Q$62) -> 0.12456605 | S26: =AVERAGE(E26:OFFSET(E26,0,$Q$3-1)) -> 51676.292
A27: 6-0105 | C27: Communication | D27: 519.93512 | E27: 504.55728 | F27: 468.64223 | G27: 552.98808 | H27: 513.33262 | Q27: =SUM(E27:OFFSET(E27,0,$Q$3-1)) -> 2039.5202 | R27: =+Q27/($Q$46+$Q$62) -> 0.0012290693 | S27: =AVERAGE(E27:OFFSET(E27,0,$Q$3-1)) -> 509.88005
A28: 6-0106 | C28: Electricity | D28: 5811.083 | E28: 2273.363 | F28: 3631.2689 | G28: 3247.2722 | H28: 4612.383 | Q28: =SUM(E28:OFFSET(E28,0,$Q$3-1)) -> 13764.287 | R28: =+Q28/($Q$46+$Q$62) -> 0.0082947267 | S28: =AVERAGE(E28:OFFSET(E28,0,$Q$3-1)) -> 3441.0718
A29: 6-0108 | C29: Commission fee (M&C SG,KR,CH,JP) | D29: 30004.385 | E29: 10398.846 | F29: 0 | G29: 10140 | H29: 10318.788 | Q29: =SUM(E29:OFFSET(E29,0,$Q$3-1)) -> 30857.635 | R29: =+Q29/($Q$46+$Q$62) -> 0.018595634 | S29: =AVERAGE(E29:OFFSET(E29,0,$Q$3-1)) -> 7714.4087
A30: 6-0109 | C30: Consulting | D30: 3917.9305 | E30: 5199.2402 | F30: 2290.5983 | G30: 7317.3775 | H30: 4768.2416 | Q30: =SUM(E30:OFFSET(E30,0,$Q$3-1)) -> 19575.458 | R30: =+Q30/($Q$46+$Q$62) -> 0.011796693 | S30: =AVERAGE(E30:OFFSET(E30,0,$Q$3-1)) -> 4893.8644
A31: 6-0110 | C31: cars relative | D31: 9646.4987 | E31: 6865.1066 | F31: 8327.2716 | G31: 8229.7944 | H31: 8579.3791 | Q31: =SUM(E31:OFFSET(E31,0,$Q$3-1)) -> 32001.552 | R31: =+Q31/($Q$46+$Q$62) -> 0.019284989 | S31: =AVERAGE(E31:OFFSET(E31,0,$Q$3-1)) -> 8000.3879
A32: 6-0111 | C32: Rental others(house, land..) | D32: 6084.5 | E32: 4902.4552 | F32: 4071.9849 | G32: 4346.3261 | H32: 4928.6418 | Q32: =SUM(E32:OFFSET(E32,0,$Q$3-1)) -> 18249.408 | R32: =+Q32/($Q$46+$Q$62) -> 0.01099758 | S32: =AVERAGE(E32:OFFSET(E32,0,$Q$3-1)) -> 4562.352
A33: 6-0112 | C33: Rental - oversea -warehouse | D33: 39635.471 | E33: 43561.063 | F33: 40420.792 | G33: 41677.704 | H33: 56755.041 | Q33: =SUM(E33:OFFSET(E33,0,$Q$3-1)) -> 182414.6 | R33: =+Q33/($Q$46+$Q$62) -> 0.10992791 | S33: =AVERAGE(E33:OFFSET(E33,0,$Q$3-1)) -> 45603.65
A34: 6-0113 | C34: Sorting | D34: 41246.382 | E34: 54131.265 | F34: 65976.92 | G34: 66618.489 | H34: 48253.842 | Q34: =SUM(E34:OFFSET(E34,0,$Q$3-1)) -> 234980.52 | R34: =+Q34/($Q$46+$Q$62) -> 0.14160553 | S34: =AVERAGE(E34:OFFSET(E34,0,$Q$3-1)) -> 58745.129
... A45: 6-0126 | C45: Others (Garden,EHS,Unreasonable...) | D45: 19508.392 | E45: 3174.5671 | F45: 12165.537 | G45: 16816.728 | H45: 12507.059 | Q45: =SUM(E45:OFFSET(E45,0,$Q$3-1)) -> 44663.891 | R45: =+Q45/($Q$46+$Q$62) -> 0.026915653 | S45: =AVERAGE(E45:OFFSET(E45,0,$Q$3-1)) -> 11165.973
C46: Total Expenses Without R&D | D46: 407120.99 | E46: =SUM(E23:E45) -> 348666.18 | F46: =SUM(F23:F45) -> 334109.77 | G46: =SUM(G23:G45) -> 351521.91 | H46: =SUM(H23:H45) -> 366191.26 | I46: =SUM(I23:I45) -> 0 | J46: =SUM(J23:J45) -> 0 | K46: =SUM(K23:K45) -> 0 | L46: =SUM(L23:L45) -> 0 | ... Q46: =SUM(Q23:Q45) -> 1400489.1 | R46: =+Q46/($Q$46+$Q$62) -> 0.84397211 | S46: =AVERAGE(E46:OFFSET(E46,0,$Q$3-1)) -> 350122.28
C47: Salary (Included PIT,SHUI) | D47: 55502.412 | E47: 50620.956 | F47: 47781.144 | G47: 46669.745 | H47: 45478.654 | Q47: =SUM(E47:OFFSET(E47,0,$Q$3-1)) -> 190550.5 | R47: =+Q47/($Q$46+$Q$62) -> 0.11483082 | S47: =AVERAGE(E47:OFFSET(E47,0,$Q$3-1)) -> 47637.625
C48: Meal + other Welfare | D48: 4909.5409 | E48: 1372.1695 | F48: 1085.2895 | G48: 1644.478 | H48: 1487.7466 | Q48: =SUM(E48:OFFSET(E48,0,$Q$3-1)) -> 5589.6837 | R48: =+Q48/($Q$46+$Q$62) -> 0.0033684925 | S48: =AVERAGE(E48:OFFSET(E48,0,$Q$3-1)) -> 1397.4209
C49: Travel -business trips | D49: 0 | E49: 0 | F49: 999.92385 | G49: 0 | H49: 0 | Q49: =SUM(E49:OFFSET(E49,0,$Q$3-1)) -> 999.92385 | R49: =+Q49/($Q$46+$Q$62) -> 0.00060258079 | S49: =AVERAGE(E49:OFFSET(E49,0,$Q$3-1)) -> 249.98096
C50: Logistics | D50: 619.91923 | E50: 556.65 | F50: 0 | G50: 1119.5784 | H50: 0 | Q50: =SUM(E50:OFFSET(E50,0,$Q$3-1)) -> 1676.2284 | R50: =+Q50/($Q$46+$Q$62) -> 0.00101014 | S50: =AVERAGE(E50:OFFSET(E50,0,$Q$3-1)) -> 419.0571
...

Sheet Sch 2 - Manufacturing State
B1: Sch2.Manufacturing Statement
K2: 25500
B3: Category | C3: Dec.2025 | D3: Jan.26 | F3: Feb.26 | H3: Mar.26 | J3: Apr.26
B4: 1. Material Cost | C4: 1149307 | E4: =D5+D6-D8-D7 -> 1168999.4 | G4: =F5+F6-F8-F7 -> 703067.01 | I4: =H5+H6-H8-H7 -> 1269497.5 | K4: =J5+J6-J8-J7 -> 891773.11
B5: 1. Beginning Balance | C5: 1030861 | D5: 856754.83 | F5: =D8 -> 772365.72 | H5: =F8 -> 638942.02 | J5: =H8 -> 602966.12
B6: 2. Input Materials | C6: 1085840.3 | D6: 1247024.2 | F6: 672651.56 | H6: 1375706.6 | J6: 1112834.9
B7: 3. Other Accounts | C7: 12121.9 | D7: =144827.980140759+17586 -> 162413.98 | F7: =7919.25513165968+95089 -> 103008.26 | H7: 142185 | J7: 13495.692 | N7: ■ 월별 인건비·인원·OT 추이
B8: 4. Ending Balance | C8: 856754.83 | D8: 772365.72 | F8: 638942.02 | H8: 602966.12 | J8: 810532.18 | N8: 항목 | O8: 단위 | P8: Jan.26 | Q8: Feb.26 | R8: Mar.26 | S8: Apr.26 | T8: 1Q평균 | U8: Apr vs 1Q
B9: 2. Labor Cost | E9: =D10 -> 433923.41 | G9: =F10 -> 488222.36 | I9: 547646.11 | K9: =J10 -> 598756.38 | N9: 인건비 | O9: USD | P9: 433923 | Q9: 488222 | R9: 547646 | S9: 598756 | T9: =AVERAGE(P9:R9) -> 489930.33 | U9: =IFERROR((S9-T9)/T9,0) -> 0.22212478
B10: Salary (Included PIT,SHUI) | C10: 707689.55 | D10: 433923.41 | F10: 488222.36 | H10: 547646.11 | J10: 598756.38 | N10: 총 OT시간 | O10: 시간 | P10: 84286 | Q10: 59208 | R10: 62988 | S10: 81166 | T10: =AVERAGE(P10:R10) -> 68827.333 | U10: =IFERROR((S10-T10)/T10,0) -> 0.17926986
B11: 3. Expenses | E11: =SUM(D12:D32) -> 1073405.7 | G11: =SUM(F12:F32) -> 1041810.5 | I11: =SUM(H12:H32) -> 1116032.5 | K11: =SUM(J12:J32) -> 1180722 | N11: 총 인원수 | O11: 명 | P11: 867 | Q11: 858 | R11: 827 | S11: 801 | T11: =AVERAGE(P11:R11) -> 850.66667 | U11: =IFERROR((S11-T11)/T11,0) -> -0.05838558
B12: Meal | C12: 40725.695 | D12: 30875.727 | F12: 26018.554 | H12: 39132.475 | J12: 36421.748 | N12: 인당 평균 OT시간 | O12: 시간/명 | P12: =P10/P11 -> 97.215686 | Q12: =Q10/Q11 -> 69.006993 | R12: =R10/R11 -> 76.16445 | S12: =S10/S11 -> 101.33084 | T12: =AVERAGE(P12:R12) -> 80.79571 | U12: =IFERROR((S12-T12)/T12,0) -> 0.2541611
B13: Electricity | C13: 419174.62 | D13: 165249.43 | F13: 261565.85 | H13: 233883.33 | J13: 332468.07
B14: Water | C14: 1916.4866 | D14: 2014.1002 | F14: 1722.0365 | H14: 1220.7059 | J14: 2420.7852
B15: Gas | C15: 1243.2014 | D15: 1433.0995 | F15: 1079.4899 | H15: 1615.8567 | J15: 1882.0412
B16: Repair Expense | C16: 20311.871 | D16: 9777.1292 | F16: 5936.5594 | H16: 25174.583 | J16: 21625.904
B17: Transportation | C17: 8829.0432 | D17: 9193.138 | F17: 4507.1177 | H17: 6140.4254 | J17: 7120.412
B18: Travel(Business) | C18: 525.15269 | D18: 0 | F18: 3165.6298 | H18: 0 | J18: 858.98831
B19: Rent Expense (SG MCT, Outside WH, etc) | C19: 41890.523 | D19: 39464.832 | F19: 39304 | H19: 40245.248 | J19: 41604.532
B20: Tax (FCT machines and RM) | C20: 4185.0893 | D20: 3673.9295 | F20: 1429.8447 | H20: 6763.4757 | J20: 5937.7376
B21: Depreciation | C21: 189836.69 | D21: 194564.23 | F21: 197097.28 | H21: 196701.99 | J21: 192632.5
B22: Amortization | C22: 121129.46 | D22: 120468.21 | F22: 124800.87 | H22: 127080.79 | J22: 130447.54
B23: Amotization (Mold) | C23: 68404.037 | D23: 66169.142 | F23: 67646.068 | H23: 68804.584 | J23: 69983.352
B24: Outsourcing (Ano, Paint, Chromate ,CNC) | C24: 87754.566 | D24: 98953.735 | F24: 72915.855 | H24: 68269.669 | J24: 51752.566
... B32: Others (Garden and cleaning,EHS,comsumption,Unreasonable...) | C32: 40330.683 | D32: 21950.47 | F32: 20733.982 | H32: 19562.117 | J32: 24714.681
B33: 4. Total Production Cost | C33: 3177993.8 | E33: =E4+E9+E11 -> 2676328.5 | G33: =G4+G9+G11 -> 2233099.9 | I33: =I4+I9+I11 -> 2933176.2 | K33: =K4+K9+K11 -> 2671251.5
B34: 5. Beginning Balance(WIP) | C34: 515178.85 | E34: 400127 | G34: =E36 -> 419869.6 | I34: =G36 -> 439834.96 | K34: =I36 -> 240830.66
B35: 6. Total | C35: 3693172.7 | E35: =E33+E34 -> 3076455.5 | G35: =G33+G34 -> 2652969.5 | I35: =I33+I34 -> 3373011.1 | K35: =K33+K34 -> 2912082.1
B36: 7. Ending Balance(WIP) | C36: 400127 | E36: 419869.6 | G36: 439834.96 | I36: 240830.66 | K36: 194873.58
B37: 8. Other Accounts | C37: 28799.842 | E37: -155823.36 | G37: 2360.8871 | I37: 275644 | K37: 40
B38: 9. Manufacturing Cost | C38: =C35-C36-C37 -> 3264245.8 | E38: =E35-E36-E37 -> 2812409.3 | G38: =G35-G36-G37 -> 2210773.6 | I38: =I35-I36-I37 -> 2856536.5 | K38: =K35-K36-K37 -> 2717168.6

Sheet NG by Customers
B1: NG FG Detail by months | U1: Exr: 26000
B2: Customers | C2: Jan.26 | E2: Feb.26 | G2: Mar.26 | I2: Apr.26 | K2: May.26 | M2: Jun.26 | O2: Jul.26 | Q2: Aug.26 | S2: Sep.26 | U2: Oct.26 | W2: Nov.26 | Y2: Dec.26 | AA2: YTD26
C3: Qty Jan.26 | D3: Amt Jan.26 | E3: Qty Feb.26 | F3: Amt Feb.26 | G3: Qty Mar.26 | H3: Amt Mar.26 | I3: Qty Apr.26 | J3: Amt Apr.26 | K3: Qty Mat.26 | L3: Amt May.26 | M3: Qty Jun.26 | N3: Amt Jul.26 | O3: Qty Jul.26 | P3: Amt Jul.26 | Q3: Qty Aug.26 | R3: Amt Aug.26 | S3: Qty Sep.26 | T3: Amt Sep.26 | U3: Qty Oct.26 | V3: Amt Oct.26 | W3: Qty Nov.26 | X3: Amt Nov.26 | Y3: Qty Dec.26 | Z3: Amt Dec.26 | AA3: Qty total | AB3: Amt Total | AC3: Sale | AD3: Rate
B4: LG | C4: =SUMIF('NG by model'!$A:$A,B4,'NG by model'!D:D) -> 82154 | D4: =SUMIF('NG by model'!$A:$A,B4,'NG by model'!E:E) -> 83789.62 | E4: =SUMIF('NG by model'!$A:$A,B4,'NG by model'!F:F) -> 15974 | F4: =SUMIF('NG by model'!$A:$A,B4,'NG by model'!G:G) -> 11734.884 | G4: =SUMIF('NG by model'!$A:$A,B4,'NG by model'!H:H) -> 109353 | H4: =SUMIF('NG by model'!$A:$A,B4,'NG by model'!I:I) -> 138744.48 | I4: =SUMIF('NG by model'!$A:$A,B4,'NG by model'!J:J) -> 74013 | J4: =SUMIF('NG by model'!$A:$A,B4,'NG by model'!K:K) -> 114274.94 | AA4: =C4+E4+G4+I4+K4+M4+O4+Q4+S4+U4+W4 -> 281494 | AB4: =D4+F4+H4+J4+L4+N4+P4+R4+T4+V4+X4 -> 348543.92 | AC4: =SUMIF('Sch 1 - Sales'!R:R,B4,'Sch 1 - Sales'!P:P) -> 0 | AD4: =AB4/$AB$9 -> 0.39690465
B5: Samsung | C5: 3919 | D5: =SUMIF('NG by model'!$A:$A,B5,'NG by model'!E:E) -> 47060.262 | E5: =SUMIF('NG by model'!$A:$A,B5,'NG by model'!F:F) -> 24530 | F5: =SUMIF('NG by model'!$A:$A,B5,'NG by model'!G:G) -> 18277.96 | G5: =SUMIF('NG by model'!$A:$A,B5,'NG by model'!H:H) -> 100143 | H5: =SUMIF('NG by model'!$A:$A,B5,'NG by model'!I:I) -> 62822.712 | I5: =SUMIF('NG by model'!$A:$A,B5,'NG by model'!J:J) -> 103193 | J5: =SUMIF('NG by model'!$A:$A,B5,'NG by model'!K:K) -> 62099.278 | AA5: =C5+E5+G5+I5+K5+M5+O5+Q5+S5+U5+W5 -> 231785 | AB5: =D5+F5+H5+J5+L5+N5+P5+R5+T5+V5+X5 -> 190260.21 | AC5: =SUMIF('Sch 1 - Sales'!R:R,B5,'Sch 1 - Sales'!P:P) -> 0 | AD5: =AB5/$AB$9 -> 0.21665895
B6: Mando | C6: 19807 | D6: =SUMIF('NG by model'!$A:$A,B6,'NG by model'!E:E) -> 60051.501 | E6: =SUMIF('NG by model'!$A:$A,B6,'NG by model'!F:F) -> 11056 | F6: =SUMIF('NG by model'!$A:$A,B6,'NG by model'!G:G) -> 12286.579 | G6: =SUMIF('NG by model'!$A:$A,B6,'NG by model'!H:H) -> 55934 | H6: =SUMIF('NG by model'!$A:$A,B6,'NG by model'!I:I) -> 94008.948 | I6: =SUMIF('NG by model'!$A:$A,B6,'NG by model'!J:J) -> 41752 | J6: =SUMIF('NG by model'!$A:$A,B6,'NG by model'!K:K) -> 62956.794 | AA6: =C6+E6+G6+I6+K6+M6+O6+Q6+S6+U6+W6 -> 128549 | AB6: =D6+F6+H6+J6+L6+N6+P6+R6+T6+V6+X6 -> 229303.82 | AC6: =SUMIF('Sch 1 - Sales'!R:R,B6,'Sch 1 - Sales'!P:P) -> 2680709 | AD6: =AB6/$AB$9 -> 0.26111989
B7: ZF | C7: 58068 | D7: =SUMIF('NG by model'!$A:$A,B7,'NG by model'!E:E) -> 26455.294 | E7: =SUMIF('NG by model'!$A:$A,B7,'NG by model'!F:F) -> 16611 | F7: =SUMIF('NG by model'!$A:$A,B7,'NG by model'!G:G) -> 11075.958 | G7: =SUMIF('NG by model'!$A:$A,B7,'NG by model'!H:H) -> 65767 | H7: =SUMIF('NG by model'!$A:$A,B7,'NG by model'!I:I) -> 28491.299 | I7: =SUMIF('NG by model'!$A:$A,B7,'NG by model'!J:J) -> 46003 | J7: =SUMIF('NG by model'!$A:$A,B7,'NG by model'!K:K) -> 25824.411 | AA7: =C7+E7+G7+I7+K7+M7+O7+Q7+S7+U7+W7 -> 186449 | AB7: =D7+F7+H7+J7+L7+N7+P7+R7+T7+V7+X7 -> 91846.962 | AC7: =SUMIF('Sch 1 - Sales'!R:R,B7,'Sch 1 - Sales'!P:P) -> 2385496.5 | AD7: =AB7/$AB$9 -> 0.1045908
B8: Qualcom | C8: 672 | D8: =SUMIF('NG by model'!$A:$A,B8,'NG by model'!E:E) -> 7382.5641 | E8: =SUMIF('NG by model'!$A:$A,B8,'NG by model'!F:F) -> 1668 | F8: =SUMIF('NG by model'!$A:$A,B8,'NG by model'!G:G) -> 3585.0749 | G8: =SUMIF('NG by model'!$A:$A,B8,'NG by model'!H:H) -> 2222 | H8: =SUMIF('NG by model'!$A:$A,B8,'NG by model'!I:I) -> 5019.2724 | I8: =SUMIF('NG by model'!$A:$A,B8,'NG by model'!J:J) -> 711 | J8: =SUMIF('NG by model'!$A:$A,B8,'NG by model'!K:K) -> 2213.48 | AA8: =C8+E8+G8+I8+K8+M8+O8+Q8+S8+U8+W8 -> 5273 | AB8: =D8+F8+H8+J8+L8+N8+P8+R8+T8+V8+X8 -> 18200.391 | AC8: =SUMIF('Sch 1 - Sales'!R:R,B8,'Sch 1 - Sales'!P:P) -> 0 | AD8: =AB8/$AB$9 -> 0.020725709
B9: Total | C9: =SUM(C4:C8) -> 164620 | D9: =SUM(D4:D8) -> 224739.24 | E9: =SUM(E4:E8) -> 69839 | F9: =SUM(F4:F8) -> 56960.455 | G9: =SUM(G4:G8) -> 333419 | H9: =SUM(H4:H8) -> 329086.71 | I9: =SUM(I4:I8) -> 265672 | J9: =SUM(J4:J8) -> 267368.91 | ... AD9: =SUM(AD4:AD8) -> 1
B10: Rate by months | D10: =+D9/$AB$9 -> 0.25592197 | F10: =+F9/$AB$9 -> 0.06486376 | H10: =+H9/$AB$9 -> 0.37474773 | J10: =+J9/$AB$9 -> 0.30446654 | L10: =+L9/$AB$9 -> 0 | N10: =+N9/$AB$9 -> 0 | P10: =+P9/$AB$9 -> 0 | R10: =+R9/$AB$9 -> 0 | T10: =+T9/$AB$9 -> 0 | V10: =+V9/$AB$9 -> 0 | X10: =+X9/$AB$9 -> 0 | Z10: =+Z9/$AB$9 -> 0
B12: Content | C12: Jan.26 | D12: Feb.26 | E12: Mar.26 | F12: Apr.26
B13: Qty NG | C13: =+C9 -> 164620 | D13: =+E9 -> 69839 | E13: =+G9 -> 333419 | F13: =+I9 -> 265672
B14: Amt NG | C14: =+D9 -> 224739.24 | D14: =+F9 -> 56960.455 | E14: =+H9 -> 329086.71 | F14: =+J9 -> 267368.91
B35: * NG by customers | J35: * Amt NG by months
B36: -From Jan to Jul LG had the highest cost of discarded goods with an amount of $446K with 35% | J36: -July is the month with the highest amount of NG incurred at $297k with 23%
B37: -LG also had the highest proportion of discarded goods value in July with an amount of $134k with 45% | J37: - This cost has been fully recorded in COGS and is the reason for the significant decrease in profit in July

Sheet NG by model
S1: 25500 | U1: 26000 | W1: 26000 | Y1: 26000 | AA1: 26000
D2: Jan.26 | F2: Feb.26 Before | H2: Mar.26 | J2: Apr.26 | L2: May.26 | N2: Jun.26 | P2: Jul.26 | R2: Aug.26 | T2: Sep.26 | V2: Oct.26 | X2: Nov.26 | Z2: Dec.26 | AB2: Total .2026Y
A3: Customer | B3: item code | C3: Name | D3: Qty NG | E3: Amt NG | F3: Qty NG | G3: Amt NG | H3: Qty NG | I3: Amt NG | J3: Qty NG | K3: Amt NG | L3: Qty NG | M3: Amt NG | N3: Qty NG | O3: Amt NG | P3: Qty NG | Q3: Amt NG | R3: Qty NG | S3: Amt NG | T3: Qty NG | U3: Amt NG | V3: Qty NG | W3: Amt NG | X3: Qty NG | Y3: Amt NG | Z3: Qty NG | AA3: Amt NG | AB3: Qty NG | AC3: TOT Amt NG
A4: Samsung | B4: 120438 | C4: PK SM-A176B | D4: 34558 | E4: 19659.483 | F4: 5420 | G4: 3772.4068 | H4: 62447 | I4: 36654.309 | J4: 90710 | K4: 55851.949 | AB4: =D4+F4+H4+J4+L4+N4+P4+R4+T4+V4+X4+Z4 -> 193135 | AC4: =E4+G4+I4+K4+M4+O4+Q4+S4+U4+W4+Y4+AA4 -> 115938.15
A5: LG | B5: 120157 | C5: PK LGIT Gen3 AL5 | D5: 18581 | E5: 29502.25 | F5: 1042 | G5: 1956.7246 | H5: 28792 | I5: 48686.602 | J5: 15198 | K5: 27650.593 | AB5: =D5+F5+H5+J5+L5+N5+P5+R5+T5+V5+X5+Z5 -> 63613 | AC5: =E5+G5+I5+K5+M5+O5+Q5+S5+U5+W5+Y5+AA5 -> 107796.17
A6: Mando | B6: 120368 | C6: PK Mando Brose IMEB2 Housing(2) | D6: 11549 | E6: 23987.888 | F6: 0 | G6: 0 | H6: 21999 | I6: 47619.547 | J6: 9324 | K6: 19845.452 | AB6: =D6+F6+H6+J6+L6+N6+P6+R6+T6+V6+X6+Z6 -> 42872 | AC6: =E6+G6+I6+K6+M6+O6+Q6+S6+U6+W6+Y6+AA6 -> 91452.888
A7: LG | B7: 120415 | C7: PK LGIT 3CAZ00041A CL4 Housing | D7: 4387 | E7: 9934.2606 | F7: 0 | G7: 0 | H7: 17963 | I7: 39851.716 | J7: 11063 | K7: 24576.381 | AB7: =D7+F7+H7+J7+L7+N7+P7+R7+T7+V7+X7+Z7 -> 33413 | AC7: =E7+G7+I7+K7+M7+O7+Q7+S7+U7+W7+Y7+AA7 -> 74362.358
A8: Mando | B8: 120309 | C8: PK Mando NX4 Motor Housing | D8: 4985 | E8: 12334.884 | F8: 995 | G8: 2797.0888 | H8: 7624 | I8: 18631.284 | J8: 6620 | K8: 15480.379 | AB8: =D8+F8+H8+J8+L8+N8+P8+R8+T8+V8+X8+Z8 -> 20224 | AC8: =E8+G8+I8+K8+M8+O8+Q8+S8+U8+W8+Y8+AA8 -> 49243.636
A9: Samsung | B9: 120443 | C9: PK SM-A376B | D9: 16887 | E9: 12918.38 | F9: 12609 | G9: 9671.9326 | H9: 33199 | I9: 23305.396 | J9: 623 | K9: 461.55821 | AB9: =D9+F9+H9+J9+L9+N9+P9+R9+T9+V9+X9+Z9 -> 63318 | AC9: =E9+G9+I9+K9+M9+O9+Q9+S9+U9+W9+Y9+AA9 -> 46357.267
A10: LG | B10: 120414 | C10: PK LGIT MQ4a PE Housing 3CAZ00039A | D10: 6964 | E10: 16121.582 | F10: 22 | G10: 51.830122 | H10: 2111 | I10: 4643.8279 | J10: 6541 | K10: 16237.682 | AB10: =D10+F10+H10+J10+L10+N10+P10+R10+T10+V10+X10+Z10 -> 15638 | AC10: =E10+G10+I10+K10+M10+O10+Q10+S10+U10+W10+Y10+AA10 -> 37054.922
A11: LG | B11: 120362 | C11: PK LGIT MPC5.5 Cover lens 3HDC00003A | D11: 27303 | E11: 9275.5485 | F11: 7778 | G11: 4122.2081 | H11: 33180 | I11: 10226.198 | J11: 14736 | K11: 8041.6119 | AB11: =D11+F11+H11+J11+L11+N11+P11+R11+T11+V11+X11+Z11 -> 82997 | AC11: =E11+G11+I11+K11+M11+O11+Q11+S11+U11+W11+Y11+AA11 -> 31665.567
A12: Mando | B12: 120338 | C12: PK Mando N3 Motor & Heatsink Cover | D12: 5558 | E12: 4673.1824 | F12: 4877 | G12: 4896.9924 | H12: 11555 | I12: 10326.477 | J12: 10012 | K12: 9703.557 | AB12: =D12+F12+H12+J12+L12+N12+P12+R12+T12+V12+X12+Z12 -> 32002 | AC12: =E12+G12+I12+K12+M12+O12+Q12+S12+U12+W12+Y12+AA12 -> 29600.209
A13: LG | B13: 120341 | C13: PK LGIT T6M6 Housing 3HUC00006A | D13: 0 | E13: 0 | F13: 0 | G13: 0 | H13: 6246 | I13: 22597.942 | J13: 2112 | K13: 7563.0367 | AB13: =D13+F13+H13+J13+L13+N13+P13+R13+T13+V13+X13+Z13 -> 8358 | AC13: =E13+G13+I13+K13+M13+O13+Q13+S13+U13+W13+Y13+AA13 -> 30160.979
A14: ZF | B14: 120187 | C14: PK TRW-Nissan/FCA/GMT 4.8 Lenmount(336416-13/A011F352) | D14: 25043 | E14: 7476.9543 | F14: 2372 | G14: 734.89166 | H14: 42962 | I14: 12981.727 | J14: 22267 | K14: 8063.4652 | AB14: =D14+F14+H14+J14+L14+N14+P14+R14+T14+V14+X14+Z14 -> 92644 | AC14: =E14+G14+I14+K14+M14+O14+Q14+S14+U14+W14+Y14+AA14 -> 29257.038
A15: Mando | B15: 120367 | C15: PK Mando MAS65C 4.5 Heat Sink(2) | D15: 11209 | E15: 7675.1247 | F15: 4724 | G15: 3233.6503 | H15: 7224 | I15: 5483.744 | J15: 9425 | K15: 7956.4575 | AB15: =D15+F15+H15+J15+L15+N15+P15+R15+T15+V15+X15+Z15 -> 32582 | AC15: =E15+G15+I15+K15+M15+O15+Q15+S15+U15+W15+Y15+AA15 -> 24348.977
... A41: Qualcom | B41: 101263 | C41: PK Qualcomm RIDE 5 50-74187-1 MIDFRAME ASSEMBLY, RIDE 5 | D41: 0 | E41: 0 | F41: 0 | G41: 0 | H41: 453 | I41: 875.91988 | J41: 74 | K41: 507.50615 | AB41: =D41+F41+H41+J41+L41+N41+P41+R41+T41+V41+X41+Z41 -> 527 | AC41: =E41+G41+I41+K41+M41+O41+Q41+S41+U41+W41+Y41+AA41 -> 1383.426
A42: Mando | B42: 120435 | C42: PK Mando Brose JG REPS Housing cover | J42: 1160 | K42: 1256.7475 | AB42: =D42+F42+H42+J42+L42+N42+P42+R42+T42+V42+X42+Z42 -> 1160 | AC42: =E42+G42+I42+K42+M42+O42+Q42+S42+U42+W42+Y42+AA42 -> 1256.7475
A43: Qualcom | B43: 101268 | C43: PK Qualcomm RIDE 5 50-74194-1 BOTTOM HOUSING, PAINTED, BASE UNIT, RIDE 5 | D43: 0 | E43: 0 | F43: 0 | G43: 0 | H43: 106 | I43: 1153.4014 | J43: 1 | K43: 0.081069772 | AB43: =D43+F43+H43+J43+L43+N43+P43+R43+T43+V43+X43+Z43 -> 107 | AC43: =E43+G43+I43+K43+M43+O43+Q43+S43+U43+W43+Y43+AA43 -> 1153.4825
A44: Qualcom | B44: 101175 | C44: PK Qualcomm AIR GEN 5 50-36917-3 CAMERA CARD, BOTTOM TRAY (2) | D44: 1067 | E44: 685.34859 | F44: 4 | G44: 2.7083703 | H44: 75 | I44: 193.44924 | J44: 76 | K44: 96.568121 | AB44: =D44+F44+H44+J44+L44+N44+P44+R44+T44+V44+X44+Z44 -> 1222 | AC44: =E44+G44+I44+K44+M44+O44+Q44+S44+U44+W44+Y44+AA44 -> 978.07432
A45: Qualcom | B45: 101176 | C45: PK Qualcomm AIR GEN 5 50-36917-4 PCIE CARD, BOTTOM TRAY (2) | D45: 295 | E45: 434.87731 | F45: 1 | G45: 0.12916043 | H45: 68 | I45: 408.943 | J45: 66 | K45: 96.937993 | AB45: =D45+F45+H45+J45+L45+N45+P45+R45+T45+V45+X45+Z45 -> 430 | AC45: =E45+G45+I45+K45+M45+O45+Q45+S45+U45+W45+Y45+AA45 -> 940.88746
A46: Qualcom | B46: 101280 | C46: PK Qualcomm RIDE 5 50-74195-3 FRONT COVER, PAINTED, BASE UNIT SX KARUSSELL | D46: 96 | E46: 125.90229 | F46: 0 | G46: 0 | H46: 63 | I46: 717.63241 | J46: 0 | K46: 0 | AB46: =D46+F46+H46+J46+L46+N46+P46+R46+T46+V46+X46+Z46 -> 159 | AC46: =E46+G46+I46+K46+M46+O46+Q46+S46+U46+W46+Y46+AA46 -> 843.5347
A47: Qualcom | B47: 101174 | C47: PK Qualcomm AIR GEN 5 50-36917-2 SOC CARD, BOTTOM TRAY (2) | D47: 769 | E47: 667.17339 | F47: 0 | G47: 0 | H47: 0 | I47: 0 | J47: 47 | K47: 72.793922 | AB47: =D47+F47+H47+J47+L47+N47+P47+R47+T47+V47+X47+Z47 -> 816 | AC47: =E47+G47+I47+K47+M47+O47+Q47+S47+U47+W47+Y47+AA47 -> 739.96731
A48: LG | B48: 120195 | C48: PK LGIT IKC Camera base 3CAC00180A | D48: 586 | E48: 581.11106 | F48: 195 | G48: 133.53389 | H48: 0 | I48: 0 | J48: 11 | K48: 22.837742 | AB48: =D48+F48+H48+J48+L48+N48+P48+R48+T48+V48+X48+Z48 -> 792 | AC48: =E48+G48+I48+K48+M48+O48+Q48+S48+U48+W48+Y48+AA48 -> 737.48269
A49: Qualcom | B49: 101149 | C49: PK Qualcomm MTP Camano 55-PR725-20 Assy Font Housing | D49: 144 | E49: 552.66544 | F49: 0 | G49: 0 | H49: 0 | I49: 0 | J49: 0 | K49: 0 | AB49: =D49+F49+H49+J49+L49+N49+P49+R49+T49+V49+X49+Z49 -> 144 | AC49: =E49+G49+I49+K49+M49+O49+Q49+S49+U49+W49+Y49+AA49 -> 552.66544
A50: Qualcom | B50: 101301 | C50: PK Qualcomm HAWI 50-84675-1 Antenna Carrier | D50: 9 | E50: 456.66559 | F50: 0 | G50: 0 | H50: 5 | I50: 0.6236708 | J50: 0 | K50: 0 | AB50: =D50+F50+H50+J50+L50+N50+P50+R50+T50+V50+X50+Z50 -> 14 | AC50: =E50+G50+I50+K50+M50+O50+Q50+S50+U50+W50+Y50+AA50 -> 457.28926
A51: Qualcom | B51: 101177 | C51: PK Qualcomm AIR GEN 5 50-36917-5 ETHERNET CARD, BOTTOM TRAY (2) | D51: 272 | E51: 349.20641 | F51: 36 | G51: 40.675282 | H51: 17 | I51: 30.382233 | J51: 0 | K51: 0 | AB51: =D51+F51+H51+J51+L51+N51+P51+R51+T51+V51+X51+Z51 -> 325 | AC51: =E51+G51+I51+K51+M51+O51+Q51+S51+U51+W51+Y51+AA51 -> 420.26392
A52: Qualcom | B52: 101325 | C52: PK Qualcomm AMBOSELI CA90-84713-3 HIELD, HEATSINK, RF CARD, PICTOR/ALIOTH | D52: 250 | E52: 340.1084 | F52: 0 | G52: 0 | H52: 0 | I52: 0 | J52: 0 | K52: 0 | AB52: =D52+F52+H52+J52+L52+N52+P52+R52+T52+V52+X52+Z52 -> 250 | AC52: =E52+G52+I52+K52+M52+O52+Q52+S52+U52+W52+Y52+AA52 -> 340.1084
A53: Qualcom | B53: 101267 | C53: PK Qualcomm RIDE 5 50-74192-1 PCIe Cover | D53: 23 | E53: 121.66689 | F53: 37 | G53: 85.992084 | H53: 1 | I53: 5.2899269 | J53: 40 | K53: 85.144427 | AB53: =D53+F53+H53+J53+L53+N53+P53+R53+T53+V53+X53+Z53 -> 101 | AC53: =E53+G53+I53+K53+M53+O53+Q53+S53+U53+W53+Y53+AA53 -> 298.09333
A54: Qualcom | B54: 101270 | C54: PK Qualcomm RIDE 5 50-74196-1 REAR COVER, PAINTED, BASE UNIT, RIDE 5 | D54: 0 | E54: 0 | F54: 0 | G54: 0 | H54: 0 | I54: 0 | J54: 31 | K54: 292.27564 | AB54: =D54+F54+H54+J54+L54+N54+P54+R54+T54+V54+X54+Z54 -> 31 | AC54: =E54+G54+I54+K54+M54+O54+Q54+S54+U54+W54+Y54+AA54 -> 292.27564
... A58: Qualcom | B58: 101264 | C58: PK Qualcomm RIDE 5 50-74188-1 LOWER FRAME, RIDE 5 | D58: 1 | E58: 0.19304865 | F58: 9 | G58: 28.198353 | H58: 118 | I58: 182.44873 | J58: 0 | K58: 0 | AB58: =D58+F58+H58+J58+L58+N58+P58+R58+T58+V58+X58+Z58 -> 128 | AC58: =E58+G58+I58+K58+M58+O58+Q58+S58+U58+W58+Y58+AA58 -> 210.84013
A59: Qualcom | B59: 101336 | C59: PK A Sensor bar 135-8837-003 ISW Antenna Enclosure, Front Sensors | H59: 46 | I59: 203.94351 | J59: 0 | K59: 0 | AB59: =D59+F59+H59+J59+L59+N59+P59+R59+T59+V59+X59+Z59 -> 46 | AC59: =E59+G59+I59+K59+M59+O59+Q59+S59+U59+W59+Y59+AA59 -> 203.94351
A60: Qualcom | B60: 101275 | C60: PK Qualcomm AIR GEN 5 CA90-79362-1 | D60: 0 | E60: 0 | F60: 0 | G60: 0 | H60: 0 | I60: 0 | J60: 94 | K60: 195.66855 | AB60: =D60+F60+H60+J60+L60+N60+P60+R60+T60+V60+X60+Z60 -> 94 | AC60: =E60+G60+I60+K60+M60+O60+Q60+S60+U60+W60+Y60+AA60 -> 195.66855
A61: Qualcom | B61: 101282 | C61: PK Qualcomm MTP MOLOKAI 29708-70 ASSY 5G-MIDFRAME, HEAT PIPE | D61: 0 | E61: 0 | F61: 10 | G61: 64.729638 | H61: 0 | I61: 0 | J61: 15 | K61: 97.407118 | AB61: =D61+F61+H61+J61+L61+N61+P61+R61+T61+V61+X61+Z61 -> 25 | AC61: =E61+G61+I61+K61+M61+O61+Q61+S61+U61+W61+Y61+AA61 -> 162.13676
A62: Qualcom | B62: 101348 | C62: PK Qualcomm MAILI 55-97051-1 ALTERED FRAME, CAMERA CARD COVER ASSY_PROCESS | J62: 50 | K62: 107.65844 | AB62: =D62+F62+H62+J62+L62+N62+P62+R62+T62+V62+X62+Z62 -> 50 | AC62: =E62+G62+I62+K62+M62+O62+Q62+S62+U62+W62+Y62+AA62 -> 107.65844
A63: Qualcom | B63: 101059 | C63: PK Qualcomm MTP Kuno 50-PR952-3, Ant Carrier, Antenna 8 And 9 | D63: 0 | E63: 0 | F63: 0 | G63: 0 | H63: 148 | I63: 107.00637 | J63: 0 | K63: 0 | AB63: =D63+F63+H63+J63+L63+N63+P63+R63+T63+V63+X63+Z63 -> 148 | AC63: =E63+G63+I63+K63+M63+O63+Q63+S63+U63+W63+Y63+AA63 -> 107.00637
A64: Qualcom | B64: 101330 | C64: PK Qualcomm HAWI 50-84675-2 Antenna Carrier | F64: 7 | G64: 11.692582 | H64: 47 | I64: 59.570154 | J64: 9 | K64: 18.691479 | AB64: =D64+F64+H64+J64+L64+N64+P64+R64+T64+V64+X64+Z64 -> 63 | AC64: =E64+G64+I64+K64+M64+O64+Q64+S64+U64+W64+Y64+AA64 -> 89.954216
A65: Qualcom | B65: 101051 | C65: PK Qualcomm MTP Pinnacles 55-29819-1 Front Housing | J65: 30 | K65: 85.922555 | AB65: =D65+F65+H65+J65+L65+N65+P65+R65+T65+V65+X65+Z65 -> 30 | AC65: =E65+G65+I65+K65+M65+O65+Q65+S65+U65+W65+Y65+AA65 -> 85.922555
A66: Qualcom | B66: 101049 | C66: PK Qualcomm IDP Cedros 55-PR954-70 Assy, Rear Housing | D66: 0 | E66: 0 | F66: 41 | G66: 4.5522635 | H66: 0 | I66: 0 | J66: 43 | K66: 79.150839 | AB66: =D66+F66+H66+J66+L66+N66+P66+R66+T66+V66+X66+Z66 -> 84 | AC66: =E66+G66+I66+K66+M66+O66+Q66+S66+U66+W66+Y66+AA66 -> 83.703102
A67: Qualcom | B67: 101141 | C67: PK Qualcomm MTP Camano 55-PR919-20 Display Carrier Frame Assy | D67: 15 | E67: 41.266263 | F67: 0 | G67: 0 | H67: 0 | I67: 0 | J67: 0 | K67: 0 | AB67: =D67+F67+H67+J67+L67+N67+P67+R67+T67+V67+X67+Z67 -> 15 | AC67: =E67+G67+I67+K67+M67+O67+Q67+S67+U67+W67+Y67+AA67 -> 41.266263
A68: LG | B68: 120165 | C68: PK PSA BMS Bottom Cover 3CAC00182A | D68: 0 | E68: 0 | F68: 0 | G68: 0 | H68: 18 | I68: 34.804384 | J68: 0 | K68: 0 | AB68: =D68+F68+H68+J68+L68+N68+P68+R68+T68+V68+X68+Z68 -> 18 | AC68: =E68+G68+I68+K68+M68+O68+Q68+S68+U68+W68+Y68+AA68 -> 34.804384
...

Sheet 비용 증가 사유
B2: 1. 금형 실적 반영 지연 (약 +1.5만불)
B3: * A276 금형 코아 실적 5벌 - 5월 8일 입력
B4: * 4월 마감 시 인건비 및 경비 추가 반영 (약 + 1.5만불)
B5: * 5월 매출 반영필요
B6: * 기타 금형도 확인 진행중
B7: 미반영 매출 반영 | C7: 수량 | D7: 매출단가 | E7: 매출금액 | F7: 원가 | G7: 이익
B8: A276 Mold | C8: 5 | D8: =E8/C8 -> 10982.8 | E8: 54914 | F8: =6500*5 -> 32500 | G8: =E8-F8 -> 22414
B9: TRIMMING JIG(DEGATING) | C9: 5 | D9: =E9/C9 -> 2683.4 | E9: 13417 | F9: 10341 | G9: =E9-F9 -> 3076
B10: TRIMMING JIG_01 | C10: 5 | D10: =E10/C10 -> 2187.6 | E10: 10938 | F10: 9497 | G10: =E10-F10 -> 1441
B11: CNC JIG | C11: 5 | D11: =E11/C11 -> 341.4 | E11: 1707 | F11: 2400 | G11: =E11-F11 -> -693
B12: Total | E12: =SUM(E8:E11) -> 80976 | F12: =SUM(F8:F11) -> 54738 | G12: =E12-F12 -> 26238
B14: 2. 인건비 증가 (약 +5만불)
B15: * 생산직 1인당 평균 잔업시간: 76시간 → 106시간 (+39%)
B16: * 생산물량 회복 및 납기 대응 과정에서 OT 증가
B17: → 5월부터 라인별 OT 한도 설정 및 일일 모니터링 시행 예정
B18: 항목 | C18: 단위 | D18: Jan.26 | E18: Feb.26 | F18: Mar.26 | G18: Apr.26 | H18: 1Q평균 | I18: Apr vs 1Q
