Workbook

Sheet 통합사업계획
A1: MNC Group 2026–2031 중장기 사업계획 (통합 — 확정 기준안 v9)
A2: 단위: USD 천 | v9 변경: 판관비율 12.6%→매년 1%p 개선 / 순이자비용 유예기간 flat 재계산($687K, 2031 상환반영) | 투자분할(한국1단계 27·28 $3M·$2M / 서버공장 28 $5.05M / 한국2단계 29·30 $10M·$5M) | 삼성DX·AI서버 반영, 추가방산·DC·지연 미적용
A3: 구분 | B3: 2026 | C3: 2027 | D3: 2028 | E3: 2029 | F3: 2030 | G3: 2031 | H3: '26–'31 합계
A4: I. 연결 손익계산서 (P&L) [단위: $천]
A5: 매출액 — 기존사업 | B5: =핵심가정!B4 -> 44598 | C5: =핵심가정!C4 -> 46827.9 | D5: =핵심가정!D4 -> 49169.295 | E5: =핵심가정!E4 -> 51627.76 | F5: =핵심가정!F4 -> 54209.148 | G5: =핵심가정!G4 -> 56919.605 | H5: =SUM(B5:G5) -> 303351.71
A6: 매출액 — A사 프로젝트 | B6: =핵심가정!B10 -> 1200 | C6: =핵심가정!C10 -> 4500 | D6: =핵심가정!D10 -> 8000 | E6: =핵심가정!E10 -> 16000 | F6: =핵심가정!F10 -> 24000 | G6: =핵심가정!G10 -> 24000 | H6: =SUM(B6:G6) -> 77700
A7: 매출액 — 삼성DX (ZN캐스팅) | B7: =핵심가정!B12 -> 0 | C7: =핵심가정!C12 -> 4800 | D7: =핵심가정!D12 -> 9600 | E7: =핵심가정!E12 -> 12000 | F7: =핵심가정!F12 -> 12000 | G7: =핵심가정!G12 -> 12000 | H7: =SUM(B7:G7) -> 50400
A8: 매출액 — 삼성DX (갤럭시탭) | B8: =핵심가정!B13 -> 0 | C8: =핵심가정!C13 -> 2200 | D8: =핵심가정!D13 -> 2200 | E8: =핵심가정!E13 -> 2200 | F8: =핵심가정!F13 -> 2200 | G8: =핵심가정!G13 -> 2200 | H8: =SUM(B8:G8) -> 11000
A9: 매출액 — AI서버 CNC (베트남) | B9: =핵심가정!B16 -> 0 | C9: =핵심가정!C16 -> 2347 | D9: =핵심가정!D16 -> 4695 | E9: =핵심가정!E16 -> 9390 | F9: =핵심가정!F16 -> 9390 | G9: =핵심가정!G16 -> 9390 | H9: =SUM(B9:G9) -> 35212
A10: 매출액 합계 | B10: =SUM(B5:B9) -> 45798 | C10: =SUM(C5:C9) -> 60674.9 | D10: =SUM(D5:D9) -> 73664.295 | E10: =SUM(E5:E9) -> 91217.76 | F10: =SUM(F5:F9) -> 101799.15 | G10: =SUM(G5:G9) -> 104509.61 | H10: =SUM(H5:H9) -> 477663.71
A11: 매출 성장률 (YoY) | B11: — | C11: =C10/B10-1 -> 0.32483733 | D11: =D10/C10-1 -> 0.21408185 | E11: =E10/D10-1 -> 0.23829 | F11: =F10/E10-1 -> 0.1160014 | G11: =G10/F10-1 -> 0.026625541 | H11: —
A12: 기존사업 매출원가 | B12: =-B5*핵심가정!B5 -> -33716.088 | C12: =-C5*핵심가정!C5 -> -35636.032 | D12: =-D5*핵심가정!D5 -> -36901.556 | E12: =-E5*핵심가정!E5 -> -38204.542 | F12: =-F5*핵심가정!F5 -> -39545.573 | G12: =-G5*핵심가정!G5 -> -40902.428 | H12: =SUM(B12:G12) -> -224906.22
A13: 매출총이익 (합산) | B13: =(B5+B12)+B15+B16+B17 -> 11481.912 | C13: =(C5+C12)+C15+C16+C17 -> 14493.918 | D13: =(D5+D12)+D15+D16+D17 -> 18151.989 | E13: =(E5+E12)+E15+E16+E17 -> 24251.718 | F13: =(F5+F12)+F15+F16+F17 -> 29492.074 | G13: =(G5+G12)+G15+G16+G17 -> 30845.677 | H13: =SUM(B13:G13) -> 128717.29
A14: 기존사업 영업이익 | B14: =(B5+B12)-B5*핵심가정!B6 -> 5262.564 | C14: =(C5+C12)-C5*핵심가정!C6 -> 5759.8317 | D14: =(D5+D12)-D5*핵심가정!D6 -> 7055.7938 | E14: =(E5+E12)-E5*핵심가정!E6 -> 8466.9526 | F14: =(F5+F12)-F5*핵심가정!F6 -> 10001.588 | G14: =(G5+G12)-G5*핵심가정!G6 -> 11691.287 | H14: =SUM(B14:G14) -> 48238.017
A15: A사 프로젝트 영업이익 (50%) | B15: =B6*0.5 -> 600 | C15: =C6*0.5 -> 2250 | D15: =D6*0.5 -> 4000 | E15: =E6*0.5 -> 8000 | F15: =F6*0.5 -> 12000 | G15: =G6*0.5 -> 12000 | H15: =SUM(B15:G15) -> 38850
A16: 삼성DX 영업이익 (10%) | B16: =(B7+B8)*0.1 -> 0 | C16: =(C7+C8)*0.1 -> 700 | D16: =(D7+D8)*0.1 -> 1180 | E16: =(E7+E8)*0.1 -> 1420 | F16: =(F7+F8)*0.1 -> 1420 | G16: =(G7+G8)*0.1 -> 1420 | H16: =SUM(B16:G16) -> 6140
A17: AI서버CNC 영업이익 (15%) | B17: =B9*0.15 -> 0 | C17: =C9*0.15 -> 352.05 | D17: =D9*0.15 -> 704.25 | E17: =E9*0.15 -> 1408.5 | F17: =F9*0.15 -> 1408.5 | G17: =G9*0.15 -> 1408.5 | H17: =SUM(B17:G17) -> 5281.8
A18: 한국법인 운영비 | B18: 0 | C18: 0 | D18: -2000 | E18: -2000 | F18: -2000 | G18: -2000 | H18: =SUM(B18:G18) -> -8000
A19: 영업이익 | B19: =B14+B15+B16+B17+B18 -> 5862.564 | C19: =C14+C15+C16+C17+C18 -> 9061.8817 | D19: =D14+D15+D16+D17+D18 -> 10940.044 | E19: =E14+E15+E16+E17+E18 -> 17295.453 | F19: =F14+F15+F16+F17+F18 -> 22830.088 | G19: =G14+G15+G16+G17+G18 -> 24519.787 | H19: =SUM(B19:G19) -> 90509.817
A20: 영업이익률 | B20: =B19/B10 -> 0.12800917 | C20: =C19/C10 -> 0.14935141 | D20: =D19/D10 -> 0.14851216 | E20: =E19/E10 -> 0.1896062 | F20: =F19/F10 -> 0.224266 | G20: =G19/G10 -> 0.23461754 | H20: —
A21: 순이자비용 | B21: =-핵심가정!B25 -> -686.53 | C21: =-핵심가정!C25 -> -686.53 | D21: =-핵심가정!D25 -> -686.53 | E21: =-핵심가정!E25 -> -686.53 | F21: =-핵심가정!F25 -> -686.53 | G21: =-핵심가정!G25 -> -556.53 | H21: =SUM(B21:G21) -> -3989.18
A22: 기타영업외손익 | B22: -531 | C22: 0 | D22: 0 | E22: 0 | F22: 0 | G22: 0 | H22: =SUM(B22:G22) -> -531
A23: 감가상각비 (D&A, 참고) | B23: =B56 -> 4000 | C23: =C56 -> 4000 | D23: =D56 -> 4300 | E23: =E56 -> 4805 | F23: =F56 -> 5805 | G23: =G56 -> 5805 | H23: =SUM(B23:G23) -> 28715
A24: EBITDA | B24: =B19+B23 -> 9862.564 | C24: =C19+C23 -> 13061.882 | D24: =D19+D23 -> 15240.044 | E24: =E19+E23 -> 22100.453 | F24: =F19+F23 -> 28635.088 | G24: =G19+G23 -> 30324.787 | H24: =SUM(B24:G24) -> 119224.82
A25: 세전이익 | B25: =B19+B21+B22 -> 4645.034 | C25: =C19+C21+C22 -> 8375.3517 | D25: =D19+D21+D22 -> 10253.514 | E25: =E19+E21+E22 -> 16608.923 | F25: =F19+F21+F22 -> 22143.558 | G25: =G19+G21+G22 -> 23963.257 | H25: =SUM(B25:G25) -> 85989.637
A26: 법인세 (2026: 16.3%, 이후 20%) | B26: =-B25*핵심가정!B26 -> -757.14054 | C26: =-C25*핵심가정!C26 -> -1675.0703 | D26: =-D25*핵심가정!D26 -> -2050.7028 | E26: =-E25*핵심가정!E26 -> -3321.7845 | F26: =-F25*핵심가정!F26 -> -4428.7116 | G26: =-G25*핵심가정!G26 -> -4792.6514 | H26: =SUM(B26:G26) -> -17026.061
A27: 당기순이익 | B27: =B25+B26 -> 3887.8935 | C27: =C25+C26 -> 6700.2814 | D27: =D25+D26 -> 8202.8111 | E27: =E25+E26 -> 13287.138 | F27: =F25+F26 -> 17714.846 | G27: =G25+G26 -> 19170.606 | H27: =SUM(B27:G27) -> 68963.576
A28: 순이익률 | B28: =B27/B10 -> 0.084892211 | C28: =C27/C10 -> 0.11042921 | D28: =D27/D10 -> 0.11135396 | E28: =E27/E10 -> 0.14566394 | F28: =F27/F10 -> 0.17401763 | G28: =G27/G10 -> 0.18343391 | H28: —
A29: II. 연결 현금흐름 요약 [단위: $천]
A30: 기초현금 | B30: 3063.847 | C30: =B41 -> 4734.841 | D30: =C41 -> 5916.2574 | E30: =D41 -> 7635.6959 | F30: =E41 -> 10793.848 | G30: =F41 -> 22048.019 | H30: =B30 -> 3063.847
A31: 당기순이익 | B31: =B27 -> 3887.8935 | C31: =C27 -> 6700.2814 | D31: =D27 -> 8202.8111 | E31: =E27 -> 13287.138 | F31: =F27 -> 17714.846 | G31: =G27 -> 19170.606 | H31: =SUM(B31:G31) -> 68963.576
A32: 감가상각비 환입 (+) | B32: =B23 -> 4000 | C32: =C23 -> 4000 | D32: =D23 -> 4300 | E32: =E23 -> 4805 | F32: =F23 -> 5805 | G32: =G23 -> 5805 | H32: =SUM(B32:G32) -> 28715
A33: 운전자본 변동 | B33: -280.89948 | C33: -3518.8649 | D33: -2733.3726 | E33: -3933.9863 | F33: -2265.6753 | G33: -388.15642 | H33: =SUM(B33:G33) -> -13120.955
A34: 영업활동현금흐름 | B34: =B31+B32+B33 -> 7606.994 | C34: =C31+C32+C33 -> 7181.4165 | D34: =D31+D32+D33 -> 9769.4385 | E34: =E31+E32+E33 -> 14158.152 | F34: =F31+F32+F33 -> 21254.171 | G34: =G31+G32+G33 -> 24587.449 | H34: =SUM(B34:G34) -> 84557.621
A35: 베트남 설비투자 (Capex) | B35: =-B49 -> -5936 | C35: =-C49 -> -3000 | D35: =-D49 -> -1000 | E35: =-E49 -> -1000 | F35: =-F49 -> -3000 | G35: =-G49 -> -3000 | H35: =SUM(B35:G35) -> -16936
A36: 한국공장 1단계 투자 ($5M/2027) | B36: =-B50 -> 0 | C36: =-C50 -> -3000 | D36: =-D50 -> -2000 | E36: =-E50 -> 0 | F36: =-F50 -> 0 | G36: =-G50 -> 0 | H36: =SUM(B36:G36) -> -5000
A37: AI서버 공장투자 ($5.05M/2028) | B37: =-B51 -> 0 | C37: =-C51 -> 0 | D37: =-D51 -> -5050 | E37: =-E51 -> 0 | F37: =-F51 -> 0 | G37: =-G51 -> 0 | H37: =SUM(B37:G37) -> -5050
A38: 한국공장 2단계 투자 ($15M/2029) | B38: =-B52 -> 0 | C38: =-C52 -> 0 | D38: =-D52 -> 0 | E38: =-E52 -> -10000 | F38: =-F52 -> -5000 | G38: =-G52 -> 0 | H38: =SUM(B38:G38) -> -15000
A39: 투자활동현금흐름 | B39: =SUM(B35:B38) -> -5936 | C39: =SUM(C35:C38) -> -6000 | D39: =SUM(D35:D38) -> -8050 | E39: =SUM(E35:E38) -> -11000 | F39: =SUM(F35:F38) -> -8000 | G39: =SUM(G35:G38) -> -3000 | H39: =SUM(B39:G39) -> -41986
A40: 차입금 상환 (2026~29 유예 → 2030~ $2M/년 분할상환) | B40: 0 | C40: 0 | D40: 0 | E40: 0 | F40: -2000 | G40: -2000 | H40: =SUM(B40:G40) -> -4000
...

Sheet 핵심가정
A1: MNC Group — 핵심 가정 (Assumptions)
A2: 항목 | B2: 2026 | C2: 2027 | D2: 2028 | E2: 2029 | F2: 2030 | G2: 2031 | H2: 비고
A3: A. 기존사업 가정
A4: 기존사업 매출 ($K) | B4: 44598 | C4: =B4*1.05 -> 46827.9 | D4: =C4*1.05 -> 49169.295 | E4: =D4*1.05 -> 51627.76 | F4: =E4*1.05 -> 54209.148 | G4: =F4*1.05 -> 56919.605 | H4: 2027년부터 연 5%성장
A5: 기존사업 매출원가율 | B5: 0.756 | C5: 0.761 | D5: 0.7505 | E5: 0.74 | F5: 0.7295 | G5: 0.7186 | H5: 75.6%에서 출발, 매년 1.05%p 개선
A6: 기존사업 판관비율 | B6: 0.126 | C6: =B6-$B$31 -> 0.116 | D6: =C6-$B$31 -> 0.106 | E6: =D6-$B$31 -> 0.096 | F6: =E6-$B$31 -> 0.086 | G6: =F6-$B$31 -> 0.076 | H6: 2026 12.6% → 매년 1.0%p 개선 (개선폭 B31). 적용대상: 기존사업
A7: B. A사 프로젝트 가정
A8: A사 수량 (세트) | B8: 600 | C8: 2500 | D8: 5000 | E8: 10000 | F8: 15000 | G8: 15000 | H8: 양산단계 15,000세트
A9: A사 단가 ($/세트) | B9: 2000 | C9: 1800 | D9: 1600 | E9: 1600 | F9: 1600 | G9: 1600 | H9: 양산 $1,600 (20%볼륨할인)
A10: A사 매출 ($K) | B10: =B8*B9/1000 -> 1200 | C10: =C8*C9/1000 -> 4500 | D10: =D8*D9/1000 -> 8000 | E10: =E8*E9/1000 -> 16000 | F10: =F8*F9/1000 -> 24000 | G10: =G8*G9/1000 -> 24000 | H10: 영업이익률 50%
A11: C. 삼성전자 DX 가정
A12: ZN캐스팅 매출 ($K) | B12: 0 | C12: 4800 | D12: 9600 | E12: 12000 | F12: 12000 | G12: 12000 | H12: $0.40/개, 월100만개→연$4.8M
A13: 갤럭시탭 매출 ($K) | B13: 0 | C13: 2200 | D13: 2200 | E13: 2200 | F13: 2200 | G13: 2200 | H13: $2.2/개, 월8만개→연$2.2M
A14: 삼성DX 합계 ($K) | B14: =B12+B13 -> 0 | C14: =C12+C13 -> 7000 | D14: =D12+D13 -> 11800 | E14: =E12+E13 -> 14200 | F14: =F12+F13 -> 14200 | G14: =G12+G13 -> 14200 | H14: 영업이익률 10%
A15: D. AI서버 CNC 가정
A16: AI서버CNC 매출 ($K) | B16: 0 | C16: 2347 | D16: 4695 | E16: 9390 | F16: 9390 | G16: 9390 | H16: 임율 60동/초, 100대→200대, 환율 26,500동/$
A17: 기계대수 (대) | B17: 0 | C17: 100 | D17: 100 | E17: 200 | F17: 200 | G17: 200 | H17: 2029년 신공장 200대
A18: E. 투자계획 가정
A19: 베트남 Capex ($K) | B19: 5936 | C19: 3000 | D19: 1000 | E19: 1000 | F19: 3000 | G19: 3000 | H19: 2026 $5.9M / 2027·2030·2031 $3M / 2028~2029 $1M(2공장 투자로 유지보수만)
A20: 한국공장 1단계 ($K) | B20: 0 | C20: 3000 | D20: 2000 | E20: 0 | F20: 0 | G20: 0 | H20: 2027년 $3M, D&A $500K/년 2028~
A21: AI서버공장 투자 ($K) | B21: 0 | C21: 0 | D21: 5050 | E21: 0 | F21: 0 | G21: 0 | H21: 2028년 $5.05M (토지$750K+건축$800K+부대$500K+중고CNC 100대$3M)
A22: 한국공장 2단계 ($K) | B22: 0 | C22: 0 | D22: 0 | E22: 10000 | F22: 5000 | G22: 0 | H22: 2029년 $15M
A23: 감가상각 합계 ($K) | B23: =통합사업계획!B56 -> 4000 | C23: =통합사업계획!C56 -> 4000 | D23: =통합사업계획!D56 -> 4300 | E23: =통합사업계획!E56 -> 4805 | F23: =통합사업계획!F56 -> 5805 | G23: =통합사업계획!G56 -> 5805 | H23: 기존$4M + 신규투자 10년 정액(투자 익년부터)
A24: F. 재무 가정
A25: 순이자비용 ($K) | B25: =B32*$B$33 -> 686.53 | C25: =C32*$B$33 -> 686.53 | D25: =D32*$B$33 -> 686.53 | E25: =E32*$B$33 -> 686.53 | F25: =F32*$B$33 -> 686.53 | G25: =G32*$B$33 -> 556.53 | H25: 유예기간 부채유지로 flat → 2031 상환분($2M) 반영 감소. (구버전 declining 오류 수정)
A26: 법인세율 | B26: 0.163 | C26: 0.2 | D26: 0.2 | E26: 0.2 | F26: 0.2 | G26: 0.2 | H26: 2026 세제혜택 가능 (EY확인)
A27: AR 회전일수 (일) | B27: 87 | C27: 87 | D27: 87 | E27: 87 | F27: 87 | G27: 87 | H27: 2025년 실적 기준
A28: 재고 회전일수 (일) | B28: 34 | C28: 34 | D28: 34 | E28: 34 | F28: 34 | G28: 34 | H28: 2025년 실적 기준
A29: AP 회전일수 (일) | B29: 110 | C29: 110 | D29: 110 | E29: 110 | F29: 110 | G29: 110 | H29: 2025년 실적 기준
A30: G. 추가 가정 (v9 신규)
A31: 판관비율 연간 개선 (%p) | B31: 0.01 | H31: 12.6%에서 매년 1.0%p 개선 (operating leverage). 상대1% 의도면 0.126으로 변경
A32: 차입금 기초잔액 ($K) | B32: 10562 | C32: 10562 | D32: 10562 | E32: 10562 | F32: 10562 | G32: 8562 | H32: 2025말 은행차입 실적 $10.56M (Sch D-Loan). 2026~29 유예(유지), 2030·2031 각 $2M 상환
A33: 블렌디드 유효이자율 | B33: 0.065 | H33: $687K(2026예산 순이자)÷$10.56M, 설비 finance-lease 이자 포함 환산

Sheet AI서버CNC_계산근거
A1: AI서버 CNC 사업 — 월별 매출 계산 근거
A2: 기계대수 (1단계) | B2: 100대 | C2: 선반20+밀링80 | D2: 선반 20대 + 밀링 80대
A3: 기계대수 (2단계, 2029~) | B3: 200대 | C3: 기존100대 이전+신규100대 | D3: 기존 100대 이전 + 신규 100대
A4: 월 가동일 | B4: 24일 | C4: 격주 토요일 근무
A5: 일 가동시간 | B5: 20시간
A6: 기계당 시간당 임율 | B6: 216,000 VND | C6: 60동/초 × 3,600초
A7: 기계당 월 가동시간 | B7: 480시간 | C7: 20시간 × 24일
A8: 기계당 월 매출 (VND) | B8: 103,680,000 동 | C8: 216,000 × 480
A9: 적용 환율 | B9: 26,500 동/달러
A10: 기계 1대 월 매출 (USD) | B10: $3,912 | C10: 103,680,000 ÷ 26,500
A11: 100대 월 매출 (USD) | B11: $391,245 | C11: $3,912 × 100
A12: 100대 연 매출 (USD) | B12: $4,694,940 | C12: $391,245 × 12
A13: 200대 연 매출 (USD) | B13: $9,389,880 | C13: 약 $9,390K 반영
A14: 2027년 H2 매출 (6개월) | B14: $2,347,470 | C14: $391,245 × 6개월 | D14: 2027H2 시작
A15: 영업이익률 | B15: 15% | D15: 원가율 포함 전체 이익
A17: AI서버 공장 투자 내역 ($K)
A18: 토지 | B18: 5,000㎡ × $150 | C18: 750
A19: 건축 | B19: 2,000㎡ × $400 | C19: 800
A20: 공용설비·변압기 등 부대시설 | B20: 일식 | C20: 500
A21: CNC 구형/중고 (50대) | B21: $30,000 × 50대 | C21: 1500 | D21: 신규 두산 → 중고 50대로 변경 (투자규모 축소)
A22: CNC 중고 (화낙, 50대) | B22: $30,000 × 50대 | C22: 1500
A23: 합계 | C23: =SUM(C18:C22) -> 5050
