Workbook
Name __DemandLoad: TRUE
Name __IntlFixup: TRUE
Name _1a1_: {"'Sheet1'!$L$16"}
Name _1a1_: {"'Sheet1'!$L$16"}
Name _1a1_: {"'Sheet1'!$L$16"}
Name _1a1_: {"'Sheet1'!$L$16"}
Name _1a1_: {"'Sheet1'!$L$16"}
Name _1a1_: {"'Sheet1'!$L$16"}
Name _Order1: 255
Name _Order2: 255
Name _PA3: {"'Sheet1'!$L$16"}
Name _PA3: {"'Sheet1'!$L$16"}
Name _PA3: {"'Sheet1'!$L$16"}
Name _PA3: {"'Sheet1'!$L$16"}
Name _PA3: {"'Sheet1'!$L$16"}
Name _PA3: {"'Sheet1'!$L$16"}
Name _Regression_Int: 1
Name AS2DocOpenMode: "AS2DocumentEdit"
Name AS2ReportLS: 1
Name AS2SyncStepLS: 0
Name AS2VersionLS: 300
Name BG_Del: 15
Name BG_Ins: 4
Name BG_Mod: 6
Name CTCT1: {"'Sheet1'!$L$16"}
Name CTCT1: {"'Sheet1'!$L$16"}
Name CTCT1: {"'Sheet1'!$L$16"}
Name CTCT1: {"'Sheet1'!$L$16"}
Name CTCT1: {"'Sheet1'!$L$16"}
Name CTCT1: {"'Sheet1'!$L$16"}
Name HTML_CodePage: 950
Name HTML_Control: {"'Sheet1'!$L$16"}
Name HTML_Control: {"'Sheet1'!$L$16"}
Name HTML_Control: {"'Sheet1'!$L$16"}
Name HTML_Control: {"'Sheet1'!$L$16"}
Name HTML_Control: {"'Sheet1'!$L$16"}
Name HTML_Control: {"'Sheet1'!$L$16"}
Name HTML_Description: ""
Name HTML_Email: ""
Name HTML_Header: "Sheet1"
Name HTML_LastUpdate: "2000/9/14"
Name HTML_LineAfter: FALSE
Name HTML_LineBefore: FALSE
Name HTML_Name: "J.C.WONG"
Name HTML_OBDlg2: TRUE
Name HTML_OBDlg4: TRUE
Name HTML_OS: 0
Name HTML_PathFile: "C:\2689\Q\國內\00q3961台化龍德PTA3建造\MyHTML.htm"
Name HTML_Title: "00Q3961-SUM"
Name huy: {"'Sheet1'!$L$16"}
Name huy: {"'Sheet1'!$L$16"}
Name huy: {"'Sheet1'!$L$16"}
Name huy: {"'Sheet1'!$L$16"}
Name huy: {"'Sheet1'!$L$16"}
Name huy: {"'Sheet1'!$L$16"}
Name JYFUJ: BLCH
Name JYFUJ: BLCH
Name JYFUJ: BLCH
Name JYFUJ: BLCH
Name KUGHIKJ: BLCH

Sheet Cover
A3: 2026 Business Plan M&C Electronics

Sheet Index
A2: <Index>
E6: 1. Assumption
E7: - 영업, 개발, 생산, 품질, 관리, 재무
E9: 2. Sales Plan (S Plan)
E10: - 매출 수량 및 금액
E12: 3. Production Plan (P Plan)
E13: - 생산 수량 및 필요 설비 수
E15: 4. Labor Plan (L Plan)
E16: - 인원 계획
E18: 5. Material Plan (M Plan)
E19: - 원부자재 계획
E21: 6. Outsourcing (O Plan)
E22: - 외주 비용(아노다이징,분체도장)
... E40: - 대출 현황

Sheet 1. Assumption
A1: Basic Assumption
A4: ☆ M&C 베트남 법인 사업계획 보고
A6: 1) 개발영업 - 매출
B7: No. | C7: 고객사 | D7: 내용 | E7: 매출액 | F7: 비고/특이사항
B8: 1 | C8: 삼성 Bracket | D8: 26.10월부터 15대 가동 - 월 최대 2,300,000대 수준으로 변경 | E8: ='2. S Plan'!X109+'2. S Plan'!X110+'2. S Plan'!X111+'2. S Plan'!X112+'2. S Plan'!X113+'2. S Plan'!X114+'2. S Plan'!X115 -> 12243940 | F8: - AI디바이스 교체에 따른 연간 출하량 지속 증가
B9: 2 | C9: 삼성 CNC | D9: 26.8월 LGIT 종료 설비 50대 + 26.10월 만도 종료 설비 25대 투입 반영 | E9: ='2. S Plan'!X117 -> 6451579.4
B10: 3 | C10: Qualcomm | E10: ='2. S Plan'!X119+'2. S Plan'!X120+'2. S Plan'!X121+'2. S Plan'!X122+'2. S Plan'!X123+'2. S Plan'!X124 -> 693554.69
B11: 4 | C11: LGIT | D11: 협의 수량으로 조정 | E11: ='2. S Plan'!X127+'2. S Plan'!X128+'2. S Plan'!X129+'2. S Plan'!X130+'2. S Plan'!X131+'2. S Plan'!X132+'2. S Plan'!X134+'2. S Plan'!X136+'2. S Plan'!X137+'2. S Plan'!X139+'2. S Plan'!X140+'2. S Plan'!X141+'2. S Plan'!X142+'2. S Plan'!X143+'2. S Plan'!X145+'2. S Plan'!X147+'2. S Plan'!X148+'2. S Plan'!X150+'2. S Plan'!X151+'2. S Plan'!X153+'2. S Plan'!X154+'2. S Plan'!X155+'2. S Plan'!X156+'2. S Plan'!X159+'2. S Plan'!X160+'2. S Plan'!X161+'2. S Plan'!X162 -> 5008883.3 | F11: CL4 & MQ4 기존 납품처 YT -> MX 변경 예정 구체적인 일정 및 단가 변경은 고객사와 협의 후 사업계획 내 반영 예정
B12: 5 | C12: Mando | D12: 3/16 거래 종료 통보 예정. 추후 최종 공급 수량 협의 필요 | E12: ='2. S Plan'!X165+'2. S Plan'!X166+'2. S Plan'!X167+'2. S Plan'!X169+'2. S Plan'!X168+'2. S Plan'!X170+'2. S Plan'!X172+'2. S Plan'!X173+'2. S Plan'!X174+'2. S Plan'!X175+'2. S Plan'!X176+'2. S Plan'!X178+'2. S Plan'!X180 -> 6540485.5
B13: 6 | C13: ZF | D13: 2026 Forecast 반영 | E13: ='2. S Plan'!X183+'2. S Plan'!X184+'2. S Plan'!X185+'2. S Plan'!X187+'2. S Plan'!X188+'2. S Plan'!X189+'2. S Plan'!X191+'2. S Plan'!X192+'2. S Plan'!X193+'2. S Plan'!X194+'2. S Plan'!X195+'2. S Plan'!X196 -> 8333548.6
B14: 7 | C14: A | D14: 2026년 테스트용 시제품 수요 예상 (월 200개, 2026.7~ 반영) | E14: ='2. S Plan'!X200+'2. S Plan'!X201+'2. S Plan'!#REF!+'2. S Plan'!#REF!+'2. S Plan'!#REF!+'2. S Plan'!#REF!+'2. S Plan'!X199 -> #REF! | F14: 2026년 3월까지 시제품 평가 완료. 하반기 저율초도생산(LRIP)으로 전환 예상 Qualcomm과 같이 VN 20%, SG 80%
B15: 8 | C15: 기타 | D15: - 스크랩 및 금형비 반영 | E15: ='2. S Plan'!X204+'2. S Plan'!X205 -> 2283491.7
B16: 합계 | E16: =SUM(E8:E15) -> #REF!
E17: TRUE
A18: 2) 개발영업 - 제품 개발
B19: No. | C19: 고객사 | D19: 내용 | F19: 비고/특이사항
B20: 1 | C20: 삼성 | D20: 자동화 설비 연계, 제품 개발 및 생산성 확보 효율화 / Bracket 금형 추가 배정 영업 지속
B21: 2 | C21: Qualcomm | D21: 기존 제품 양산 안정화 및 신규 프로젝트 수주 활동 지속
B22: 3 | C22: ZF | D22: ADAS 외 제품군 견적 및 수주 활동 지속
B23: 4 | C23: LGIT | D23: 사업 철수 진행
B24: 5 | C24: Mando
B25: 6 | C25: A | D25: Audit 준비 및 DFM, 긴급 물량 지속 대응/협업 진행

Sheet 1-1.Assumption
A1: Basic Assumption (Expense)
A3: 3) 관리
A4: No. | B4: 주제 | C4: 항목 | D4: 내용 | E4: 추정 이유(계산) (개선방안) | F4: 비고/특이사항
A5: 1 | B5: COGS (COGM) | C5: 원재료 | D5: (ADC12 $2.65, S36 $3.30, S3Y $3.37) / Kg | E5: 25년 (1~8월) 평균가 | F5: 5.M Plan 참조
C6: 인건비 | D6: 2025년 대비 Worker 7%, 관리자 5%, 주재원 3% 인상 적용 | F6: 4.L Plan 참조
D7: 2026년 주재원 충원 미반영 | F7: 4.L Plan 참조
C8: 관리비(3대보험&복지) | D8: 베트남 기준 (사회,고용,건강보험,노동조합)가입, 복지(식대) | E8: 개인별 급여 월 23.5%보험가입비*총 인원+식대
C9: 관리비(유틸리티) | D9: 생산일수 기반으로 현재 단가 적용 | E9: 2023~2025년도 평균 4.5%인상 기준으로 2026년도 베트남 전기료 인상 4.5% 반영
C10: 관리비(유틸리티) | D10: 폐수처리 비용 (생활 폐수,오염 절삭유,크로메이트 처리 폐수 ) | E10: 캐스팅 장비수+CNC생산일수(평균)*25년 (1~8월) 평균 폐수처리 단가계산로 반영
C11: 관리비(유틸리티) | D11: 수도,하수 비용 | E11: 월 계산=3개월 평균 가격 (월 인원수+캐스팅 가동수+크로메이트처리(시간당) 기준)
C12: 관리비(아웃소싱) | D12: Samsung Bracket 월 50만개 이상시 외주 사상 진행, ZF 아노다이징, 퀄컴 레이저 및 A사 외주 비용 반영 | F12: 6.O Plan 참조
C13: 관리비(Oil & 소모품) | D13: 매출액 대비 5.5%기준 적용 | E13: 2025년 영업매출 대비 평균 % 반영
C14: 관리비(Tool 소모품) | D14: 매출액 대비 1.2%기준 적용 | E14: 2024년 1.7% 대비 2025년 1~8월 평균 1.2%로, 0.5% 감소하여 2026년 1.2% 반영
C15: 관리비(납품차량렌트) | D15: 영업 납품용 차량 (화물 탑차 5ton 2대 임대 비용)
C16: 감가상각 | D16: 고정자산(장비&설비) 회계처리 비용 | E16: 2025년 8월 기준기준 실제 비용 적용 | F16: 8.I Plan 참조
C17: 기타 비용 | D17: 각종 납품용 박스 및 파렛트 년평균 매출 %기준 대비 추정
A18: 2 | B18: SG&A | C18: 컨설팅 서비스 비용 | D18: 서비스 비용(한국 $5만, 중국$3만)
C19: 출장비 | D19: 매출액의 0.2%로 적용 | E19: 2025년도 월 평균 반영 및 A사 (미국) 출장 비용 분기별 1만불 추가 적용
C20: 차량(출퇴근)임대 | D20: 카니발 7인승 5대, 15인승 1대 ,지게차 2대 운영비용 | E20: 추가 없음
C21: 학자금 지원 | D21: 주재원 자녀 복리 학비 지원 (1명당Net $6,500$ 총$45,500 월 평균 반영) | E21: 주재원 자녀 총 7명 지원
C22: 감가상각 | D22: 2026년 8월 기준, 신규 투자 설비 반영
C23: 기타비용 (사내 경비,청소) | D23: 경비 & 청소 용역, 정원 관리 비용 | E23: 2025년 비용 평균 적용 (예비비 포함)
C24: 근무일수 | D24: 2026년도 총 302일 (주일 53일,국경절&행사 10일) | F24: 4.L.Plan 참조
A25: 4 | B25: 투자계획 | C25: 주요구입장비 | D25: 사업계획에 투자 반영 | E25: 2025년 8월 기준 업데이트, 'I plan 참조 | F25: 8.I-Plan 참조
A26: 5 | B26: 환율 적용 | C26: SGD | D26: 외화(달러)현재 적용 환율 | E26: 2026년 시장 예상(단 환율 변동이 클 경우 조정 필요, update 25.08 UOB 및 Traders Union 참조) | F26: 1.29
C27: KRW | F27: 1450
C28: CNY | F28: 6.9
C29: VND | F29: 26400

Sheet 1. Master Plan
A1: Business Relocation Master Plan
A2: No | B2: Vendor | C2: Present | D2: Future 2027 | E2: 46023 | F2: 46054 | G2: 46082 | H2: 46113 | I2: 46143 | J2: 46174 | K2: 46204 | L2: 46235 | M2: 46266 | N2: 46296 | O2: 46327 | P2: 46357 | Q2: 46388 | R2: 46419 | S2: 46447 | T2: 46478 | U2: 46508 | V2: 46539 | W2: 비고 | Z2: Sales Down | AA2: -1200
A3: 1 | B3: Samsung Bracket | C3: 12500000 | D3: 25000000 | L3: 15 | M3: 15 | N3: 15 | O3: 15 | P3: 15 | Q3: 17 | R3: =Q3 -> 17 | S3: =R3 -> 17 | T3: =S3 -> 17 | U3: =T3 -> 17 | V3: =U3 -> 17 | W3: 15대 X 7K X 25 DAYS = 2.65M/M | Z3: Material AL | AA3: 550
A4: 2 | B4: Samsung CNC | C4: 6300000 | D4: 8000000 | J4: 319 | K4: =J4 -> 319 | L4: =K4 -> 319 | M4: =L4+31 -> 350 | N4: =M4 -> 350 | O4: =N4 -> 350 | P4: =O4 -> 350 | Q4: =P4+50 -> 400 | R4: =Q4 -> 400 | S4: =R4 -> 400 | T4: =S4 -> 400 | U4: =T4 -> 400 | V4: =U4 -> 400 | W4: 삼성 CNC생산 투입 400대 (삼성 283+당사 127대) | Z4: Labor | AA4: 100
A5: 3 | B5: Samsung CNC 설비 추가 | K5: 50 | L5: =K5 -> 50 | M5: =L5 -> 50 | N5: =M5 -> 50 | O5: =N5 -> 50 | P5: =O5 -> 50 | Q5: =P5 -> 50 | R5: =Q5 -> 50 | S5: =R5 -> 50 | ... V5: =U5 -> 50 | W5: 삼성 CNC 설비 추가 50대 임대 | Z5: Consummerable & Mold Fee | AA5: 200
A6: 4 | B6: ZF | C6: 9000000 | D6: 9000000 | L6: 5 | M6: 5 | N6: 5 | O6: 5 | P6: 5 | Q6: 5 | R6: 5 | S6: 5 | T6: 5 | U6: 5 | V6: 5 | Z6: Logsitics/Warehoues/QC Exp. | AA6: 150
A7: 5 | B7: Qualcomm | C7: 6000000 | D7: 5500000 | L7: 0 | M7: 0 | N7: 0 | O7: 0 | P7: 0 | Z7: 감가상각 및 기타 | AA7: 200
A8: 6 | B8: A | D8: 2500000 | L8: 0 | M8: 0 | N8: 0 | O8: 0 | P8: 0 | Z8: Cost Reduction | AA8: =SUM(AA3:AA7) -> 1200
A9: 7 | B9: LGIT | C9: 6500000 | D9: 0 | E9: 통지 | F9: 1차회의 | G9: 2차회의 | H9: 6 | I9: 6 | J9: 5 | K9: 5 | L9: 4 | M9: 3 | N9: 2 | O9: 2 | P9: 2 | W9: 최종 만도/LG재고생산 4-5대 배치 2027 상반기까지 지원 | Z9: Sales up
A10: 8 | B10: Mando | C10: 6800000 | D10: 1500000 | G10: 통지 | H10: 1차회의 | I10: 2차회의 | J10: 6 | K10: 6 | L10: 4 | M10: 4 | N10: 3 | O10: 3 | P10: 3 | Q10: 3 | R10: 3 | S10: 3 | T10: 3 | U10: 3 | V10: 3 | W10: 외주에 400톤 2대 설치하여 종료제품 SPOT생산 지원 | Z10: Samsung Bracket | AA10: 850
A11: 9 | B11: Total | C11: =SUM(C3:C10) -> 47100000 | D11: =SUM(D3:D10) -> 51500000 | L11: =SUM(L3,L6,L9:L10) -> 28 | M11: =SUM(M3,M6,M9:M10) -> 27 | N11: =SUM(N3,N6,N9:N10) -> 25 | O11: =SUM(O3,O6,O9:O10) -> 25 | P11: =SUM(P3,P6,P9:P10) -> 25 | Q11: =SUM(Q3,Q6,Q9:Q10) -> 25 | R11: =SUM(R3,R6,R9:R10) -> 25 | S11: =SUM(S3,S6,S9:S10) -> 25 | ... V11: =SUM(V3,V6,V9:V10) -> 25 | Z11: Samsung CNC | AA11: 150
A13: No | B13: Project 명칭 | C13: 단가 | D13: 소요예산 | E13: 46023 | F13: 46054 | G13: 46082 | H13: 46113 | I13: 46143 | J13: 46174 | K13: 46204 | L13: 46235 | M13: 46266 | N13: 46296 | O13: 46327 | P13: 46357 | Q13: 46388 | R13: 46419 | S13: 46447 | T13: 46478 | U13: 46508 | V13: 46539 | W13: 비고
A14: 1 | B14: 캐스팅 125톤 외주 임대 개시 | C14: 0 | D14: =C14 -> 0 | G14: 외부설치 | H14: 2 | I14: 2 | J14: 2 | K14: 2 | L14: 2 | M14: 2 | N14: 2 | O14: 2 | P14: 2 | Q14: 2 | R14: 2 | S14: 2 | T14: 2 | U14: 2 | V14: 2
A15: 2 | B15: 삼성 CNC 화장실 공사 완료 | C15: 0 | D15: =C15 -> 0 | G15: 설치
A16: 3 | B16: CNC ZF BT30생산 BT40 이전 생산 | C16: 0 | D16: =C16 -> 0 | H16: 설치 | W16: ZF 물량 BT40으로 이전하고 BT30 12대 삼성 CNC 라인 이동 배치
A17: 4 | B17: CNC화장실 CNC12대 이동 | C17: 10000 | D17: =C17 -> 10000 | H17: 설치 | W17: 283+24+12대 총 319대 생산 및 일요일 잔업 최소화
A18: 5 | B18: 삼성 CNC Block 자동화 CNC라인 구축 (6개라인 개조) | C18: 20000 | D18: =C18*6 -> 120000 | M18: 설계 | N18: 설계 | O18: 발주 | P18: 발주 | Q18: 설치 | W18: 최소 4개라인에서 최대 6개라인 개선 변경 후 삼성 Block생산
A19: 6 | B19: 삼성 CNC 설비 추가 임대 50대 진행 (삼성지속확인) | C19: 2000 | D19: =C19*50 -> 100000 | K19: 임대확정 | L19: 공간확보 | W19: 삼성 CNC가공 확인/ GEN3쪽 CNC라인 공간 확보 및 선반 배치 확인
A20: 7 | B20: 삼성 CNC세척라인 이동 및 개조 | C20: 10000 | D20: =C20 -> 10000 | O20: 설치 | W20: 기존 하우징 세척 라인 이용
A21: 8 | B21: 삼성 CNC Block 사상 및 검사 자동화 라인 | C21: 100000 | D21: =C21 -> 100000 | J21: 설계 | K21: 설계 | L21: 발주 | O21: 설치 | W21: Almus Burr 제거라인 확인 및 공간확보 혹은 당사 외주 발주
A22: 9 | B22: 삼성 CNC라인 공조설치 | C22: 100000 | D22: =C22*2 -> 200000 | G22: 설계 | H22: 발주 | I22: 설치 | W22: 5월15일 이전까지 삼성 CNC라인 공조 설치 및 배풍 개선
A23: 10 | B23: 캐스팅 라인 덮개 26대 공사 완료 및 배풍 시설 개선 | C23: 7000 | D23: =C23*26 -> 182000 | G23: 발주 | H23: 완료
A24: 11 | B24: 캐스팅 라인 집진 장비 테스트 및 문 추가 설치(통풍) | C24: 5000 | D24: =C24*26 -> 130000 | G24: TEST | H24: 발주 | K24: 도착 | Z24: =15*7*25 -> 2625
A25: 12 | B25: 캐스팅 설비 350톤 4대 도착 및 생산 | C25: 136000 | D25: =C25*4 -> 544000 | F25: 발주 | J25: 도착 | K25: 26 | L25: 26 | M25: 26 | N25: 26 | O25: 26 | P25: 26 | Q25: 26 | R25: 26 | S25: 26 | T25: 26 | U25: 26 | V25: 26 | W25: 2026년 7월부터 350톤 24대, 125톤 2대 체제 운영
A26: 13 | B26: 캐스팅 설비 400톤 2대 외주 임대 개시 | C26: 0 | D26: =C26 -> 0 | J26: 외부설치 | K26: 2 | L26: =K26 -> 2 | M26: =L26 -> 2 | N26: =M26 -> 2 | O26: =N26 -> 2 | P26: =O26 -> 2 | Q26: =P26 -> 2 | R26: =Q26 -> 2 | S26: =R26 -> 2 | ... V26: =U26 -> 2
A27: 14 | B27: 금형라인 CNC로 임시 생산 이동 및 생산 | C27: 20000 | D27: =C27 -> 20000 | I27: 이전 | J27: 생산 | K27: 생산 | W27: 현재 설비 전부 이동 (가공기 6대/방전기2대/와이어 1대)
A28: 15 | B28: 금형라인 사무실 및 유지보수 임시 이동 운영 | C28: 20000 | D28: =C28 -> 20000 | I28: 이전 | J28: 임시운영 | K28: 임시운영 | L28: 임시운영 | M28: 복귀
A29: 16 | B29: 금형가공 라인 공사 진행 (현 가공+사무실+공구창고) | C29: 200000 | D29: =C29 -> 200000
A30: 17 | B30: 금형유지보수 라인 공사 진행 | C30: 100000 | D30: =C30 -> 100000
A31: 18 | B31: 금형설비 발주 (방전기 4대, 가공기 2대, 와이어 1대) | C31: ='8. I Plan'!G8+'8. I Plan'!G9+'8. I Plan'!G10+'8. I Plan'!G11 -> 1206042 | D31: =C31 -> 1206042 | I31: 발주 | L31: 도착 | M31: 도착 | W31: 가공 6-8대, 방전 6대, 와이어 2대, 일반 방전 2-4대
A32: 19 | B32: 금형 자동화 라인 | C32: ='8. I Plan'!E49 -> 402923.08 | D32: =C32 -> 402923.08 | J32: 발주 | L32: 도착 | M32: 도착 | W32: CMM2대 자동화 및 AMR 도입 로봇형 자동화 라인
A33: 20 | B33: 금형 자동화 라인 CMM측정설비 도입 (신규 1대) | C33: 100000 | D33: =C33 -> 100000 | L33: 발주 | N33: 도착 | W33: CMM1대는 기존 설비 이동, CMM 1대는 추가 구매 진행
A34: 21 | B34: QC측정 자동화 라인 (CMM 3대 자동측정 라인) | C34: 70000 | D34: =C34 -> 70000 | K34: 발주 | N34: 도착
A35: 22 | B35: CL4 & IMEB CNC라인 이동 | C35: 10000 | D35: =C35 -> 10000 | N35: 라인이동
A36: 23 | B36: Braket 자동화 검사 5대운영 | C36: 30000 | D36: =C36 -> 30000 | G36: 발주 | H36: 도착 | I36: 5 | J36: 5 | K36: 5 | L36: 5 | M36: 5 | N36: 5 | O36: 5 | P36: 5 | Q36: 5 | R36: 5 | S36: 5 | T36: 5 | U36: 5 | V36: 5
A37: 24 | B37: Bracket Hot Press 자동화 4개라인 운영 | C37: 19818 | D37: =C37 -> 19818 | G37: 발주 | H37: 도착 | I37: 4 | J37: 4 | K37: 4 | L37: 4 | M37: 4 | N37: 4 | O37: 4 | P37: 4 | Q37: 4 | R37: 4 | S37: 4 | T37: 4 | U37: 4 | V37: 4
A38: 25 | B38: Bracket 자동화 Index 6개 라인 운영 | C38: 31700 | D38: =C38 -> 31700 | G38: 발주 | H38: 도착 | I38: 6 | J38: 6 | K38: 6 | L38: 6 | M38: 6 | N38: 6 | O38: 6 | P38: 6 | Q38: 6 | R38: 6 | S38: 6 | T38: 6 | U38: 6 | V38: 6
A39: 26 | B39: Bracket 자동화 사상 6개라인 운영 | C39: 46500 | D39: =C39*3 -> 139500 | G39: 발주 | H39: 도착 | I39: 6 | J39: 6 | K39: 6 | L39: 6 | M39: 6 | N39: 6 | O39: 6 | P39: 6 | Q39: 6 | R39: 6 | S39: 6 | T39: 6 | U39: 6 | V39: 6
A40: 27 | B40: Bracket 자동화 로봇 사상 라인 16개 라인 운영 | C40: 20000 | D40: =C40*4 -> 80000 | G40: 설계 | H40: 발주 | I40: 도착 | J40: 16 | K40: 16 | L40: 16 | M40: 16 | N40: 16 | O40: 16 | P40: 16 | Q40: 16 | R40: 16 | S40: 16 | T40: 16 | U40: 16 | V40: 16
A41: 28 | B41: Bracket 자동화 바렐 라인 라인 운영 | C41: 30000 | D41: =C41 -> 30000 | H41: 소싱 | I41: 발주 | K41: 도착
...

Sheet 2. S Plan
A1: 2. Sales Plan
X2: Rev 26
A3: 1) Sales Quantity | X3: 2026.06.06
A4: No. | B4: Industry | C4: Customer | D4: Categories | E4: No | F4: Model | G4: U/P | H4: Q1 | I4: Q2 | J4: Q3 | K4: Q4 | L4: Jan.26 | M4: Feb.26 | N4: Mar.26 | O4: Apr.26 | P4: May.26 | Q4: Jun.26 | R4: Jul.26 | S4: Aug.26 | T4: Sep.26 | U4: Oct.26 | V4: Nov.26 | W4: Dec.26 | X4: 2026 Total | AB4: Customer | AC4: Categories
A5: 1 | B5: Mobile | C5: Samsung | D5: Mobile | F5: =B.BasicInfomation!B10 -> Galaxy Tap | G5: 1.8 | H5: 0.86499679 | I5: 0.74 | J5: 0.7252 | K5: 0.710696 | L5: 0 | M5: 0 | N5: 0 | O5: 0 | P5: 0 | Q5: 0 | R5: 0 | V5: 10000 | W5: 50000 | X5: =SUM(L5:W5) -> 60000 | AB5: Samsung | AC5: Mobile
E6: 1 | F6: A15/17 | G6: 0.618 | H6: 0.68186719 | I6: 0.6625162 | J6: 0.66529412 | K6: 0.65198824 | L6: 1134160 | M6: 804560 | N6: 887570 | O6: 972545 | P6: 970800 | Q6: 1160000 | R6: 1200000 | S6: 1200000 | T6: 800000 | U6: 750000 | V6: 750000 | W6: 750000 | X6: =SUM(L6:W6) -> 11379635 | AB6: =AB5 -> Samsung | AC6: =AC5 -> Mobile
E7: 2 | F7: A36 | G7: 0.70957692 | H7: 0.76 | I7: 0.75126469 | J7: 0.72713725 | K7: 0.71259451 | L7: 46320 | M7: 0 | N7: 60960 | O7: 80640 | P7: 20160 | Q7: 15000 | R7: 0 | S7: 0 | T7: 0 | U7: 0 | V7: 0 | W7: 0 | X7: =SUM(L7:W7) -> 223080 | AB7: =AB6 -> Samsung | AC7: =AC6 -> Mobile
E8: 3 | F8: A26 | G8: 0.68169231 | H8: 0.80160892 | I8: 0.75653268 | J8: 0.7292549 | K8: 0.7146698 | L8: 209040 | M8: 55293 | N8: 0 | O8: 9876 | P8: 83280 | R8: 0 | S8: 0 | T8: 0 | U8: 0 | V8: 0 | W8: 0 | X8: =SUM(L8:W8) -> 357489 | AB8: =AB7 -> Samsung | AC8: =AC7 -> Mobile
E9: 4 | F9: A27 | G9: 0.71 | H9: 1.0308227 | I9: 0.95888659 | J9: 0.99600625 | K9: 1.0132913 | L9: 0 | M9: 0 | N9: 0 | O9: 0 | P9: 101760 | Q9: 790000 | R9: 1000000 | S9: 1000000 | T9: 700000 | U9: 500000 | V9: 500000 | W9: 400000 | X9: =SUM(L9:W9) -> 4991760 | AB9: =AB8 -> Samsung | AC9: =AC8 -> Mobile
E10: 5 | F10: A37 | G10: 0.752 | L10: 69200 | M10: 411900 | N10: 222600 | O10: 0 | P10: 48600 | Q10: 64000 | R10: 100000 | S10: 100000 | T10: 100000 | U10: 100000 | V10: 0 | W10: 0 | X10: =SUM(L10:W10) -> 1216300 | AB10: =AB9 -> Samsung | AC10: =AC9 -> Mobile
E11: 6 | F11: A18 | G11: 0.6 | L11: 0 | M11: 0 | N11: 0 | O11: 0 | P11: 0 | Q11: 0 | R11: 0 | S11: 0 | U11: 50000 | V11: 400000 | W11: 400000 | X11: =SUM(L11:W11) -> 850000 | AB11: =AB10 -> Samsung | AC11: =AC10 -> Mobile
E12: Braket Sub Toal | L12: =SUM(L5:L11) -> 1458720 | M12: =SUM(M5:M11) -> 1271753 | N12: =SUM(N5:N11) -> 1171130 | O12: =SUM(O5:O11) -> 1063061 | P12: =SUM(P5:P11) -> 1224600 | Q12: =SUM(Q5:Q11) -> 2029000 | R12: =SUM(R5:R11) -> 2300000 | S12: =SUM(S5:S11) -> 2300000 | ... W12: =SUM(W5:W11) -> 1600000 | X12: =SUM(L12:W12) -> 19078264
F13: CNC | G13: 1.14 | H13: 1.0308227 | I13: 0.91672214 | J13: 0.85039625 | K13: 0.8294203 | L13: 481641 | M13: 309968 | N13: 520149 | O13: 384822 | P13: 393686 | Q13: 450000 | R13: 480000 | S13: 566500 | T13: 550000 | U13: 561000 | V13: 517000 | W13: 495000 | X13: =SUM(L13:W13) -> 5709766 | AB13: =AB11 -> Samsung | AC13: =AC11 -> Mobile
C14: Samsung Sub Total | L14: =SUM(L12:L13) -> 1940361 | M14: =SUM(M12:M13) -> 1581721 | N14: =SUM(N12:N13) -> 1691279 | O14: =SUM(O12:O13) -> 1447883 | P14: =SUM(P12:P13) -> 1618286 | Q14: =SUM(Q12:Q13) -> 2479000 | R14: =SUM(R12:R13) -> 2780000 | S14: =SUM(S12:S13) -> 2866500 | ... X14: =SUM(X12:X13) -> 24788030 | Y14: =X14=SUM(L14:W14) -> TRUE
C15: Qualcomm | D15: Mobile | E15: 7 | F15: MTP+IDP+ADP | G15: 1.85 | L15: 18000 | M15: 6109.2 | N15: 17266.409 | O15: 16000 | P15: 14559.846 | Q15: 18266.409 | R15: 18266.409 | S15: 18266.409 | T15: 18266.409 | U15: 18266.409 | V15: 13633.205 | W15: 13633.205 | X15: =SUM(L15:W15) -> 190533.91 | Z15: =G15/4*10 -> 4.625 | AB15: Qualcomm | AC15: Mobile
E16: 8 | F16: Ride5 | G16: 71.43 | L16: 200 | M16: 200 | N16: 0 | O16: 141.99916 | P16: 200 | Q16: 200 | R16: 250 | S16: 250 | T16: 250 | U16: 200 | V16: 100 | W16: 100 | X16: =SUM(L16:W16) -> 2091.9992 | Z16: =G16/4*10 -> 178.575 | AB16: =AB15 -> Qualcomm | AC16: =AC15 -> Mobile
F17: Glymur | G17: 4.9 | L17: 0 | M17: 0 | N17: 0 | O17: 0 | P17: 0 | Q17: 0 | R17: 0 | S17: 0 | T17: 0 | U17: 0 | V17: 0 | W17: 0 | X17: =SUM(L17:W17) -> 0 | Z17: =G17/4*10 -> 12.25 | AB17: =AB16 -> Qualcomm | AC17: =AC16 -> Mobile
E18: 9 | F18: MTP Hawi | G18: 8.23 | L18: 1000 | M18: 812.06756 | N18: 1000 | O18: 1000 | P18: 1000 | Q18: 1000 | R18: 1000 | S18: 1000 | T18: 1000 | U18: 1000 | V18: 1000 | W18: 1000 | X18: =SUM(L18:W18) -> 11812.068 | Z18: =G18/4*10 -> 20.575 | AB18: =AB17 -> Qualcomm | AC18: =AC17 -> Mobile
E19: 10 | F19: QMP Amboseli | G19: 8.23 | L19: 500 | M19: 500 | N19: 531.22722 | O19: 0 | P19: 500 | Q19: 0 | R19: 500 | S19: 0 | T19: 500 | U19: 0 | V19: 500 | W19: 0 | X19: =SUM(L19:W19) -> 3531.2272 | Z19: =G19/4*10 -> 20.575 | AB19: =AB18 -> Qualcomm | AC19: =AC18 -> Mobile
F20: LDS Antenna | G20: 2.68 | L20: 3604.4776 | M20: 2000 | N20: 2000 | O20: 4500 | P20: 2500 | Q20: 1200 | R20: 2500 | S20: 1200 | T20: 1200 | U20: 1200 | V20: 1200 | W20: 1200 | X20: =SUM(L20:W20) -> 24304.478 | Z20: =G20/4*10 -> 6.7 | AB20: =AB19 -> Qualcomm | AC20: =AC19 -> Mobile
E21: Qualcomm Sub Total | L21: =SUM(L15:L20) -> 23304.478 | M21: =SUM(M15:M20) -> 9621.2676 | N21: =SUM(N15:N20) -> 20797.636 | O21: =SUM(O15:O20) -> 21641.999 | P21: =SUM(P15:P20) -> 18759.846 | Q21: =SUM(Q15:Q20) -> 20666.409 | R21: =SUM(R15:R20) -> 22516.409 | S21: =SUM(S15:S20) -> 20716.409 | ... W21: =SUM(W15:W20) -> 15933.205 | X21: =SUM(L21:W21) -> 232273.68 | Y21: =X21=SUM(L21:W21) -> TRUE
C22: Mobile Sub-Total | L22: =SUM(L21+L14) -> 1963665.5 | M22: =SUM(M21+M14) -> 1591342.3 | N22: =SUM(N21+N14) -> 1712076.6 | O22: =SUM(O21+O14) -> 1469525 | P22: =SUM(P21+P14) -> 1637045.8 | Q22: =SUM(Q21+Q14) -> 2499666.4 | R22: =SUM(R21+R14) -> 2802516.4 | S22: =SUM(S21+S14) -> 2887216.4 | ... W22: =SUM(W21+W14) -> 2110933.2 | X22: =SUM(L22:W22) -> 25020304 | Y22: =X22=SUM(L22:W22) -> TRUE
A23: 2 | B23: Automotive | C23: LGIT | D23: Motor HSG | E23: 11 | F23: GEN3 AL5 Housing (YT) | G23: 2.2135429 | L23: 38642.124 | M23: 37783.41 | N23: 54957.688 | O23: 54473.685 | P23: 47343.108 | Q23: 69934.438 | R23: 56323.823 | S23: 53208.763 | T23: 0 | U23: 0 | V23: 0 | W23: 0 | X23: =SUM(L23:W23) -> 412667.04 | AB23: LGIT | AC23: Motor HSG
E24: 12 | F24: GEN3 AL6 Housing (YT) | G24: 2.2725264 | L24: 0 | M24: 0 | N24: 3436.9501 | O24: 5550.8265 | P24: 520.07316 | Q24: 0 | R24: 0 | S24: 0 | T24: 0 | U24: 0 | V24: 0 | W24: 0 | X24: =SUM(L24:W24) -> 9507.8498 | AB24: =AB23 -> LGIT | AC24: =AC23 -> Motor HSG
F25: GEN3 AL5 Housing (MX) | G25: 2.0915656 | L25: 0 | M25: 0 | N25: 0 | O25: 0 | P25: 0 | Q25: 0 | R25: 0 | S25: 0 | T25: 0 | U25: 0 | V25: 0 | W25: 0 | X25: =SUM(L25:W25) -> 0 | AB25: =AB24 -> LGIT | AC25: =AC24 -> Motor HSG
F26: GEN3 AL6 Housing (MX) | G26: 2.2086071 | L26: 0 | M26: 0 | N26: 0 | O26: 0 | P26: 0 | Q26: 0 | R26: 0 | S26: 0 | T26: 0 | U26: 0 | V26: 0 | W26: 0 | X26: =SUM(L26:W26) -> 0 | AB26: =AB25 -> LGIT | AC26: =AC25 -> Motor HSG
F27: T6 Housing | G27: 4.226861 | L27: 0 | M27: 0 | N27: 24602.655 | O27: 12914.397 | P27: 0 | Q27: 0 | R27: 0 | S27: 0 | T27: 0 | U27: 0 | V27: 0 | W27: 0 | X27: =SUM(L27:W27) -> 37517.051 | AB27: =AB26 -> LGIT | AC27: =AC26 -> Motor HSG
E28: 13 | F28: CL4 Housing (YT) | G28: 3.3439707 | L28: 47052.918 | M28: 31690.774 | N28: 37461.345 | O28: 44492.256 | P28: 47519.124 | Q28: 28507.534 | R28: 0 | S28: 0 | T28: 0 | U28: 0 | V28: 0 | W28: 0 | X28: =SUM(L28:W28) -> 236723.95 | AB28: =AB27 -> LGIT | AC28: =AC27 -> Motor HSG
F29: CL4 Housing (MX) | G29: 3.32 | L29: 0 | M29: 19698.795 | N29: 0 | O29: 19698.795 | P29: 26807.229 | Q29: 23590.361 | R29: 19698.795 | S29: 0 | T29: 0 | X29: =SUM(L29:W29) -> 109493.98 | AB29: =AB28 -> LGIT | AC29: =AC28 -> Motor HSG
E30: 14 | F30: MQ4a PE Housing (YT) | G30: 3.3731399 | L30: 588.76894 | M30: 15896.761 | N30: 26916.553 | O30: 21502.775 | P30: 27132.204 | Q30: 10171.366 | R30: 16644.053 | S30: 30004.673 | T30: 10286.95 | U30: 0 | V30: 0 | W30: 0 | X30: =SUM(L30:W30) -> 159144.1 | AB30: =AB29 -> LGIT | AC30: =AC29 -> Motor HSG
F31: MQ4a PE Housing (MX) | G31: 3.26 | L31: 0 | M31: 19693.252 | N31: 0 | O31: 19693.252 | P31: 24763.804 | Q31: 21533.742 | R31: 19693.252 | S31: 0 | T31: 0 | X31: =SUM(L31:W31) -> 105377.3 | AB31: =AB30 -> LGIT | AC31: =AC30 -> Motor HSG
F32: BYD Housing | G32: 2.2574248 | L32: 0 | M32: 0 | N32: 0 | O32: 0 | P32: 0 | Q32: 0 | R32: 0 | S32: 0 | T32: 0 | U32: 0 | V32: 0 | W32: 0 | X32: =SUM(L32:W32) -> 0 | AB32: =AB31 -> LGIT | AC32: =AC31 -> Motor HSG
E33: 15 | F33: MX5 Housing | G33: 4.59 | L33: 0 | M33: 0 | N33: 0 | O33: 0 | P33: 0 | Q33: 0 | R33: 0 | S33: 0 | T33: 0 | U33: 0 | V33: 0 | W33: 0 | X33: =SUM(L33:W33) -> 0 | AB33: =AB32 -> LGIT | AC33: =AC32 -> Motor HSG
E34: Motor HSG Sub Total | L34: =SUM(L23:L31) -> 86283.811 | M34: =SUM(M23:M31) -> 124762.99 | N34: =SUM(N23:N31) -> 147375.19 | O34: =SUM(O23:O31) -> 178325.99 | P34: =SUM(P23:P31) -> 174085.54 | Q34: =SUM(Q23:Q31) -> 153737.44 | R34: =SUM(R23:R31) -> 112359.92 | S34: =SUM(S23:S31) -> 83213.436 | ... W34: =SUM(W23:W31) -> 0 | X34: =SUM(X23:X33) -> 1070431.3 | Y34: =X34=SUM(L34:W34) -> TRUE
D35: Motor CVR | F35: Gen2 Cover | G35: 2.1305741 | L35: 3579.0354 | M35: 0 | N35: 0 | O35: 0 | R35: 21960.081 | S35: 0 | T35: 0 | U35: 0 | V35: 0 | W35: 0 | X35: =SUM(L35:W35) -> 25539.117 | AB35: =AB33 -> LGIT | AC35: Motor CVR
F36: T6 Cover | G36: 1.2189326 | L36: 0 | M36: 0 | N36: 14112.348 | O36: 26901.406 | P36: 0 | Q36: 0 | R36: 0 | S36: 0 | T36: 0 | U36: 0 | V36: 0 | W36: 0 | X36: =SUM(L36:W36) -> 41013.754 | AB36: =AB35 -> LGIT | AC36: =AC35 -> Motor CVR
E37: 16 | F37: EK_Part Cover | G37: 1.7131494 | L37: 20264.152 | M37: 14474.394 | N37: 13026.955 | O37: 16520.147 | P37: 18736.264 | Q37: 16520.147 | R37: 16520.147 | S37: 13528.58 | X37: =SUM(L37:W37) -> 129590.78 | AB37: =AB36 -> LGIT | AC37: =AC36 -> Motor CVR
F38: 570W Cover | G38: 1.93 | L38: 0 | M38: 0 | N38: 0 | O38: 0 | P38: 0 | Q38: 0 | R38: 0 | S38: 0 | T38: 0 | U38: 0 | V38: 0 | W38: 0 | X38: =SUM(L38:W38) -> 0 | AB38: =AB37 -> LGIT | AC38: =AC37 -> Motor CVR
E39: 17 | F39: CL4 Cover (YT) | G39: 1.3549204 | L39: 7552.473 | M39: 18888.681 | N39: 19225.926 | O39: 7460.8071 | P39: 13586.038 | Q39: 12319.543 | R39: 0 | S39: 0 | T39: 0 | U39: 0 | V39: 0 | W39: 0 | X39: =SUM(L39:W39) -> 79033.467 | AB39: =AB38 -> LGIT | AC39: =AC38 -> Motor CVR
F40: CL4 Cover (MX) | G40: 1.34 | L40: 0 | M40: 19701.493 | N40: 0 | O40: 19701.493 | P40: 21720.896 | Q40: 25539.866 | R40: 30461.463 | S40: 0 | X40: =SUM(L40:W40) -> 117125.21 | AB40: =AB39 -> LGIT | AC40: =AC39 -> Motor CVR
...

Sheet 요약
A1: Basic Assumption (Expense)
A3: 5) 관리
A4: No. | B4: 담당부서 | C4: 주제 | D4: Category | E4: Content | F4: Remarks
A5: 1 | B5: EM | C5: S Plan | D5: 매출 계획 재 확인 | E5: - 각 고객사 2025년 SOP 최신 데이터 입수 후 반영 - T6 멕시코향 기존 3분기 시작 → 2분기 시작으로 변경 CL4 '24년 수량 수준 반영 (기존 월 4.8만개 → 6만개) IMEB2 고객사로부터 증량 수량 수취 (기존 월 2.9만개 → 4.2만개) 삼성 A26, A36 수주 건 (월 30만개(2벌) 기준)
D6: 개발 중 제품 | E6: - 고객사 및 품명 : LGIT eK Cover - 양산 기간 : 25년 하반기 ~ 2031년 - 총 매출 : $1,748,858
A7: 2 | B7: Production Plan | C7: P Plan | D7: 125Ton 부족 | E7: 125ton 부족으로 예상되어 현재 양산중인 125Ton 제품 350Ton으로 변경 필요
D8: MCT 부족 | E8: 4월 T6 Mexico 향 신규 물량 수주로 기존 6월 추가 5대 구매 계획 4월로 변경 필요
A9: 3 | B9: Production Plan, EM | C9: P Plan-2 | D9: 예상 금형 제작 벌 수 | E9: - 사내 제작 : $835,807 (79set) - 외주 제작 : $492,370 (20set - 한국) + $53,500 (5set - 베트남) - 합계 : $1,328,177 (104set)
A10: 4 | B10: Production, Production Plan, Quality, Finance | C10: L Plan | D10: 고객사별 인원 | E10: - 삼성 제품 생산을 위한 직접 인력: 103명 - LG/Mando/Hyosung 제품 생산을 위한 직접 인력: 303명 - ZF 제품 생산을 위한 직접 인력: 180명 | F10: 586명
D11: 오피스 인원 | E11: 2024년 90명, 2025년 70명으로 축소
D12: CNC 자동화 | E12: - CNC 선반 + MCT 자동화 도입 (1X3)+(1X2) - CNC 자동화(1X6) - 다관절 로봇타입 - 세척 및 검사 결합라인 등을 통한 인력절감
D13: 사상 자동화 | E13: - 하우징/ 플레이트 사상 자동화 도입으로 인원절감 추진 - 카메라류/브라캣 류 사상 자동화 도입 - 브라캣류 열정형 자동화 진행
D14: 비용 절감 (품질팀) | E14: - 검사 인원 축소 (152명 → 87명, 43% 인원절감) - 외관 한도 완화 : AUTO 제품 4% 폐기 비용 절감
A15: 5 | B15: Production Plan | C15: M Plan | D15: 내부 리사이클 진행 | E15: - 내부 리사이클 진행 예정으로, 리사이클링 비용 삭제 - 신재 52% 재생 48% 유지하되, 신재 사용 절감 방안 지속 강구
A16: 6 | B16: Production Plan | C16: O Plan | D16: 외주 진행 | E16: - 아노다이징 및 퀄컴 외주 외 100% 내부 진행
A17: 7 | B17: Finance | C17: E Plan
A22: 8 | B22: Automation | C22: I Plan
A27: 9 | B27: Finance | C27: C Plan

Sheet SOP 2024
A1: Customer | B1: Model | C1: PART NO. | D1: 2024-Q1 Unit Price | E1: 2024-Q2 Unit Price | F1: 2024-Q3 Unit Price | G1: 2024-Q4 Unit Price | H1: 2025 Unit Price | I1: 2026 Unit Price | J1: 2027 Unit Price | K1: 2028 Unit Price | M1: 2024 Quantity | Z1: 2024 Amount (USD) | AM1: 2025 Quantity | AZ1: 2025 Amount (USD) | BM1: 2026 Quantity | BZ1: 2026 Amount (USD) | CM1: 2027 Quantity | CZ1: 2027 Amount (USD) | DM1: 2028 Quantity | DZ1: 2028 Amount (USD)
M2: Jan | N2: Feb | O2: Mar | P2: Apr | Q2: May | R2: Jun | S2: Jul | T2: Aug | U2: Sep | V2: Oct | W2: Nov | X2: Dec | Y2: Total 2024 | Z2: 45293 | AA2: 45324 | AB2: 45353 | AC2: 45384 | AD2: 45414 | AE2: 45445 | AF2: 45475 | AG2: 45506 | AH2: 45537 | AI2: 45567 | AJ2: 45598 | AK2: 45628 | AL2: Total 2024 | AM2: Jan | AN2: Feb | AO2: Mar | AP2: Apr | AQ2: May | AR2: Jun | AS2: Jul | AT2: Aug | AU2: Sep | AV2: Oct | AW2: Nov | AX2: Dec | AY2: Total 2025 | AZ2: Jan | BA2: Feb | BB2: Mar | BC2: Apr | BD2: May | BE2: Jun | BF2: Jul | BG2: Aug | BH2: Sep | BI2: Oct | BJ2: Nov | BK2: Dec | BL2: Total 2025 | BM2: Jan | BN2: Feb | BO2: Mar | BP2: Apr | BQ2: May | BR2: Jun | BS2: Jul | BT2: Aug | BU2: Sep | BV2: Oct | BW2: Nov | BX2: Dec | BY2: Total 2026 | BZ2: Jan | CA2: Feb | CB2: Mar | CC2: Apr | CD2: May | CE2: Jun | CF2: Jul | CG2: Aug | CH2: Sep | CI2: Oct | CJ2: Nov | CK2: Dec | CL2: Total 2026 | CM2: Jan | CN2: Feb | CO2: Mar | CP2: Apr | CQ2: May | CR2: Jun | CS2: Jul | CT2: Aug | CU2: Sep | CV2: Oct | CW2: Nov | CX2: Dec | CY2: Total 2027 | CZ2: Jan | DA2: Feb | DB2: Mar | DC2: Apr | DD2: May | DE2: Jun | DF2: Jul | DG2: Aug | DH2: Sep | DI2: Oct | DJ2: Nov | DK2: Dec | DL2: Total 2027 | DM2: Jan | DN2: Feb | DO2: Mar | DP2: Apr | DQ2: May | DR2: Jun | DS2: Jul | DT2: Aug | DU2: Sep | DV2: Oct | DW2: Nov | DX2: Dec | DY2: Total 2028 | DZ2: Jan | EA2: Feb | EB2: Mar | EC2: Apr | ED2: May | EE2: Jun | EF2: Jul | EG2: Aug | EH2: Sep | EI2: Oct | EJ2: Nov | EK2: Dec | EL2: Total 2028
A3: Hosiden | B3: HEG Stand Cover | D3: 3.99 | E3: 3.578 | F3: 3.578 | G3: 3.578 | H3: =G3 -> 3.578 | I3: 3.79 | J3: 3.79 | K3: 3.79 | M3: 105000 | N3: 75000 | O3: 90000 | P3: 150000 | Q3: 200000 | R3: 250000 | S3: 250000 | T3: 230000 | U3: 130000 | V3: 130000 | W3: 130000 | X3: 130000 | Y3: =SUM(M3:X3) -> 1870000 | Z3: =M3*$D3 -> 418950 | AA3: =N3*$D3 -> 299250 | AB3: =O3*3.578 -> 322020 | AC3: =P3*3.578 -> 536700 | AD3: =17534800000/25000 -> 701392 | AE3: =R3*3.507 -> 876750 | AF3: =S3*3.778 -> 944500 | AG3: =T3*3.778 -> 868940 | AH3: =U3*3.778 -> 491140 | AI3: =V3*3.778 -> 491140 | AJ3: =W3*3.778 -> 491140 | AK3: =X3*3.778 -> 491140 | AL3: =SUM(Z3:AK3) -> 6933062 | AM3: 25000 | AN3: 25000 | AO3: 25000 | AP3: 25000 | AQ3: 25000 | AR3: 25000 | AS3: 25000 | AT3: 25000 | AU3: 25000 | AV3: 25000 | AW3: 25000 | AX3: 25000 | AY3: =SUM(AM3:AX3) -> 300000 | AZ3: =AM3*$H3 -> 89450 | BA3: =AN3*$H3 -> 89450 | BB3: =AO3*$H3 -> 89450 | BC3: =AP3*$H3 -> 89450 | BD3: =AQ3*$H3 -> 89450 | BE3: =AR3*$H3 -> 89450 | BF3: =AS3*$H3 -> 89450 | BG3: =AT3*$H3 -> 89450 | ... BK3: =AX3*$H3 -> 89450 | BL3: =SUM(AZ3:BK3) -> 1073400 | BY3: =SUM(BM3:BX3) -> 0 | BZ3: =BM3*$I3 -> 0 | CA3: =BN3*$I3 -> 0 | CB3: =BO3*$I3 -> 0 | CC3: =BP3*$I3 -> 0 | CD3: =BQ3*$I3 -> 0 | CE3: =BR3*$I3 -> 0 | CF3: =BS3*$I3 -> 0 | CG3: =BT3*$I3 -> 0 | ... CK3: =BX3*$I3 -> 0 | CL3: =SUM(BZ3:CK3) -> 0 | CY3: =SUM(CM3:CX3) -> 0 | CZ3: =CM3*$J3 -> 0 | DA3: =CN3*$J3 -> 0 | DB3: =CO3*$J3 -> 0 | DC3: =CP3*$J3 -> 0 | DD3: =CQ3*$J3 -> 0 | DE3: =CR3*$J3 -> 0 | DF3: =CS3*$J3 -> 0 | DG3: =CT3*$J3 -> 0 | ... DK3: =CX3*$J3 -> 0 | DL3: =SUM(CZ3:DK3) -> 0 | DY3: =SUM(DM3:DX3) -> 0 | DZ3: =DM3*$K3 -> 0 | EA3: =DN3*$K3 -> 0 | EB3: =DO3*$K3 -> 0 | EC3: =DP3*$K3 -> 0 | ED3: =DQ3*$K3 -> 0 | EE3: =DR3*$K3 -> 0 | EF3: =DS3*$K3 -> 0 | EG3: =DT3*$K3 -> 0 | ... EK3: =DX3*$K3 -> 0 | EL3: =SUM(DZ3:EK3) -> 0
A4: Hosiden | B4: Mold/Credit note | Y4: =SUM(M4:X4) -> 0 | Z4: =-(70333362+68963060+425415309+11353023+19844715)/24000 -> -24829.561 | AA4: =-(286963809+114084036+35604541)/24000 -> -18193.849 | AB4: 0 | AC4: =-(642) -> -642 | AD4: =-5692 -> -5692 | AE4: =-(15101) -> -15101 | AF4: =-(4506+8946) -> -13452 | AH4: =U4*$F4 -> 0 | AI4: =V4*$G4 -> 0 | AJ4: =W4*$G4 -> 0 | AK4: =X4*$G4 -> 0 | AL4: =SUM(Z4:AK4) -> -77910.411 | AY4: =SUM(AM4:AX4) -> 0 | AZ4: =AM4*$H4 -> 0 | BA4: =AN4*$H4 -> 0 | BB4: =AO4*$H4 -> 0 | BC4: =AP4*$H4 -> 0 | BD4: =AQ4*$H4 -> 0 | BE4: =AR4*$H4 -> 0 | BF4: =AS4*$H4 -> 0 | BG4: =AT4*$H4 -> 0 | ... BK4: =AX4*$H4 -> 0 | BL4: =SUM(AZ4:BK4) -> 0 | BY4: =SUM(BM4:BX4) -> 0 | BZ4: =BM4*$I4 -> 0 | CA4: =BN4*$I4 -> 0 | CB4: =BO4*$I4 -> 0 | CC4: =BP4*$I4 -> 0 | CD4: =BQ4*$I4 -> 0 | CE4: =BR4*$I4 -> 0 | CF4: =BS4*$I4 -> 0 | CG4: =BT4*$I4 -> 0 | ... CK4: =BX4*$I4 -> 0 | CL4: =SUM(BZ4:CK4) -> 0 | CY4: =SUM(CM4:CX4) -> 0 | CZ4: =CM4*$J4 -> 0 | DA4: =CN4*$J4 -> 0 | DB4: =CO4*$J4 -> 0 | DC4: =CP4*$J4 -> 0 | DD4: =CQ4*$J4 -> 0 | DE4: =CR4*$J4 -> 0 | DF4: =CS4*$J4 -> 0 | DG4: =CT4*$J4 -> 0 | ... DK4: =CX4*$J4 -> 0 | DL4: =SUM(CZ4:DK4) -> 0 | DY4: =SUM(DM4:DX4) -> 0 | DZ4: =DM4*$K4 -> 0 | EA4: =DN4*$K4 -> 0 | EB4: =DO4*$K4 -> 0 | EC4: =DP4*$K4 -> 0 | ED4: =DQ4*$K4 -> 0 | EE4: =DR4*$K4 -> 0 | EF4: =DS4*$K4 -> 0 | EG4: =DT4*$K4 -> 0 | ... EK4: =DX4*$K4 -> 0 | EL4: =SUM(DZ4:EK4) -> 0
A5: Hosiden Total | M5: =SUM(M3:M4) -> 105000 | N5: =SUM(N3:N4) -> 75000 | O5: =SUM(O3:O4) -> 90000 | P5: =SUM(P3:P4) -> 150000 | Q5: =SUM(Q3:Q4) -> 200000 | R5: =SUM(R3:R4) -> 250000 | S5: =SUM(S3:S4) -> 250000 | T5: =SUM(T3:T4) -> 230000 | ... EL5: =SUM(EL3:EL4) -> 0
A6: Samsung BRK | B6: A245 Mobase | C6: GH61-17884A | D6: 0.7448 | E6: 0.729904 | F6: 0.71530592 | G6: 0.71530592 | H6: =G6 -> 0.71530592 | M6: 71200 | Y6: =SUM(M6:X6) -> 71200 | Z6: =M6*$D6 -> 53029.76 | AA6: =N6*$D6 -> 0 | AB6: =O6*$E6 -> 0 | AC6: =P6*$E6 -> 0 | AD6: =Q6*$E6 -> 0 | AE6: =R6*$F6 -> 0 | AF6: =S6*$F6 -> 0 | AG6: =T6*$F6 -> 0 | AH6: =U6*$G6 -> 0 | AI6: =V6*$G6 -> 0 | AJ6: =W6*$G6 -> 0 | AK6: =X6*$G6 -> 0 | AL6: =SUM(Z6:AK6) -> 53029.76 | AY6: =SUM(AM6:AX6) -> 0 | AZ6: =AM6*$H6 -> 0 | BA6: =AN6*$H6 -> 0 | BB6: =AO6*$H6 -> 0 | BC6: =AP6*$H6 -> 0 | BD6: =AQ6*$H6 -> 0 | BE6: =AR6*$H6 -> 0 | BF6: =AS6*$H6 -> 0 | BG6: =AT6*$H6 -> 0 | ... BK6: =AX6*$H6 -> 0 | BL6: =SUM(AZ6:BK6) -> 0 | BY6: =SUM(BM6:BX6) -> 0 | BZ6: =BM6*$I6 -> 0 | CA6: =BN6*$I6 -> 0 | CB6: =BO6*$I6 -> 0 | CC6: =BP6*$I6 -> 0 | CD6: =BQ6*$I6 -> 0 | CE6: =BR6*$I6 -> 0 | CF6: =BS6*$I6 -> 0 | CG6: =BT6*$I6 -> 0 | ... CK6: =BX6*$I6 -> 0 | CL6: =SUM(BZ6:CK6) -> 0 | CY6: =SUM(CM6:CX6) -> 0 | CZ6: =CM6*$J6 -> 0 | DA6: =CN6*$J6 -> 0 | DB6: =CO6*$J6 -> 0 | DC6: =CP6*$J6 -> 0 | DD6: =CQ6*$J6 -> 0 | DE6: =CR6*$J6 -> 0 | DF6: =CS6*$J6 -> 0 | DG6: =CT6*$J6 -> 0 | ... DK6: =CX6*$J6 -> 0 | DL6: =SUM(CZ6:DK6) -> 0 | DY6: =SUM(DM6:DX6) -> 0 | DZ6: =DM6*$K6 -> 0 | EA6: =DN6*$K6 -> 0 | EB6: =DO6*$K6 -> 0 | EC6: =DP6*$K6 -> 0 | ED6: =DQ6*$K6 -> 0 | EE6: =DR6*$K6 -> 0 | EF6: =DS6*$K6 -> 0 | EG6: =DT6*$K6 -> 0 | ... EK6: =DX6*$K6 -> 0 | EL6: =SUM(DZ6:EK6) -> 0
A7: Samsung BRK | B7: A245 Elentec | C7: GH61-17884A | D7: 0.76350167 | E7: 0.73669388 | F7: 0.733267 | G7: 0.733267 | H7: =G7 -> 0.733267 | M7: 86400 | N7: 66800 | O7: 73800 | Y7: =SUM(M7:X7) -> 227000 | Z7: =M7*$D7 -> 65966.544 | AA7: =N7*$D7 -> 51001.911 | AB7: =O7*$E7 -> 54368.008 | AC7: =P7*$E7 -> 0 | AD7: =Q7*$E7 -> 0 | AE7: =R7*$F7 -> 0 | AF7: =S7*$F7 -> 0 | AG7: =T7*$F7 -> 0 | AH7: =U7*$G7 -> 0 | AI7: =V7*$G7 -> 0 | AJ7: =W7*$G7 -> 0 | AK7: =X7*$G7 -> 0 | AL7: =SUM(Z7:AK7) -> 171336.46 | AY7: =SUM(AM7:AX7) -> 0 | AZ7: =AM7*$H7 -> 0 | BA7: =AN7*$H7 -> 0 | BB7: =AO7*$H7 -> 0 | BC7: =AP7*$H7 -> 0 | BD7: =AQ7*$H7 -> 0 | BE7: =AR7*$H7 -> 0 | BF7: =AS7*$H7 -> 0 | BG7: =AT7*$H7 -> 0 | ... BK7: =AX7*$H7 -> 0 | BL7: =SUM(AZ7:BK7) -> 0 | BY7: =SUM(BM7:BX7) -> 0 | BZ7: =BM7*$I7 -> 0 | CA7: =BN7*$I7 -> 0 | CB7: =BO7*$I7 -> 0 | CC7: =BP7*$I7 -> 0 | CD7: =BQ7*$I7 -> 0 | CE7: =BR7*$I7 -> 0 | CF7: =BS7*$I7 -> 0 | CG7: =BT7*$I7 -> 0 | ... CK7: =BX7*$I7 -> 0 | CL7: =SUM(BZ7:CK7) -> 0 | CY7: =SUM(CM7:CX7) -> 0 | CZ7: =CM7*$J7 -> 0 | DA7: =CL4*$J7 -> 0 | DB7: =CO7*$J7 -> 0 | DC7: =CP7*$J7 -> 0 | DD7: =CQ7*$J7 -> 0 | DE7: =CR7*$J7 -> 0 | DF7: =CS7*$J7 -> 0 | DG7: =CT7*$J7 -> 0 | DH7: =CU7*$J7 -> 0 | DI7: =CV7*$J7 -> 0 | ... DK7: =CX7*$J7 -> 0 | DL7: =SUM(CZ7:DK7) -> 0 | DY7: =SUM(DM7:DX7) -> 0 | DZ7: =DM7*$K7 -> 0 | EA7: =DN7*$K7 -> 0 | EB7: =DO7*$K7 -> 0 | EC7: =DP7*$K7 -> 0 | ED7: =DQ7*$K7 -> 0 | EE7: =DR7*$K7 -> 0 | EF7: =DS7*$K7 -> 0 | EG7: =DT7*$K7 -> 0 | ... EK7: =DX7*$K7 -> 0 | EL7: =SUM(DZ7:EK7) -> 0
A8: Samsung BRK | B8: A346 Mobase | C8: GH61-17770A | D8: 0.77273 | E8: =D8*0.98 -> 0.7572754 | F8: =E8*0.98 -> 0.74212989 | G8: =F8 -> 0.74212989 | H8: =G8 -> 0.74212989 | Y8: =SUM(M8:X8) -> 0 | Z8: =M8*$D8 -> 0 | AA8: =N8*$D8 -> 0 | AB8: =O8*$E8 -> 0 | AC8: =P8*$E8 -> 0 | AD8: =Q8*$E8 -> 0 | AE8: =R8*$F8 -> 0 | AF8: =S8*$F8 -> 0 | AG8: =T8*$F8 -> 0 | AH8: =U8*$G8 -> 0 | AI8: =V8*$G8 -> 0 | AJ8: =W8*$G8 -> 0 | AK8: =X8*$G8 -> 0 | AL8: =SUM(Z8:AK8) -> 0 | AY8: =SUM(AM8:AX8) -> 0 | AZ8: =AM8*$H8 -> 0 | BA8: =AN8*$H8 -> 0 | BB8: =AO8*$H8 -> 0 | BC8: =AP8*$H8 -> 0 | BD8: =AQ8*$H8 -> 0 | BE8: =AR8*$H8 -> 0 | BF8: =AS8*$H8 -> 0 | BG8: =AT8*$H8 -> 0 | ... BK8: =AX8*$H8 -> 0 | BL8: =SUM(AZ8:BK8) -> 0 | BY8: =SUM(BM8:BX8) -> 0 | BZ8: =BM8*$I8 -> 0 | CA8: =BN8*$I8 -> 0 | CB8: =BO8*$I8 -> 0 | CC8: =BP8*$I8 -> 0 | CD8: =BQ8*$I8 -> 0 | CE8: =BR8*$I8 -> 0 | CF8: =BS8*$I8 -> 0 | CG8: =BT8*$I8 -> 0 | ... CK8: =BX8*$I8 -> 0 | CL8: =SUM(BZ8:CK8) -> 0 | CY8: =SUM(CM8:CX8) -> 0 | CZ8: =CM8*$J8 -> 0 | DA8: =CN8*$J8 -> 0 | DB8: =CO8*$J8 -> 0 | DC8: =CP8*$J8 -> 0 | DD8: =CQ8*$J8 -> 0 | DE8: =CR8*$J8 -> 0 | DF8: =CS8*$J8 -> 0 | DG8: =CT8*$J8 -> 0 | ... DK8: =CX8*$J8 -> 0 | DL8: =SUM(CZ8:DK8) -> 0 | DY8: =SUM(DM8:DX8) -> 0 | DZ8: =DM8*$K8 -> 0 | EA8: =DN8*$K8 -> 0 | EB8: =DO8*$K8 -> 0 | EC8: =DP8*$K8 -> 0 | ED8: =DQ8*$K8 -> 0 | EE8: =DR8*$K8 -> 0 | EF8: =DS8*$K8 -> 0 | EG8: =DT8*$K8 -> 0 | ... EK8: =DX8*$K8 -> 0 | EL8: =SUM(DZ8:EK8) -> 0
A9: Samsung BRK | B9: A546 Elentec | C9: GH61-17786A | D9: 0.77791583 | E9: =D9*0.98 -> 0.76235752 | F9: =E9*0.98 -> 0.74711037 | G9: =F9 -> 0.74711037 | H9: =G9 -> 0.74711037 | M9: 0 | Y9: =SUM(M9:X9) -> 0 | Z9: =M9*$D9 -> 0 | AA9: =N9*$D9 -> 0 | AB9: =O9*$E9 -> 0 | AC9: =P9*$E9 -> 0 | AD9: =Q9*$E9 -> 0 | AE9: =R9*$F9 -> 0 | AF9: =S9*$F9 -> 0 | AG9: =T9*$F9 -> 0 | AH9: =U9*$G9 -> 0 | AI9: =V9*$G9 -> 0 | AJ9: =W9*$G9 -> 0 | AK9: =X9*$G9 -> 0 | AL9: =SUM(Z9:AK9) -> 0 | AY9: =SUM(AM9:AX9) -> 0 | AZ9: =AM9*$H9 -> 0 | BA9: =AN9*$H9 -> 0 | BB9: =AO9*$H9 -> 0 | BC9: =AP9*$H9 -> 0 | BD9: =AQ9*$H9 -> 0 | BE9: =AR9*$H9 -> 0 | BF9: =AS9*$H9 -> 0 | BG9: =AT9*$H9 -> 0 | ... BK9: =AX9*$H9 -> 0 | BL9: =SUM(AZ9:BK9) -> 0 | BY9: =SUM(BM9:BX9) -> 0 | BZ9: =BM9*$I9 -> 0 | CA9: =BN9*$I9 -> 0 | CB9: =BO9*$I9 -> 0 | CC9: =BP9*$I9 -> 0 | CD9: =BQ9*$I9 -> 0 | CE9: =BR9*$I9 -> 0 | CF9: =BS9*$I9 -> 0 | CG9: =BT9*$I9 -> 0 | ... CK9: =BX9*$I9 -> 0 | CL9: =SUM(BZ9:CK9) -> 0 | CY9: =SUM(CM9:CX9) -> 0 | CZ9: =CM9*$J9 -> 0 | DA9: =CN9*$J9 -> 0 | DB9: =CO9*$J9 -> 0 | DC9: =CP9*$J9 -> 0 | DD9: =CQ9*$J9 -> 0 | DE9: =CR9*$J9 -> 0 | DF9: =CS9*$J9 -> 0 | DG9: =CT9*$J9 -> 0 | ... DK9: =CX9*$J9 -> 0 | DL9: =SUM(CZ9:DK9) -> 0 | DY9: =SUM(DM9:DX9) -> 0 | DZ9: =DM9*$K9 -> 0 | EA9: =DN9*$K9 -> 0 | EB9: =DO9*$K9 -> 0 | EC9: =DP9*$K9 -> 0 | ED9: =DQ9*$K9 -> 0 | EE9: =DR9*$K9 -> 0 | EF9: =DS9*$K9 -> 0 | EG9: =DT9*$K9 -> 0 | ... EK9: =DX9*$K9 -> 0 | EL9: =SUM(DZ9:EK9) -> 0
A10: Samsung BRK | B10: A15 | C10: GH61-18886A | D10: 0.7817 | E10: 0.75428571 | F10: 0.718 | G10: =F10*0.98 -> 0.70364 | H10: =G10 -> 0.70364 | M10: 821300 | N10: 610000 | O10: 785200 | P10: 800400 | Q10: 753500 | R10: 767650 | S10: 800000 | T10: 800000 | U10: 800000 | V10: 600000 | W10: 400000 | X10: 300000 | Y10: =SUM(M10:X10) -> 8238050 | Z10: 642010.21 | AA10: 476837 | AB10: 592265.14 | AC10: 603730.29 | AD10: =556987.2+528 -> 557515.2 | AE10: =R10*$F10+400-30-17385 -> 534157.7 | AF10: =S10*$F10 -> 574400 | AG10: =T10*$F10 -> 574400 | AH10: =U10*$G10 -> 562912 | AI10: =V10*$G10 -> 422184 | AJ10: =W10*$G10 -> 281456 | AK10: =X10*$H10 -> 211092 | AL10: =SUM(Z10:AK10) -> 6032959.5 | AM10: 100000 | AN10: 50000 | AY10: =SUM(AM10:AX10) -> 150000 | AZ10: =AM10*$H10 -> 70364 | BA10: =AN10*$H10 -> 35182 | BB10: =AO10*$H10 -> 0 | BC10: =AP10*$H10 -> 0 | BD10: =AQ10*$H10 -> 0 | BE10: =AR10*$H10 -> 0 | BF10: =AS10*$H10 -> 0 | BG10: =AT10*$H10 -> 0 | ... BK10: =AX10*$H10 -> 0 | BL10: =SUM(AZ10:BK10) -> 105546 | BY10: =SUM(BM10:BX10) -> 0 | BZ10: =BM10*$I10 -> 0 | CA10: =BN10*$I10 -> 0 | CB10: =BO10*$I10 -> 0 | CC10: =BP10*$I10 -> 0 | CD10: =BQ10*$I10 -> 0 | CE10: =BR10*$I10 -> 0 | CF10: =BS10*$I10 -> 0 | CG10: =BT10*$I10 -> 0 | ... CK10: =BX10*$I10 -> 0 | CL10: =SUM(BZ10:CK10) -> 0 | CY10: =SUM(CM10:CX10) -> 0 | CZ10: =CM10*$J10 -> 0 | DA10: =CN10*$J10 -> 0 | DB10: =CO10*$J10 -> 0 | DC10: =CP10*$J10 -> 0 | DD10: =CQ10*$J10 -> 0 | DE10: =CR10*$J10 -> 0 | DF10: =CS10*$J10 -> 0 | DG10: =CT10*$J10 -> 0 | ... DK10: =CX10*$J10 -> 0 | DL10: =SUM(CZ10:DK10) -> 0 | DY10: =SUM(DM10:DX10) -> 0 | DZ10: =DM10*$K10 -> 0 | EA10: =DN10*$K10 -> 0 | EB10: =DO10*$K10 -> 0 | EC10: =DP10*$K10 -> 0 | ED10: =DQ10*$K10 -> 0 | EE10: =DR10*$K10 -> 0 | EF10: =DS10*$K10 -> 0 | EG10: =DT10*$K10 -> 0 | ... EK10: =DX10*$K10 -> 0 | EL10: =SUM(DZ10:EK10) -> 0
A11: Samsung BRK | B11: A35 | C11: GH61-18868A | D11: 0.83 | E11: 0.81330612 | F11: =E11*0.97 -> 0.78890694 | G11: =F11*0.97 -> 0.76523973 | H11: =G11 -> 0.76523973 | M11: 92149 | N11: 312000 | O11: 453100 | P11: 116300 | Y11: =SUM(M11:X11) -> 973549 | Z11: =M11*$D11+2000-400 -> 78083.67 | AA11: =N11*$D11 -> 258960 | AB11: =O11*$E11 -> 368509 | AC11: =P11*$E11 -> 94587.502 | AD11: =Q11*$E11 -> 0 | AE11: =R11*$F11 -> 0 | AF11: =S11*$F11 -> 0 | AG11: =T11*$F11 -> 0 | AH11: =U11*$G11 -> 0 | AI11: =V11*$G11 -> 0 | AJ11: =W11*$G11 -> 0 | AK11: =X11*$G11 -> 0 | AL11: =SUM(Z11:AK11) -> 800140.18 | AY11: =SUM(AM11:AX11) -> 0 | AZ11: =AM11*$H11 -> 0 | BA11: =AN11*$H11 -> 0 | BB11: =AO11*$H11 -> 0 | BC11: =AP11*$H11 -> 0 | BD11: =AQ11*$H11 -> 0 | BE11: =AR11*$H11 -> 0 | BF11: =AS11*$H11 -> 0 | BG11: =AT11*$H11 -> 0 | ... BK11: =AX11*$H11 -> 0 | BL11: =SUM(AZ11:BK11) -> 0 | BY11: =SUM(BM11:BX11) -> 0 | BZ11: =BM11*$I11 -> 0 | CA11: =BN11*$I11 -> 0 | CB11: =BO11*$I11 -> 0 | CC11: =BP11*$I11 -> 0 | CD11: =BQ11*$I11 -> 0 | CE11: =BR11*$I11 -> 0 | CF11: =BS11*$I11 -> 0 | CG11: =BT11*$I11 -> 0 | ... CK11: =BX11*$I11 -> 0 | CL11: =SUM(BZ11:CK11) -> 0 | CY11: =SUM(CM11:CX11) -> 0 | CZ11: =CM11*$J11 -> 0 | DA11: =CN11*$J11 -> 0 | DB11: =CO11*$J11 -> 0 | DC11: =CP11*$J11 -> 0 | DD11: =CQ11*$J11 -> 0 | DE11: =CR11*$J11 -> 0 | DF11: =CS11*$J11 -> 0 | DG11: =CT11*$J11 -> 0 | ... DK11: =CX11*$J11 -> 0 | DL11: =SUM(CZ11:DK11) -> 0 | DY11: =SUM(DM11:DX11) -> 0 | DZ11: =DM11*$K11 -> 0 | EA11: =DN11*$K11 -> 0 | EB11: =DO11*$K11 -> 0 | EC11: =DP11*$K11 -> 0 | ED11: =DQ11*$K11 -> 0 | EE11: =DR11*$K11 -> 0 | EF11: =DS11*$K11 -> 0 | EG11: =DT11*$K11 -> 0 | ... EK11: =DX11*$K11 -> 0 | EL11: =SUM(DZ11:EK11) -> 0
A12: Samsung BRK | B12: New BRK 1 | E12: 0.69 | F12: 0.69 | G12: 0.69 | H12: =G12*0.98 -> 0.6762 | I12: =H12*0.98 -> 0.662676 | J12: =I12*0.98 -> 0.64942248 | K12: =J12*0.98 -> 0.63643403 | Y12: =SUM(M12:X12) -> 0 | Z12: =M12*$D12 -> 0 | AA12: =N12*$D12 -> 0 | AB12: =O12*$D12 -> 0 | AC12: =P12*$D12 -> 0 | AD12: =Q12*$D12 -> 0 | AE12: =R12*$D12 -> 0 | AF12: =S12*$D12 -> 0 | AG12: =T12*$D12 -> 0 | AH12: =U12*$G12 -> 0 | AI12: =V12*$G12 -> 0 | AJ12: =W12*$G12 -> 0 | AK12: =X12*$H12 -> 0 | AL12: =SUM(Z12:AK12) -> 0 | AY12: =SUM(AM12:AX12) -> 0 | AZ12: =AM12*$H12 -> 0 | BA12: =AN12*$H12 -> 0 | BB12: =AO12*$H12 -> 0 | BC12: =AP12*$H12 -> 0 | BD12: =AQ12*$H12 -> 0 | BE12: =AR12*$H12 -> 0 | BF12: =AS12*$H12 -> 0 | BG12: =AT12*$H12 -> 0 | ... BK12: =AX12*$H12 -> 0 | BL12: =SUM(AZ12:BK12) -> 0 | BM12: 500000 | BN12: 300000 | BO12: 300000 | BP12: 400000 | BQ12: =25000*24 -> 600000 | BR12: =25000*24 -> 600000 | BS12: =30000*26 -> 780000 | BT12: =30000*26 -> 780000 | BU12: =30000*26 -> 780000 | BV12: =30000*26 -> 780000 | BW12: =30000*26 -> 780000 | BX12: =30000*26 -> 780000 | BY12: =SUM(BM12:BX12) -> 7380000 | BZ12: =BM12*$I12 -> 331338 | CA12: =BN12*$I12 -> 198802.8 | CB12: =BO12*$I12 -> 198802.8 | CC12: =BP12*$I12 -> 265070.4 | CD12: =BQ12*$I12 -> 397605.6 | CE12: =BR12*$I12 -> 397605.6 | CF12: =BS12*$I12 -> 516887.28 | CG12: =BT12*$I12 -> 516887.28 | ... CK12: =BX12*$I12 -> 516887.28 | CL12: =SUM(BZ12:CK12) -> 4890548.9 | CM12: 500000 | CN12: 300000 | CO12: 300000 | CP12: 400000 | CQ12: =25000*24 -> 600000 | CR12: =25000*24 -> 600000 | CS12: =30000*26 -> 780000 | CT12: =30000*26 -> 780000 | CU12: =30000*26 -> 780000 | CV12: =30000*26 -> 780000 | CW12: =30000*26 -> 780000 | CX12: =30000*26 -> 780000 | CY12: =SUM(CM12:CX12) -> 7380000 | CZ12: =CM12*$J12 -> 324711.24 | DA12: =CN12*$J12 -> 194826.74 | DB12: =CO12*$J12 -> 194826.74 | DC12: =CP12*$J12 -> 259768.99 | DD12: =CQ12*$J12 -> 389653.49 | DE12: =CR12*$J12 -> 389653.49 | DF12: =CS12*$J12 -> 506549.53 | DG12: =CT12*$J12 -> 506549.53 | ... DK12: =CX12*$J12 -> 506549.53 | DL12: =SUM(CZ12:DK12) -> 4792737.9 | DM12: 500000 | DN12: 300000 | DO12: 300000 | DP12: 400000 | DQ12: =25000*24 -> 600000 | DR12: =25000*24 -> 600000 | DS12: =30000*26 -> 780000 | DT12: =30000*26 -> 780000 | DU12: =30000*26 -> 780000 | DV12: =30000*26 -> 780000 | DW12: =30000*26 -> 780000 | DX12: =30000*26 -> 780000 | DY12: =SUM(DM12:DX12) -> 7380000 | DZ12: =DM12*$K12 -> 318217.02 | EA12: =DN12*$K12 -> 190930.21 | EB12: =DO12*$K12 -> 190930.21 | EC12: =DP12*$K12 -> 254573.61 | ED12: =DQ12*$K12 -> 381860.42 | EE12: =DR12*$K12 -> 381860.42 | EF12: =DS12*$K12 -> 496418.54 | EG12: =DT12*$K12 -> 496418.54 | ... EK12: =DX12*$K12 -> 496418.54 | EL12: =SUM(DZ12:EK12) -> 4696883.1
A13: Samsung BRK | B13: New BRK 2 | F13: 0.8 | G13: 0.8 | H13: =G13*0.98 -> 0.784 | I13: =H13*0.98 -> 0.76832 | J13: =I13*0.98 -> 0.7529536 | K13: =J13*0.98 -> 0.73789453 | Y13: =SUM(M13:X13) -> 0 | Z13: =M13*$D13 -> 0 | AA13: =N13*$D13 -> 0 | AB13: =O13*$D13 -> 0 | AC13: =P13*$D13 -> 0 | AD13: =Q13*$D13 -> 0 | AE13: =R13*$D13 -> 0 | AF13: =S13*$D13 -> 0 | AG13: =T13*$D13 -> 0 | AH13: =U13*$G13 -> 0 | AI13: =V13*$G13 -> 0 | AJ13: =W13*$G13 -> 0 | AK13: =X13*$H13 -> 0 | AL13: =SUM(Z13:AK13) -> 0 | AY13: =SUM(AM13:AX13) -> 0 | AZ13: =AM13*$H13 -> 0 | BA13: =AN13*$H13 -> 0 | BB13: =AO13*$H13 -> 0 | BC13: =AP13*$H13 -> 0 | BD13: =AQ13*$H13 -> 0 | BE13: =AR13*$H13 -> 0 | BF13: =AS13*$H13 -> 0 | BG13: =AT13*$H13 -> 0 | ... BK13: =AX13*$H13 -> 0 | BL13: =SUM(AZ13:BK13) -> 0 | BM13: 300000 | BN13: 300000 | BO13: 400000 | BP13: 500000 | BQ13: 400000 | BR13: 500000 | BS13: 400000 | BT13: 200000 | BU13: 100000 | BV13: 50000 | BY13: =SUM(BM13:BX13) -> 3150000 | BZ13: =BM13*$I13 -> 230496 | CA13: =BN13*$I13 -> 230496 | CB13: =BO13*$I13 -> 307328 | CC13: =BP13*$I13 -> 384160 | CD13: =BQ13*$I13 -> 307328 | CE13: =BR13*$I13 -> 384160 | CF13: =BS13*$I13 -> 307328 | CG13: =BT13*$I13 -> 153664 | ... CK13: =BX13*$I13 -> 0 | CL13: =SUM(BZ13:CK13) -> 2420208 | CM13: 300000 | CN13: 300000 | CO13: 400000 | CP13: 500000 | CQ13: 400000 | CR13: 500000 | CS13: 400000 | CT13: 200000 | CU13: 100000 | CV13: 50000 | CY13: =SUM(CM13:CX13) -> 3150000 | CZ13: =CM13*$J13 -> 225886.08 | DA13: =CN13*$J13 -> 225886.08 | DB13: =CO13*$J13 -> 301181.44 | DC13: =CP13*$J13 -> 376476.8 | DD13: =CQ13*$J13 -> 301181.44 | DE13: =CR13*$J13 -> 376476.8 | DF13: =CS13*$J13 -> 301181.44 | DG13: =CT13*$J13 -> 150590.72 | ... DK13: =CX13*$J13 -> 0 | DL13: =SUM(CZ13:DK13) -> 2371803.8 | DM13: 300000 | DN13: 300000 | DO13: 400000 | DP13: 500000 | DQ13: 400000 | DR13: 500000 | DS13: 400000 | DT13: 200000 | DU13: 100000 | DV13: 50000 | DY13: =SUM(DM13:DX13) -> 3150000 | DZ13: =DM13*$K13 -> 221368.36 | EA13: =DN13*$K13 -> 221368.36 | EB13: =DO13*$K13 -> 295157.81 | EC13: =DP13*$K13 -> 368947.26 | ED13: =DQ13*$K13 -> 295157.81 | EE13: =DR13*$K13 -> 368947.26 | EF13: =DS13*$K13 -> 295157.81 | EG13: =DT13*$K13 -> 147578.91 | ... EK13: =DX13*$K13 -> 0 | EL13: =SUM(DZ13:EK13) -> 2324367.8
A14: Samsung BRK VN Total | M14: =SUM(M6:M13) -> 1071049 | N14: =SUM(N6:N13) -> 988800 | O14: =SUM(O6:O13) -> 1312100 | P14: =SUM(P6:P13) -> 916700 | Q14: =SUM(Q6:Q13) -> 753500 | R14: =SUM(R6:R13) -> 767650 | S14: =SUM(S6:S13) -> 800000 | T14: =SUM(T6:T13) -> 800000 | ... EL14: =SUM(EL6:EL13) -> 7021250.9
A15: Samsung CNC | B15: DM3 (S23) | C15: GH94-35427A | D15: 1.305 | E15: 1.305 | F15: 1.305 | G15: 1.34 | H15: 1.34 | I15: 1.34 | J15: 1.34 | K15: 1.34 | M15: 80500 | N15: 66800 | O15: 89800 | P15: 78900 | Q15: 44204 | R15: 20900 | S15: 115000 | T15: 80000 | U15: 70000 | V15: 80000 | W15: 80000 | X15: 60000 | Y15: =SUM(M15:X15) -> 866104 | Z15: 107870 | AA15: 89512 | AB15: 120332 | AC15: 104263.93 | AD15: 58349.28 | AE15: 27588 | AF15: =S15*$E15 -> 150075 | AG15: =T15*$E15 -> 104400 | AH15: =U15*$E15 -> 91350 | AI15: =V15*$E15 -> 104400 | AJ15: =W15*$E15 -> 104400 | AK15: =X15*$E15 -> 78300 | AL15: =SUM(Z15:AK15) -> 1140840.2 | AM15: 80500 | AN15: 66800 | AO15: 50000 | AP15: 40000 | AY15: =SUM(AM15:AX15) -> 237300 | AZ15: =AM15*$H15 -> 107870 | BA15: =AN15*$H15 -> 89512 | BB15: =AO15*$H15 -> 67000 | BC15: =AP15*$H15 -> 53600 | BD15: =AQ15*$H15 -> 0 | BE15: =AR15*$H15 -> 0 | BF15: =AS15*$H15 -> 0 | BG15: =AT15*$H15 -> 0 | ... BK15: =AX15*$H15 -> 0 | BL15: =SUM(AZ15:BK15) -> 317982 | BY15: =SUM(BM15:BX15) -> 0 | BZ15: =BM15*$I15 -> 0 | CA15: =BN15*$I15 -> 0 | CB15: =BO15*$I15 -> 0 | CC15: =BP15*$I15 -> 0 | CD15: =BQ15*$I15 -> 0 | CE15: =BR15*$I15 -> 0 | CF15: =BS15*$I15 -> 0 | CG15: =BT15*$I15 -> 0 | ... CK15: =BX15*$I15 -> 0 | CL15: =SUM(BZ15:CK15) -> 0 | CY15: =SUM(CM15:CX15) -> 0 | CZ15: =CM15*$J15 -> 0 | DA15: =CN15*$J15 -> 0 | DB15: =CO15*$J15 -> 0 | DC15: =CP15*$J15 -> 0 | DD15: =CQ15*$J15 -> 0 | DE15: =CR15*$J15 -> 0 | DF15: =CS15*$J15 -> 0 | DG15: =CT15*$J15 -> 0 | ... DK15: =CX15*$J15 -> 0 | DL15: =SUM(CZ15:DK15) -> 0 | DY15: =SUM(DM15:DX15) -> 0 | DZ15: =DM15*$K15 -> 0 | EA15: =DN15*$K15 -> 0 | EB15: =DO15*$K15 -> 0 | EC15: =DP15*$K15 -> 0 | ED15: =DQ15*$K15 -> 0 | EE15: =DR15*$K15 -> 0 | EF15: =DS15*$K15 -> 0 | EG15: =DT15*$K15 -> 0 | ... EK15: =DX15*$K15 -> 0 | EL15: =SUM(DZ15:EK15) -> 0
A16: Samsung CNC | B16: Q4 | C16: GH94-34528A | D16: 0.8 | E16: 0.8 | F16: 0.8 | G16: 0.79 | H16: 0.79 | I16: 0.79 | J16: 0.79 | K16: =J16*0.98 -> 0.7742 | M16: 157900 | N16: 93500 | O16: 129000 | P16: 94640 | Q16: 75282 | R16: 71000 | T16: 10000 | U16: 20000 | V16: 20000 | W16: 20000 | X16: 20000 | Y16: =SUM(M16:X16) -> 711322 | Z16: 126320 | AA16: 74800 | AB16: 103200 | AC16: 75712 | AD16: 61454.694 | AE16: 56800 | AF16: =S16*$E16 -> 0 | AG16: =T16*$E16 -> 8000 | AH16: =U16*$E16 -> 16000 | AI16: =V16*$E16 -> 16000 | AJ16: =W16*$E16 -> 16000 | AK16: =X16*$E16 -> 16000 | AL16: =SUM(Z16:AK16) -> 570286.69 | AM16: 157900 | AN16: 93500 | AO16: 150000 | AP16: 120000 | AQ16: 100000 | AR16: 110000 | AS16: 100000 | AT16: 100000 | AU16: 100000 | AV16: 100000 | AW16: 100000 | AX16: 100000 | AY16: =SUM(AM16:AX16) -> 1331400 | AZ16: =AM16*$H16 -> 124741 | BA16: =AN16*$H16 -> 73865 | BB16: =AO16*$H16 -> 118500 | BC16: =AP16*$H16 -> 94800 | BD16: =AQ16*$H16 -> 79000 | BE16: =AR16*$H16 -> 86900 | BF16: =AS16*$H16 -> 79000 | BG16: =AT16*$H16 -> 79000 | ... BK16: =AX16*$H16 -> 79000 | BL16: =SUM(AZ16:BK16) -> 1051806 | BY16: =SUM(BM16:BX16) -> 0 | BZ16: =BM16*$I16 -> 0 | CA16: =BN16*$I16 -> 0 | CB16: =BO16*$I16 -> 0 | CC16: =BP16*$I16 -> 0 | CD16: =BQ16*$I16 -> 0 | CE16: =BR16*$I16 -> 0 | CF16: =BS16*$I16 -> 0 | CG16: =BT16*$I16 -> 0 | ... CK16: =BX16*$I16 -> 0 | CL16: =SUM(BZ16:CK16) -> 0 | CY16: =SUM(CM16:CX16) -> 0 | CZ16: =CM16*$J16 -> 0 | DA16: =CN16*$J16 -> 0 | DB16: =CO16*$J16 -> 0 | DC16: =CP16*$J16 -> 0 | DD16: =CQ16*$J16 -> 0 | DE16: =CR16*$J16 -> 0 | DF16: =CS16*$J16 -> 0 | DG16: =CT16*$J16 -> 0 | ... DK16: =CX16*$J16 -> 0 | DL16: =SUM(CZ16:DK16) -> 0 | DY16: =SUM(DM16:DX16) -> 0 | DZ16: =DM16*$K16 -> 0 | EA16: =DN16*$K16 -> 0 | EB16: =DO16*$K16 -> 0 | EC16: =DP16*$K16 -> 0 | ED16: =DQ16*$K16 -> 0 | EE16: =DR16*$K16 -> 0 | EF16: =DS16*$K16 -> 0 | EG16: =DT16*$K16 -> 0 | ... EK16: =DX16*$K16 -> 0 | EL16: =SUM(DZ16:EK16) -> 0
A17: Samsung CNC | B17: Q5 | C17: GH94-35418A | D17: 0.92 | E17: 0.92 | F17: 0.92 | G17: 0.94293878 | H17: 0.94293878 | I17: 0.94293878 | J17: 0.94293878 | K17: =J17*0.98 -> 0.92408 | M17: 7000 | Q17: 37400 | R17: 4400 | S17: 1700 | Y17: =SUM(M17:X17) -> 50500 | Z17: 6300 | AA17: 0 | AB17: 0 | AC17: 0 | AD17: 35265.91 | AE17: 4048 | AF17: =S17*$E17 -> 1564 | AG17: =T17*$E17 -> 0 | AH17: =U17*$E17 -> 0 | AI17: =V17*$E17 -> 0 | AJ17: =W17*$E17 -> 0 | AK17: =X17*$E17 -> 0 | AL17: =SUM(Z17:AK17) -> 47177.91 | AM17: 7000 | AY17: =SUM(AM17:AX17) -> 7000 | AZ17: =AM17*$H17 -> 6600.5714 | BA17: =AN17*$H17 -> 0 | BB17: =AO17*$H17 -> 0 | BC17: =AP17*$H17 -> 0 | BD17: =AQ17*$H17 -> 0 | BE17: =AR17*$H17 -> 0 | BF17: =AS17*$H17 -> 0 | BG17: =AT17*$H17 -> 0 | ... BK17: =AX17*$H17 -> 0 | BL17: =SUM(AZ17:BK17) -> 6600.5714 | BY17: =SUM(BM17:BX17) -> 0 | BZ17: =BM17*$I17 -> 0 | CA17: =BN17*$I17 -> 0 | CB17: =BO17*$I17 -> 0 | CC17: =BP17*$I17 -> 0 | CD17: =BQ17*$I17 -> 0 | CE17: =BR17*$I17 -> 0 | CF17: =BS17*$I17 -> 0 | CG17: =BT17*$I17 -> 0 | ... CK17: =BX17*$I17 -> 0 | CL17: =SUM(BZ17:CK17) -> 0 | CY17: =SUM(CM17:CX17) -> 0 | CZ17: =CM17*$J17 -> 0 | DA17: =CN17*$J17 -> 0 | DB17: =CO17*$J17 -> 0 | DC17: =CP17*$J17 -> 0 | DD17: =CQ17*$J17 -> 0 | DE17: =CR17*$J17 -> 0 | DF17: =CS17*$J17 -> 0 | DG17: =CT17*$J17 -> 0 | ... DK17: =CX17*$J17 -> 0 | DL17: =SUM(CZ17:DK17) -> 0 | DY17: =SUM(DM17:DX17) -> 0 | DZ17: =DM17*$K17 -> 0 | EA17: =DN17*$K17 -> 0 | EB17: =DO17*$K17 -> 0 | EC17: =DP17*$K17 -> 0 | ED17: =DQ17*$K17 -> 0 | EE17: =DR17*$K17 -> 0 | EF17: =DS17*$K17 -> 0 | EG17: =DT17*$K17 -> 0 | ... EK17: =DX17*$K17 -> 0 | EL17: =SUM(DZ17:EK17) -> 0
A18: Samsung CNC | B18: HX1 | C18: GH94-26469A | D18: 1.1 | E18: 1.1 | F18: 1.1 | G18: 1.1 | H18: 1.1 | I18: 1.1 | J18: 1.1 | K18: =J18*0.98 -> 1.078 | M18: 17353 | Y18: =SUM(M18:X18) -> 17353 | Z18: 19088.3 | AA18: 0 | AB18: 0 | AC18: 0 | AD18: 0 | AE18: 0 | AF18: =S18*$E18 -> 0 | AG18: =T18*$E18 -> 0 | AH18: =U18*$E18 -> 0 | AI18: =V18*$E18 -> 0 | AJ18: =W18*$E18 -> 0 | AK18: =X18*$E18 -> 0 | AL18: =SUM(Z18:AK18) -> 19088.3 | AM18: 17353 | AY18: =SUM(AM18:AX18) -> 17353 | AZ18: =AM18*$H18 -> 19088.3 | BA18: =AN18*$H18 -> 0 | BB18: =AO18*$H18 -> 0 | BC18: =AP18*$H18 -> 0 | BD18: =AQ18*$H18 -> 0 | BE18: =AR18*$H18 -> 0 | BF18: =AS18*$H18 -> 0 | BG18: =AT18*$H18 -> 0 | ... BK18: =AX18*$H18 -> 0 | BL18: =SUM(AZ18:BK18) -> 19088.3 | BY18: =SUM(BM18:BX18) -> 0 | BZ18: =BM18*$I18 -> 0 | CA18: =BN18*$I18 -> 0 | CB18: =BO18*$I18 -> 0 | CC18: =BP18*$I18 -> 0 | CD18: =BQ18*$I18 -> 0 | CE18: =BR18*$I18 -> 0 | CF18: =BS18*$I18 -> 0 | CG18: =BT18*$I18 -> 0 | ... CK18: =BX18*$I18 -> 0 | CL18: =SUM(BZ18:CK18) -> 0 | CY18: =SUM(CM18:CX18) -> 0 | CZ18: =CM18*$J18 -> 0 | DA18: =CN18*$J18 -> 0 | DB18: =CO18*$J18 -> 0 | DC18: =CP18*$J18 -> 0 | DD18: =CQ18*$J18 -> 0 | DE18: =CR18*$J18 -> 0 | DF18: =CS18*$J18 -> 0 | DG18: =CT18*$J18 -> 0 | ... DK18: =CX18*$J18 -> 0 | DL18: =SUM(CZ18:DK18) -> 0 | DY18: =SUM(DM18:DX18) -> 0 | DZ18: =DM18*$K18 -> 0 | EA18: =DN18*$K18 -> 0 | EB18: =DO18*$K18 -> 0 | EC18: =DP18*$K18 -> 0 | ED18: =DQ18*$K18 -> 0 | EE18: =DR18*$K18 -> 0 | EF18: =DS18*$K18 -> 0 | EG18: =DT18*$K18 -> 0 | ... EK18: =DX18*$K18 -> 0 | EL18: =SUM(DZ18:EK18) -> 0
A19: Samsung CNC | B19: B0 | C19: GH94-32719A | D19: 1.19 | E19: 1.19 | F19: 1.19 | G19: 1.203 | H19: 1.203 | I19: 1.203 | J19: 1.203 | K19: =J19*0.98 -> 1.17894 | M19: 59600 | N19: 34200 | O19: 56805 | P19: 37207 | Q19: 28440 | R19: 72400 | S19: 100000 | T19: 75000 | U19: 75000 | V19: 80000 | W19: 80000 | X19: 80000 | Y19: =SUM(M19:X19) -> 778652 | Z19: 73308 | AA19: 42066 | AB19: 69870.15 | AC19: 44980.985 | AD19: 35172.735 | AE19: 87604 | AF19: =S19*$E19 -> 119000 | AG19: =T19*$E19 -> 89250 | AH19: =U19*$E19 -> 89250 | AI19: =V19*$E19 -> 95200 | AJ19: =W19*$E19 -> 95200 | AK19: =X19*$E19 -> 95200 | AL19: =SUM(Z19:AK19) -> 936101.87 | AM19: 59600 | AN19: 34200 | AO19: 40000 | AP19: 70000 | AQ19: 100000 | AR19: 120000 | AS19: 120000 | AT19: 120000 | AU19: 100000 | AV19: 100000 | AW19: 100000 | AX19: 100000 | AY19: =SUM(AM19:AX19) -> 1063800 | AZ19: =AM19*$H19 -> 71698.8 | BA19: =AN19*$H19 -> 41142.6 | BB19: =AO19*$H19 -> 48120 | BC19: =AP19*$H19 -> 84210 | BD19: =AQ19*$H19 -> 120300 | BE19: =AR19*$H19 -> 144360 | BF19: =AS19*$H19 -> 144360 | BG19: =AT19*$H19 -> 144360 | ... BK19: =AX19*$H19 -> 120300 | BL19: =SUM(AZ19:BK19) -> 1279751.4 | BM19: 150000 | BN19: 100000 | BO19: 150000 | BP19: 150000 | BQ19: 150000 | BR19: 150000 | BS19: 150000 | BT19: 150000 | BU19: 150000 | BV19: 150000 | BW19: 150000 | BX19: 150000 | BY19: =SUM(BM19:BX19) -> 1750000 | BZ19: =BM19*$I19 -> 180450 | CA19: =BN19*$I19 -> 120300 | CB19: =BO19*$I19 -> 180450 | CC19: =BP19*$I19 -> 180450 | CD19: =BQ19*$I19 -> 180450 | CE19: =BR19*$I19 -> 180450 | CF19: =BS19*$I19 -> 180450 | CG19: =BT19*$I19 -> 180450 | ... CK19: =BX19*$I19 -> 180450 | CL19: =SUM(BZ19:CK19) -> 2105250 | CM19: 150000 | CN19: 100000 | CO19: 150000 | CP19: 150000 | CQ19: 150000 | CR19: 150000 | CS19: 150000 | CT19: 150000 | CU19: 150000 | CV19: 150000 | CW19: 150000 | CX19: 150000 | CY19: =SUM(CM19:CX19) -> 1750000 | CZ19: =CM19*$J19 -> 180450 | DA19: =CN19*$J19 -> 120300 | DB19: =CO19*$J19 -> 180450 | DC19: =CP19*$J19 -> 180450 | DD19: =CQ19*$J19 -> 180450 | DE19: =CR19*$J19 -> 180450 | DF19: =CS19*$J19 -> 180450 | DG19: =CT19*$J19 -> 180450 | ... DK19: =CX19*$J19 -> 180450 | DL19: =SUM(CZ19:DK19) -> 2105250 | DM19: 150000 | DN19: 100000 | DO19: 150000 | DP19: 150000 | DQ19: 150000 | DR19: 150000 | DS19: 150000 | DT19: 150000 | DU19: 150000 | DV19: 150000 | DW19: 150000 | DX19: 150000 | DY19: =SUM(DM19:DX19) -> 1750000 | DZ19: =DM19*$K19 -> 176841 | EA19: =DN19*$K19 -> 117894 | EB19: =DO19*$K19 -> 176841 | EC19: =DP19*$K19 -> 176841 | ED19: =DQ19*$K19 -> 176841 | EE19: =DR19*$K19 -> 176841 | EF19: =DS19*$K19 -> 176841 | EG19: =DT19*$K19 -> 176841 | ... EK19: =DX19*$K19 -> 176841 | EL19: =SUM(DZ19:EK19) -> 2063145
A20: Samsung CNC | B20: E1 | C20: GH94-38080A | D20: 1.18 | E20: 1.18 | F20: 1.18 | G20: 1.2040816 | H20: 1.2040816 | I20: 1.2040816 | J20: 1.2040816 | K20: =J20*0.98 -> 1.18 | M20: 156400 | N20: 129500 | O20: 181500 | P20: 127500 | Q20: 111260 | R20: 13000 | S20: 80000 | T20: 80000 | U20: 75000 | V20: 80000 | W20: 80000 | X20: 80000 | Y20: =SUM(M20:X20) -> 1194160 | Z20: 189244 | AA20: 156695 | AB20: 223604 | AC20: 151136.53 | AD20: 133966.12 | AE20: 15340 | AF20: =S20*$E20 -> 94400 | AG20: =T20*$E20 -> 94400 | AH20: =U20*$E20 -> 88500 | AI20: =V20*$E20 -> 94400 | AJ20: =W20*$E20 -> 94400 | AK20: =X20*$E20 -> 94400 | AL20: =SUM(Z20:AK20) -> 1430485.7 | AM20: 156400 | AN20: 129500 | AO20: 200000 | AP20: 180000 | AQ20: 180000 | AR20: 220000 | AS20: 220000 | AT20: 220000 | AU20: 200000 | AV20: 200000 | AW20: 200000 | AX20: 200000 | AY20: =SUM(AM20:AX20) -> 2305900 | AZ20: =AM20*$H20 -> 188318.37 | BA20: =AN20*$H20 -> 155928.57 | BB20: =AO20*$H20 -> 240816.33 | BC20: =AP20*$H20 -> 216734.69 | BD20: =AQ20*$H20 -> 216734.69 | BE20: =AR20*$H20 -> 264897.96 | BF20: =AS20*$H20 -> 264897.96 | BG20: =AT20*$H20 -> 264897.96 | ... BK20: =AX20*$H20 -> 240816.33 | BL20: =SUM(AZ20:BK20) -> 2776491.8 | BM20: 250000 | BN20: 129500 | BO20: 250000 | BP20: 250000 | BQ20: 250000 | BR20: 250000 | BS20: 250000 | BT20: 250000 | BU20: 250000 | BV20: 250000 | BW20: 250000 | BX20: 250000 | BY20: =SUM(BM20:BX20) -> 2879500 | BZ20: =BM20*$I20 -> 301020.41 | CA20: =BN20*$I20 -> 155928.57 | CB20: =BO20*$I20 -> 301020.41 | CC20: =BP20*$I20 -> 301020.41 | CD20: =BQ20*$I20 -> 301020.41 | CE20: =BR20*$I20 -> 301020.41 | CF20: =BS20*$I20 -> 301020.41 | CG20: =BT20*$I20 -> 301020.41 | ... CK20: =BX20*$I20 -> 301020.41 | CL20: =SUM(BZ20:CK20) -> 3467153.1 | CM20: 250000 | CN20: 129500 | CO20: 250000 | CP20: 250000 | CQ20: 250000 | CR20: 250000 | CS20: 250000 | CT20: 250000 | CU20: 250000 | CV20: 250000 | CW20: 250000 | CX20: 250000 | CY20: =SUM(CM20:CX20) -> 2879500 | CZ20: =CM20*$J20 -> 301020.41 | DA20: =CN20*$J20 -> 155928.57 | DB20: =CO20*$J20 -> 301020.41 | DC20: =CP20*$J20 -> 301020.41 | DD20: =CQ20*$J20 -> 301020.41 | DE20: =CR20*$J20 -> 301020.41 | DF20: =CS20*$J20 -> 301020.41 | DG20: =CT20*$J20 -> 301020.41 | ... DK20: =CX20*$J20 -> 301020.41 | DL20: =SUM(CZ20:DK20) -> 3467153.1 | DM20: 250000 | DN20: 129500 | DO20: 250000 | DP20: 250000 | DQ20: 250000 | DR20: 250000 | DS20: 250000 | DT20: 250000 | DU20: 250000 | DV20: 250000 | DW20: 250000 | DX20: 250000 | DY20: =SUM(DM20:DX20) -> 2879500 | DZ20: =DM20*$K20 -> 295000 | EA20: =DN20*$K20 -> 152810 | EB20: =DO20*$K20 -> 295000 | EC20: =DP20*$K20 -> 295000 | ED20: =DQ20*$K20 -> 295000 | EE20: =DR20*$K20 -> 295000 | EF20: =DS20*$K20 -> 295000 | EG20: =DT20*$K20 -> 295000 | ... EK20: =DX20*$K20 -> 295000 | EL20: =SUM(DZ20:EK20) -> 3397810
A21: Samsung CNC | B21: B6 | C21: GH94-39228A | D21: 0.63 | E21: 0.63 | F21: 0.63 | G21: 0.6 | H21: 0.6 | I21: 0.6 | J21: 0.6 | K21: =J21*0.98 -> 0.588 | Q21: 29000 | R21: 185544 | S21: 75000 | T21: 80000 | U21: 110000 | V21: 140000 | W21: 150000 | X21: 150000 | Y21: =SUM(M21:X21) -> 919544 | AD21: 11278.857 | AE21: 113181.84 | AF21: =S21*$E21 -> 47250 | AG21: =T21*$E21 -> 50400 | AH21: =U21*$E21 -> 69300 | AI21: =V21*$E21 -> 88200 | AJ21: =W21*$E21 -> 94500 | AK21: =X21*$E21 -> 94500 | AL21: =SUM(Z21:AK21) -> 568610.7 | AY21: =SUM(AM21:AX21) -> 0 | BL21: =SUM(AZ21:BK21) -> 0 | BY21: =SUM(BM21:BX21) -> 0 | CL21: =SUM(BZ21:CK21) -> 0 | CY21: =SUM(CM21:CX21) -> 0 | DL21: =SUM(CZ21:DK21) -> 0 | DY21: =SUM(DM21:DX21) -> 0 | EL21: =SUM(DZ21:EK21) -> 0
