Workbook
Name __CON1: #REF!
Name __CON2: #REF!
Name __NET2: #REF!
Name _1: #N/A
Name _2: #REF!
Name _3: #N/A
Name _4: #N/A
Name _CON1: #REF!
Name _CON2: #REF!
Name _DAT1: [2]Sheet1!#REF!
Name _DAT13: [2]Sheet1!#REF!
Name _DAT16: [2]Sheet1!#REF!
Name _DAT17: [2]Sheet1!#REF!
Name _DAT18: [2]Sheet1!#REF!
Name _DAT19: [2]Sheet1!#REF!
Name _DAT20: [2]Sheet1!#REF!
Name _DAT3: [2]Sheet1!#REF!
Name _DAT9: [2]Sheet1!#REF!
Name _NET2: #REF!
Name a277Print_Titles: #REF!
Name aerg: #N/A
Name Assessment_Types: #REF!
Name B_Isc: #REF!
Name bang_gia: #REF!
Name BOQ: #REF!
Name BVCISUMMARY: #REF!
Name Calqty: #REF!
Name Choices: [6]Sheet7!$A$19:$A$20
Name Co: #REF!
Name code: #REF!
Name CODENO: '[8]BOM LIST 정리'!$D$7:$D$48
Name COMMON: #REF!
Name CON_EQP_COS: #REF!
Name Cong_HM_DTCT: #REF!
Name Cong_M_DTCT: #REF!
Name Cong_NC_DTCT: #REF!
Name Cong_VL_DTCT: #REF!
Name CONTRACT: #REF!
Name COVER: #REF!
Name CRITINST: #REF!
Name CRITPURC: #REF!
Name CS_10: #REF!
Name CS_100: #REF!
Name CS_10S: #REF!
Name CS_120: #REF!
Name CS_140: #REF!
Name CS_160: #REF!
Name CS_20: #REF!
Name CS_30: #REF!
Name CS_40: #REF!
Name CS_40S: #REF!
Name CS_5S: #REF!
Name CS_60: #REF!
Name CS_80: #REF!
Name CS_80S: #REF!
Name CS_STD: #REF!
Name CS_XS: #REF!
Name CS_XXS: #REF!
Name ctiep: #REF!
Name den_bu: #REF!

Sheet Cover.
E13: Supplier name | G13: BANGSHI BẮC NINH
E14: Major Product | G14: The re-evaluation
E15: Audit Object | G15: Anodizing
E16: Date of Audit | G16: 23/11/2019
E17: Auditor | G17: 홍 선생님
E18: Grade
E19: Result
B22: M&C Electronics Vina

Sheet Result Report
B1: Quality Process Audit Result Report
C3: □ Audit Result
C4: Audit Object | F4: =Cover.!G14 | J4: Grade | M4: =[32]Cover.!G18 | O4: Date of Audit | Q4: =Cover.!G16
C5: Major Product | F5: =Cover.!G15 | J5: Auditor | M5: =Cover.!G17 | O5: Auditee
C8: □Scores and Grade by sector
C9: No | D9: evaluation sector | E9: Evaluation requiment | H9: Evaluation result | M9: note
E10: the whole | H10: Result | K10: Degree of Completion
C11: 1 | D11: Warehouse for Materials | E11: ='checksheet QPA'!E51 | H11: ='checksheet QPA'!G10 | K11: =H11/E11*100
C12: 2 | D12: Material Inspection and Preparation | E12: ='checksheet QPA'!E52 | H12: ='checksheet QPA'!G16 | K12: =H12/E12*100
C13: 3 | D13: Production Process | E13: ='checksheet QPA'!E53 | H13: ='checksheet QPA'!G23 | K13: =H13/E13*100
C14: 4 | D14: Product Evaluation (OQC) | E14: ='checksheet QPA'!E54 | H14: ='checksheet QPA'!G34 | K14: =H14/E14*100
C15: 5 | D15: Packing and Shipment | E15: ='checksheet QPA'!E55 | H15: ='checksheet QPA'!G43 | K15: =H15/E15*100
C16: Evaluation Score/Grade | E16: =SUM(H11:J15) | H16: =IF(E16>=90,"A",IF(E16>=80,"B",IF(E16>=70,"C",IF(E16>=60,"D","E")))) | K16: =IF(H16="A","Very Good",IF(H16="B"," Good",IF(H16="C","Need Improvement",IF(H16="D","Unsatisfactory","Unsatisfactory"))))
C18: □ Improvement object Status by type
C19: Classification | E19: Number of Cases
C20: Material Management
C21: Material Inspection and Preparation
C22: Production Process
C23: Product Evaluation
C24: Packing Management
C25: Total

Sheet Non-Conforming Item
B2: Quality Process Audit Non-Conforming Item
M5: 해결
M6: 미결
B8: Classification | C8: NO | D8: Problem | F8: Countermeasure for Improvement | J8: Confirmation Result | M8: Completion Status | N8: Reproducibility status
D9: Pointed-out Item | E9: Phenomenon | F9: Improvement Plan | G9: Pictrue | H9: Person in charge | I9: Schedule | J9: Confirmed content | K9: Schedule | L9: person in charge

Sheet checksheet QPA
C1: VENDOR QUALIFICATION CHECKSHEET | F1: 양식 코드/양식 번호 | H1: PUR.04.00.07
F2: Effective Date/ 시행일 | H2: 43466
C3: 첫 평가/처음으로 평가 | E3: 재평가/다시 평가 | F3: Page/ 합계 trang | H3: 6
A4: 공급업체 코드/ 공급업체 코드(ERP) | C4: 공급업체 이름/공급업체 이름 | E4: Address/ 주소 | F4: 제공되는 제품 유형/제공되는 제품 유형:
A5: P1030 | C5: HM AL TECH VINA COMPANY LIMITED | E5: 박닌성 박닌시 Khac Niem Ward, Khac Niem 산업 클러스터(Hoang Nam Company에서 임대) | F5: 원자재/ 원자재 메인 서브재료/ 보조재료 | H5: 아웃소싱 자재/ 아웃소싱 소스로부터 원자재
A6: P.I.C/담당자 | C6: Job title/ 직위 | D6: Department/ 팀 ban | E6: Email | F6: Phone No.
A7: Ms An | C7: 관리 | D7: QC | E7: truonganvt.94@gmail.com | F7: 0986453190
A9: CONTENT OF EVALUATION
A10: Section 1 - Warehouse for Materials | E10: Sub total (Score) | F10: =SUM(F13:F15) | G10: =SUM(G13:G15) | H10: COMMENT
E11: Achievement rate | F11: =F10/100 | G11: =G10/100
A12: Question Number | B12: Element | C12: Requirement | D12: VNM | E12: Rating Criteria | F12: Score | G12: Result
A13: 1 | B13: Standard | C13: Is the material storage standard established, and are the warehoused materials structuralized for first-in/first-out, and is there management tools? | D13: 자재보관기준이 확립되어 있는지, 선입선출 기준이 있는지, 관리 이력이 있는지? | E13: Score 0: No standard for first-in/first-out, and materials in need of first-in/first-out are not managed. Score 1 : There is no management standard for first-in/first-out, but first-in/first-out is available for materias in need of it, or only the first-in/first-out management standard is retained. Score 2: There is first-in/first-out management standard, but required is partial improvement of the management object, or a state of management. Score 3 : The first-in/first-out management standard is established, and first-in, first-out process is in progress according to the management standard. | F13: 4
A14: 2 | B14: Environment | C14: 3.1 Are the material storing requirements defined? 3.2 Are the environmental temperature, humidity controlled? 3.3 Are the storing space well ventilated? 3.4 Are the risk of ignition prevented in the storing area? 3.5 Are all the materials be sealed? 3.6 Are fire extinguishers, sands be prepared in the storing area? 3.7 Are the leakage prevent solution be taken? 3.8 Are explosion-proof lamps, switches used in the storing area? | D14: 3.1 자재 보관 요구 사항이 식별되어 있습니까? 3.2 환경의 온도와 습도가 통제됩니까? 3.3 보관공간은 통풍이 잘 되나요? 3.4 보관 장소에서는 발화 위험이 방지되어 있습니까? 3.5 모든 재료는 밀봉되어 있습니까? 3.6 보관 장소에 소화기 및 모래가 준비되어 있습니까? 3.7 누출을 방지하는 솔루션인가요? 3.8 보관 장소에 사용되는 방폭 조명 및 스위치는 무엇입니까? | E14: Score 0: : The environmental condition is not defined, nor is the temperature/humidity managed. Score 1: : Although the environmental condition is not defiend, temperature/humdity is managed, or the environmental condition for materials storage is established. Score 2: : The environmental condition is established, but a state of management needs to be improved. Score 3: : The environmental condition is established, and it is managed according to the established standard. | F14: 4
A15: 3 | B15: Layout | C15: Are the products classified by item in time of materials storage, and is there an identification mark for materials? | D15: 자재는 보관시 품목별로 분류되어 있으며, 자재에 대한 식별 표시가 있나요? | E15: Score 0: There is no standard for identification of the stored materials, and it's difficult to identify the materials in storage. Score 1 : Though there is no standard for identification of the materials in storage, the materials in storage are identified, or there is only the standard of identification management of the stored materials. Score 2: There is the identification standard of the materials in storage, but partial improvement is required. (difficulty in identifying some materials, etc.) Score 3: There is the identification standard of the materials in storage, and materials are identified according to the standard. | F15: 4
A16: Section 2- Material Inspection and Preparation | E16: Sub total (Score) | F16: =SUM(F19:F22) | G16: =SUM(G19:G22) | H16: COMMENT
E17: Achievement rate | F17: =F16/100 | G17: =G16/100
A18: Question Number | B18: Element | C18: Question / Requirement | D18: VNM | E18: Rating Criteria | F18: Score | G18: Result
A19: 1 | B19: Material Inspection (WH) | C19: Are below critical quality control points of the material inspected in incoming? - Part Number and Lot Number - Maker/ Provider - Status of product - Packing condition - Quantity / Weight - Expiry Date | D19: 입고 시 원자재의 다음과 같은 중요한 품질 관리 사항이 평가됩니까? - 제품코드 및 로트번호 - 제조자/공급자 -제품의 상태 - 포장 사양 - 수량 / 중량 - 날짜가 만료되었습니다 | E19: Score 0 - More than 3 critical control point missed to be inspected in incoming. Score 1 - Some critical control points are inspected, but 2~3 critical control points missed. Score 2 - Some critical control points are inspected, but one critical control points missed. Score 3 - All critical control points are inspected in incoming | F19: 4
A20: 2 | B20: Material Inspection (IQC) | C20: Are below critical quality control points of material inspected ? - Spec - Appearance no damage, scratch, missing line, contamination, break line, etc. -Certification MSDS,SGS | D20: 재료의 중요한 품질 관리 지점이 검사됩니까? - 기술 사양 및 제품 품질 -외관 - MSDS, SGS 인증.. | E20: Score 0 - More than 3 critical control point missed to be inspected Score 1 - Some critical control points are inspected, but 2~3 critical control points missed. Score 2 - Some critical control points are inspected, but one critical control points missed. | F20: 4
A21: 3 | B21: Material Inspection (IQC) | C21: - Do inspectors receive training in inspection and compliance methods? | D21: - 검사관은 검사방법 및 준수사항에 대한 교육을 받았는가? | E21: Score 0. Do not meet requirement 1.1. Score 1. Meet requirement 1.1. Only use of c. Score 2. Meet requirement 1.1. Use of a or b. Score 3. Meet all requirements. | F21: 4
A22: 4 | B22: Pot Life Control for Partially Used Material | C22: - Is there a pot life control process for partially used material, one times material ? - Is there expiration date/time of the partially used material marked? - Are all these partially used materials used before the expiration date/time? | D22: - 부분적으로 또는 여러 번 사용되는 소재에 대해 유통기한을 관리하는 프로세스가 있나요? - 부분적으로 사용된 재료의 사용기한/시간이 표시되어 있나요? - 부분적으로 사용된 재료는 모두 유효기간/시간 이전에 사용되었나요? | E22: Score 0 - Do not meet requirement 4.1 Score 1 - Meet requirement 4.1, but found multiple cases do not meet requirement 4.2 and/or 4.3 and/or 4.4. Score 2 - Meet requirement 4.1, but found isolated case do not meet requirement 4.2 and/or 4.3 and/or 4.4. Score 3 - Meet all requirements | F22: 4
A23: Section 3- Production Process | E23: Sub total (Score) | F23: =SUM(F26:F33) | G23: =SUM(G26:G33) | H23: COMMENT
E24: Achievement rate | F24: =F23/100 | G24: =G23/100
A25: Question Number | B25: Element | C25: Question / Requirement | E25: Rating Criteria | F25: Score | G25: Result
A26: 1 | B26: Neutralizing | C26: Are below key process parameters controlled in the neutralizing process? - PH of neutralizing solvent - Time for neutralizing (or conveyor line speed) - Temperature of the tank liquor - The frequency to clean up the whole tank - Spray pressure, if spray neutralizing method used. | D26: 중화 중에 다음 매개변수가 제어됩니까? - 중성 용매의 PH - 중립화 시간(또는 컨베이어 라인 속도) - 탱크 와인의 온도 - 탱크 전체를 청소하는 빈도 - 스프레이 중화 방법을 사용하는 경우 스프레이 압력. | E26: Score 0 - None of the listed key process parameter is controlled. Score 2 - Some listed key process parameters are controlled, but missed any 2~3 of the listed key parameters. Score 4 - Some listed key process parameters are controlled, but missed any 1 of the listed key parameters. Score 5 - All the listed key process parameters are controlled. N/A - If no neutralizing process is applicable. | F26: 4 | J26: 9
A27: 2 | B27: Rinsing | C27: Are below key process parameters controlled in the rinsing process? - Time for rinsing (or conveyor line speed) - Conductivity - PH - Spray pressure, if spray rinsing method used. Remark: It is applicable to the rinsing process between all above processes and the final rinsing process. | D27: 헹굼 공정 중에 아래의 주요 공정 매개변수가 제어됩니까? - 헹굼 시간(또는 컨베이어 속도) - 전기 전도성 - PH - 스프레이 헹굼 방법을 사용하는 경우 스프레이 압력. 주의사항 : 위의 모든 과정과 최종 헹굼 과정 사이의 헹굼 과정에 적용됩니다. | E27: Score 0 - None of the listed key process parameter is controlled. Score 2 - Some listed key process parameters are controlled, but missed any 2~3 of the listed key parameters. Score 4 - Some listed key process parameters are controlled, but missed any 1 of the listed key parameters. Score 5 - All the listed key process parameters are controlled. N/A - If no rinsing process is required. | F27: 4 | J27: 22
A28: 3 | B28: Chemical Mixing Ratio | C28: - Is there chemical, thinner and curing agent mixing ratio verified and defined in the process document? - Is there mixing ratio followed in the production? | D28: - 공정 문서에서 화학적 혼합 비율, 희석제 및 경화제가 검증되고 정의되어 있습니까? - 생산시 혼합비율이 지켜지나요? | E28: Score 0 - Do not meet requirement Score 2 - Meet requirement but found multiple cases do not meet requirement Score 4 - Meet requirement but found isolated case do not meet requirement Score 5 - Meet all requirements | F28: 4
A29: 4 | B29: Chemical Material Inspection | C29: Are below critical quality control points of the paint inspected in incoming? - Part Number and Lot Number - Color - Viscosity - Solid Content - Quantity / Weight - Expiry Date | D29: 도착 시 페인트의 중요 품질 관리 지점을 검사합니까? - 부품번호 및 로트번호 - 색상 - 점도 - 내용이 탄탄하다 - 수량 / 중량 - 날짜가 만료되었습니다 | E29: Score 0 - More than 3 critical control point missed to be inspected in incoming. Score 2 - Some critical control points are inspected, but 2~3 critical control points missed. Score 4 - Some critical control points are inspected, but one critical control points missed. Score 5 - All critical control points are inspected in incoming | F29: 4
A30: 5 | B30: Chemical Storing | C30: - Are the material storing requirements defined? - Are the environmental temperature, humidity controlled? - Are the storing space well ventilated? - Are the risk of ignition prevented in the storing area? - Are all the materials be sealed? - Are fire extinguishers, sands be prepared in the storing area? - Are the leakage prevent solution be taken? - Are explosion-proof lamps, switches used in the storing area? | D30: 자재 보관 요구 사항이 식별되어 있습니까? - 주변 온도와 습도가 관리되고 있나요? - 보관공간은 통풍이 잘 되나요? - 보관장소에서는 발화위험이 방지되어 있는가? - 모든 자재는 밀봉되어 있나요? - 보관장소에 소화기, 모래 등이 준비되어 있는가? - 누수방지를 위한 솔루션인가? - 보관 장소에 방폭형 조명 및 스위치를 사용합니까? | E30: Score 0 - Do not meet requirement Score 2 - Meet requirement , but do not meet any 2 or more requirements from 3 to 4. Score 4 - Meet requirement , but do not meet any 1 requirement from 3 to 4. Score 5 - Meet all requirements | F30: 4
A31: 6 | B31: Polishing | C31: - Does the product polish before anodizing? - Have the product checked before and after polishing? | D31: - 아노다이징 전 제품이 광택 처리되어 있나요? - 폴리싱 전후에 제품의 육안검사가 이루어지나요? | E31: Score 0 - Do not meet requirement Score 1 - Meet requirement but found multiple cases do not meet requirement Score 2 - Meet requirement but found isolated case do not meet requirement Score 3 - Meet all requirements | F31: 4
A32: 7 | B32: Static Dust Removal | C32: - Is the static dust removal executed before Anodizing? - Is the static dust removal device maintained at a defined frequency? | D32: - 아노다이징 전 정전기 제거가 이루어지나요? - 정전기 제진장비는 규정된 빈도로 유지되고 있는가? | E32: Score 0 - Do not meet requirement Score 2 - Meet requirement , but do not meet requirement 6 Score 5 - Meet all requirements. N/A - Not applicable for metal parts painting. | F32: 4
A33: 8 | B33: Temperature control | C33: - Is there a product drying process? - Is the drying temperature controlled? - Is there any control of drying time? | D33: - 제품 건조과정이 있나요? - 건조온도 조절이 가능한가요? - 건조시간 조절이 가능한가요? | E33: Score 0 - No any of the listed critical control point is inspected for drying process Score 2 - Some critical control points are inspected, but missed any 2~3 of the listed critical control points. Score 4 - Some critical control points are inspected, but missed any 1 of the listed critical control points. Score 5 - All the listed critical control points are inspected in drying process | F33: 4
A34: Section 4- Product Evaluation (OQC) | E34: Sub total (Score) | F34: =SUM(F36:F42) | G34: =SUM(G37:G42) | H34: COMMENT
E35: Achievement rate | F35: =F34/100 | G35: =G34/100
A36: 1 | B36: Training | C36: Did an auditor receive an education about the measuring method, auditing method, and equipment use method , and get certified? | D36: 검사자는 측정 방법, 시험 방법, 장비 사용 방법에 대한 교육을 받고 인증을 받았습니까? | E36: Score 0: There is no auditor certiification standard, and an auditor has not been certified. Score 1: Though there is no auditor certification standard, the auditor certification has been invested, or the auditor certification standard is retained. Score 2: Though there is an auditor certification standard, the auditor certification system, identification management, and cyclic education management, etc are required to be partly improved. Score 3- There is the auditor certification standard, and certification evaluation/ identification management/ cyclic education, etc. are normally implemented. | F36: 4
A37: 2 | B37: Standard | C37: Are the audit standard and drawings are kept, and does the standard coincide with the products which are under auditing? | D37: 검사 기준이 적절하고 제품 검사 구역에 게시되어 있습니까? | E37: Score 0: There are no audit standard management criteria, and an audit is done under an auditor's self-judgment without the audit standard and drawings. Score 1:Though the related standard is not available, an audit is performed according to the audit standard suited for products , or the criteria for the audit standard management are retained. Score 2: The audit standard is prepared and applied according to audit standard criteria, but audit items/method are required to be partly improved. Score 3: An audit is performed based on the audit standard prepared according to the audit standard management critera. | F37: 4
A38: 3 | B38: Layout | C38: Are the products/pre/post shipment inspection, and the storage place for rejected products under separately classified management, and marked? of pre/post audit for products is clearly handled. | D38: 검사구역은 검사대기품, NG품, OK품으로 구분되나요? | E38: Score 0: There is no separate storage place, and products are stored in a state without distinction of pre/post audit. Score 1: Though there is no separate storage place for products, they are stored under classified management, or only the separate storage place is designated. Score 2: Products are kept in a separate storage place under classified management, but there are some products without distinction of pre/post audit. Score 3: Products are kept in a separate storage place under classified management, and distintion of pre/post audit for products is clearly handled. | F38: 4
A39: 4 | B39: Measuring equipmen | C39: Is the measuring equipment controlled and calibrated? | D39: 측정 장비가 관리되고 교정됩니까? | E39: Score 0 : There is no measuring instrument selection standard, and the accuracy of a measuring instrument is not compatible with the allowance of actual measurement items (ex. standard: xx.xx, measuring equipment: xx.x) Score 1 : There is the measuring instrument selection standard, or a measuring instrument in use is suitable for allowance measurement of actual products despite the absence of the standard. Score 2: There is the measuring instrument selection standard, but there exists a measuring instrument which is not selected according to the standard, or partial improvements are required, such as converiience of measurement, etc. Score 3: There is the the measuring instrument selection standard, and the accuracy of the measuring instrument in use is suited for measurement item allowance. (ex. standard: xx.xx, measuring equipment: xx.xx abnormal) | F39: 4
A40: 5 | B40: Follow customer | C40: Is the unacceptable item arising from a customer reflected in the management point of the audit process? | D40: 고객불만 처리 프로세스가 있나요? | E40: Score 0: There is no system for revison by reflecting unacceptable item in the audit standard, and it is not reflected as the audit item. Score 1: Although there is no audit standard reflection system, it is reflected through the revision and addition of the audit item, or the system reflecting it in the audit standard is established. Score 2: Established is the system reflecting it in the audit item according to the countermeasures against an unacceptable item, but there are some cases of omissions, or partial improvement are required. Score 3: Etablished is the system reflecting it in the audit standard according to an unacceptable item, and actually such an unacceptable item is reflected in the audit standard. | F40: 4
A41: 6 | B41: Internal audit | C41: Is the receiving audit history managment register under record management?(receiving audit report, audit history, rejection status, corrective measures, and post-management, etc. ) | D41: 내부감사가 실시되나요? 적시에 해결해야 할 문제가 개선되고 있습니까? | E41: Score 0: There is no receiving audit history management standard, and history management is not in progress. Score 1: Although there is no receiving audit history management standard, the audit history is managed, or only the standard for history management is retained. Score 2: Although there is the receiving audit history management standard in time of the receiving audit, partial improvements of the history maintenance state(post-measure contents, etc.) are required. . Score 3: There is the receiving audit management standard, and all audit history records are maintained. | F41: 4
...
