Workbook

Sheet Balance at 30.Apr.2026
D1: MOLD -JIG BALANCE AT APR.2026
A2: 1- | D2: List of Goods Trading not yet selling
B3: No | C3: Code | D3: Description | F3: Customer | G3: Month of Buying | H3: Balance at 30.Apr.2026 | K3: Reason | L3: Selling Plan | M3: Acounting confirm for Clearing
H4: Qty | I4: Amount VND | J4: Amount USD
H5: =SUBTOTAL(9,H10:H57) -> 1705 | I5: =SUBTOTAL(9,I10:I57) -> 5.1972508e+09 | J5: =SUBTOTAL(9,J10:J57) -> 199894.26
A7: Trading | B7: 1 | C7: 900196 | D7: Battery door #1 (50-PE623-1) | E7: Mold-Jig | F7: Qualcomm | G7: 05/2018 | H7: 1 | I7: 3.40275e+08 | J7: =+I7/26000 -> 13087.5 | L7: don't have PO, check is it possible to change name and us for current PO that we don’t make JIG actual
A8: Trading | B8: 2 | C8: 900205 | D8: Rear - Housing | E8: Mold-Jig | F8: Qualcomm | G8: 07/2018 | H8: 1 | I8: 399000000 | J8: =+I8/26000 -> 15346.154 | L8: Can not check out the reason why can not clear stock
A9: Trading | B9: 3 | C9: 900198 | D9: DOOR #1 (50-PE401-1) | E9: Mold-Jig | F9: Qualcomm | G9: 05/2018 | H9: 1 | I9: 3.40275e+08 | J9: =+I9/26000 -> 13087.5 | L9: don't have PO, check is it possible to change name and us for current PO that we don’t make JIG actual
A10: Trading | B10: 4 | C10: 901362 | D10: LOWER CORE OF JG REPS HOUSING MOLD - ECN CHANGE(LC - NEW MAKE) / Nhân bên dưới của khuôn JG Reps Housing | E10: Mold-Jig | G10: 03/2025 | H10: 1 | I10: 135000000 | J10: =+I10/26000 -> 5192.3077 | L10: May.26
A11: Trading | B11: 5 | C11: 901364 | D11: Mold Die casting LT2 Housing, 1 CAV (Full set)/Khuôn đúc LT2 Housing #1 | E11: Mold-Jig | F11: Mando Korea | G11: 05/2025 | H11: 1 | I11: 452000000 | J11: =+I11/26000 -> 17384.615 | L11: May.26
A12: Trading | B12: 6 | C12: 901365 | D12: Mold Die casting US cover 2 CAV (Full set)/Khuôn đúc US Cover #1 | E12: Mold-Jig | F12: Mando Korea | G12: 05/2025 | H12: 1 | I12: 480000000 | J12: =+I12/26000 -> 18461.538 | L12: May.26
A13: Trading | B13: 7 | C13: 901369 | D13: RWS COVER - ECN CHANGE (LC - NEW MAKE) | E13: Mold-Jig | F13: Mando Korea | G13: 05/2025 | H13: 1 | I13: 74000000 | J13: =+I13/26000 -> 2846.1538 | L13: May.26
A14: Trading | B14: 8 | C14: 900531 | D14: 50-PP795-1 PAD, CAMERA DIVIDER, BĂNG DÍNH 50-PP795-1 | E14: Product | F14: Qualcomm | G14: 07/2025 | H14: 850 | I14: 762450 | J14: =+I14/26000 -> 29.325 | L14: Waiting for upcoming PO (ko có forecast cho mã này)
A15: Trading | B15: 9 | C15: 901030 | D15: 50-40356-2_DISPLAY COVER, PLASTIC, MTP KUNO, Linh kiện qualcomm 50-40356-2 | E15: Product | F15: Qualcomm | G15: 08/2025 | H15: 200 | I15: 7904000 | J15: =+I15/26000 -> 304 | L15: Waiting for upcoming PO (ko có forecast cho mã này)
A16: Trading | B16: 10 | C16: 901405 | D16: LT2 HSG - MCT Jig (new vesion) | E16: Mold-Jig | F16: Mando Korea | G16: 08/2025 | H16: 1 | I16: 28000000 | J16: =+I16/26000 -> 1076.9231 | L16: Developed model, haven't got plan
A17: Trading | B17: 11 | C17: 901408 | D17: NX4 HSG - AIR GAGE HEAD/MASTER | E17: Mold-Jig | F17: Mando | G17: 09/2025 | H17: 1 | I17: 65721742 | J17: =+I17/26000 -> 2527.7593 | L17: Mr Noh xđ sẽ bán
A18: Trading | B18: 12 | C18: 901409 | D18: JK1-LHD HSG_New Bore core | E18: Mold-Jig | F18: Mando | G18: 09/2025 | H18: 1 | I18: 27000000 | J18: =+I18/26000 -> 1038.4615 | L18: Mr Noh xđ sẽ bán
A19: Trading | B19: 13 | C19: 900668 | D19: Left bracket 50-36919-1/Khung đỡ màn hình bên trái dùng cho oto bằng nhôm 50-36919-1 | E19: Product | F19: Qualcomm | G19: 11/2025 | H19: 7 | I19: 4232949.8 | J19: =+I19/26000 -> 162.80576 | L19: 4-Mar, shipped
A20: Trading | B20: 14 | C20: 901373 | D20: Mold Die casting MQ4aPE Housing 1 CAV (Full set) #12 | E20: Mold-Jig | F20: LG Yantai | G20: 11/2025 | H20: 1 | I20: 450000000 | J20: =+I20/26000 -> 17307.692 | L20: Jun.26
A21: Trading | B21: 15 | C21: 901422 | D21: US4 RHD Cover - MCT Jig - Ver 02 | E21: Mold-Jig | F21: Mando Korea | G21: 12/2025 | H21: 1 | I21: 24000000 | J21: =+I21/26000 -> 923.07692 | L21: Developed model, haven't got plan
A22: Trading | B22: 16 | C22: 901425 | D22: JG REPS LHD Cover - MCT Jig - Ver 02 | E22: Mold-Jig | F22: Mando Korea | G22: 12/2025 | H22: 1 | I22: 22800000 | J22: =+I22/26000 -> 876.92308 | L22: Developed model, haven't got plan
... A24: Trading | B24: 18 | C24: 901427 | D24: JG REPS LHD_MARKING JIG | E24: Mold-Jig | F24: Mando Korea | G24: 12/2025 | H24: 2 | I24: 1140000 | J24: =+I24/26000 -> 43.846154 | L24: Developed model, haven't got plan
A25: Trading | B25: 19 | C25: 901015 | D25: 50-43615-1_BackPlane Stiffener_ADP Arnage (4.0) | E25: Product | G25: 01/2026 | H25: 74 | I25: 50493305 | J25: =+I25/26000 -> 1942.0502 | L25: Waiting for upcoming PO (ko có forecast cho mã này)
A26: Trading | B26: 20 | C26: 901049 | D26: QRANIUM CARRIER, ADP RIDE ARNAGE (4.0) | E26: Product | G26: 01/2026 | H26: 73 | I26: 55782115 | J26: =+I26/26000 -> 2145.466 | L26: Waiting for upcoming PO (ko có forecast cho mã này)
A27: Trading | B27: 21 | C27: 901439 | D27: US4 RHD_MARKING JIG | E27: Mold-Jig | G27: 01/2026 | H27: 2 | I27: 1140000 | J27: =+I27/26000 -> 43.846154 | L27: Developed model, haven't got plan
A28: Trading | B28: 22 | C28: 901440 | D28: JG RWS_MARKING JIG | E28: Mold-Jig | G28: 01/2026 | H28: 2 | I28: 1260000 | J28: =+I28/26000 -> 48.461538 | L28: Developed model, haven't got plan
A29: Trading | B29: 23 | C29: 901410 | D29: Mold Die Casting CL4 HOUSING #18 | E29: Mold-Jig | F29: LG Yantai | G29: 02/2026 | H29: 1 | I29: 450000000 | J29: =+I29/26000 -> 17307.692 | L29: Haven't got plan
A30: Trading | B30: 24 | C30: 901445 | D30: T1XX_HOUSING_MCT_JIG_OP10 | E30: Mold-Jig | G30: 02/2026 | H30: 1 | I30: 17900000 | J30: =+I30/26000 -> 688.46154 | L30: Developed model, haven't got plan
A31: Trading | B31: 25 | C31: 901448 | D31: T1XX-2 Housing - CMM Jig | E31: Mold-Jig | G31: 02/2026 | H31: 2 | I31: 11800000 | J31: =+I31/26000 -> 453.84615 | L31: Developed model, haven't got plan
A32: Trading | B32: 26 | C32: 901449 | D32: T1XX-2 Bearing Plate - CMM Jig | E32: Mold-Jig | G32: 02/2026 | H32: 2 | I32: 12800000 | J32: =+I32/26000 -> 492.30769 | L32: Developed model, haven't got plan
A33: Trading | B33: 27 | C33: 901451 | D33: T1XX-2 Bearing Plate - MCT Jig | E33: Mold-Jig | G33: 02/2026 | H33: 1 | I33: 36000000 | J33: =+I33/26000 -> 1384.6154 | L33: Developed model, haven't got plan
A34: Trading | B34: 28 | C34: 901452 | D34: T1XX Housing - Cutting Jig | E34: Mold-Jig | G34: 02/2026 | H34: 1 | I34: 1420000 | J34: =+I34/26000 -> 54.615385 | L34: Developed model, haven't got plan
A35: Trading | B35: 29 | C35: 901458 | D35: O-ring for Battery Pack Rear-to-Front Cable (P/N: 143-8808-001-A03) | E35: Product | G35: 02/2026 | H35: 175 | I35: 2186625 | J35: =+I35/26000 -> 84.100962 | L35: Tooling sold, wait for receiving payment
A36: Trading | B36: 30 | C36: 901459 | D36: Oring for BATTERY PACK, TOP LID (P/N: 143-6225-001-A04) | E36: Product | G36: 02/2026 | H36: 175 | I36: 2186625 | J36: =+I36/26000 -> 84.100962 | L36: Tooling sold, wait for receiving payment
A37: Trading | B37: 31 | C37: 901411 | D37: Mold Die Casting CL4 HOUSING #19 | E37: Mold-Jig | G37: 04/2026 | H37: 1 | I37: 450000000 | J37: =+I37/26000 -> 17307.692
A38: Trading | B38: 32 | C38: 901443 | D38: T1XX-2 BEARING PLATE - Trimming Mold | E38: Mold-Jig | G38: 04/2026 | H38: 1 | I38: 60000000 | J38: =+I38/26000 -> 2307.6923
A39: Trading | B39: 33 | C39: 901444 | D39: T1XX Housing - VERTICAL RUBBER INNER SUPPORT/FIXTURE JPT230-OP20 | E39: Mold-Jig | G39: 04/2026 | H39: 1 | I39: 151612000 | J39: =+I39/26000 -> 5831.2308
A40: Trading | B40: 34 | C40: 901450 | D40: T1XX-2 Bearing Plate - Turning Jig | E40: Mold-Jig | G40: 04/2026 | H40: 1 | I40: 9700000 | J40: =+I40/26000 -> 373.07692
A41: Trading | B41: 35 | C41: 901453 | D41: LT2 HOUSING - Upper core | E41: Mold-Jig | G41: 04/2026 | H41: 1 | I41: 99000000 | J41: =+I41/26000 -> 3807.6923
A42: Trading | B42: 36 | C42: 901454 | D42: LT2 HOUSING - Bore core | E42: Mold-Jig | G42: 04/2026 | H42: 1 | I42: 37000000 | J42: =+I42/26000 -> 1423.0769
...

Sheet Trading-Buying 2026
B2: List of Goods Trading 2026 not yet selling
A3: item code | B3: Name | C3: Input in 2025 | F3: Openning 1. Jan.2025 | H3: Input in 2026 | K3: Balance 30.Apr.2026 | M3: Note plan of Selling | N3: PIC ( sale team)
C4: month | D4: Qty | E4: Amount | F4: Qty | G4: Amount | H4: month | I4: Qty | J4: Amount | K4: Qty | L4: Amount
A5: 900531 | B5: 50-PP795-1 PAD, CAMERA DIVIDER, BĂNG DÍNH 50-PP795-1 | C5: 202507 | D5: 1000 | E5: 897000 | F5: 850 | G5: 762450 | K5: 850 | L5: 762450 | M5: =VLOOKUP(A5,'Balance at 30.Apr.2026'!$C$10:$L$54,9,0) -> 0 | O5: =VLOOKUP(A5,'Balance at 30.Apr.2026'!$C$10:$C$13,1,0) -> #N/A | P5: =VLOOKUP(A5,'Balance at 30.Apr.2026'!$C$10:$I$13,6,0) -> #N/A
A6: 901362 | B6: LOWER CORE OF JG REPS HOUSING MOLD - ECN CHANGE(LC - NEW MAKE) / Nhân bên dưới của khuôn JG Reps Housing | C6: 202503 | D6: 1 | E6: 135000000 | F6: 1 | G6: 135000000 | K6: 1 | L6: 135000000 | M6: =VLOOKUP(A6,'Balance at 30.Apr.2026'!$C$10:$L$54,9,0) -> 0 | O6: =VLOOKUP(A6,'Balance at 30.Apr.2026'!$C$10:$C$13,1,0) -> 901362 | P6: =VLOOKUP(A6,'Balance at 30.Apr.2026'!$C$10:$I$13,6,0) -> 1
A7: 901364 | B7: Mold Die casting LT2 Housing, 1 CAV (Full set)/Khuôn đúc LT2 Housing #1 | C7: 202505 | D7: 1 | E7: 452000000 | F7: 1 | G7: 452000000 | K7: 1 | L7: 452000000 | M7: =VLOOKUP(A7,'Balance at 30.Apr.2026'!$C$10:$L$54,9,0) -> 0 | O7: =VLOOKUP(A7,'Balance at 30.Apr.2026'!$C$10:$C$13,1,0) -> 901364 | P7: =VLOOKUP(A7,'Balance at 30.Apr.2026'!$C$10:$I$13,6,0) -> 1
A8: 901365 | B8: Mold Die casting US cover 2 CAV (Full set)/Khuôn đúc US Cover #1 | C8: 202505 | D8: 1 | E8: 480000000 | F8: 1 | G8: 480000000 | K8: 1 | L8: 480000000 | M8: =VLOOKUP(A8,'Balance at 30.Apr.2026'!$C$10:$L$54,9,0) -> 0 | O8: =VLOOKUP(A8,'Balance at 30.Apr.2026'!$C$10:$C$13,1,0) -> 901365 | P8: =VLOOKUP(A8,'Balance at 30.Apr.2026'!$C$10:$I$13,6,0) -> 1
A9: 901369 | B9: RWS COVER - ECN CHANGE (LC - NEW MAKE) | C9: 202505 | D9: 1 | E9: 74000000 | F9: 1 | G9: 74000000 | K9: 1 | L9: 74000000 | M9: =VLOOKUP(A9,'Balance at 30.Apr.2026'!$C$10:$L$54,9,0) -> 0 | O9: =VLOOKUP(A9,'Balance at 30.Apr.2026'!$C$10:$C$13,1,0) -> 901369 | P9: =VLOOKUP(A9,'Balance at 30.Apr.2026'!$C$10:$I$13,6,0) -> 1
A10: 901373 | B10: Mold Die casting MQ4aPE Housing 1 CAV (Full set) #12 | C10: 202511 | D10: 1 | E10: 450000000 | F10: 1 | G10: 450000000 | K10: 1 | L10: 450000000 | M10: =VLOOKUP(A10,'Balance at 30.Apr.2026'!$C$10:$L$54,9,0) -> 0 | O10: =VLOOKUP(A10,'Balance at 30.Apr.2026'!$C$10:$C$13,1,0) -> #N/A | P10: =VLOOKUP(A10,'Balance at 30.Apr.2026'!$C$10:$I$13,6,0) -> #N/A
A11: 901422 | B11: US4 RHD Cover - MCT Jig - Ver 02 | C11: 202512 | D11: 1 | E11: 24000000 | F11: 1 | G11: 24000000 | K11: 1 | L11: 24000000 | M11: =VLOOKUP(A11,'Balance at 30.Apr.2026'!$C$10:$L$54,9,0) -> 0 | O11: =VLOOKUP(A11,'Balance at 30.Apr.2026'!$C$10:$C$13,1,0) -> #N/A | P11: =VLOOKUP(A11,'Balance at 30.Apr.2026'!$C$10:$I$13,6,0) -> #N/A
A12: 901425 | B12: JG REPS LHD Cover - MCT Jig - Ver 02 | C12: 202512 | D12: 1 | E12: 22800000 | F12: 1 | G12: 22800000 | K12: 1 | L12: 22800000 | M12: =VLOOKUP(A12,'Balance at 30.Apr.2026'!$C$10:$L$54,9,0) -> 0 | O12: =VLOOKUP(A12,'Balance at 30.Apr.2026'!$C$10:$C$13,1,0) -> #N/A | P12: =VLOOKUP(A12,'Balance at 30.Apr.2026'!$C$10:$I$13,6,0) -> #N/A
A13: 901426 | B13: JG RWS Cover - MCT Jig -Ver 02 | C13: 202512 | D13: 1 | E13: 22800000 | F13: 1 | G13: 22800000 | K13: 1 | L13: 22800000 | M13: =VLOOKUP(A13,'Balance at 30.Apr.2026'!$C$10:$L$54,9,0) -> 0 | O13: =VLOOKUP(A13,'Balance at 30.Apr.2026'!$C$10:$C$13,1,0) -> #N/A | P13: =VLOOKUP(A13,'Balance at 30.Apr.2026'!$C$10:$I$13,6,0) -> #N/A
A14: 901427 | B14: JG REPS LHD_MARKING JIG | C14: 202601 | D14: 1 | E14: 570000 | F14: 1 | G14: 570000 | H14: 202601 | I14: 1 | J14: 570000 | K14: 2 | L14: 1140000 | M14: =VLOOKUP(A14,'Balance at 30.Apr.2026'!$C$10:$L$54,9,0) -> 0 | O14: =VLOOKUP(A14,'Balance at 30.Apr.2026'!$C$10:$C$13,1,0) -> #N/A | P14: =VLOOKUP(A14,'Balance at 30.Apr.2026'!$C$10:$I$13,6,0) -> #N/A
A15: 901408 | B15: NX4 HSG - AIR GAGE HEAD/MASTER | C15: 202509 | D15: 1 | E15: 65721742 | F15: 1 | G15: 65721742 | K15: 1 | L15: 65721742 | M15: =VLOOKUP(A15,'Balance at 30.Apr.2026'!$C$10:$L$54,9,0) -> 0 | O15: =VLOOKUP(A15,'Balance at 30.Apr.2026'!$C$10:$C$13,1,0) -> #N/A | P15: =VLOOKUP(A15,'Balance at 30.Apr.2026'!$C$10:$I$13,6,0) -> #N/A
A16: 901409 | B16: JK1-LHD HSG_New Bore core | C16: 202509 | D16: 1 | E16: 27000000 | F16: 1 | G16: 27000000 | K16: 1 | L16: 27000000 | M16: =VLOOKUP(A16,'Balance at 30.Apr.2026'!$C$10:$L$54,9,0) -> 0 | O16: =VLOOKUP(A16,'Balance at 30.Apr.2026'!$C$10:$C$13,1,0) -> #N/A | P16: =VLOOKUP(A16,'Balance at 30.Apr.2026'!$C$10:$I$13,6,0) -> #N/A
A17: 901030 | B17: 50-40356-2_DISPLAY COVER, PLASTIC, MTP KUNO, Linh kiện qualcomm 50-40356-2 | C17: 202508 | D17: 300 | E17: 11856000 | F17: 200 | G17: 7904000 | K17: 200 | L17: 7904000 | M17: =VLOOKUP(A17,'Balance at 30.Apr.2026'!$C$10:$L$54,9,0) -> 0 | O17: =VLOOKUP(A17,'Balance at 30.Apr.2026'!$C$10:$C$13,1,0) -> #N/A | P17: =VLOOKUP(A17,'Balance at 30.Apr.2026'!$C$10:$I$13,6,0) -> #N/A
A18: 901405 | B18: LT2 HSG - MCT Jig (new vesion) | C18: 202508 | D18: 1 | E18: 28000000 | F18: 1 | G18: 28000000 | K18: 1 | L18: 28000000 | M18: =VLOOKUP(A18,'Balance at 30.Apr.2026'!$C$10:$L$54,9,0) -> 0 | O18: =VLOOKUP(A18,'Balance at 30.Apr.2026'!$C$10:$C$13,1,0) -> #N/A | P18: =VLOOKUP(A18,'Balance at 30.Apr.2026'!$C$10:$I$13,6,0) -> #N/A
A19: 900196 | B19: Battery door #1 (50-PE623-1), Linh kiện Qualcom 50-PE623-1 | F19: 1 | G19: 3.40275e+08 | K19: 1 | L19: 3.40275e+08 | M19: =VLOOKUP(A19,'Balance at 30.Apr.2026'!$C$10:$L$54,9,0) -> #N/A
A20: 900198 | B20: DOOR #1 (50-PE401-1), Linh kiện Qualcom 50-PE401-1 | F20: 1 | G20: 3.40275e+08 | K20: 1 | L20: 3.40275e+08 | M20: =VLOOKUP(A20,'Balance at 30.Apr.2026'!$C$10:$L$54,9,0) -> #N/A
A21: 900205 | B21: Rear - Housing, Linh kiện Qualcom Rear Housing | F21: 1 | G21: 399000000 | K21: 1 | L21: 399000000 | M21: =VLOOKUP(A21,'Balance at 30.Apr.2026'!$C$10:$L$54,9,0) -> #N/A
A22: 901015 | B22: 50-43615-1_BackPlane Stiffener_ADP Arnage (4.0) | H22: 202601 | I22: 200 | J22: 136468392 | K22: 74 | L22: 50493305 | M22: =VLOOKUP(A22,'Balance at 30.Apr.2026'!$C$10:$L$54,9,0) -> 0
A23: 901049 | B23: QRANIUM CARRIER, ADP RIDE ARNAGE (4.0) | H23: 202601 | I23: 200 | J23: 152827712 | K23: 73 | L23: 55782115 | M23: =VLOOKUP(A23,'Balance at 30.Apr.2026'!$C$10:$L$54,9,0) -> 0
A24: 901439 | B24: US4 RHD_MARKING JIG | H24: 202601 | I24: 2 | J24: 1140000 | K24: 2 | L24: 1140000 | M24: =VLOOKUP(A24,'Balance at 30.Apr.2026'!$C$10:$L$54,9,0) -> 0
A25: 901440 | B25: JG RWS_MARKING JIG | H25: 202601 | I25: 2 | J25: 1260000 | K25: 2 | L25: 1260000 | M25: =VLOOKUP(A25,'Balance at 30.Apr.2026'!$C$10:$L$54,9,0) -> 0
A26: 901410 | B26: Mold Die Casting CL4 HOUSING #18 | H26: 202602 | I26: 1 | J26: 450000000 | K26: 1 | L26: 450000000 | M26: =VLOOKUP(A26,'Balance at 30.Apr.2026'!$C$10:$L$54,9,0) -> 0
A27: 901445 | B27: T1XX_HOUSING_MCT_JIG_OP10 | H27: 202602 | I27: 1 | J27: 17900000 | K27: 1 | L27: 17900000 | M27: =VLOOKUP(A27,'Balance at 30.Apr.2026'!$C$10:$L$54,9,0) -> 0
A28: 901448 | B28: T1XX-2 Housing - CMM Jig | H28: 202602 | I28: 2 | J28: 11800000 | K28: 2 | L28: 11800000 | M28: =VLOOKUP(A28,'Balance at 30.Apr.2026'!$C$10:$L$54,9,0) -> 0
A29: 901449 | B29: T1XX-2 Bearing Plate - CMM Jig | H29: 202602 | I29: 2 | J29: 12800000 | K29: 2 | L29: 12800000 | M29: =VLOOKUP(A29,'Balance at 30.Apr.2026'!$C$10:$L$54,9,0) -> 0
A30: 901451 | B30: T1XX-2 Bearing Plate - MCT Jig | H30: 202602 | I30: 1 | J30: 36000000 | K30: 1 | L30: 36000000 | M30: =VLOOKUP(A30,'Balance at 30.Apr.2026'!$C$10:$L$54,9,0) -> 0
A31: 901452 | B31: T1XX Housing - Cutting Jig | H31: 202602 | I31: 1 | J31: 1420000 | K31: 1 | L31: 1420000 | M31: =VLOOKUP(A31,'Balance at 30.Apr.2026'!$C$10:$L$54,9,0) -> 0
A32: 901458 | B32: O-ring for Battery Pack Rear-to-Front Cable (P/N: 143-8808-001-A03) | H32: 202602 | I32: 400 | J32: 4998000 | K32: 175 | L32: 2186625 | M32: =VLOOKUP(A32,'Balance at 30.Apr.2026'!$C$10:$L$54,9,0) -> 0
A33: 901459 | B33: Oring for BATTERY PACK, TOP LID (P/N: 143-6225-001-A04) | H33: 202602 | I33: 400 | J33: 4998000 | K33: 175 | L33: 2186625 | M33: =VLOOKUP(A33,'Balance at 30.Apr.2026'!$C$10:$L$54,9,0) -> 0
A34: 901411 | B34: Mold Die Casting CL4 HOUSING #19 | H34: 202603 | I34: 1 | J34: 450000000 | K34: 1 | L34: 450000000
A35: 901443 | B35: T1XX-2 BEARING PLATE - Trimming Mold | H35: 202603 | I35: 1 | J35: 60000000 | K35: 1 | L35: 60000000
A36: 901444 | B36: T1XX Housing - VERTICAL RUBBER INNER SUPPORT/FIXTURE JPT230-OP20 | H36: 202603 | I36: 1 | J36: 151612000 | K36: 1 | L36: 151612000
A37: 901450 | B37: T1XX-2 Bearing Plate - Turning Jig | H37: 202603 | I37: 1 | J37: 9700000 | K37: 1 | L37: 9700000
A38: 901453 | B38: LT2 HOUSING - Upper core | H38: 202603 | I38: 1 | J38: 99000000 | K38: 1 | L38: 99000000
A39: 901454 | B39: LT2 HOUSING - Bore core | H39: 202603 | I39: 1 | J39: 37000000 | K39: 1 | L39: 37000000
A40: 901455 | B40: US4 COVER - Lower core | H40: 202603 | I40: 1 | J40: 94000000 | K40: 1 | L40: 94000000
A41: 901456 | B41: US4 COVER - New Lower core pin | H41: 202603 | I41: 1 | J41: 5000000 | K41: 1 | L41: 5000000
...
