Workbook
Name _1: #N/A
Name _3: #N/A
Name _4: #N/A
Name _DAT1: [1]Sheet1!#REF!
Name _DAT13: [1]Sheet1!#REF!
Name _DAT16: [1]Sheet1!#REF!
Name _DAT17: [1]Sheet1!#REF!
Name _DAT18: [1]Sheet1!#REF!
Name _DAT19: [1]Sheet1!#REF!
Name _DAT20: [1]Sheet1!#REF!
Name _DAT3: [1]Sheet1!#REF!
Name _DAT9: [1]Sheet1!#REF!
Name Assessment_Types: #REF!
Name Calqty: #REF!
Name Choices: [5]Sheet7!$A$19:$A$20
Name code: #REF!
Name CODENO: '[7]BOM LIST 정리'!$D$7:$D$48
Name CONTRACT: #REF!
Name it: [9]!it
Name jan: #REF!
Name lll: [9]!lll
Name MRP: #REF!
Name NORM: [9]!NORM
Name purpose: [10]Notes!$B$4:$B$13
Name qqqq: #REF!
Name qty: #REF!
Name Question_Scores: '[11]Data Summary - Do Not Use'!$E$10:$E$12
Name scores: [5]Sheet7!$A$1:$A$5
Name scores3: [5]Sheet7!$I$1:$I$3
Name SCORES4: [5]Sheet7!$K$1:$K$4
Name scores5: [5]Sheet7!$M$1:$M$2
Name scores6: [5]Sheet7!$A$9:$A$13
Name scores8: [5]Sheet7!$K$9:$K$12
Name sss: [1]Sheet1!#REF!
Name sssss: [9]!sssss
Name table1: [12]Sheet1!$A$1:$A$5
Name table2: [12]Sheet1!$B$1:$B$4
Name TEST1: [1]Sheet1!#REF!
Name U: '[13]BOM LIST 정리'!#REF!
Name VER: [5]Sheet7!$A$23:$A$24
Name WOST: [9]!WOST
Name Y: '[13]BOM LIST 정리'!#REF!
Name 경통1: [9]!경통1
Name 경통2: [9]!경통2
Name ㄴ: #REF!
Name ㄴㄴ: [9]!ㄴㄴ
Name 대표자: [16]기본데이타!$C$6
Name 동화: [1]Sheet1!#REF!
Name ㅁ: [1]Sheet1!#REF!
Name ㅁ1: '[17]매출이익(실적)'!#REF!
Name ㅁ109: #REF!
Name ㅁㅁㅁ: [1]Sheet1!#REF!
Name ㅁㅂ: [1]Sheet1!#REF!
Name 면허번호: [16]기본데이타!$C$9
Name 몰려: #REF!
Name ㅂㅈ: [1]Sheet1!#REF!
Name 부적합유형: #REF!
Name 생산계획: '[19]1월월보'!#REF!
Name 서일: [7]기준정보!$A$4:$B$20
Name 서일ITEM구분: '[7]BOM LIST 정리'!$D$7:$G$146

Sheet Cover.
E13: Supplier name
E14: Major Product
E15: Audit Object
E16: Date of Audit
E17: Auditor
E18: Grade
E19: Result
B22: M&C Electronics Vina

Sheet Result Report
B1: Quality Process Audit Result Report
C3: □ Audit Result
C4: Audit Object | F4: =Cover.!G14 | J4: Grade | M4: =Cover.!G18 | O4: Date of Audit
C5: Major Product | F5: =Cover.!G15 | J5: Auditor | M5: =Cover.!G17 | O5: Auditee
C8: □Scores and Grade by sector
C9: No | D9: evaluation sector | E9: Evaluation requiment | H9: Evaluation result | M9: note
E10: the whole | H10: Result | K10: Degree of Completion
C11: 1 | D11: Material Management | E11: ='Checksheet QPA'!E53 | H11: ='Checksheet QPA'!G10 | K11: =H11/E11*100
C12: 2 | D12: Material Inspection and Preparation | E12: ='Checksheet QPA'!E54 | H12: ='Checksheet QPA'!G16 | K12: =H12/E12*100
C13: 3 | D13: Production Process | E13: ='Checksheet QPA'!E55 | H13: ='Checksheet QPA'!G23 | K13: =H13/E13*100
C14: 4 | D14: Product Evaluation | E14: ='Checksheet QPA'!E56 | H14: ='Checksheet QPA'!G36 | K14: =H14/E14*100
C15: 5 | D15: Packing Management | E15: ='Checksheet QPA'!E57 | H15: ='Checksheet QPA'!G45 | K15: =H15/E15*100
C16: Evaluation Score/Grade | E16: =SUM(H11:J15) | H16: =IF(E16>=90,"A",IF(E16>=80,"B",IF(E16>=70,"C",IF(E16>=60,"D","E")))) | K16: =IF(H16="A","Very Good",IF(H16="B"," Good",IF(H16="C","Need Improvement",IF(H16="D","Unsatisfactory","Unsatisfactory"))))
C18: □ Improvement object Status by type
C19: Classification | E19: Number of Cases
C20: Material Management
C21: Material Inspection and Preparation
C22: Production Process
C23: Product Evaluation
C24: Packing Management
C25: Total

Sheet Non-Conforming Item
B2: Quality Process Audit Non-Conforming Item
M5: 해결
M6: 미결
B8: Classification | C8: NO | D8: Problem | F8: Countermeasure for Improvement | J8: Confirmation Result | M8: Completion Status | N8: Reproducibility status
D9: Pointed-out Item | E9: Phenomenon | F9: Improvement Plan | G9: Pictrue | H9: Person in charge | I9: Schedule | J9: Confirmed content | K9: Schedule | L9: person in charge

Sheet Checksheet QPA
C1: VENDOR QUALIFICATION CHECKSHEET | F1: 양식 코드/양식 번호 | H1: PUR.04.01.07
F2: Effective Date/ 시행일 | H2: 43466
C3: o 1차 평가/최초로 평가 | E3: 재평가/다시 평가 | F3: Page/ 합계 trang | H3: 06
A4: 공급업체 코드/ 공급업체 코드(ERP) | C4: 공급업체 이름/공급업체 이름 | E4: Address/ 주소 | F4: 제공되는 제품 유형/제공되는 제품 유형:
F5: þ 원자재/ 원자재 메인 o 부재료/ 보조재료 | H5: o 아웃소싱 자재/ 아웃소싱 소스로부터 원자재
A6: P.I.C/담당자 | C6: Job title/ 직위 | D6: Department/ 팀 ban | E6: Email | F6: Phone No.
A9: CONTENT OF EVALUATION
A10: Section 1 - Warehouse for Materials | E10: Sub total (Score) | F10: =SUM(F13:F15) | G10: =SUM(G13:G15) | H10: COMMENT
E11: Achievement rate | F11: =F10/100 | G11: =G10/100
A12: Question Number | B12: Element | C12: Requirement | D12: VNM | E12: Rating Criteria | F12: Score | G12: Result
A13: 1 | B13: Standard | C13: Is the material storage standard established, and are the warehoused materials structuralized for first-in/first-out, and is there management tools? | D13: 자재보관기준이 확립되어 있는지, 선입선출 기준이 있는지, 관리 이력이 있는지? | E13: Score 1: No standard for first-in/first-out, and materials in need of first-in/first-out are not managed. Score 2 : There is no management standard for first-in/first-out, but first-in/first-out is available for materias in need of it, or only the first-in/first-out management standard is retained. Score 3: There is first-in/first-out management standard, but required is partial improvement of the management object, or a state of management. Score 4 : The first-in/first-out management standard is established, and first-in, first-out process is in progress according to the management standard. | F13: 4
A14: 2 | B14: Environment | C14: 3.1 Are the material storing requirements defined? 3.2 Are the environmental temperature, humidity controlled? 3.3 Are the storing space well ventilated? 3.4 Are the risk of ignition prevented in the storing area? 3.5 Are all the materials be sealed? 3.6 Are fire extinguishers, sands be prepared in the storing area? 3.7 Are the leakage prevent solution be taken? 3.8 Are explosion-proof lamps, switches used in the storing area? | D14: 3.1 자재 보관 요구 사항이 식별되어 있습니까? 3.2 환경의 온도와 습도가 통제됩니까? 3.3 보관공간은 통풍이 잘 되나요? 3.4 보관 장소에서는 발화 위험이 방지되어 있습니까? 3.5 모든 재료는 밀봉되어 있습니까? 3.6 보관 장소에 소화기 및 모래가 준비되어 있습니까? 3.7 누출을 방지하는 솔루션인가요? 3.8 보관 장소에 사용되는 방폭 조명 및 스위치는 무엇입니까? | E14: Score 1: : The environmental condition is not defined, nor is the temperature/humidity managed. Score 2: : Although the environmental condition is not defiend, temperature/humdity is managed, or the environmental condition for materials storage is established. Score 3: : The environmental condition is established, but a state of management needs to be improved. Score 4: : The environmental condition is established, and it is managed according to the established standard. | F14: 4
A15: 3 | B15: Layout | C15: Are the products classified by item in time of materials storage, and is there an identification mark for materials? | D15: 자재는 보관시 품목별로 분류되어 있으며, 자재에 대한 식별 표시가 있나요? | E15: Score 1: There is no standard for identification of the stored materials, and it's difficult to identify the materials in storage. Score 2 : Though there is no standard for identification of the materials in storage, the materials in storage are identified, or there is only the standard of identification management of the stored materials. Score 3: There is the identification standard of the materials in storage, but partial improvement is required. (difficulty in identifying some materials, etc.) Score 4: There is the identification standard of the materials in storage, and materials are identified according to the standard. | F15: 4
A16: Section 2- Material Inspection and Preparation | E16: Sub total (Score) | F16: =SUM(F19:F22) | G16: =SUM(G19:G22) | H16: COMMENT
E17: Achievement rate | F17: =15/100 | G17: =G16/100
A18: Question Number | B18: Element | C18: Question / Requirement | D18: VNM | E18: Rating Criteria | F18: Score | G18: Result
A19: 1 | B19: Material Inspection (WH) | C19: Are below critical quality control points of the material inspected in incoming? - Part Number and Lot Number - Maker/ Provider - Status of product - Packing condition - Quantity / Weight - Expiry Date | D19: 입고 시 원자재의 다음과 같은 중요한 품질 관리 사항이 평가됩니까? - 제품코드 및 로트번호 - 제조자/공급자 -제품의 상태 - 포장 사양 - 수량 / 중량 - 날짜가 만료되었습니다 | E19: Score 1 - More than 3 critical control point missed to be inspected in incoming. Score 2 - Some critical control points are inspected, but 2~3 critical control points missed. Score 3 - Some critical control points are inspected, but one critical control points missed. Score 4 - All critical control points are inspected in incoming | F19: 4
A20: 2 | B20: Material Inspection (IQC) | C20: Are below critical quality control points of material inspected ? - Spec - Appearance no damage, scratch, missing line, contamination, break line, etc. | D20: 재료의 중요한 품질 관리 지점이 검사됩니까? - 기술 사양 및 제품 품질 - 외관 : 파손, 긁힘, 줄빠짐, 오염, 파선 등이 없습니다. | E20: Score 1 - More than 3 critical control point missed to be inspected Score 2 - Some critical control points are inspected, but 2~3 critical control points missed. Score 3 - Some critical control points are inspected, but one critical control points missed. Score 4 - All critical control points are inspected | F20: 4
A21: 3 | B21: Material Inspection (IQC) | C21: - Does the supplier have a precision testing process and devices that measure the accuracy of the product? - Are the methods below are use? a. X-ray, b. Optic measurement c. Overlay | D21: - 협력업체/공급업체는 제품 정확도 측정을 위한 정확도 테스트 프로세스와 장비를 보유하고 있는가? - 테스트에는 어떤 장비가 적용되나요? 가. 엑스레이 기계, b. 광학 적용 범위 측정기 c. 오버레이 | E21: Score 1. Do not meet requirement 1.1. Score 2. Meet requirement 1.1. Only use of c. Score 3. Meet requirement 1.1. Use of a or b. Score 4. Meet all requirements. | F21: 4
A22: 4 | B22: Pot Life Control for Partially Used Material | C22: - Is there a pot life control process for partially used material, one times material ? - Is there expiration date/time of the partially used material marked? - Are all these partially used materials used before the expiration date/time? | D22: - 부분적으로 또는 여러 번 사용되는 소재에 대해 유통기한을 관리하는 프로세스가 있나요? - 부분적으로 사용된 재료의 사용기한/시간이 표시되어 있나요? - 부분적으로 사용된 재료는 모두 유효기간/시간 이전에 사용되었나요? | E22: Score 1- Do not meet requirement 4.1 Score 2 - Meet requirement 4.1, but found multiple cases do not meet requirement 4.2 and/or 4.3 and/or 4.4. Score 3 - Meet requirement 4.1, but found isolated case do not meet requirement 4.2 and/or 4.3 and/or 4.4. Score 4 - Meet all requirements | F22: 4
A23: Section 3- Production Process | E23: Sub total (Score) | F23: =SUM(F26:F35) | G23: =SUM(G26:G35) | H23: COMMENT
E24: Achievement rate | F24: =F23/100 | G24: =G23/100
A25: Question Number | B25: Element | C25: Question / Requirement | E25: Rating Criteria | F25: Score | G25: Result
A26: 1 | B26: Requirements Communicate to Tooling Sub-Supplier | C26: 1.1 Is there a process of communicating the requirements to tooling sub-suppliers in place? 1.2 Are all critical requirements communicated to tooling sub-supplier? Notes: Critical requirements may include but not limited to: product drawing, product cosmetic requirements, tooling type (flatbed tooling or rotatory tooling), tooling life, delivery schedule, tooling verification requirements, etc. | D26: 1.1 하위 공급업체에 대한 관리 프로세스가 있습니까? 1.2 모든 주요 금형 요구 사항이 공급업체에 전달됩니까? 주의 사항: 중요한 요구 사항에는 제품 도면, 제품 외관 요구 사항, 도구 유형(플랫 도구 또는 회전 도구), 도구 수명, 배송 일정, 도구 검증 요구 사항 등이 포함되지만 이에 국한되지는 않습니다. | E26: Score 1- Do not meet requirement 1.1. Score 2 - Meet requirement 1.1. But multiple cases do not meet requirement 1.2. Score 3 - Meet requirement 1.1. But isolated case do not meet requirement 1.2. Score 4 - Meet all requirements N/A - If supplier do not develop the tooling outsourcing. | F26: 4
A27: 2 | B27: DFM Review | C27: If DFM is required by customer: 2.1 Is there a process to review the tooling DFM from tooling sub-supplier? 2.2 Are the tooling DFMs actually reviewed and approved by supplier (who purchase the tooling and use it for production)? 2.3 Are the tooling DFMs submitted to and approved by customer? 2.4 Does the DFM cover all the critical characteristics of product? | D27: 고객이 DFM을 요청한 경우: 2.1 도구 하위 공급업체의 도구 DFM을 검토하는 프로세스가 있습니까? 2.2 툴링 DFM은 실제로 공급업체(툴링을 구매하고 생산에 사용하는 사람)가 검토하고 승인합니까? 2.3 고객이 툴링 DFM을 제출하고 승인했습니까? 2.4 DFM에는 중요한 제품 특성이 모두 포함되어 있습니까? | E27: Score 21- Meet requirement 2.1. But do not meet requirement 2.2 and/or 2.3. Score 2- Meet requirements 2.1, 2.2 and 2.3. But do not meet requirement 2.4. Score 3 - Meet all requirements N/A - If supplier do not develop the tooling outsourcing, or DFM is not required by customer. | F27: 4
A28: 3 | B28: Tooling Verification | C28: 3.1 Is there a process to verify the tooling before deliver the tooling from sub tooling supplier to production? 3.2 Are the tooling verification actually implemented and the verification results meet the requirements before tooling release? Remark: a). Tooling verification requirements may include but not limited to: trial run test, FAIR, Cpk, product appearance review, etc. Depends on customer requirements and internal requirements. b). 1 tooling count as 1 case. | D28: 3.1 금형을 2차 금형 공급업체에서 생산으로 옮기기 전에 금형 검증 프로세스가 있나요? 3.2 실제로 금형 검증이 이루어지고 검증 결과가 금형 이형 전 요구사항을 만족하는가? 비고: 가). 금형 검증 요구 사항에는 시운전 테스트, FAIR, Cpk, 제품 외관 평가 등이 포함될 수 있지만 이에 국한되지는 않습니다. 고객 요구 사항 및 내부 요구 사항에 따라 다릅니다. 비). 금형 1개가 1건으로 계산됩니다. " | E28: Score 1 - Do not meet requirement 3.1. Score 2 - Meet requirement 3.1. But find multiple cases do not meet requirement 3.2. Score 3 - Meet requirement 3.1. But find isolated case do not meet requirement 3.2. Score 4 - Meet all requirements. N/A - If supplier do not develop the tooling outsourcing. | F28: 4
A29: 4 | B29: Quality Inspection for Material | C29: Are below critical quality control points of electrical characteristics inspected in incoming? Notes: Critical quality control points should include below, but may not limited to 1.1 Is the Characteristics, as per material spec? - Particle size - Particle shape. -Particle quantity. 1.2 Is the Powder Ceramic 'stored' in correct temperature as per material spec? | D29: 도착 시 품질 관리 포인트는 다음과 같습니다. 주의 사항: 중요 품질 관리 사항에는 다음 사항이 포함되어야 하지만 이에 국한되지는 않습니다. 1.1 재료 매개변수에 따른 특성은 무엇입니까? - 입자 크기 - 곡물 모양. -수량 씨앗. 1.2 알루미늄 분말은 재료 사양에 따라 올바른 온도에서 '보관'됩니까? " | E29: Score 1- More than 3 critical control point missed to be inspected in incoming. Score 2 - Some critical control points are inspected, but 2~3 critical control points missed. Score 3 - Some critical control points are inspected, but one critical control points missed. Score 4 - All critical control points are inspected in incoming. | F29: 4
A30: 5 | B30: Mixing Process | C30: 2.1 Is there a documented process parameters for the Mixing process? 2.2 Is there process parameters include for quantity used and specified time used? 2.3 Is there objective documents of the verification on the actual process against process parameters? 2.4 Is the mixing process time controlled as per spec? | D30: 2.1 혼합 공정에 대해 문서화된 공정 매개변수가 있습니까? 2.2 사용량, 사용시간 등 공정변수가 명시되어 있는가? 2.3 공정 매개변수의 실제 공정 검증에 대한 객관적인 문서가 있습니까? 2.4 혼합 공정 시간은 사양에 따라 제어됩니까? " | E30: Score 1 - Did not meet requirement 2.1 Score 2 - Meet requirement 3.1, but did not meet requirement 2.2 and/or 2.3 Score 3 - Meet requirement 2.1,2.2, and 2.3 but did not meet requirement 2.4. Score 4 - Meet all requirements | F30: 4
A31: 6 | B31: Slip Casting Process | C31: 5.1 Is there a documented process parameters for the slip casting process? 5.2 Is there process parameters include for thickens checks and appearance 5.3 Is there objective documents of the verification on the actual process against process parameters? 5.4 Is the "glass plate" (tools) cleaned prior to the process? | D31: 3.1 슬립 캐스팅 공정에 대해 문서화된 공정 매개변수가 있습니까? 3.2 두께, 외관 검사를 포함한 공정 변수가 있습니다. 3.3 프로세스 매개변수의 실제 프로세스 검증에 대한 객관적인 문서가 있습니까? 3.4 가공 전에 "금형"(도구)을 청소합니까? | E31: Score 1 - Did not meet requirement 5.1 Score 2 - Meet requirement 5.1, but did not meet requirement 5.2 and/or 5.3 Score 3 - Meet requirement 5.1, 5.2 and 5.3, but did not meet requirement 5.4. Score 4 - Meet all requirements | F31: 4
A32: 7 | B32: Material Melting | C32: 3.1 Are material melting requirements defined? 3.2 Are the defined material melting requirements actually followed? Remark: The material melting requirements may include but not limited to: the furnace type selection, the furnace cleaning/drying, the furnace pre-heating temperature, material pre-heating/drying, melting temperature control, frequency to remove the slugs from the melting furnace, etc. | D32: 5.1 재료 용해 요건이 결정되어 있습니까? 5.2 확인된 재료 용해 요건을 실제로 준수하고 있습니까? 주의 사항: 재료 용융 요구 사항에는 로 유형 선택, 로 청소/건조, 로 예열 온도, 재료 예열/건조, 용융 온도 제어, 로 용융에서 슬러그 제거 빈도 등이 포함되지만 이에 국한되지는 않습니다. | E32: Score 01- Do not meet requirement 4.1. Score 2 - Meet requirement 4.1, but find multiple cases do not meet requirement 4.2. Score 3 - Meet requirement 4.1, but find isolated cases do not meet requirement 4.2. Score 4 - Meet all requirements. | F32: 4
A33: 8 | B33: Key Process Parameter Control for Die Cutting Process | C33: Are below key process parameters controlled in the die cutting process? - Shut height or cutting pressure - Speed - Material feeding distance | D33: "다이 커팅 중에 제어되는 주요 공정 매개변수는 다음과 같습니다. - 가까운 절단 높이 또는 압력 - 속도 -창고에서 재료를 기계에 넣는 방법" | E33: Score 0 - No any of the listed key process parameter is controlled. Score 1 - Some listed key process parameters are controlled, but missed any 2 of the listed key parameters. Score 2 - Some listed key process parameters are controlled, but missed any 1 of the listed key parameters. Score 3 - All the listed key process parameters are controlled. | F33: 4
A34: 9 | B34: Scrap Removing | C34: 6.1 Are the scrap removing methods defined in the process documents (i.e. WI, SOP, etc.). 6.2 Are all scrap materials be completely removed after die-cutting? | D34: 7.1 스크랩 처리 방법은 프로세스 문서(예: WI, SOP 등)에 식별되어 있습니다. 7.2 절단 후 모든 스크랩 재료가 완전히 제거됩니까? " | E34: Score 1 - Do not meet requirement 6.1. Score 2 - Meet requirement 6.1. But find multiple cases do not meet requirement 6.2. Score 3 - Meet requirement 6.1. But find isolated case do not meet requirement 6.2. Score 4 - Meet all requirements. | F34: 4
A35: 10 | B35: Quality Inspection for Product | C35: Are below critical quality control points of product inspected after die cutting? - Product structure: no missing any cutting or feature forming, no overcut of the release liner. - no damage, scratch, contamination, etc. - Dimension check. | D35: 다이컷팅 후 검사한 제품의 품질관리기준점 이하입니까? - 제품 구조 : 절단이나 성형 기능이 누락되지 않고 이형 라이너가 과도하게 절단되지 않습니다. - 파손, 긁힘, 오염 등이 없습니다. - 검사 크기. " | E35: Score 01- No any of the listed critical control point is inspected after die cutting. Score 2- Some critical control points are inspected, but missed any 2 of the listed critical control points. Score 3 - Some critical control points are inspected, but missed any 1 of the listed critical control points. Score 4 - All the listed critical control points are inspected after die cutting. | F35: 4
A36: Section 4- Product Evaluation (OQC) | E36: Sub total (Score) | F36: =SUM(F38:F44) | G36: =SUM(G38:G44) | H36: COMMENT
A37: Question Number | B37: Element | C37: Question / Requirement | E37: Achievement rate | F37: =F36/100 | G37: =G36/100
A38: 1 | B38: Training | C38: Did an auditor receive an education about the measuring method, auditing method, and equipment use method , and get certified? | D38: 검사자는 측정 방법, 시험 방법, 장비 사용 방법에 대한 교육을 받고 인증을 받았습니까? | E38: Score 0: There is no auditor certiification standard, and an auditor has not been certified. Score 1: Though there is no auditor certification standard, the auditor certification has been invested, or the auditor certification standard is retained. Score 2: Though there is an auditor certification standard, the auditor certification system, identification management, and cyclic education management, etc are required to be partly improved. Score 3- There is the auditor certification standard, and certification evaluation/ identification management/ cyclic education, etc. are normally implemented. | F38: 4
A39: 2 | B39: Standard | C39: Are the audit standard and drawings are kept, and does the standard coincide with the products which are under auditing? | D39: 검사 기준이 적절하고 제품 검사 구역에 게시되어 있습니까? | E39: Score 0: There are no audit standard management criteria, and an audit is done under an auditor's self-judgment without the audit standard and drawings. Score 1:Though the related standard is not available, an audit is performed according to the audit standard suited for products , or the criteria for the audit standard management are retained. Score 2: The audit standard is prepared and applied according to audit standard criteria, but audit items/method are required to be partly improved. Score 3: An audit is performed based on the audit standard prepared according to the audit standard management critera. | F39: 4
A40: 3 | B40: Layout | C40: Are the products/pre/post shipment inspection, and the storage place for rejected products under separately classified management, and marked? of pre/post audit for products is clearly handled. | D40: 검사구역은 검사대기품, NG품, OK품으로 구분되나요? | E40: Score 0: There is no separate storage place, and products are stored in a state without distinction of pre/post audit. Score 1: Though there is no separate storage place for products, they are stored under classified management, or only the separate storage place is designated. Score 2: Products are kept in a separate storage place under classified management, but there are some products without distinction of pre/post audit. Score 3: Products are kept in a separate storage place under classified management, and distintion of pre/post audit for products is clearly handled. | F40: 4
A41: 4 | B41: Measuring equipmen | C41: Is the measuring equipment controlled and calibrated? | D41: 측정 장비가 관리되고 교정됩니까? | E41: Score 0 : There is no measuring instrument selection standard, and the accuracy of a measuring instrument is not compatible with the allowance of actual measurement items (ex. standard: xx.xx, measuring equipment: xx.x) Score 1 : There is the measuring instrument selection standard, or a measuring instrument in use is suitable for allowance measurement of actual products despite the absence of the standard. Score 2: There is the measuring instrument selection standard, but there exists a measuring instrument which is not selected according to the standard, or partial improvements are required, such as converiience of measurement, etc. Score 3: There is the the measuring instrument selection standard, and the accuracy of the measuring instrument in use is suited for measurement item allowance. (ex. standard: xx.xx, measuring equipment: xx.xx abnormal) | F41: 4
A42: 5 | B42: Follow customer | C42: Is the unacceptable item arising from a customer reflected in the management point of the audit process? | D42: 고객불만 처리 프로세스가 있나요? | E42: Score 0: There is no system for revison by reflecting unacceptable item in the audit standard, and it is not reflected as the audit item. Score 1: Although there is no audit standard reflection system, it is reflected through the revision and addition of the audit item, or the system reflecting it in the audit standard is established. Score 2: Established is the system reflecting it in the audit item according to the countermeasures against an unacceptable item, but there are some cases of omissions, or partial improvement are required. Score 3: Etablished is the system reflecting it in the audit standard according to an unacceptable item, and actually such an unacceptable item is reflected in the audit standard. | F42: 4
...
