Workbook

Sheet 00_요약
B2: 고속가공기 견적 비교 평가 보고서
B3: M&C Electronics VINA — 설비구매계획 4차 (2026.04)
B4: 대상: Roeders RXP500 / RXP400, Makino V33i, Komatech KT420A
B5: 작성일: 2026-04-25 | 통화기준: USD (환율 EUR1.08 / JPY150 / KRW1440)
B7: ⚠ 객관성 확보를 위한 핵심 사전 인지사항
B8: Komatech KT420A는 24,000rpm BT30 탭핑센터 클래스이며, Roeders(42K~50K rpm HSK)·Makino(20K rpm HSK-A63)와는 정밀도·용도 클래스가 다릅니다. 단순 가격 비교는 부적절하며, "가공 정밀도 요구 수준"을 먼저 정의한 후 동급군 내에서 비교해야 합니다.
B10: 1. 가격 요약 (1대 기준, USD 환산)
B11: 항목 | C11: Roeders RXP500 | D11: Roeders RXP400 | E11: Makino V33i | F11: Komatech KT420A | G11: 비고
B12: 견적가 (원통화) | C12: EUR 249,255 | D12: EUR 229,355 | E12: JPY 34,498,418 | F12: USD 59,500 | G12: 원견적 통화
B13: USD 환산 | C13: =249255*1.08 -> 269195.4 | D13: =229355*1.08 -> 247703.4 | E13: =34498418*0.00666666666666667 -> 229989.45 | F13: =59500 -> 59500 | G13: 환율 적용 (4월 2026 가정)
B14: 클래스 | C14: 고속가공기 (HSK-E40) | D14: 초정밀 (HSK-E32) | E14: 머시닝센터 (HSK-F63, 30K) | F14: 탭핑센터 (BT30) | G14: 용도/정밀도 등급 차이
B15: 최대 스핀들 RPM | C15: 42000 | D15: 50000 | E15: 30000 | F15: 24000 | G15: 높을수록 고속·정밀가공 유리
B16: 납기 (개월) | C16: 6 | D16: 6 | E16: 3.5 | F16: 3 | G16: 짧을수록 유리
B17: 보증 (개월, 기계) | C17: 12 (리니어 60) | D17: 12 (리니어 60) | E17: 12 (FANUC 24) | F17: 12 | G17: 길수록 유리
B19: 2. 종합 평가 점수 (가중치 적용, 100점 만점)
B20: 항목 | C20: RXP500 | D20: RXP400 | E20: V33i | F20: KT420A | G20: 평가 의견
B21: 종합 점수 | C21: ='02_평가매트릭스'!C25 -> 78.5 | D21: ='02_평가매트릭스'!D25 -> 82.05 | E21: ='02_평가매트릭스'!E25 -> 86.8 | F21: ='02_평가매트릭스'!F25 -> 80.75 | G21: 평가매트릭스 시트 자동참조
B22: 순위 | C22: =RANK(C21,$C$21:$F$21) -> 4 | D22: =RANK(D21,$C$21:$F$21) -> 2 | E22: =RANK(E21,$C$21:$F$21) -> 1 | F22: =RANK(F21,$C$21:$F$21) -> 3 | G22: 점수가 높을수록 1위
B24: 3. 권장 의사결정 가이드 (객관적 분류)
B25: 초정밀 가공 (≤±2μm) 필요 | C25: Roeders RXP400 (50,000 RPM, 초정밀 클래스) | F25: 독일 정밀도 + 5년 리니어모터 보증
B26: 정밀+양산 균형 (1순위) | C26: Makino V33i (30K rpm + 60ATC 업그레이드) | F26: DAP Bac Ninh 통관·운송 책임, 검증된 안정성
B27: 중대형 정밀가공 (≤±5μm) | C27: Roeders RXP500 (42,000 RPM, 400kg 워크피스) | F27: 큰 작업영역 + 정밀도 균형
B28: 단순 탭핑/홀가공 양산 (4대 동시) | C28: Komatech KT420A | F28: 저가·단납기, 단 클래스가 다름
B30: 주: 본 평가는 표준 가중치 (가격25/사양25/성능15/납기10/AS10/TCO10/레퍼런스5)를 적용한 결과입니다. 평가매트릭스 시트에서 가중치 변경 시 모든 점수가 자동 재계산됩니다.

Sheet 01_평가방법론
B2: 평가 방법론 및 가중치
B3: 본 평가는 TCO 관점의 다항목 가중치 평가법(Weighted Scoring Method)을 적용합니다.
B5: 평가 카테고리 및 가중치 (총합 100%)
B6: 평가 카테고리 | C6: 가중치(%) | D6: 세부 평가 항목 | E6: 평가 방식 | F6: 점수 산정 | G6: 데이터 출처
B7: 가격·비용 | C7: 0.25 | D7: 본체가, 옵션, 운송·설치, 환율 | E7: 정량 | F7: 최저가=100, 비례환산 | G7: 견적서
B8: 기술 사양 | C8: 0.25 | D8: 스핀들 RPM·토크, 정밀도, 작업영역, 축구성, 제어기 | E8: 정량 | F8: 최고사양=100, 비례환산 | G8: 견적서
B9: 가공 성능 | C9: 0.15 | D9: 가공속도, 표면조도, 소재 적합성 | E9: 정성+데모 | F9: 평가위원 합의점수 | G9: 데모/카탈로그
B10: 납기·공급 | C10: 0.1 | D10: 납기 개월, 설치·시운전 기간 | E10: 정량 | F10: 최단=100, 역비례 | G10: 견적서
B11: A/S·유지보수 | C11: 0.1 | D11: 보증기간, 국내 엔지니어, 부품수급, 응답시간 | E11: 정성 | F11: 평가위원 점수 | G11: 벤더 답변/실적
B12: 운영비 (TCO) | C12: 0.1 | D12: 5년 전력비+유지보수+소모품 | E12: 정량 | F12: 최저TCO=100, 비례환산 | G12: TCO 시뮬레이션
B13: 레퍼런스·신뢰성 | C13: 0.05 | D13: 동종 산업 납품실적, MTBF | E13: 정성 | F13: 평가위원 점수 | G13: 벤더 레퍼런스
B14: 합계 | C14: =SUM(C7:C13) -> 1
B16: 점수 환산 공식 (객관성 확보)
B17: 구분 | C17: 계산 공식
B18: 정량지표 - 낮을수록 좋음 (가격, 납기, TCO) | C18: 점수 = (최저값 / 평가값) × 100
B19: 정량지표 - 높을수록 좋음 (RPM, 정밀도, 작업영역) | C19: 점수 = (평가값 / 최고값) × 100
B20: 정성지표 (A/S, 레퍼런스, 가공성능) | C20: 평가위원 다수 평가 → 평균 (1~100점)
B21: 가중 종합점수 | C21: Σ (카테고리 점수 × 가중치)
B23: Apple-to-Apple 비교를 위한 정규화 원칙
B24: ① 통화: 모두 USD로 환산 (EUR/JPY/KRW → USD)
B25: ② 가격 범위: 모두 동일 Incoterms (CIF Vietnam port) 기준으로 통일
B26: ③ 옵션: 동일 기능 옵션을 동일 카테고리로 분류
B27: ④ 사양: ISO/VDI 동일 기준으로 정밀도 환산
B28: ⑤ 클래스: 동급(고속가공기 vs 탭핑센터)을 별도 그룹으로 비교

Sheet 02_평가매트릭스
B2: 가중치 평가 매트릭스
B3: ※ 노란색 셀(가중치/점수)을 변경하면 종합점수가 자동 재계산됩니다.
B5: 평가 카테고리 | C5: RXP500 | D5: RXP400 | E5: V33i | F5: KT420A | G5: 가중치 | H5: 평가 근거
B6: 가격·비용 (USD환산 비례) | C6: 65 | D6: 72 | E6: 80 | F6: 100 | G6: 0.25 | H6: KT420A 최저, V33i 사양UP로 +
B7: 기술 사양 (RPM/정밀도/영역) | C7: 92 | D7: 95 | E7: 90 | F7: 60 | G7: 0.25 | H7: V33i 30K rpm + 60ATC 업그레이드
B8: 가공 성능 (표면조도/속도) | C8: 90 | D8: 95 | E8: 92 | F8: 65 | G8: 0.15 | H8: V33i 60ATC 양산 효율 향상
B9: 납기 (개월) | C9: 65 | D9: 65 | E9: 85 | F9: 100 | G9: 0.1 | H9: KT420A 3개월 최단
B10: A/S·유지보수 | C10: 70 | D10: 70 | E10: 95 | F10: 85 | G10: 0.1 | H10: V33i DAP Bac Ninh 통관·운송 책임
B11: 운영비 (5년 TCO) | C11: 75 | D11: 78 | E11: 80 | F11: 90 | G11: 0.1 | H11: TCO 시트 참조
B12: 레퍼런스·신뢰성 | C12: 95 | D12: 95 | E12: 90 | F12: 70 | G12: 0.05 | H12: 글로벌 브랜드 평판
B14: 가중치 합계 (100% 검증) | G14: =SUM(G6:G12) -> 1
B16: 가중 점수 (점수 × 가중치)
B17: 가격·비용 (USD환산 비례) | C17: =C6*$G$6 -> 16.25 | D17: =D6*$G$6 -> 18 | E17: =E6*$G$6 -> 20 | F17: =F6*$G$6 -> 25
B18: 기술 사양 (RPM/정밀도/영역) | C18: =C7*$G$7 -> 23 | D18: =D7*$G$7 -> 23.75 | E18: =E7*$G$7 -> 22.5 | F18: =F7*$G$7 -> 15
B19: 가공 성능 (표면조도/속도) | C19: =C8*$G$8 -> 13.5 | D19: =D8*$G$8 -> 14.25 | E19: =E8*$G$8 -> 13.8 | F19: =F8*$G$8 -> 9.75
B20: 납기 (개월) | C20: =C9*$G$9 -> 6.5 | D20: =D9*$G$9 -> 6.5 | E20: =E9*$G$9 -> 8.5 | F20: =F9*$G$9 -> 10
B21: A/S·유지보수 | C21: =C10*$G$10 -> 7 | D21: =D10*$G$10 -> 7 | E21: =E10*$G$10 -> 9.5 | F21: =F10*$G$10 -> 8.5
B22: 운영비 (5년 TCO) | C22: =C11*$G$11 -> 7.5 | D22: =D11*$G$11 -> 7.8 | E22: =E11*$G$11 -> 8 | F22: =F11*$G$11 -> 9
B23: 레퍼런스·신뢰성 | C23: =C12*$G$12 -> 4.75 | D23: =D12*$G$12 -> 4.75 | E23: =E12*$G$12 -> 4.5 | F23: =F12*$G$12 -> 3.5
B25: 종합 점수 (100점 만점) | C25: =SUM(C17:C23) -> 78.5 | D25: =SUM(D17:D23) -> 82.05 | E25: =SUM(E17:E23) -> 86.8 | F25: =SUM(F17:F23) -> 80.75
B26: 순위 | C26: =RANK(C25,$C$25:$F$25) -> 4 | D26: =RANK(D25,$C$25:$F$25) -> 2 | E26: =RANK(E25,$C$25:$F$25) -> 1 | F26: =RANK(F25,$C$25:$F$25) -> 3

Sheet 03_사양비교
B2: 기술 사양 비교표 (Apple-to-Apple)
B3: 4개 설비를 동일 기준으로 정규화한 비교표 (출처: 견적서 본문)
B5: 항목 | C5: Roeders RXP500 | D5: Roeders RXP400 | E5: Makino V33i | F5: Komatech KT420A | G5: 비고
B6: ▣ 기본정보
B7: 제조국 | C7: 독일 (Roeders) | D7: 독일 (Roeders) | E7: 일본/싱가포르 (Makino) | F7: 한국 (Komatech)
B8: 설비 분류 | C8: 3축 정밀 고속가공기 | D8: 3축 정밀 고속가공기 | E8: 수직 머시닝센터 | F8: 수직 탭핑센터 | G8: 클래스 다름
B9: 견적 모델 | C9: RXP500 | D9: RXP400 | E9: V33i (JV-1308) | F9: KT420A
B10: 견적번호 | C10: MA262498 | D10: MA262499 | E10: 1011045204 | F10: KTVTN26D20
B11: 견적일 | C11: 2026-04-24 | D11: 2026-04-24 | E11: 2026-04-06 | F11: 2026-04-20
B12: 견적 유효기간 | C12: 2개월 | D12: 2개월 | E12: 2026-05-06까지 | F12: 1개월
B13: ▣ 작업영역
B14: X축 (mm) | C14: 500 | D14: 410 | E14: 미명시 | F14: 560 | G14: 클수록 유리
B15: Y축 (mm) | C15: 455 | D15: 294 | E15: 미명시 | F15: 420
B16: Z축 (mm) | C16: 240 | D16: 210 | E16: 미명시 | F16: 480
B17: 테이블 크기 (mm) | C17: 550 x 450 | D17: 450 x 300 | E17: 미명시 | F17: 660 x 400
B18: 최대 작업물 무게 (kg) | C18: 400 | D18: 100 | E18: 미명시 | F18: 미명시
B19: ▣ 스핀들
B20: 최대 RPM | C20: 42000 | D20: 50000 | E20: 30000 | F20: 24000 | G20: 높을수록 고속
B21: 스핀들 모델 | C21: FISCHER MFW1224/42 | D21: FISCHER MFW1024/50 | E21: 30,000Min-1 (업그레이드) | F21: 24K rpm
B22: 공구 인터페이스 | C22: HSK-E40 | D22: HSK-E32 | E22: HSK-F63 (업그레이드) | F22: BT30 | G22: 클래스 차이
B23: 출력 (kW S1) | C23: 15 | D23: 6 | E23: 미명시 | F23: 미명시
B24: 최대 토크 (Nm) | C24: 미명시 | D24: 2.4 | E24: 미명시 | F24: 미명시
B25: 최대 공구경 (mm) | C25: 16 | D25: 10 | E25: 미명시 | F25: 미명시
B26: ▣ 정밀도
B27: 스케일 피드백 정밀도 | C27: 리니어 모터/스케일 | D27: 리니어 모터/스케일 | E27: 0.05 µm 스케일 | F27: 미명시
B28: 반복 정밀도 | C28: 리니어 모터 정밀급 | D28: 리니어 모터 정밀급 | E28: 미명시 | F28: ≤ 3 µm
B29: 스핀들 보정 (Spindle Comp.) | C29: 포함 | D29: 포함 | E29: 미포함 | F29: 미포함
B30: ▣ 이송
B31: 최대 이송속도 (mm/min) | C31: 42000 | D31: 42000 | E31: 미명시 | F31: 60000
B32: 급송 X/Y/Z (m/min) | C32: 리니어모터 | D32: 리니어모터 | E32: 미명시 | F32: 60/60/60
B33: 구동 방식 | C33: 리니어 모터 (전축) | D33: 리니어 모터 (전축) | E33: 볼스크류 (추정) | F33: 볼스크류
B34: ▣ 공구매거진
B35: 표준 매거진 용량 | C35: 21 places (HSK-E40) | D35: 18 places (HSK-E32) | E35: 60-Tool (업그레이드) | F35: BT30 / TWIN-ARM 26T
B36: 공구교환시간 T-T (초) | C36: 미명시 | D36: 미명시 | E36: 미명시 | F36: 1.2
B37: 공구교환시간 C-C (초) | C37: 미명시 | D37: 미명시 | E37: 미명시 | F37: 1.8
B38: ▣ 제어기
B39: CNC 제어기 | C39: Roeders RMS6 (자체) | D39: Roeders RMS6 (자체) | E39: FANUC + Super GI .5 | F39: Mitsubishi M80A (10.4")
B40: 주요 기능 | C40: RACECUT, 32kHz drive | D40: RACECUT, 32kHz drive | E40: AC Function, GI Control | F40: 표준 머시닝/탭핑
B41: UPS / Z축 리프트업 | C41: 포함 | D41: 포함 | E41: 미포함 | F41: 미포함
B42: 원격 제어 (Teamviewer) | C42: 포함 | D42: 포함 | E42: 미포함 | F42: 미포함
...

Sheet 04_가격분석
B2: 가격 분석 (환율 시뮬레이션 가능)
B3: ※ 환율(노란색 셀)을 변경하면 모든 USD 환산 금액이 자동 재계산됩니다.
B5: 환율 가정 (수정 가능)
B6: EUR → USD | C6: 1.08 | D6: JPY → USD (1USD =) | E6: 150 | F6: KRW → USD (1USD =) | G6: 1440
B8: 항목 | C8: Roeders RXP500 | D8: Roeders RXP400 | E8: Makino V33i | F8: Komatech KT420A | G8: 단위 | H8: 비고
B9: 원견적 통화 | C9: EUR | D9: EUR | E9: JPY | F9: USD | G9: - | H9: 각사 견적 통화
B10: Total Price (원통화) | C10: 249255 | D10: 229355 | E10: 34498418 | F10: 59500 | G10: 원통화 | H10: CIF/FOB 별도 표기
B11: Incoterms | C11: CIF Vietnam port | D11: CIF Vietnam port | E11: DAP Bac Ninh ★ | F11: FOB Busan | G11: - | H11: Komatech 운송비 별도
B12: USD 환산 (Net) | C12: =C10*$C$6 -> 269195.4 | D12: =D10*$C$6 -> 247703.4 | E12: =E10/$E$6 -> 229989.45 | F12: =F10 -> 59500 | G12: USD | H12: 환율 적용 자동계산
B13: 1대당 USD | C13: =C12 -> 269195.4 | D13: =D12 -> 247703.4 | E13: =E12 -> 229989.45 | F13: =F12 -> 59500 | G13: USD
B14: 상대 가격 지수 (KT420A=100) | C14: =C12/$F$12*100 -> 452.42924 | D14: =D12/$F$12*100 -> 416.30824 | E14: =E12/$F$12*100 -> 386.5369 | F14: =F12/$F$12*100 -> 100 | G14: 지수 | H14: 저가 대비 배수
B15: ₩환산 (1USD=1,440원) | C15: =C12*$G$6 -> 3.8764138e+08 | D15: =D12*$G$6 -> 3.566929e+08 | E15: =E12*$G$6 -> 3.3118481e+08 | F15: =F12*$G$6 -> 85680000 | G15: KRW | H15: 한국법인 비교용
B17: Makino V33i 가격 분해 (참고)
B18: Total List Price (60ATC + 30K rpm) | C18: 42053100 | F18: JPY | G18: USD 280,354
B19: Discount (22.0%) | C19: -9251682 | F19: JPY | G19: USD -61,678
B20: Freight (DAP Bac Ninh) | C20: 1697000 | F20: JPY | G20: USD 11,313
B21: Net Total | C21: 34498418 | F21: JPY | G21: USD 229,989

Sheet 05_TCO_5년
B2: Total Cost of Ownership — 5년 시뮬레이션
B3: 구입가 + 운송·설치 + 5년 (전력+유지보수+소모품) - 잔존가치
B5: TCO 계산 가정
B6: 운영기간 (년) | C6: 5 | D6: 연간 가동시간 (h) | E6: 4000 | F6: 전력단가 (USD/kWh) | G6: 0.1
B8: TCO 항목 | C8: RXP500 | D8: RXP400 | E8: V33i | F8: KT420A | G8: 단위 | H8: 산출 근거
B9: ① 구입가 (USD, 환산) | C9: ='04_가격분석'!C12 -> 269195.4 | D9: ='04_가격분석'!D12 -> 247703.4 | E9: ='04_가격분석'!E12 -> 229989.45 | F9: ='04_가격분석'!F12 -> 59500 | G9: USD | H9: CIF/FOB 환산
B10: ② 운송·설치비 (추정) | C10: 5000 | D10: 5000 | E10: 0 | F10: 5000 | G10: USD | H10: CIF면 0, FOB면 5천 가정
B11: ③ 시운전·교육비 | C11: 0 | D11: 0 | E11: 0 | F11: 0 | G11: USD | H11: 견적가 포함
B12: --- 초기투자 합계 --- | C12: =C9+C10+C11 -> 274195.4 | D12: =D9+D10+D11 -> 252703.4 | E12: =E9+E10+E11 -> 229989.45 | F12: =F9+F10+F11 -> 64500 | G12: USD
B14: 연간 전력 (kVA) | C14: 22 | D14: 10 | E14: 25 | F14: 15 | G14: kVA | H14: 추정 (V33i/KT420A 미명시)
B15: 연간 전력비 (USD/년) | C15: =C14*0.7*$E$6*$G$6 -> 6160 | D15: =D14*0.7*$E$6*$G$6 -> 2800 | E15: =E14*0.7*$E$6*$G$6 -> 7000 | F15: =F14*0.7*$E$6*$G$6 -> 4200 | G15: USD | H15: 효율0.7 × 시간 × 단가
B16: 연간 유지보수 (구입가 3%) | C16: =C9*0.03 -> 8075.862 | D16: =D9*0.03 -> 7431.102 | E16: =E9*0.03 -> 6899.6836 | F16: =F9*0.03 -> 1785 | G16: USD | H16: 업계 평균 가정
B17: 연간 소모품·공구 | C17: 5000 | D17: 4000 | E17: 5000 | F17: 3000 | G17: USD | H17: 추정 (RPM 클래스별)
B18: 연간 운영비 합계 | C18: =SUM(C15:C17) -> 19235.862 | D18: =SUM(D15:D17) -> 14231.102 | E18: =SUM(E15:E17) -> 18899.684 | F18: =SUM(F15:F17) -> 8985 | G18: USD
B19: 5년 운영비 (×5) | C19: =C18*$C$6 -> 96179.31 | D19: =D18*$C$6 -> 71155.51 | E19: =E18*$C$6 -> 94498.418 | F19: =F18*$C$6 -> 44925 | G19: USD
B20: 잔존가치 (5년 후 30%) | C20: =-C9*0.3 -> -80758.62 | D20: =-D9*0.3 -> -74311.02 | E20: =-E9*0.3 -> -68996.836 | F20: =-F9*0.3 -> -17850 | G20: USD | H20: 음수 (회수)
B21: ◆ 5년 TCO 합계 | C21: =C12+C19+C20 -> 289616.09 | D21: =D12+D19+D20 -> 249547.89 | E21: =E12+E19+E20 -> 255491.04 | F21: =F12+F19+F20 -> 91575 | G21: USD
B22: 연평균 TCO (USD/년) | C22: =C21/$C$6 -> 57923.218 | D22: =D21/$C$6 -> 49909.578 | E22: =E21/$C$6 -> 51098.207 | F22: =F21/$C$6 -> 18315 | G22: USD
B23: 초기투자 대비 TCO 비율 | C23: =C21/C9 -> 1.0758582 | D23: =D21/D9 -> 1.0074464 | E23: =E21/E9 -> 1.1108815 | F23: =F21/F9 -> 1.5390756 | G23: 배수

Sheet 06_상업조건
B2: 상업조건 / 계약조건 비교
B4: 항목 | C4: Roeders RXP500 | D4: Roeders RXP400 | E4: Makino V33i | F4: Komatech KT420A | G4: 리스크
B5: 견적 통화 | C5: EUR | D5: EUR | E5: JPY | F5: USD | G5: 환율
B6: Incoterms | C6: CIF Vietnam port | D6: CIF Vietnam port | E6: DAP Bac Ninh ★ | F6: FOB Busan | G6: 운임
B7: 운임 포함 여부 | C7: 포함 (CIF 6,830 EUR) | D7: 포함 (CIF 6,830 EUR) | E7: 포함+통관+공장운송 (1,697,000 JPY) | F7: 미포함 (FOB) | G7: 추가비용
B8: 결제 조건 | C8: 1/3 down + 2/3 선적전 또는 100% L/C | D8: 1/3 down + 2/3 선적전 또는 100% L/C | E8: 20% 계약 후 + 80% 선적전 L/C | F8: T/T 30% 계약 + 70% 선적전 | G8: 자금부담
B9: 견적 유효기간 | C9: 2개월 | D9: 2개월 | E9: 2026-05-06까지 | F9: 1개월 (환율 ±5% 재견적) | G9: 재견적
B10: 납기 (개월) | C10: 5~7개월 | D10: 5~7개월 | E10: 12~16주 (3~4개월) | F10: 3개월 | G10: 리드타임
B11: 보증 (기계, 개월) | C11: 12 (리니어모터 60) | D11: 12 (리니어모터 60) | E11: 12 | F11: 12 | G11: 하자담보
B12: CNC 보증 | C12: 12개월 | D12: 12개월 | E12: FANUC 24개월 | F12: 12개월
B13: 소유권 이전 시점 | C13: 대금 100% 완납 후 | D13: 대금 100% 완납 후 | E13: 대금 100% 완납 후 | F13: Inco terms 기준
B14: 교육 (Training) | C14: 3일 현장교육 + 출장비 포함 | D14: 3일 현장교육 + 출장비 포함 | E14: 현장+센터 무상 (출장비 별도) | F14: 미명시
B15: 원격지원 (Teamviewer 등) | C15: 포함 (보증기간 내 무상) | D15: 포함 | E15: 미명시 | F15: 미명시
B16: A/S 거점 | C16: 독일 본사 + 현지 대리점 | D16: 독일 본사 + 현지 대리점 | E16: Makino Vietnam (직판+공장 직배송) | F16: 한국 (Komatech 본사) | G16: 응답시간
B17: 수출 라이선스 | C17: BAFA 필요 (납기 영향) | D17: BAFA 필요 (납기 영향) | E17: METI/TSC 필요 | F17: 불필요 | G17: 납기 변동성
B18: 취소 조건 | C18: ORGALIME 약관 적용 | D18: ORGALIME 약관 적용 | E18: 계약금 몰수 + 손해배상 | F18: 미명시 | G18: 계약위험
B19: 관할 법원 | C19: 독일 (Vendor 측) | D19: 독일 (Vendor 측) | E19: 호치민 + 싱가포르 법원 | F19: 한국 (추정) | G19: 분쟁해결

Sheet 07_리스크
B2: 리스크 평가 매트릭스 (심각도 × 발생가능성)
B3: 평가기준: 심각도 1(낮음)~5(매우높음), 발생가능성 1(드뭄)~5(매우잦음), 리스크지수 = 심각도×발생가능성
B5: 리스크 카테고리 | C5: 리스크 내용 | D5: 심각도 | E5: 가능성 | F5: 리스크지수 | G5: 대상 설비 | H5: 대응 방안
B6: 환율 변동 | C6: EUR 환율 +10% 시 RXP500 가격 USD 27만→ 30만 상승 | D6: 4 | E6: 4 | F6: =D6*E6 -> 16 | G6: RXP500/400 | H6: 선물환 헤지 또는 분할 결제
B7: 환율 변동 | C7: JPY 환율 변동 시 V33i 가격 변동 | D7: 3 | E7: 3 | F7: =D7*E7 -> 9 | G7: V33i | H7: 계약 환율 고정 협의
B8: 환율 변동 | C8: KRW 환율 ±5% 변동 시 KT420A 재견적 | D8: 3 | E8: 5 | F8: =D8*E8 -> 15 | G8: KT420A | H8: 신속 발주로 환율 고정
B9: 납기 지연 | C9: 독일 BAFA 수출허가 지연 시 +1~2개월 | D9: 3 | E9: 3 | F9: =D9*E9 -> 9 | G9: RXP500/400 | H9: 계약 시 BAFA 진행 사전 확인
B10: 납기 지연 | C10: 일본 METI 승인 지연 시 | D10: 3 | E10: 2 | F10: =D10*E10 -> 6 | G10: V33i | H10: 계약 시 METI 진행 확인
B11: 납기 지연 | C11: 한국 부산항 → 베트남 운송 지연 | D11: 2 | E11: 2 | F11: =D11*E11 -> 4 | G11: KT420A | H11: 여유 있는 운송 일정 확보
B12: A/S 응답성 | C12: 독일 본사 의존 시 출장비·시간 부담 | D12: 4 | E12: 3 | F12: =D12*E12 -> 12 | G12: RXP500/400 | H12: 베트남 현지 엔지니어 사전 양성
B13: A/S 응답성 | C13: 한국 거점 응답 시간 | D13: 2 | E13: 2 | F13: =D13*E13 -> 4 | G13: KT420A | H13: A/S SLA 계약서 명문화
B14: A/S 응답성 | C14: 베트남 직지원 (Makino Vietnam) | D14: 1 | E14: 2 | F14: =D14*E14 -> 2 | G14: V33i | H14: 강점 - 활용
B15: 정밀도 미달 | C15: 도착 후 기온차로 정밀도 변동 | D15: 3 | E15: 2 | F15: =D15*E15 -> 6 | G15: 전체 | H15: 온도 안정화 기간 5일 이상 확보
B16: 운영비 초과 | C16: 리니어모터 마모 시 교체비 고가 | D16: 4 | E16: 2 | F16: =D16*E16 -> 8 | G16: RXP500/400 | H16: 5년 보증 활용 + 예방정비
B17: 운영비 초과 | C17: 소모품 가격 상승 | D17: 2 | E17: 3 | F17: =D17*E17 -> 6 | G17: 전체 | H17: 복수 공구 벤더 확보
... B23: 환경·안전 | C23: 오일미스트·소음·진동 | D23: 2 | E23: 4 | F23: =D23*E23 -> 8 | G23: 전체 | H23: 집진기·차음·방진 별도 시공
B25: 리스크 등급 범례: | C25: 낮음 (1~3) | D25: 중간 (4~8) | E25: 높음 (9~14) | F25: 매우높음 (15+)

Sheet 08_권고사항
B2: 최종 권고사항 및 의사결정 가이드
B4: 용도별 권장 모델 매트릭스
B5: # | C5: 가공 요구 시나리오 | D5: 권장 모델 | E5: 권장 사유 | F5: 대안
B6: 1 | C6: 초정밀 다이몰드 가공 (≤±2μm, 거울면 마감) | D6: Roeders RXP400 | E6: 50,000 RPM, HSK-E32, 리니어모터 5년 보증, RACECUT 32kHz drive로 표면조도 최우수 | F6: V33i (Super GI .5)
B7: 2 | C7: 중대형 정밀 금형/지그 가공 (≤±5μm) | D7: Roeders RXP500 | E7: X500/Y455 큰 작업영역 + 400kg 워크피스, 42,000 RPM HSK-E40, 정밀도와 용량 균형 | F7: V33i
B8: 3 | C8: 정밀 + 양산 균형 (1순위 추천) | D8: Makino V33i (60ATC + 30K rpm) | E8: 30K rpm 업그레이드, 60-Tool 양산 효율, Super GI .5 + MARPOSS, DAP Bac Ninh 통관·운송 책임, FANUC 2년 | F8: RXP400 (초정밀 한정)
B9: 4 | C9: 단순 탭핑·홀가공 4대 동시투자 (저가 양산) | D9: Komatech KT420A × 4 | E9: 단가 USD 59,500 × 4 = 23.8만 (V33i 1대급), 3개월 단납기, BT30 24K rpm으로 충분 | F9: 국내 동급 (화천/현대위아)
B10: 5 | C10: 최소 투자로 시범 구축 후 단계 확장 | D10: Komatech 1대 + V33i 검토 | E10: 1단계 KT420A로 양산 시작, 2단계 V33i/RXP400 추가 도입 검토
B11: 6 | C11: 균형 포트폴리오 (정밀+양산) | D11: RXP400 1대 + KT420A 2대 | E11: 초정밀은 RXP400, 양산 보조는 KT420A로 비용 효율 극대화 | F11: RXP500 + V33i
B14: 벤더별 협상 포인트 (Negotiation Levers)
B15: Roeders | C15: ① 옵션 패키지 무상화 (RMS6/SO, RMSEdit/Cam, 매뉴얼도어) ② 운송비·보험 추가 할인 ③ 베트남 현지 엔지니어 양성 프로그램 ④ 5년 풀서비스 계약 단가 ⑤ 환율 락인 (계약 환율 고정)
B16: Makino | C16: ① Discount 추가 (현재 22.0%, 25% 협상) ② Super GI .5 무상 옵션화 (1.7M JPY) ③ FANUC 보증 36개월 연장 ④ Makino Vietnam 24/7 SLA + DAP 유지 ⑤ 운영자 교육 무상 인원 확대
B17: Komatech | C17: ① 4대 동시 발주 → 단가 재협상 (5,000~10,000 USD/대) ② FOB → CIF Hai Phong 무상 전환 ③ 보증 24개월 연장 ④ 옵션 추가 무상 (현재 무상 옵션 외) ⑤ 환율 변동 흡수 폭 확대
B19: 구매 결정 전 최종 체크리스트
B20: ☐ 가공 대상 제품의 정밀도 요구사항 (μm 단위)이 문서로 확정되어 있는가?
B21: ☐ 향후 5년 가공 물량 및 가동률 예측이 합리적인가? (TCO 시나리오 기반)
B22: ☐ 베트남 공장 현장 환경(전력·온습도·바닥평탄도)이 사양 요구를 충족하는가?
B23: ☐ 견적서 기재된 옵션 외에 추가 필요 옵션 (집진기·CAM·계측기) 비용이 산정되어 있는가?
B24: ☐ A/S SLA(응답시간·출장비·부품 단가)가 계약서에 명문화되었는가?
B25: ☐ 결제 조건(L/C·T/T)에 대한 자금 조달 계획이 수립되었는가?
B26: ☐ 환헤지(선물환·옵션) 또는 계약 환율 고정 조항이 협의되었는가?
B27: ☐ 시운전(Acceptance Test) 합격 기준이 정량화되어 있는가? (정밀도·가공시간·표면조도)
B28: ☐ 운영자·정비자 교육 계획이 수립되었는가? (인원·기간·내용)
B29: ☐ 동종 산업 레퍼런스 방문 또는 데모 가공이 완료되었는가?
