Workbook

Sheet Summary.
A1: Status 2025 | B1: SLMV
C3: Values
A4: Kind | B4: Note | C4: Qty Blance | D4: Amount Balance ( VND)
A5: FG | B5: Keep provision | C5: 172145 | D5: 2.7610329e+09
B6: No provision | C6: 12913 | D6: 8.1430181e+08
B7: Reverse provison | C7: 127669 | D7: 2.0073344e+09
A8: FG Total | C8: 312727 | D8: 5.5826691e+09
A9: RM | B9: Keep provision | C9: 2983098 | D9: 3309687928
B10: Make provision 2025 | C10: 80760 | D10: 2686138185
B11: No provision | C11: 1100223 | D11: 1.7597279e+09
B12: Reverse provison | C12: 399001 | D12: 1454433383
A13: RM Total | C13: 4563082 | D13: 9.2099874e+09
A14: Trading | B14: No provision | C14: 6 | D14: 1.10835e+09
A15: Trading Total | C15: 6 | D15: 1.10835e+09
A16: WIP | B16: Keep provision | C16: 1121441.1 | D16: 6.9010404e+09
B17: Reverse provison | C17: 13108 | D17: 4.9041556e+08
A18: WIP Total | C18: 1134549.1 | D18: 7.391456e+09
A19: Grand Total | C19: 6010364.2 | D19: 2.3292462e+10

Sheet MC propose
C1: Openning 2025 | E1: Movement 2025 | H1: Ending 2025
A3: Sum of 12.end amnt=2+8-10 | B3: Column Labels
A4: Row Labels | B4: Provision 2020 | C4: (blank) | D4: Grand Total
A5: FG | B5: 1.2153954e+08 | D5: 1.2153954e+08
A6: RM | B6: 5.8074429e+09 | C6: 1.38677e+09 | D6: 7.1942129e+09
A7: Suplies | B7: 73161632 | D7: 73161632
A8: WIP | B8: 4.5364014e+08 | D8: 4.5364014e+08
A9: Grand Total | B9: 6.4557842e+09 | C9: 1.38677e+09 | D9: 7.8425542e+09
B10: Total | C10: -8866172212
B11: NRV | C11: 2410388030
A12: No | B12: Type | C12: VND | D12: USD | E12: Clear at 31.Dec.2025 | F12: Reverse Provision 2024 | G12: Add at 31.Dec.2025 | H12: VND | I12: USD
A13: I | B13: Provison Stock | C13: =SUM(C14:C17) -> 1.7286985e+10 | D13: =+C13/25000 -> 691479.4 | E13: =SUM(E14:E18) -> 82219484 | F13: =SUM(F14:F18) -> 4.0048158e+09 | G13: =SUM(G14:G17) -> 0 | H13: =SUM(H14:H17) -> 1.324011e+10 | I13: =SUM(I14:I17) -> 551671.24
A14: 1 | B14: FG | C14: 4.7709049e+09 | D14: =+C14/26000 -> 183496.34 | F14: =SUMIFS('SLMV end2025'!K:K,'SLMV end2025'!M:M,"Reverse provison",'SLMV end2025'!A:A,B14) -> 2.0073344e+09 | G14: =SUMIFS('SLMV end2025'!F:F,'SLMV end2025'!M:M,"Make provision 2025",'SLMV end2025'!A:A,B14) -> 0 | H14: =+C14-E14-F14+G14 -> 2.7635705e+09 | I14: =H14/24000 -> 115148.77
A15: 2 | B15: RM | C15: 4.8851483e+09 | D15: =+C15/26000 -> 187890.32 | E15: 15809484 | F15: =SUMIFS('SLMV end2025'!K:K,'SLMV end2025'!M:M,"Reverse provison",'SLMV end2025'!A:A,B15) -> 1.5070659e+09 | G15: =SUMIFS('SLMV end2025'!F:F,'SLMV end2025'!M:M,"Make provision 2025",'SLMV end2025'!A:A,B15) -> 0 | H15: =+C15-E15-F15+G15 -> 3.3622729e+09 | I15: =H15/24000 -> 140094.7
A16: 3 | B16: Supply | C16: 26250000 | D16: =+C16/26000 -> 1009.6154 | E16: 26250000 | F16: =SUMIFS('SLMV end2025'!K:K,'SLMV end2025'!M:M,"Reverse provison",'SLMV end2025'!A:A,B16) -> 0 | G16: =SUMIFS('SLMV end2025'!F:F,'SLMV end2025'!M:M,"Make provision 2025",'SLMV end2025'!A:A,B16) -> 0 | H16: =+C16-E16-F16+G16 -> 0 | I16: =H16/24000 -> 0
A17: 4 | B17: WIP | C17: 7.6046819e+09 | D17: =+C17/26000 -> 292487.76 | F17: =SUMIFS('SLMV end2025'!K:K,'SLMV end2025'!M:M,"Reverse provison",'SLMV end2025'!A:A,B17) -> 4.9041556e+08 | G17: =SUMIFS('SLMV end2025'!F:F,'SLMV end2025'!M:M,"Make provision 2025",'SLMV end2025'!A:A,B17) -> 0 | H17: =+C17-E17-F17+G17 -> 7.1142663e+09 | I17: =H17/24000 -> 296427.76
A18: 5 | B18: Trading | C18: 40160000 | D18: =+C18/26000 -> 1544.6154 | E18: 40160000 | F18: =SUMIFS('SLMV end2025'!K:K,'SLMV end2025'!M:M,"Reverse provison",'SLMV end2025'!A:A,B18) -> 0 | G18: =SUMIFS('SLMV end2025'!F:F,'SLMV end2025'!M:M,"Make provision 2025",'SLMV end2025'!A:A,B18) -> 0 | H18: =+C18-E18-F18+G18 -> 0
A19: II | B19: NRV | G19: ='SLMV end2025'!S3*0 -> 0 | H19: =+C19-E19+G19 -> 0 | I19: =H19/25000 -> 0
A20: (I) +(II) | B20: Total VND | C20: =+C13+C19 -> 1.7286985e+10 | D20: =+C20/25000 -> 691479.4 | E20: =+E13+E19 -> 82219484 | F20: =+F13+F19 -> 4.0048158e+09 | G20: =+G13+G19 -> 0 | H20: =+H13+H19 -> 1.324011e+10 | I20: =+I13+I19 -> 551671.24
F21: =+F20/26000 -> 154031.38

Sheet SLMV end2025
F1: Exr | G1: 26000 | I1: PROVISION 2024
C2: INVENTORY BALANCE END-2025 | E2: ENDING 2025 | J2: =SUBTOTAL(9,J5:J3685) -> 4861326.7 | K2: =SUBTOTAL(9,K5:K3685) -> 1.6983711e+10 | O2: NRV
A3: Kind | B3: item code | C3: Name | D3: Classify | E3: Qty Blance | F3: Amount Balance ( VND) | G3: Amount Balance ( USD) | H3: Unit price | I3: Technical Justification | J3: Qty provision | K3: Amt provision | L3: Status 2025 | M3: Note | N3: AUDITED | O3: Unit Selling 2025 | P3: 0.069360811 | Q3: Diff unit amt (Sale vs cost) | R3: =SUBTOTAL(9,R4:R3689) -> -3.1135471e+08 | S3: =SUM(S4:S3685) -> 3.1135471e+08
L4: xx
A5: RM | B5: 760011 | C5: Nhôm hợp kim dạng thanh S36 | D5: Alumium | E5: 19237.399 | F5: 5.4981198e+08 | G5: =+F5/$G$1 -> 21146.615 | H5: =IFERROR(F5/E5,0) -> 28580.37 | J5: 0 | K5: 0 | L5: OK | N5: N | T5: 25415 | U5: =+E5-T5 -> -6177.6009
A6: RM | B6: 760309 | C6: Aluminum Ingots ADC3 , Hợp kim nhôm ADC3 | D6: Alumium | E6: 2657.3005 | F6: 2.0903568e+08 | G6: =+F6/$G$1 -> 8039.834 | H6: =IFERROR(F6/E6,0) -> 78664.677 | I6: 0 | J6: 0 | K6: 0 | L6: OK | N6: N | T6: 2144.1705 | U6: =+E6-T6 -> 513.13
A7: RM | B7: 762249 | C7: Aluminum S3Y/Nhôm hợp kim dạng thanh S3Y | D7: Alumium | E7: 16146.277 | F7: 5.2496466e+08 | G7: =+F7/$G$1 -> 20190.949 | H7: =IFERROR(F7/E7,0) -> 32513.046 | J7: 0 | K7: 0 | L7: OK | N7: N | T7: 28122.491 | U7: =+E7-T7 -> -11976.213
A8: RM | B8: 762750 | C8: Aluminum A380/Nhôm A380 | D8: Alumium | E8: 272 | F8: 8031878.2 | G8: =+F8/$G$1 -> 308.91839 | H8: =IFERROR(F8/E8,0) -> 29528.964 | J8: 0 | K8: 0 | L8: SLMV | N8: Y | T8: 272 | U8: =+E8-T8 -> 0
A9: RM | B9: 762800 | C9: A413 Aluminium alloy for Handle Bar product-Nguyên liệu A413 sản xuất Handle bar | D9: Alumium | E9: 9910 | F9: 352468421 | G9: =+F9/$G$1 -> 13556.478 | H9: =IFERROR(F9/E9,0) -> 35566.945 | I9: Raw Material relating to Aluminium, which is the core material of the company. No movement is due to company has been actively using another size. Item able to recycle and re-produce to new size. | J9: 0 | K9: 0 | L9: SLMV | N9: Y | T9: 0 | U9: =+E9-T9 -> 9910
A10: RM | B10: 762802 | C10: Aluminium ALDCS 12 Fe 0.9%-Nhôm thỏi ALDC12 thành phần Fe 0.9% | D10: Alumium | E10: 32883.937 | F10: 1.0227306e+09 | G10: =+F10/$G$1 -> 39335.791 | H10: =IFERROR(F10/E10,0) -> 31101.22 | J10: 0 | K10: 0 | L10: OK | N10: N | T10: 40543.033 | U10: =+E10-T10 -> -7659.0961
A11: RM | B11: 763915 | C11: Aluminium plate for bracket(0102-002945)-B6/ Phôi nhôm (0102-002945)-B6 | D11: AL-SEVT | E11: 4292 | F11: 0 | G11: =+F11/$G$1 -> 0 | H11: =IFERROR(F11/E11,0) -> 0 | I11: 0 | J11: 0 | K11: 0 | L11: OK | N11: N | T11: 0 | U11: =+E11-T11 -> 4292
A12: RM | B12: 762897 | C12: Bracket Q4/Vỏ (khung đỡ) điện thoại di động bằng kim loại/Q4 | D12: AL-SEVT | E12: 97 | F12: 0 | G12: =+F12/$G$1 -> 0 | H12: =IFERROR(F12/E12,0) -> 0 | I12: 0 | J12: 0 | K12: 0 | L12: OK | N12: N | T12: 0 | U12: =+E12-T12 -> 97
A13: RM | B13: 740202 | C13: Hexagonal bolt/chìm lục giác kt M8*60 | D13: Mold Jig Material | E13: 110 | F13: 256410 | G13: =+F13/$G$1 -> 9.8619231 | H13: =IFERROR(F13/E13,0) -> 2331 | J13: 0 | K13: 0 | L13: OK | N13: N | T13: 100 | U13: =+E13-T13 -> 10
A14: RM | B14: 740215 | C14: Hexagonal bolt/ Chìm lục giác M10*60(1) | D14: Mold Jig Material | E14: 30 | F14: 107520 | G14: =+F14/$G$1 -> 4.1353846 | H14: =IFERROR(F14/E14,0) -> 3584 | J14: 0 | K14: 0 | L14: OK | N14: N | T14: 6 | U14: =+E14-T14 -> 24
A15: RM | B15: 741351 | C15: Master box label/Giấy in tem cuộn. Size: 30*13mm (2 tem) | D15: Etc | E15: 15 | F15: 1687500 | G15: =+F15/$G$1 -> 64.903846 | H15: =IFERROR(F15/E15,0) -> 112500 | I15: Currenly no customer using these RM. Hence, full provision to be made | J15: 15 | K15: 1687500 | L15: SLMV | M15: Reverse provison | N15: Y | T15: 15 | U15: =+E15-T15 -> 0
A16: RM | B16: 741352 | C16: Master box label/ Giấy in tem cuộn. Size: 100*150mm | D16: Etc | E16: 5 | F16: 900000 | G16: =+F16/$G$1 -> 34.615385 | H16: =IFERROR(F16/E16,0) -> 180000 | J16: 0 | K16: 0 | L16: OK | N16: N | T16: 5 | U16: =+E16-T16 -> 0
A17: RM | B17: 741689 | C17: Inner label/ Giấy in tem cuộn. Size: 13*32mm (khổ cuộn 75mm) | D17: Etc | E17: 5 | F17: 1100000 | G17: =+F17/$G$1 -> 42.307692 | H17: =IFERROR(F17/E17,0) -> 220000 | I17: These raw materials are in good condition and can be used for other customer, no expiry date on these raw materials. Hence, no provison | J17: 0 | K17: 0 | L17: OK | N17: N | T17: 5 | U17: =+E17-T17 -> 0
A18: RM | B18: 742008 | C18: Master box label/Giấy in tem cuộn. Size: 30*13mm (3 tem) | D18: Cosmetic | E18: 7 | F18: 787500 | G18: =+F18/$G$1 -> 30.288462 | H18: =IFERROR(F18/E18,0) -> 112500 | I18: BU Discontinued - [1] | J18: 7 | K18: 787500 | L18: SLMV | M18: Keep provision | N18: Y | T18: 7 | U18: =+E18-T18 -> 0
A19: RM | B19: 742255 | C19: PE bag/ Túi chống tĩnh điện màu xanh dương 21cm*25cm*0.04mm (dùng cho model hàng GEN2/1v5 pre/Al5) | D19: Etc | E19: 275.02306 | F19: 12405820 | G19: =+F19/$G$1 -> 477.14694 | H19: =IFERROR(F19/E19,0) -> 45108.292 | J19: 0 | K19: 0 | L19: OK | N19: N | T19: 219.02306 | U19: =+E19-T19 -> 56
A20: RM | B20: 742313 | C20: Vacuum poly bag 350*490*0.1/Túi chân không | D20: Etc | E20: 1350.0237 | F20: 3915068.7 | G20: =+F20/$G$1 -> 150.57956 | H20: =IFERROR(F20/E20,0) -> 2900 | J20: 0 | K20: 0 | L20: OK | N20: N | T20: 800.02367 | U20: =+E20-T20 -> 550
A21: RM | B21: 742342 | C21: Zipper bag/Túi zipper KT: 180*250*0.05mm | D21: Etc | E21: 500 | F21: 300000 | G21: =+F21/$G$1 -> 11.538462 | H21: =IFERROR(F21/E21,0) -> 600 | I21: Currenly no customer using these RM. Hence, full provision to be made | J21: 2100 | K21: 1260000 | L21: OK | M21: Reverse provison | N21: N | T21: 500 | U21: =+E21-T21 -> 0
A22: RM | B22: 742343 | C22: Tem QR/Sticker for QR printing, kt: 10*10mm | D22: Etc | E22: 1372800 | F22: 27456000 | G22: =+F22/$G$1 -> 1056 | H22: =IFERROR(F22/E22,0) -> 20 | J22: 0 | K22: 0 | L22: OK | N22: N | T22: 370000 | U22: =+E22-T22 -> 1002800
A23: RM | B23: 742369 | C23: PE bag/ Túi chống tĩnh điện màu trắng 680mm*600mm*0.04mm | D23: Etc | E23: 60.243324 | F23: 2289246.3 | G23: =+F23/$G$1 -> 88.047936 | H23: =IFERROR(F23/E23,0) -> 38000 | J23: 0 | K23: 0 | L23: OK | N23: N | T23: 28.243324 | U23: =+E23-T23 -> 32
A24: RM | B24: 742370 | C24: PE bag/Túi chống tĩnh điện màu xanh lá 21cm*25cm*0.04mm(570W/AL6) | D24: Etc | E24: 35.038255 | F24: 1582433.8 | G24: =+F24/$G$1 -> 60.86284 | H24: =IFERROR(F24/E24,0) -> 45163.032 | J24: 0 | K24: 0 | L24: OK | N24: N | T24: 75.038255 | U24: =+E24-T24 -> -40
A25: RM | B25: 742371 | C25: PE bag/Túi chống tĩnh điện màu vàng 21cm*25cm*0.04mm( 1v5 base/BYD housing/Nu) | D25: Etc | E25: 74.532165 | F25: 3359138 | G25: =+F25/$G$1 -> 129.19761 | H25: =IFERROR(F25/E25,0) -> 45069.642 | J25: 0 | K25: 0 | L25: OK | N25: N | T25: 92.532165 | U25: =+E25-T25 -> -18
A26: RM | B26: 742399 | C26: PE bag/ Túi chống tĩnh điện màu xanh dương 210mm*350mm*0.04mm (dùng cho model hàng 1V5 Housing 1826) | D26: Etc | E26: 149.91644 | F26: 6757585.2 | G26: =+F26/$G$1 -> 259.90712 | H26: =IFERROR(F26/E26,0) -> 45075.679 | J26: 0 | K26: 0 | L26: OK | N26: N | T26: 177.91644 | U26: =+E26-T26 -> -28
A27: RM | B27: 752055 | C27: Hair/ tóc thật | D27: Cosmetic | E27: 10 | F27: 26661450 | G27: =+F27/$G$1 -> 1025.4404 | H27: =IFERROR(F27/E27,0) -> 2666145 | I27: BU Discontinued - [1] | J27: 10 | K27: 26661450 | L27: SLMV | M27: Keep provision | N27: Y | T27: 10 | U27: =+E27-T27 -> 0
A28: RM | B28: 754012 | C28: Miếng dán móng tay 412-24 (từ 0-3) | D28: Cosmetic | E28: 400 | F28: 173600 | G28: =+F28/$G$1 -> 6.6769231 | H28: =IFERROR(F28/E28,0) -> 434 | I28: BU Discontinued - [1] | J28: 400 | K28: 173600 | L28: SLMV | M28: Keep provision | N28: Y | T28: 400 | U28: =+E28-T28 -> 0
A29: RM | B29: 754576 | C29: Silical gel 50 gr/hạt hút ẩm | D29: Etc | E29: 150.15499 | F29: 6886708.5 | G29: =+F29/$G$1 -> 264.8734 | H29: =IFERROR(F29/E29,0) -> 45864 | J29: 0 | K29: 0 | L29: OK | N29: N | T29: 535.15499 | U29: =+E29-T29 -> -385
A30: RM | B30: 754654 | C30: Mold Pin-EJECTOR PIN _x000D_/Chốt hãm bằng thép SKD61 của khuôn đúc d2*L100*H4*D4/ 밀핀" EPN2-100 | D30: Mold Jig Material | E30: 99 | F30: 2772000 | G30: =+F30/$G$1 -> 106.61538 | H30: =IFERROR(F30/E30,0) -> 28000 | J30: 0 | K30: 0 | L30: OK | N30: N | T30: 87 | U30: =+E30-T30 -> 12
A31: RM | B31: 760018 | C31: Carton box. 5 Plate: 1 surface Yellow, 1 surface raw. Thùng carton 5 lớp,mặt ngoài vàng, mặt trong thô MC-YLR01 | D31: Etc | E31: 345.90514 | F31: 5090015.5 | G31: =+F31/$G$1 -> 195.76983 | H31: =IFERROR(F31/E31,0) -> 14715.062 | J31: 0 | K31: 0 | L31: OK | N31: N | T31: 251.72836 | U31: =+E31-T31 -> 94.176775
A32: RM | B32: 760119 | C32: Clear Sticker-Stick paper box, dim: 16mm_x000D_ /Miếng dán ở giữa vị trí trên cùng và dưới cùng hộp đựng lông mi giả | D32: Cosmetic | E32: 45000 | F32: 3573812 | G32: =+F32/$G$1 -> 137.45431 | H32: =IFERROR(F32/E32,0) -> 79.418044 | I32: BU Discontinued - [1] | J32: 45000 | K32: 3573812 | L32: SLMV | M32: Keep provision | N32: Y | T32: 45000 | U32: =+E32-T32 -> 0
A33: RM | B33: 760120 | C33: Inner box. Size: 97*77*83mm . Color : white/Hộp Inner box đựng ngoài hộp lông mi giả, màu trắng | D33: Cosmetic | E33: 4700 | F33: 10180752 | G33: =+F33/$G$1 -> 391.56738 | H33: =IFERROR(F33/E33,0) -> 2166.1174 | I33: BU Discontinued - [1] | J33: 4700 | K33: 10180752 | L33: SLMV | M33: Keep provision | N33: Y | T33: 4700 | U33: =+E33-T33 -> 0
A34: RM | B34: 760233 | C34: PET13 Tray. Color: White 0.4T. Model MC-PET13-1Pair_x000D_ /Khay đựng lông mi giả - PET13-1 đôi . Size 95*55*15 | D34: Cosmetic | E34: 2594 | F34: 941172 | G34: =+F34/$G$1 -> 36.198923 | H34: =IFERROR(F34/E34,0) -> 362.82652 | I34: BU Discontinued - [1] | J34: 2594 | K34: 941172 | L34: SLMV | M34: Keep provision | N34: Y | T34: 2594 | U34: =+E34-T34 -> 0
A35: RM | B35: 760235 | C35: PET15 Tray. Color: White. Model MC-PET15-4pairs_x000D_ /Khay đựng lông mi giả - PET15-4 đôi. Size: 95*96*15 | D35: Cosmetic | E35: 16 | F35: 11200 | G35: =+F35/$G$1 -> 0.43076923 | H35: =IFERROR(F35/E35,0) -> 700 | I35: BU Discontinued - [1] | J35: 16 | K35: 11200 | L35: SLMV | M35: Keep provision | N35: Y | T35: 16 | U35: =+E35-T35 -> 0
A36: RM | B36: 760246 | C36: EYELENE box. Color: Pink. 1 pair /Hộp EYELENE, 30-88133-E01, 1 đôi | D36: Cosmetic | E36: 904 | F36: 1075285 | G36: =+F36/$G$1 -> 41.357115 | H36: =IFERROR(F36/E36,0) -> 1189.4746 | I36: BU Discontinued - [1] | J36: 904 | K36: 1075285 | L36: SLMV | M36: Keep provision | N36: Y | T36: 904 | U36: =+E36-T36 -> 0
A37: RM | B37: 760300 | C37: Tray PP 0.4T Black_x000D_ /(Khay 932-63) Khay nhựa PP-04 Đen , 10 ô | D37: Etc | E37: 200 | F37: 360000 | G37: =+F37/$G$1 -> 13.846154 | H37: =IFERROR(F37/E37,0) -> 1800 | I37: Currenly no customer using these RM. Hence, full provision to be made | J37: 200 | K37: 360000 | L37: SLMV | M37: Reverse provison | N37: Y | T37: 200 | U37: =+E37-T37 -> 0
A38: RM | B38: 760318 | C38: Bar code 01-91295-002. Size: 20*34mm_x000D_ /Tem mã vạch 079181912952. Loại mã Code UPCA-12 | D38: Etc | E38: 900 | F38: 150442 | G38: =+F38/$G$1 -> 5.7862308 | H38: =IFERROR(F38/E38,0) -> 167.15778 | I38: Currenly no customer using these RM. Hence, full provision to be made | J38: 900 | K38: 150442 | L38: SLMV | M38: Reverse provison | N38: Y | T38: 900 | U38: =+E38-T38 -> 0
A39: RM | B39: 760319 | C39: Bar code 01-91297-002. Size: 20*34mm_x000D_ /Tem mã vạch 079181912976. Loại mã Code UPCA-12 | D39: Etc | E39: 1500 | F39: 55500 | G39: =+F39/$G$1 -> 2.1346154 | H39: =IFERROR(F39/E39,0) -> 37 | I39: Currenly no customer using these RM. Hence, full provision to be made | J39: 1500 | K39: 55500 | L39: SLMV | M39: Reverse provison | N39: Y | T39: 1500 | U39: =+E39-T39 -> 0
A40: RM | B40: 760367 | C40: Item label, Black ink_x000D_ / Tem số 88132 mực đen . Size : 17*8mm | D40: Cosmetic | E40: 9702 | F40: 1293276 | G40: =+F40/$G$1 -> 49.741385 | H40: =IFERROR(F40/E40,0) -> 133.29994 | I40: BU Discontinued - [1] | J40: 9702 | K40: 1293276 | L40: SLMV | M40: Keep provision | N40: Y | T40: 9702 | U40: =+E40-T40 -> 0
...

Sheet Sheet1
G1: Status 2025 | H1: SLMV
A3: Row Labels | B3: Sum of Qty Blance | C3: Sum of Amount Balance ( VND) | E3: 2024 Make provision | G3: Row Labels | H3: Sum of Qty Blance | I3: Sum of Amount Balance ( VND)
A4: FG | B4: 1469823 | C4: 4.0354451e+10 | E4: =SUMIF('SLM 2024 updated Dec.25'!A:A,A4,'SLM 2024 updated Dec.25'!L:L) -> 4.7709049e+09 | G4: FG | H4: 312727 | I4: 5.5826691e+09
A5: RM | B5: 8953586.2 | C5: 2.2272429e+10 | E5: =SUMIF('SLM 2024 updated Dec.25'!A:A,A5,'SLM 2024 updated Dec.25'!L:L) -> 4.8851483e+09 | G5: RM | H5: 4573264 | I5: 9.5704877e+09
A6: Supply | B6: 431983.5 | C6: 2.1009464e+10 | E6: =SUMIF('SLM 2024 updated Dec.25'!A:A,A6,'SLM 2024 updated Dec.25'!L:L) -> 26250000 | G6: Supply | H6: 8336 | I6: 1.2212376e+09
A7: Trading | B7: 1084 | C7: 4.8099794e+09 | E7: =SUMIF('SLM 2024 updated Dec.25'!A:A,A7,'SLM 2024 updated Dec.25'!L:L) -> 40160000 | G7: Trading | H7: 6 | I7: 1.10835e+09
A8: WIP | B8: 1339044.1 | C8: 1.0403302e+10 | E8: =SUMIF('SLM 2024 updated Dec.25'!A:A,A8,'SLM 2024 updated Dec.25'!L:L) -> 7.6046819e+09 | G8: WIP | H8: 1134549.1 | I8: 7.391456e+09
A9: (blank) | E9: =SUM(E3:E8) -> 1.7327145e+10 | G9: Grand Total | H9: 6028882.2 | I9: 2.48742e+10
A10: Grand Total | B10: 12195521 | C10: 9.8849625e+10

Sheet SLM 2024 updated Dec.25
C1: Slow-Moving List ASSESSMENT (Audit's file) | K1: Provision Dec.2024 | O1: SLMV at Ending 31.12.24 (Accounting book) | S1: Remaining Ending
A2: Kind | B2: item code | C2: Name | D2: Qty Slm | E2: Amount Slm | F2: Price | G2: xxx | H2: Condition | I2: Technical Justification | J2: Disposition Plan | K2: Qty Provision | L2: Amt provision | M2: % | N2: XX | O2: Qty | P2: Amt VND | Q2: Qty | R2: Amt VND | S2: Qty | T2: Amt VND | U2: Note
E3: =SUM(E4:E3436) -> 9.4908928e+10 | L3: =SUM(L4:L3436) -> 1.7327145e+10 | O3: =SUM(O4:O3436) -> 15557575 | P3: =SUM(P4:P3436) -> 1.1454977e+11 | Q3: =SUM(Q4:Q3436) -> 7827112.2 | R3: =SUM(R4:R3436) -> 8.5190233e+10 | S3: =SUM(S4:S3436) -> 2810813 | T3: =SUM(T4:T3436) -> 1.2032731e+10
A4: FG | B4: 100876 | C4: PK Qualcomm IDP CEDROS 50-PT525-2 Ant Carrier, Antenna 5 And 6 | D4: 26 | E4: 58655288 | F4: =+E4/D4 -> 2255972.6 | H4: Good | I4: No provision to be made, as item will be recycle to New Ingot in Year 2025 | J4: Recycle | K4: 0 | L4: 0 | M4: =+L4/E4 -> 0 | O4: 26 | P4: 58655288 | Q4: 26 | R4: 58655288 | S4: =O4-K4-Q4 -> 0 | T4: =P4-L4-R4 -> 0 | U4: Produce again 2025
A5: FG | B5: 100913 | C5: PK Qualcom QRD Fillmore MCVC21-003 Front Housing | D5: 120 | E5: 84446843 | F5: =+E5/D5 -> 703723.69 | H5: Good | I5: No provision to be made, as item will be recycle to New Ingot in Year 2025 | J5: Recycle | K5: 0 | L5: 0 | M5: =+L5/E5 -> 0 | O5: 153 | P5: 1.0766972e+08 | Q5: 153 | R5: 1.0766972e+08 | S5: =O5-K5-Q5 -> 0 | T5: =P5-L5-R5 -> 0 | U5: Clearing ok
A6: FG | B6: 100723 | C6: PK Qualcomm Front housing CNC JIG STEP 2 | D6: 1 | E6: 603989.42 | F6: =+E6/D6 -> 603989.42 | H6: Good | I6: No provision to be made, amount can be recover - [2] | J6: N.A | K6: 0 | L6: 0 | M6: =+L6/E6 -> 0 | O6: 1 | P6: 603989.42 | Q6: 1 | R6: 603989.42 | S6: =O6-K6-Q6 -> 0 | T6: =P6-L6-R6 -> 0 | U6: Clearing ok
A7: FG | B7: 100725 | C7: PK Qualcomm Front housing CNC JIG STEP 4 | D7: 2 | E7: 1207978.8 | F7: =+E7/D7 -> 603989.42 | H7: Good | I7: No provision to be made, amount can be recover - [2] | J7: N.A | K7: 0 | L7: 0 | M7: =+L7/E7 -> 0 | O7: 2 | P7: 1207978.8 | Q7: 2 | R7: 1207978.8 | S7: =O7-K7-Q7 -> 0 | T7: =P7-L7-R7 -> 0 | U7: Clearing ok
A8: FG | B8: 100472 | C8: PK Viettel VPH-411S-1 Inner base Frame( Sanding& Anodizing) | D8: 16 | E8: 9069087.9 | F8: =+E8/D8 -> 566818 | H8: Good | I8: No provision to be made, as item will be recycle to New Ingot in Year 2025 | J8: Recycle | K8: 0 | L8: 0 | M8: =+L8/E8 -> 0 | O8: 16 | P8: 9069087.9 | Q8: 16 | R8: 9069087.9 | S8: =O8-K8-Q8 -> 0 | T8: =P8-L8-R8 -> 0 | U8: Clearing ok
A9: FG | B9: 100477 | C9: PK Viettel VPH-411S-6 Back cover( Sanding& Anodizing) | D9: 23 | E9: 11410849 | F9: =+E9/D9 -> 496123.87 | H9: Good | I9: No provision to be made, as item will be recycle to New Ingot in Year 2025 | J9: Recycle | K9: 0 | L9: 0 | M9: =+L9/E9 -> 0 | O9: 23 | P9: 11410849 | Q9: 23 | R9: 11410849 | S9: =O9-K9-Q9 -> 0 | T9: =P9-L9-R9 -> 0 | U9: Clearing ok
A10: FG | B10: 100476 | C10: PK Viettel VPH-411S-5 Back base (Sanding) | D10: 106 | E10: 52500352 | F10: =+E10/D10 -> 495286.34 | H10: Good | I10: No provision to be made, as item will be recycle to New Ingot in Year 2025 | J10: Recycle | K10: 0 | L10: 0 | M10: =+L10/E10 -> 0 | O10: 106 | P10: 52500352 | Q10: 106 | R10: 52500352 | S10: =O10-K10-Q10 -> 0 | T10: =P10-L10-R10 -> 0 | U10: Clearing ok
A11: FG | B11: 100428 | C11: PK CP15 DCT002 (Logo DW ) | D11: 72 | E11: 30046293 | F11: =+E11/D11 -> 417309.62 | H11: Good | I11: BU Discontinued - [1] | J11: Full Provision | K11: =D11 -> 72 | L11: =E11 -> 30046293 | M11: =+L11/E11 -> 1 | O11: 72 | P11: 30046293 | Q11: 0 | R11: 0 | S11: =O11-K11-Q11 -> 0 | T11: =P11-L11-R11 -> 0 | U11: Make provision 2024
A12: FG | B12: 100416 | C12: ACE Tech 83A-00167 | D12: 359 | E12: 1.3713226e+08 | F12: =+E12/D12 -> 381984.01 | H12: Good | I12: No provision to be made, as item will be recycle to New Ingot in Year 2025 | J12: Recycle | K12: 0 | L12: 0 | M12: =+L12/E12 -> 0 | O12: 359 | P12: 1.3713226e+08 | Q12: 359 | R12: 1.3713226e+08 | S12: =O12-K12-Q12 -> 0 | T12: =P12-L12-R12 -> 0 | U12: Clearing ok
A13: FG | B13: 100474 | C13: PK Viettel VPH-411S-3 Right cover (Sanding) | D13: 97 | E13: 32672242 | F13: =+E13/D13 -> 336827.23 | H13: Good | I13: No provision to be made, as item will be recycle to New Ingot in Year 2025 | J13: Recycle | K13: 0 | L13: 0 | M13: =+L13/E13 -> 0 | O13: 97 | P13: 32672242 | Q13: 97 | R13: 32672242 | S13: =O13-K13-Q13 -> 0 | T13: =P13-L13-R13 -> 0 | U13: Clearing ok
A14: FG | B14: 100475 | C14: PK Viettel VPH-411S-4 Left Cover (Sanding) | D14: 97 | E14: 32672242 | F14: =+E14/D14 -> 336827.23 | H14: Good | I14: No provision to be made, as item will be recycle to New Ingot in Year 2025 | J14: Recycle | K14: 0 | L14: 0 | M14: =+L14/E14 -> 0 | O14: 97 | P14: 32672242 | Q14: 97 | R14: 32672242 | S14: =O14-K14-Q14 -> 0 | T14: =P14-L14-R14 -> 0 | U14: Clearing ok
A15: FG | B15: 100646 | C15: PK Qualcomm CPE Huracan 50-PM307-1 Stand | D15: 6 | E15: 1882766 | F15: =+E15/D15 -> 313794.33 | H15: Good | I15: No provision to be made, as item will be recycle to New Ingot in Year 2025 | J15: Recycle | M15: =+L15/E15 -> 0 | O15: 6 | P15: 1882766 | Q15: 6 | R15: 1882766 | S15: =O15-K15-Q15 -> 0 | T15: =P15-L15-R15 -> 0 | U15: Clearing ok
A16: FG | B16: 150581 | C16: PK NF0019AF(36 Nails) | D16: 220 | E16: 51958758 | F16: =+E16/D16 -> 236176.17 | H16: Good | I16: BU Discontinued - [1] | J16: Full Provision | K16: 220 | L16: 51958758 | M16: =+L16/E16 -> 1 | O16: 220 | P16: 51958758 | Q16: 0 | R16: 0 | S16: =O16-K16-Q16 -> 0 | T16: =P16-L16-R16 -> 0 | U16: Make provision 2024
A17: FG | B17: 100413 | C17: ACE Tech 83A-00220 | D17: 48 | E17: 11046054 | F17: =+E17/D17 -> 230126.14 | H17: Good | I17: No provision to be made, as item will be recycle to New Ingot in Year 2025 | J17: Recycle | K17: 0 | L17: 0 | M17: =+L17/E17 -> 0 | O17: 48 | P17: 11046054 | Q17: 48 | R17: 11046054 | S17: =O17-K17-Q17 -> 0 | T17: =P17-L17-R17 -> 0 | U17: Clearing ok
A18: FG | B18: 100551 | C18: PK ACE Tech 83A-00185 ( not Base) | D18: 178 | E18: 37894005 | F18: =+E18/D18 -> 212887.67 | H18: Good | I18: No provision to be made, as item will be recycle to New Ingot in Year 2025 | J18: Recycle | K18: 0 | L18: 0 | M18: =+L18/E18 -> 0 | O18: 178 | P18: 37894005 | Q18: 178 | R18: 37894005 | S18: =O18-K18-Q18 -> 0 | T18: =P18-L18-R18 -> 0 | U18: Clearing ok
A19: FG | B19: 100306 | C19: HM003 | D19: 78 | E19: 15542026 | F19: =+E19/D19 -> 199256.74 | H19: Good | I19: No provision to be made, as item will be recycle to New Ingot in Year 2025 | J19: Recycle | K19: 0 | L19: 0 | M19: =+L19/E19 -> 0 | O19: 78 | P19: 15542026 | Q19: 78 | R19: 15542026 | S19: =O19-K19-Q19 -> 0 | T19: =P19-L19-R19 -> 0 | U19: Clearing ok
A20: FG | B20: 100480 | C20: PK Viettel VPH-411S-9 Bottom Front deco (Sanding) | D20: 88 | E20: 16109462 | F20: =+E20/D20 -> 183062.07 | H20: Good | I20: No provision to be made, as item will be recycle to New Ingot in Year 2025 | J20: Recycle | K20: 0 | L20: 0 | M20: =+L20/E20 -> 0 | O20: 88 | P20: 16109462 | Q20: 88 | R20: 16109462 | S20: =O20-K20-Q20 -> 0 | T20: =P20-L20-R20 -> 0 | U20: Clearing ok
A21: FG | B21: 100789 | C21: PK Vinsmart V650 Front Frame Assy | D21: 81 | E21: 13645344 | F21: =+E21/D21 -> 168461.04 | H21: Good | I21: No provision to be made, as item will be recycle to New Ingot in Year 2025 | J21: Recycle | M21: =+L21/E21 -> 0 | O21: 81 | P21: 13645344 | Q21: 81 | R21: 13645344 | S21: =O21-K21-Q21 -> 0 | T21: =P21-L21-R21 -> 0 | U21: Clearing ok
A22: FG | B22: 101220 | C22: PK Qualcomm MTP KAANAPALI 50-58183-2 FRAME, WLAN AREA, MULTIPURPOSE | D22: 4.2472055 | E22: 703523.43 | F22: =+E22/D22 -> 165643.84 | H22: Good | I22: No provision to be made, as item will be recycle to New Ingot in Year 2025 | J22: Recycle | M22: =+L22/E22 -> 0 | O22: 144 | P22: 23852713 | Q22: 144 | R22: 23852713 | S22: =O22-K22-Q22 -> 0 | T22: =P22-L22-R22 -> 0 | U22: Produce again 2025
A23: FG | B23: 100473 | C23: PK Viettel VPH-411S-2 Back deco (Sanding) | D23: 90 | E23: 14898140 | F23: =+E23/D23 -> 165534.89 | H23: Good | I23: No provision to be made, as item will be recycle to New Ingot in Year 2025 | J23: Recycle | K23: 0 | L23: 0 | M23: =+L23/E23 -> 0 | O23: 90 | P23: 14898140 | Q23: 90 | R23: 14898140 | S23: =O23-K23-Q23 -> 0 | T23: =P23-L23-R23 -> 0 | U23: Clearing ok
A24: FG | B24: 101135 | C24: PK Qualcomm MTP Pinnacles 50-28768-2 Frame Wlan Area, Multipurpose | D24: 156 | E24: 25658410 | F24: =+E24/D24 -> 164476.99 | H24: Good | I24: No provision to be made, as item will be recycle to New Ingot in Year 2025 | J24: Recycle | K24: 0 | L24: 0 | M24: =+L24/E24 -> 0 | O24: 156 | P24: 25658410 | Q24: 0 | R24: 0 | S24: =O24-K24-Q24 -> 156 | T24: =P24-L24-R24 -> 25658410 | U24: Will sale again
A25: FG | B25: 101168 | C25: PK Qualcomm MTP PAKALA 55-58184-1 CARRIER FRAME, ASSY | D25: 51 | E25: 8223562.6 | F25: =+E25/D25 -> 161246.33 | H25: Good | I25: No provision to be made, as item will be recycle to New Ingot in Year 2025 | J25: Recycle | K25: 0 | L25: 0 | M25: =+L25/E25 -> 0 | O25: 51 | P25: 8223562.6 | Q25: 0 | R25: 0 | S25: =O25-K25-Q25 -> 51 | T25: =P25-L25-R25 -> 8223562.6 | U25: Will sale again
A26: FG | B26: 100300 | C26: AS DCT048 | D26: 85 | E26: 13370582 | F26: =+E26/D26 -> 157300.96 | H26: Good | I26: No provision to be made, as item will be recycle to New Ingot in Year 2025 | J26: Recycle | K26: 0 | L26: 0 | M26: =+L26/E26 -> 0 | O26: 85 | P26: 13370582 | Q26: 85 | R26: 13370582 | S26: =O26-K26-Q26 -> 0 | T26: =P26-L26-R26 -> 0 | U26: Clearing ok
A27: FG | B27: 100558 | C27: PK Qualcomm IDP Moorea 55-PF951-4 Front housing | D27: 60 | E27: 9325947.1 | F27: =+E27/D27 -> 155432.45 | H27: Good | I27: No provision to be made, as item will be recycle to New Ingot in Year 2025 | J27: Recycle | K27: 0 | L27: 0 | M27: =+L27/E27 -> 0 | O27: 60 | P27: 9325947.1 | Q27: 60 | R27: 9325947.1 | S27: =O27-K27-Q27 -> 0 | T27: =P27-L27-R27 -> 0 | U27: Clearing ok
A28: FG | B28: 150564 | C28: PK ZN0022 | D28: 636 | E28: 92683686 | F28: =+E28/D28 -> 145729.07 | H28: Good | I28: BU Discontinued - [1] | J28: Full Provision | K28: =+D28 -> 636 | L28: =+E28 -> 92683686 | M28: =+L28/E28 -> 1 | O28: 636 | P28: 92683686 | Q28: 0 | R28: 0 | S28: =O28-K28-Q28 -> 0 | T28: =P28-L28-R28 -> 0 | U28: Make provision 2024
A29: FG | B29: 101051 | C29: PK Qualcomm MTP Pinnacles 55-29819-1 Front Housing | D29: 160 | E29: 22938399 | F29: =+E29/D29 -> 143364.99 | H29: Good | I29: No provision to be made, as item will be recycle to New Ingot in Year 2025 | J29: Recycle | K29: 0 | L29: 0 | M29: =+L29/E29 -> 0 | O29: 160 | P29: 22938399 | Q29: 160 | R29: 22938399 | S29: =O29-K29-Q29 -> 0 | T29: =P29-L29-R29 -> 0 | U29: Clearing ok
A30: FG | B30: 100641 | C30: PK Qualcomm Kona 55-PG165-4 Ant Carrier 1 | D30: 365 | E30: 51357507 | F30: =+E30/D30 -> 140705.5 | H30: Good | I30: No provision to be made, as item will be recycle to New Ingot in Year 2025 | J30: Recycle | K30: 0 | L30: 0 | M30: =+L30/E30 -> 0 | O30: 365 | P30: 51357507 | Q30: 365 | R30: 51357507 | S30: =O30-K30-Q30 -> 0 | T30: =P30-L30-R30 -> 0 | U30: Clearing ok
A31: FG | B31: 101093 | C31: PK Qualcomm CPE Pinnacles 50-38556-1 LDS, Antenna, Left | D31: 15 | E31: 2064524.3 | F31: =+E31/D31 -> 137634.95 | H31: Good | I31: No provision to be made, as item will be recycle to New Ingot in Year 2025 | J31: Recycle | K31: 0 | L31: 0 | M31: =+L31/E31 -> 0 | O31: 15 | P31: 2064524.3 | Q31: 15 | R31: 2064524.3 | S31: =O31-K31-Q31 -> 0 | T31: =P31-L31-R31 -> 0 | U31: Sale again 2025
A32: FG | B32: 100479 | C32: PK Viettel VPH-411S-8 Top Front deco 2 (Sanding) | D32: 77 | E32: 10295810 | F32: =+E32/D32 -> 133711.82 | H32: Good | I32: No provision to be made, as item will be recycle to New Ingot in Year 2025 | J32: Recycle | K32: 0 | L32: 0 | M32: =+L32/E32 -> 0 | O32: 77 | P32: 10295810 | Q32: 77 | R32: 10295810 | S32: =O32-K32-Q32 -> 0 | T32: =P32-L32-R32 -> 0 | U32: Clearing ok
A33: FG | B33: 150565 | C33: PK ZN0023 | D33: 100 | E33: 13167147 | F33: =+E33/D33 -> 131671.47 | H33: Good | I33: BU Discontinued - [1] | J33: Full Provision | K33: =+D33 -> 100 | L33: =+E33 -> 13167147 | M33: =+L33/E33 -> 1 | O33: 100 | P33: 13167147 | Q33: 0 | R33: 0 | S33: =O33-K33-Q33 -> 0 | T33: =P33-L33-R33 -> 0 | U33: Make provision 2024
A34: FG | B34: 120196 | C34: PK ZF IPM Housing A010R190 | D34: 897 | E34: 1.1766951e+08 | F34: =+E34/D34 -> 131181.17 | H34: Good | I34: No provision to be made, as item will be recycle to New Ingot in Year 2025 | J34: Recycle | K34: 0 | L34: 0 | M34: =+L34/E34 -> 0 | O34: 897 | P34: 1.1766951e+08 | Q34: 897 | R34: 1.1766951e+08 | S34: =O34-K34-Q34 -> 0 | T34: =P34-L34-R34 -> 0 | U34: Clearing ok
A35: FG | B35: 100831 | C35: PK Qualcomm MTP Olympic Waipio 55-PV454-11 Sub Assy Front Bottom | D35: 10 | E35: 1310782.8 | F35: =+E35/D35 -> 131078.28 | H35: Good | I35: No provision to be made, as item will be recycle to New Ingot in Year 2025 | J35: Recycle | M35: =+L35/E35 -> 0 | O35: 275 | P35: 36046528 | Q35: 275 | R35: 36046528 | S35: =O35-K35-Q35 -> 0 | T35: =P35-L35-R35 -> 0 | U35: Clearing ok
A36: FG | B36: 101185 | C36: PK Qualcomm MTP PAKALA 55-58184-20 CARRIER FRAME, ASSY | D36: 21 | E36: 2740084.2 | F36: =+E36/D36 -> 130480.2 | H36: Good | I36: No provision to be made, as item will be recycle to New Ingot in Year 2025 | J36: Recycle | K36: 0 | L36: 0 | M36: =+L36/E36 -> 0 | O36: 21 | P36: 2740084.2 | Q36: 0 | R36: 0 | S36: =O36-K36-Q36 -> 21 | T36: =P36-L36-R36 -> 2740084.2 | U36: Will sale again
A37: FG | B37: 120430 | C37: PK LGIT MRA2 Camera Base 3CAC00196A( Casting MC) (2) | D37: 8345 | E37: 1.0720066e+09 | F37: =+E37/D37 -> 128460.94 | H37: Good | I37: No provision to be made, as item will be recycle to New Ingot in Year 2025 | J37: Recycle | K37: 0 | L37: 0 | M37: =+L37/E37 -> 0 | O37: 8345 | P37: 1.0720066e+09 | Q37: 5476 | R37: 7.0345211e+08 | S37: =O37-K37-Q37 -> 2869 | T37: =P37-L37-R37 -> 3.6855444e+08 | U37: Sale again 2025
A38: FG | B38: 120303 | C38: PK LGIT MRA2 Camera Base 3CAC00196A( Casting MC) | D38: 52 | E38: 6506626.2 | F38: =+E38/D38 -> 125127.43 | H38: Good | I38: No provision to be made, as item will be recycle to New Ingot in Year 2025 | J38: Recycle | K38: 0 | L38: 0 | M38: =+L38/E38 -> 0 | O38: 3062 | P38: 3.8314018e+08 | Q38: 3062 | R38: 3.8314018e+08 | S38: =O38-K38-Q38 -> 0 | T38: =P38-L38-R38 -> 0 | U38: Sale again 2025
A39: FG | B39: 150552 | C39: PK ZN0006 | D39: 200 | E39: 24351591 | F39: =+E39/D39 -> 121757.95 | H39: Good | I39: BU Discontinued - [1] | J39: Full Provision | K39: =+D39 -> 200 | L39: =+E39 -> 24351591 | M39: =+L39/E39 -> 1 | O39: 200 | P39: 24351591 | Q39: 0 | R39: 0 | S39: =O39-K39-Q39 -> 0 | T39: =P39-L39-R39 -> 0 | U39: Make provision 2024
A40: FG | B40: 100716 | C40: PK Qualcomm MTP Bittra 55-PM920-10 Front housing | D40: 108 | E40: 13066087 | F40: =+E40/D40 -> 120982.29 | H40: Good | I40: No provision to be made, as item will be recycle to New Ingot in Year 2025 | J40: Recycle | K40: 0 | L40: 0 | M40: =+L40/E40 -> 0 | O40: 849 | P40: 1.0271396e+08 | Q40: 849 | R40: 1.0271396e+08 | S40: =O40-K40-Q40 -> 0 | T40: =P40-L40-R40 -> 0 | U40: Sale again 2025
...
